Workbook

Sheet  SUMMARY 24-25
B2: SUMMARY
C3: SALE | F3: PURCHASE
C4: LOSE | D4: PROFIT | E4: PROFIT & LOSE | F4: LOSE | G4: PROFIT | H4: PROFIT & LOSE | I4: PROFIT & LOSE
B5: 45404 | C5: ='SALE PL'!B55 -> -3147562 | D5: ='SALE PL'!C53 -> 1317621 | E5: =C5+D5 -> -1829941 | F5: ='PUR PL'!B58 -> -3696170 | G5: ='PUR PL'!C58 -> 3559004 | H5: =F5+G5 -> -137166 | I5: =H5+E5 -> -1967107
B6: 45434 | C6: ='SALE PL'!E55 -> -7501200 | D6: ='SALE PL'!F55 -> 3551295 | E6: =C6+D6 -> -3949905 | F6: ='PUR PL'!D58 -> -11838344 | G6: ='PUR PL'!E58 -> 3817407 | H6: =F6+G6 -> -8020937 | I6: =H6+E6 -> -11970842
B7: 45465 | C7: ='SALE PL'!H55 -> -9347555 | D7: ='SALE PL'!I55 -> 5639400 | E7: =C7+D7 -> -3708155 | F7: ='PUR PL'!F58 -> -12192111 | G7: ='PUR PL'!G58 -> 5932995 | H7: =F7+G7 -> -6259116 | I7: =H7+E7 -> -9967271
B8: 45495 | C8: ='SALE PL'!K55 -> -10623096 | D8: ='SALE PL'!L55 -> 5916128 | E8: =C8+D8 -> -4706968 | F8: ='PUR PL'!H58 -> -6305520.2 | G8: ='PUR PL'!I58 -> 3278168.2 | H8: =F8+G8 -> -3027352 | I8: =H8+E8 -> -7734320
B9: 45526 | C9: ='SALE PL'!N55 -> -5465977 | D9: ='SALE PL'!O55 -> 6077385 | E9: =C9+D9 -> 611408 | F9: ='PUR PL'!J58 -> -2671060 | G9: ='PUR PL'!K58 -> 2829638 | H9: =F9+G9 -> 158578 | I9: =H9+E9 -> 769986
B10: 45557 | C10: ='SALE PL'!Q53 -> -5995591 | D10: ='SALE PL'!R53 -> 5370750 | E10: =C10+D10 -> -624841 | F10: ='PUR PL'!L58 -> -4622753.6 | G10: ='PUR PL'!M58 -> 8647744 | H10: =F10+G10 -> 4024990.4 | I10: =H10+E10 -> 3400149.4
B11: 45587 | C11: ='SALE PL'!T53 -> -11173844 | D11: ='SALE PL'!U53 -> 4661083 | E11: =C11+D11 -> -6512761 | F11: ='PUR PL'!N58 -> -5426385 | G11: ='PUR PL'!O58 -> 7864728 | H11: =F11+G11 -> 2438343 | I11: =H11+E11 -> -4074418
B12: 45618 | C12: ='SALE PL'!W53 -> -6253038 | D12: ='SALE PL'!X53 -> 5186072 | E12: =C12+D12 -> -1066966 | F12: ='PUR PL'!P58 -> -3329409 | G12: ='PUR PL'!Q58 -> 7683721 | H12: =F12+G12 -> 4354312 | I12: =H12+E12 -> 3287346
B13: 45648 | C13: -10809163 | D13: 3896784 | E13: =C13+D13 -> -6912379 | F13: ='PUR PL'!R58 -> -3914667 | G13: ='PUR PL'!S58 -> 7732277 | H13: =F13+G13 -> 3817610 | I13: =H13+E13 -> -3094769
B14: 45679 | C14: ='SALE PL'!AC53 -> -10228573 | D14: ='SALE PL'!AD53 -> 3070685 | E14: =C14+D14 -> -7157888 | F14: ='PUR PL'!T58 -> -4731153 | G14: ='PUR PL'!U58 -> 9702473 | H14: =F14+G14 -> 4971320 | I14: =H14+E14 -> -2186568
B15: 45710 | C15: ='SALE PL'!AF53 -> -14343286 | D15: ='SALE PL'!AG53 -> 3676295 | E15: =C15+D15 -> -10666991 | F15: ='PUR PL'!V58 -> -5185880 | G15: ='PUR PL'!W58 -> 6682817 | H15: =F15+G15 -> 1496937 | I15: =H15+E15 -> -9170054
B16: 45738 | C16: ='SALE PL'!AI53 -> -20342203 | D16: ='SALE PL'!AJ53 -> 6610115 | E16: =C16+D16 -> -13732088 | F16: ='PUR PL'!X58 -> -6658226 | G16: ='PUR PL'!Y58 -> 16705406 | H16: =F16+G16 -> 10047180 | I16: =H16+E16 -> -3684908
B17: TOTAL | C17: =sum(C5:C16) -> -115231088 | D17: =sum(D5:D16) -> 54973613 | E17: =C17+D17 -> -60257475 | F17: =sum(F5:F16) -> -70571679 | G17: =sum(G5:G16) -> 84436378 | H17: =F17+G17 -> 13864699 | I17: =H17+E17 -> -46392776
C19: DIFF SALE | D19: =E17 -> -60257475 | F19: DIFF PUR | G19: =H17 -> 13864699
D21: NET BALANCE | E21: =D19+G19 -> -46392776

Sheet  SUMMARY 23-24
B2: SUMMARY
C3: SALE | F3: PURCHASE
C4: LOSE | D4: PROFIT | E4: PROFIT & LOSE | F4: LOSE | G4: PROFIT | H4: PROFIT & LOSE | I4: PROFIT & LOSE
B5: 45038 | C5: -5689153 | D5: 7458522 | E5: 1769369 | F5: -6483958 | G5: 16505960 | H5: 10022002 | I5: 11791371 | K5: 1769369
B6: 45068 | C6: -11776042 | D6: 5839788 | E6: -5936254 | F6: -2483687 | G6: 11498804 | H6: 9015117 | I6: 3078863 | K6: -5936254
B7: 45099 | C7: -12208244 | D7: 6598142 | E7: -5610102 | F7: -1012828.8 | G7: 19046848 | H7: 18034019 | I7: 12423917 | K7: -5610102
B8: 45129 | C8: -12685240 | D8: 5835025 | E8: -6850215 | F8: -1957418 | G8: 15572420 | H8: 13615002 | I8: 6764787 | K8: -6850215
B9: 45160 | C9: -9874051 | D9: 4231064 | E9: -5642987 | F9: -2438040.7 | G9: 36541795 | H9: 34103754 | I9: 28460767 | K9: -5642987
B10: 45191 | C10: -12130677 | D10: 4043430 | E10: -8087247 | F10: -2127090 | G10: 23591367 | H10: 21464277 | I10: 13377030 | K10: -8087247
B11: 45221 | C11: -18019571 | D11: 4134735 | E11: -13884836 | F11: -1964670 | G11: 2171417 | H11: 206747 | I11: -13678089 | K11: -8116751
B12: 45252 | C12: -23323347 | D12: 3243407 | E12: -20079940 | F12: -1428221 | G12: 18282227 | H12: 16854006 | I12: -3225934.2 | K12: 29504
B13: 45282 | C13: -15268893 | D13: 3976756 | E13: -11292137 | F13: -1570772 | G13: 25863085 | H13: 24292313 | I13: 13000176
B14: 45313 | C14: -15243446 | D14: 3809903 | E14: -11433543 | F14: -983635 | G14: 36685929 | H14: 35702294 | I14: 24268751
B15: 45344 | C15: -17066467 | D15: 3862308 | E15: -13204159 | F15: -2648919 | G15: 29229306 | H15: 26580387 | I15: 13376228
B16: 45373 | C16: -31165191 | D16: 6588173 | E16: -24577018 | F16: -3460620 | G16: 27777186 | H16: 24316566 | I16: -260452
B17: TOTAL | C17: -184450322 | D17: 59621253 | E17: -124829069 | F17: -28559860 | G17: 2.6276634e+08 | H17: 2.3420648e+08 | I17: 1.0937741e+08
C19: DIFF SALE | D19: -124829069 | F19: DIFF PUR | G19: 2.3420648e+08
D21: NET BALANCE | E21: 1.0937741e+08

Sheet SUMMARY 22-23
B2: SUMMARY
C3: SALE | F3: PURCHASE
C4: LOSE | D4: PROFIT | E4: PROFIT & LOSE | F4: LOSE | G4: PROFIT | H4: PROFIT & LOSE | I4: PROFIT & LOSE
B5: 44652 | C5: -2288412 | D5: 8912190 | E5: 6623778 | F5: -5870297 | G5: 4551854 | H5: -1318443 | I5: 5305335
B6: 44682 | C6: -2914247 | D6: 8138644 | E6: 5224397 | F6: -6810797 | G6: 3119443 | H6: -3691354 | I6: 1533043
B7: 44713 | C7: -11083576 | D7: 8070391 | E7: -3013185 | F7: -6117285 | G7: 4703325 | H7: -1413960 | I7: -4427145
B8: 44743 | C8: -11609766 | D8: 6545897 | E8: -5063869 | F8: -4816917 | G8: 5539940 | H8: 723023 | I8: -4340846
B9: 44774 | C9: -16282798 | D9: 7224385 | E9: -9058413 | F9: -3625049 | G9: 14079179 | H9: 10454130 | I9: 1395717
B10: 44805 | C10: -45364754 | D10: 6768086 | E10: -38596668 | F10: -3004609 | G10: 14467190 | H10: 11462581 | I10: -27134087
B11: 44835 | C11: -20060008 | D11: 5919053 | E11: -14140955 | F11: -2776341 | G11: 15093366 | H11: 12317025 | I11: -1823930
B12: 44866 | C12: -28538594 | D12: 6357898 | E12: -22180696 | F12: -2577566 | G12: 25119092 | H12: 22541526 | I12: 360830
B13: 44896 | C13: -25094130 | D13: 7176527 | E13: -17917603 | F13: -1929742 | G13: 24166072 | H13: 22236330 | I13: 4318727
B14: 44927 | C14: -45385504 | D14: 5615307 | E14: -39770197 | F14: -2903489 | G14: 26242235 | H14: 23338746 | I14: -16431451
B15: 44958 | C15: -30227857 | D15: 6225085 | E15: -24002772 | F15: -3207476 | G15: 33048583 | H15: 29841107 | I15: 5838335
B16: 44986 | C16: -49530589 | D16: 10189087 | E16: -39341502 | F16: -4120469 | G16: 44987491 | H16: 40867022 | I16: 1525520
B17: TOTAL | C17: =SUM(C4:C16) -> -288380235 | D17: =SUM(D4:D16) -> 87142550 | E17: =SUM(E4:E16) -> -201237685 | F17: =SUM(F4:F16) -> -47760037 | G17: =SUM(G4:G16) -> 215117770 | H17: =SUM(H4:H16) -> 167357733 | I17: =SUM(I4:I16) -> -33879952
C19: DIFF SALE | D19: =E17 -> -201237685 | F19: DIFF PUR | G19: =H17 -> 167357733
D21: NET BALANCE | E21: =D19-G19 -> -368595418

Sheet SUMMARY 21-22
A2: SUMMARY
B3: SALE | E3: PURCHASE
B4: LOSE | C4: PROFIT | D4: PROFIT & LOSE | E4: LOSE | F4: PROFIT | G4: PROFIT & LOSE | H4: PROFIT & LOSE
A5: 45037 | B5: -1518981 | C5: 4883091 | D5: 3364110 | E5: -13545944 | F5: 110104 | G5: -13435840 | H5: -10071730
A6: 45067 | B6: -875527 | C6: 4470885 | D6: 3595358 | E6: -2854887 | F6: 20968 | G6: -2833919 | H6: 761439
A7: 45098 | B7: -3347550 | C7: 8877943 | D7: 5530393 | E7: -3681159 | F7: 167984 | G7: -3513175 | H7: 2017218
A8: 45128 | B8: -3443916 | C8: 8890124 | D8: 5446208 | E8: -20227691 | F8: 320771 | G8: -19906920 | H8: -14460712
A9: 45159 | B9: -3771585 | C9: 9567913 | D9: 5796328 | E9: -23893768 | F9: 642002 | G9: -23251766 | H9: -17455438
A10: 45190 | B10: -5346594 | C10: 12486454 | D10: 7139860 | E10: -38708794 | F10: 633587 | G10: -38075207 | H10: -30935347
A11: 45220 | B11: -2034591 | C11: 16065151 | D11: 14030560 | E11: -32509300 | F11: 236900 | G11: -32272400 | H11: -18241840
A12: 45251 | B12: -1073603 | C12: 23162230 | D12: 22088627 | E12: -12977217 | F12: 64002 | G12: -12913215 | H12: 9175412
A13: 45281 | B13: -2637803 | C13: 28301559 | D13: 25663756 | E13: -27266364 | F13: 174688 | G13: -27091676 | H13: -1427920
A14: 44948 | B14: -2299494 | C14: 23738252 | D14: 21438758 | E14: -29919171 | F14: 2119654 | G14: -27799517 | H14: -6360759
A15: 44979 | B15: -3084251 | C15: 24856393 | D15: 21772142 | E15: -36334114 | F15: 657712 | G15: -35676402 | H15: -13904260
A16: 45007 | B16: -4418624 | C16: 39419847 | D16: 35001223 | E16: -35522920 | F16: 886169 | G16: -34636751 | H16: 364472
A17: TOTAL | B17: -33852519 | C17: 204719842 | D17: 170867323 | E17: -277441329 | F17: 6034541 | G17: -271406788 | H17: -100539465
B19: DIFF SALE | C19: 170867323 | E19: DIFF PUR | F19: -271406788
C21: NET BALANCE | E21: -100539465

Sheet SALE PL
A1: Profit & loss (SALE)
A3: MONTH | B3: 45406 | E3: 44705 | H3: 44736 | K3: 44766 | N3: 44797 | Q3: 44828 | T3: 44858 | W3: 44889 | Z3: 44919 | AC3: 44951 | AF3: 44982 | AI3: 45010
A4: SENGMENT | B4: LOSE | C4: PROFIT | D4: Diffrance | E4: LOSE | F4: PROFIT | G4: Diffrance | H4: LOSE | I4: PROFIT | J4: Diffrance | K4: LOSE | L4: PROFIT | M4: Diffrance | N4: LOSE | O4: PROFIT | P4: Diffrance | Q4: LOSE | R4: PROFIT | S4: Diffrance | T4: LOSE | U4: PROFIT | V4: Diffrance | W4: LOSE | X4: PROFIT | Y4: Diffrance | Z4: LOSE | AA4: PROFIT | AB4: Diffrance | AC4: LOSE | AD4: PROFIT | AE4: Diffrance | AF4: LOSE | AG4: PROFIT | AH4: Diffrance | AI4: LOSE | AJ4: PROFIT | AK4: Diffrance
A5: PTMT | B5: -380516 | C5: 215880 | D5: =B5+C5 -> -164636 | E5: -849715 | F5: 222947 | G5: =E5+F5 -> -626768 | H5: -878453 | I5: 308326 | J5: =H5+I5 -> -570127 | K5: -749916 | L5: 859450 | M5: =K5+L5 -> 109534 | N5: -951921 | O5: 1339610 | P5: =N5+O5 -> 387689 | Q5: -703493 | R5: 1209477 | S5: =Q5+R5 -> 505984 | T5: -457831 | U5: 1190748 | V5: =T5+U5 -> 732917 | W5: -544621 | X5: 1204971 | Y5: =W5+X5 -> 660350 | Z5: -835481 | AA5: 1370095 | AB5: =Z5+AA5 -> 534614 | AC5: -630007 | AD5: 1144507 | AE5: =AC5+AD5 -> 514500 | AF5: -770904 | AG5: 1203851 | AH5: =AF5+AG5 -> 432947 | AI5: -1465733 | AJ5: 2063338 | AK5: =AI5+AJ5 -> 597605 | AL5: =D5+G5+J5+M5+P5+S5+V5+Y5+AB5+AE5+AH5+AK5 -> 3114609
A6: CISTERN | B6: 0 | C6: 458313 | D6: =B6+C6 -> 458313 | E6: 0 | F6: 1153958 | G6: =E6+F6 -> 1153958 | H6: -1345 | I6: 1135281 | J6: =H6+I6 -> 1133936 | K6: -160 | L6: 768179 | M6: =K6+L6 -> 768019 | N6: 0 | O6: 725666 | P6: =N6+O6 -> 725666 | Q6: 0 | R6: 600834 | S6: =Q6+R6 -> 600834 | T6: 0 | U6: 575848 | V6: =T6+U6 -> 575848 | W6: -4032 | X6: 535554 | Y6: =W6+X6 -> 531522 | Z6: -57 | AA6: 483050 | AB6: =Z6+AA6 -> 482993 | AC6: -5574 | AD6: 437332 | AE6: =AC6+AD6 -> 431758 | AF6: -7125 | AG6: 508539 | AH6: =AF6+AG6 -> 501414 | AI6: -10865 | AJ6: 647841 | AK6: =AI6+AJ6 -> 636976 | AL6: =D6+G6+J6+M6+P6+S6+V6+Y6+AB6+AE6+AH6+AK6 -> 8001237
A7: CABINET | B7: -1009 | C7: 9955 | D7: =B7+C7 -> 8946 | E7: -2323 | F7: 18480 | G7: =E7+F7 -> 16157 | H7: -14680 | I7: 5676 | J7: =H7+I7 -> -9004 | K7: -138 | L7: 64998 | M7: =K7+L7 -> 64860 | N7: 0 | O7: 66361 | P7: =N7+O7 -> 66361 | Q7: 0 | R7: 83793 | S7: =Q7+R7 -> 83793 | T7: 0 | U7: 60528 | V7: =T7+U7 -> 60528 | W7: -689 | X7: 34691 | Y7: =W7+X7 -> 34002 | Z7: 0 | AA7: 89961 | AB7: =Z7+AA7 -> 89961 | AC7: -4837 | AD7: 68904 | AE7: =AC7+AD7 -> 64067 | AF7: -1225 | AG7: 83413 | AH7: =AF7+AG7 -> 82188 | AI7: -3084 | AJ7: 64126 | AK7: =AI7+AJ7 -> 61042 | AL7: =D7+G7+J7+M7+P7+S7+V7+Y7+AB7+AE7+AH7+AK7 -> 622901
A8: SEAT COVER | B8: -217 | C8: 158352 | D8: =B8+C8 -> 158135 | E8: -6274 | F8: 183791 | G8: =E8+F8 -> 177517 | H8: -4922 | I8: 281061 | J8: =H8+I8 -> 276139 | K8: -6836 | L8: 192831 | M8: =K8+L8 -> 185995 | N8: -1665 | O8: 153975 | P8: =N8+O8 -> 152310 | Q8: -4958 | R8: 78658 | S8: =Q8+R8 -> 73700 | T8: -2618 | U8: 96297 | V8: =T8+U8 -> 93679 | W8: -5091 | X8: 115180 | Y8: =W8+X8 -> 110089 | Z8: 0 | AA8: 96186 | AB8: =Z8+AA8 -> 96186 | AC8: -3270 | AD8: 110742 | AE8: =AC8+AD8 -> 107472 | AF8: -2265 | AG8: 98349 | AH8: =AF8+AG8 -> 96084 | AI8: -3659 | AJ8: 161331 | AK8: =AI8+AJ8 -> 157672 | AL8: =D8+G8+J8+M8+P8+S8+V8+Y8+AB8+AE8+AH8+AK8 -> 1684978
A9: QUAA | B9: -50 | C9: 3540 | D9: =B9+C9 -> 3490 | E9: -3997 | F9: 4608 | G9: =E9+F9 -> 611 | H9: 0 | I9: 0 | J9: =H9+I9 -> 0 | K9: -4252 | L9: 15675 | M9: =K9+L9 -> 11423 | N9: -775 | O9: 1695 | P9: =N9+O9 -> 920 | Q9: -965 | R9: 9036 | S9: =Q9+R9 -> 8071 | T9: 0 | U9: 58 | V9: =T9+U9 -> 58 | W9: -679 | X9: 1363 | Y9: =W9+X9 -> 684 | Z9: -1527 | AA9: 14610 | AB9: =Z9+AA9 -> 13083 | AC9: -180 | AD9: 0 | AE9: =AC9+AD9 -> -180 | AF9: -20 | AG9: 532 | AH9: =AF9+AG9 -> 512 | AI9: -171 | AJ9: 0 | AK9: =AI9+AJ9 -> -171 | AL9: =D9+G9+J9+M9+P9+S9+V9+Y9+AB9+AE9+AH9+AK9 -> 38501
A11: TOTAL | B11: =SUM(B5:B9) -> -381792 | C11: =SUM(C5:C9) -> 846040 | D11: =B11+C11 -> 464248 | E11: =SUM(E5:E9) -> -862309 | F11: =SUM(F5:F9) -> 1583784 | G11: =E11+F11 -> 721475 | H11: =SUM(H5:H9) -> -899400 | I11: =SUM(I5:I9) -> 1730344 | J11: =H11+I11 -> 830944 | K11: =SUM(K5:K9) -> -761302 | L11: =SUM(L5:L9) -> 1901133 | M11: =K11+L11 -> 1139831 | N11: =SUM(N5:N9) -> -954361 | O11: =SUM(O5:O9) -> 2287307 | P11: =N11+O11 -> 1332946 | Q11: =SUM(Q5:Q9) -> -709416 | R11: =SUM(R5:R9) -> 1981798 | S11: =Q11+R11 -> 1272382 | T11: =SUM(T5:T9) -> -460449 | U11: =SUM(U5:U9) -> 1923479 | V11: =T11+U11 -> 1463030 | W11: =SUM(W5:W9) -> -555112 | X11: =SUM(X5:X9) -> 1891759 | Y11: =W11+X11 -> 1336647 | Z11: =SUM(Z5:Z9) -> -837065 | AA11: =SUM(AA5:AA9) -> 2053902 | AB11: =Z11+AA11 -> 1216837 | AC11: =SUM(AC5:AC9) -> -643868 | AD11: =SUM(AD5:AD9) -> 1761485 | AE11: =AC11+AD11 -> 1117617 | AF11: =SUM(AF5:AF9) -> -781539 | AG11: =SUM(AG5:AG9) -> 1894684 | AH11: =AF11+AG11 -> 1113145 | AI11: =SUM(AI5:AI9) -> -1483512 | AJ11: =SUM(AJ5:AJ9) -> 2936636 | AK11: =AI11+AJ11 -> 1453124 | AL11: =SUM(AL5:AL9) -> 13462226
A13: CP | B13: -764139 | C13: 144046 | D13: =B13+C13 -> -620093 | E13: -1050448 | F13: 362883 | G13: =E13+F13 -> -687565 | H13: -500973 | I13: 1637248 | J13: =H13+I13 -> 1136275 | K13: -345919 | L13: 1542411 | M13: =K13+L13 -> 1196492 | N13: -572487 | O13: 1695322 | P13: =N13+O13 -> 1122835 | Q13: -658544 | R13: 1738960 | S13: =Q13+R13 -> 1080416 | T13: -264737 | U13: 1419880 | V13: =T13+U13 -> 1155143 | W13: -469166 | X13: 1741604 | Y13: =W13+X13 -> 1272438 | Z13: -1363445 | AA13: 857935 | AB13: =Z13+AA13 -> -505510 | AC13: -1713745 | AD13: 637629 | AE13: =AC13+AD13 -> -1076116 | AF13: -2529010 | AG13: 654262 | AH13: =AF13+AG13 -> -1874748 | AI13: -3144160 | AJ13: 1467454 | AK13: =AI13+AJ13 -> -1676706 | AL13: =D13+G13+J13+M13+P13+S13+V13+Y13+AB13+AE13+AH13+AK13 -> 522861
A14: CP ACCESSORIES | B14: -217301 | C14: 65036 | D14: =B14+C14 -> -152265 | E14: -516237 | F14: 144494 | G14: =E14+F14 -> -371743 | H14: -184215 | I14: 404081 | J14: =H14+I14 -> 219866 | K14: -97439 | L14: 351775 | M14: =K14+L14 -> 254336 | N14: -93905 | O14: 391455 | P14: =N14+O14 -> 297550 | Q14: -157301 | R14: 294019 | S14: =Q14+R14 -> 136718 | T14: -53741 | U14: 266054 | V14: =T14+U14 -> 212313 | W14: -104133 | X14: 419985 | Y14: =W14+X14 -> 315852 | Z14: -167338 | AA14: 298891 | AB14: =Z14+AA14 -> 131553 | AC14: -263910 | AD14: 294109 | AE14: =AC14+AD14 -> 30199 | AF14: -235152 | AG14: 321054 | AH14: =AF14+AG14 -> 85902 | AI14: -370850 | AJ14: 893398 | AK14: =AI14+AJ14 -> 522548 | AL14: =D14+G14+J14+M14+P14+S14+V14+Y14+AB14+AE14+AH14+AK14 -> 1682829
A15: TEFLON TAPE | B15: -11074 | C15: 12940 | D15: =B15+C15 -> 1866 | E15: -95116 | F15: 611 | G15: =E15+F15 -> -94505 | H15: -106946 | I15: 4797 | J15: =H15+I15 -> -102149 | K15: -128899 | L15: 0 | M15: =K15+L15 -> -128899 | N15: -145018 | O15: 340 | P15: =N15+O15 -> -144678 | Q15: -98783 | R15: 0 | S15: =Q15+R15 -> -98783 | T15: -8251 | U15: -68753 | V15: 8207 | W15: -59804 | X15: 510 | Y15: =W15+X15 -> -59294 | Z15: -173009 | AA15: 0 | AB15: =Z15+AA15 -> -173009 | AC15: -93801 | AD15: 2100 | AE15: =AC15+AD15 -> -91701 | AF15: -194072 | AG15: 510 | AH15: =AF15+AG15 -> -193562 | AI15: -204886 | AJ15: 0 | AK15: 0 | AL15: =D15+G15+J15+M15+P15+S15+V15+Y15+AB15+AE15+AH15+AK15 -> -1076507
A16: GEYSER | B16: -22126 | C16: 0 | D16: =B16+C16 -> -22126 | E16: 0 | F16: 0 | G16: =E16+F16 -> 0 | H16: 0 | I16: 0 | J16: =H16+I16 -> 0 | K16: 0 | L16: 0 | M16: =K16+L16 -> 0 | N16: 0 | O16: 0 | P16: 0 | Q16: -7814 | R16: 1424 | S16: =Q16+R16 -> -6390 | T16: 0 | U16: 30107 | V16: =T16+U16 -> 30107 | W16: -47898 | X16: 1918 | Y16: =W16+X16 -> -45980 | Z16: -151350 | AA16: 6345 | AB16: =Z16+AA16 -> -145005 | AC16: -11315 | AD16: 2866 | AE16: =AC16+AD16 -> -8449 | AF16: 0 | AG16: 0 | AH16: =AF16+AG16 -> 0 | AI16: 0 | AJ16: 1977 | AK16: 0 | AL16: =D16+G16+J16+M16+P16+S16+V16+Y16+AB16+AE16+AH16+AK16 -> -197843
A17: GLASS | E17: 0 | F17: 0 | H17: -578 | I17: 0 | J17: =H17+I17 -> -578 | K17: 0 | L17: 0 | M17: =K17+L17 -> 0 | N17: 0 | O17: 0 | P17: 0 | AL17: =D17+G17+J17+M17+P17+S17+V17+Y17+AB17+AE17+AH17+AK17 -> -578
A18: TOTAL | B18: =SUM(B13:B17) -> -1014640 | C18: =SUM(C13:C17) -> 222022 | D18: =B18+C18 -> -792618 | E18: =SUM(E13:E17) -> -1661801 | F18: =SUM(F13:F17) -> 507988 | G18: =E18+F18 -> -1153813 | H18: =SUM(H13:H17) -> -792712 | I18: =SUM(I13:I17) -> 2046126 | J18: =H18+I18 -> 1253414 | K18: =SUM(K13:K17) -> -572257 | L18: =SUM(L13:L17) -> 1894186 | M18: =K18+L18 -> 1321929 | N18: =SUM(N13:N17) -> -811410 | O18: =SUM(O13:O17) -> 2087117 | P18: =N18+O18 -> 1275707 | Q18: =SUM(Q13:Q17) -> -922442 | R18: =SUM(R13:R17) -> 2034403 | S18: =Q18+R18 -> 1111961 | T18: =SUM(T13:T17) -> -326729 | U18: =SUM(U13:U17) -> 1647288 | V18: =T18+U18 -> 1320559 | W18: =SUM(W13:W17) -> -681001 | X18: =SUM(X13:X17) -> 2164017 | Y18: =W18+X18 -> 1483016 | Z18: =SUM(Z13:Z17) -> -1855142 | AA18: =SUM(AA13:AA17) -> 1163171 | AB18: =Z18+AA18 -> -691971 | AC18: =SUM(AC13:AC17) -> -2082771 | AD18: =SUM(AD13:AD17) -> 936704 | AE18: =AC18+AD18 -> -1146067 | AF18: =SUM(AF13:AF17) -> -2958234 | AG18: =SUM(AG13:AG17) -> 975826 | AH18: =AF18+AG18 -> -1982408 | AI18: =SUM(AI13:AI17) -> -3719896 | AJ18: =SUM(AJ13:AJ17) -> 2362829 | AK18: =AI18+AJ18 -> -1357067 | AL18: =SUM(AL13:AL17) -> 930762
A20: SINK | B20: -90310 | C20: 15463 | D20: =B20+C20 -> -74847 | E20: -166402 | F20: 30664 | G20: =E20+F20 -> -135738 | H20: -94084 | I20: 36007 | J20: =H20+I20 -> -58077 | K20: -34941 | L20: 181911 | M20: =K20+L20 -> 146970 | N20: -17777 | O20: 171336 | P20: =N20+O20 -> 153559 | Q20: -38452 | R20: 140886 | S20: =Q20+R20 -> 102434 | T20: -28070 | U20: 111166 | V20: =T20+U20 -> 83096 | W20: -18505 | X20: 152526 | Y20: =W20+X20 -> 134021 | Z20: -1144541 | AA20: 40262 | AB20: =Z20+AA20 -> -1104279 | AC20: -1060070 | AD20: 6803 | AE20: =AC20+AD20 -> -1053267 | AF20: -1040183 | AG20: 57158 | AH20: =AF20+AG20 -> -983025 | AI20: -1362026 | AJ20: 83132 | AK20: =AI20+AJ20 -> -1278894 | AL20: =D20+G20+J20+M20+P20+S20+V20+Y20+AB20+AE20+AH20+AK20 -> -4068047
A21: JALI | B21: -1301 | C21: 1677 | D21: =B21+C21 -> 376 | E21: -32631 | F21: 1953 | G21: =E21+F21 -> -30678 | H21: -7814 | I21: 1977 | J21: =H21+I21 -> -5837 | K21: -5362 | L21: 13300 | M21: =K21+L21 -> 7938 | N21: -7664 | O21: 41108 | P21: =N21+O21 -> 33444 | Q21: -28301 | R21: 20685 | S21: =Q21+R21 -> -7616 | T21: -16960 | U21: 10843 | V21: =T21+U21 -> -6117 | W21: -10517 | X21: 25723 | Y21: =W21+X21 -> 15206 | Z21: -91862 | AA21: 0 | AB21: =Z21+AA21 -> -91862 | AC21: -82261 | AD21: 0 | AE21: =AC21+AD21 -> -82261 | AF21: -120896 | AG21: 0 | AH21: =AF21+AG21 -> -120896 | AI21: -109468 | AJ21: 0 | AK21: =AI21+AJ21 -> -109468 | AL21: =D21+G21+J21+M21+P21+S21+V21+Y21+AB21+AE21+AH21+AK21 -> -397771
A22: P-RACK | B22: -5726 | C22: 6759 | D22: =B22+C22 -> 1033 | E22: -849 | F22: 5319 | G22: =E22+F22 -> 4470 | H22: -3855 | I22: 13834 | J22: =H22+I22 -> 9979 | K22: -2434 | L22: 28374 | M22: =K22+L22 -> 25940 | N22: -13010 | O22: 27155 | P22: =N22+O22 -> 14145 | Q22: -17559 | R22: 34318 | S22: =Q22+R22 -> 16759 | T22: -3383 | U22: 18008 | V22: =T22+U22 -> 14625 | W22: -24645 | X22: 18760 | Y22: =W22+X22 -> -5885 | Z22: -192932 | AA22: 484 | AB22: =Z22+AA22 -> -192448 | AC22: -15627 | AD22: 0 | AE22: =AC22+AD22 -> -15627 | AF22: -71048 | AG22: 0 | AH22: =AF22+AG22 -> -71048 | AI22: -243104 | AJ22: 0 | AK22: =AI22+AJ22 -> -243104 | AL22: =D22+G22+J22+M22+P22+S22+V22+Y22+AB22+AE22+AH22+AK22 -> -441161
A24: TOTAL | B24: =SUM(B20:B23) -> -97337 | C24: =SUM(C20:C23) -> 23899 | D24: =B24+C24 -> -73438 | E24: =SUM(E20:E23) -> -199882 | F24: =SUM(F20:F23) -> 37936 | G24: =E24+F24 -> -161946 | H24: =SUM(H20:H23) -> -105753 | I24: =SUM(I20:I23) -> 51818 | J24: =H24+I24 -> -53935 | K24: =SUM(K20:K23) -> -42737 | L24: =SUM(L20:L23) -> 223585 | M24: =K24+L24 -> 180848 | N24: =SUM(N20:N23) -> -38451 | O24: =SUM(O20:O23) -> 239599 | P24: =N24+O24 -> 201148 | Q24: =SUM(Q20:Q23) -> -84312 | R24: =SUM(R20:R23) -> 195889 | S24: =Q24+R24 -> 111577 | T24: =SUM(T20:T23) -> -48413 | U24: =SUM(U20:U23) -> 140017 | V24: =T24+U24 -> 91604 | W24: =SUM(W20:W23) -> -53667 | X24: =SUM(X20:X23) -> 197009 | Y24: =W24+X24 -> 143342 | Z24: =SUM(Z20:Z23) -> -1429335 | AA24: =SUM(AA20:AA23) -> 40746 | AB24: =Z24+AA24 -> -1388589 | AC24: =SUM(AC20:AC23) -> -1157958 | AD24: =SUM(AD20:AD23) -> 6803 | AE24: =AC24+AD24 -> -1151155 | AF24: =SUM(AF20:AF23) -> -1232127 | AG24: =SUM(AG20:AG23) -> 57158 | AH24: =AF24+AG24 -> -1174969 | AI24: =SUM(AI20:AI23) -> -1714598 | AJ24: =SUM(AJ20:AJ23) -> 83132 | AK24: =AI24+AJ24 -> -1631466 | AL24: =SUM(AL20:AL22) -> -4906979
A26: CPVC | B26: -228270 | C26: 0 | D26: =B26+C26 -> -228270 | E26: -749515 | F26: 215868 | G26: =E26+F26 -> -533647 | H26: -304080 | I26: 230750 | J26: =H26+I26 -> -73330 | K26: -535188 | L26: 302368 | M26: =K26+L26 -> -232820 | N26: -809286 | O26: 343515 | P26: =N26+O26 -> -465771 | Q26: -443488 | R26: 209777 | S26: =Q26+R26 -> -233711 | T26: -562557 | U26: 151227 | V26: =T26+U26 -> -411330 | W26: -729778 | X26: 123380 | Y26: =W26+X26 -> -606398 | Z26: -725634 | AA26: 164000 | AB26: =Z26+AA26 -> -561634 | AC26: -790679 | AD26: 189434 | AE26: =AC26+AD26 -> -601245 | AF26: -846962 | AG26: 123279 | AH26: =AF26+AG26 -> -723683 | AI26: -1789957 | AJ26: 228694 | AK26: =AI26+AJ26 -> -1561263 | AL26: =D26+G26+J26+M26+P26+S26+V26+Y26+AB26+AE26+AH26+AK26 -> -6233102
A27: CPVC PIPE | B27: -243699 | C27: 2242 | D27: =B27+C27 -> -241457 | E27: -893678 | F27: 373 | G27: =E27+F27 -> -893305 | H27: -200578 | I27: 1359 | J27: =H27+I27 -> -199219 | K27: -614632 | L27: 1145 | M27: =K27+L27 -> -613487 | N27: -781792 | O27: 0 | P27: =N27+O27 -> -781792 | Q27: -481049 | R27: 5141 | S27: =Q27+R27 -> -475908 | T27: -656082 | U27: 123 | V27: =T27+U27 -> -655959 | W27: -808953 | X27: 0 | Y27: =W27+X27 -> -808953 | Z27: -961367 | AA27: 0 | AB27: =Z27+AA27 -> -961367 | AC27: -821050 | AD27: 19461 | AE27: =AC27+AD27 -> -801589 | AF27: -993218 | AG27: 6575 | AH27: =AF27+AG27 -> -986643 | AI27: -1854618 | AJ27: 0 | AK27: =AI27+AJ27 -> -1854618 | AL27: =D27+G27+J27+M27+P27+S27+V27+Y27+AB27+AE27+AH27+AK27 -> -9274297
A28: UPVC | B28: -194357 | C28: 5649 | D28: =B28+C28 -> -188708 | E28: -469755 | F28: 428227 | G28: =E28+F28 -> -41528 | H28: -336032 | I28: 410772 | J28: =H28+I28 -> 74740 | K28: -277067 | L28: 306697 | M28: =K28+L28 -> 29630 | N28: -386234 | O28: 204511 | P28: =N28+O28 -> -181723 | Q28: -583755 | R28: 166902 | S28: =Q28+R28 -> -416853 | T28: -299889 | U28: 75090 | V28: =T28+U28 -> -224799 | W28: -501440 | X28: 153535 | Y28: =W28+X28 -> -347905 | Z28: -729204 | AA28: 111142 | AB28: =Z28+AA28 -> -618062 | AC28: -961294 | AD28: 95510 | AE28: =AC28+AD28 -> -865784 | AF28: -1210230 | AG28: 130500 | AH28: =AF28+AG28 -> -1079730 | AI28: -1802727 | AJ28: 263407 | AK28: =AI28+AJ28 -> -1539320 | AL28: =D28+G28+J28+M28+P28+S28+V28+Y28+AB28+AE28+AH28+AK28 -> -5400042
A29: UPVC PIPE | B29: -190267 | C29: 21872 | D29: =B29+C29 -> -168395 | E29: -367411 | F29: 84794 | G29: =E29+F29 -> -282617 | H29: -16268 | I29: 169968 | J29: =H29+I29 -> 153700 | K29: -72098 | L29: 33538 | M29: =K29+L29 -> -38560 | N29: -480945 | O29: 10295 | P29: =N29+O29 -> -470650 | Q29: -774462 | R29: 3639 | S29: =Q29+R29 -> -770823 | T29: -661109 | U29: 4938 | V29: =T29+U29 -> -656171 | W29: -684630 | X29: 8989 | Y29: =W29+X29 -> -675641 | Z29: -904903 | AA29: 17260 | AB29: =Z29+AA29 -> -887643 | AC29: -951787 | AD29: 432 | AE29: =AC29+AD29 -> -951355 | AF29: -1971395 | AG29: 3475 | AH29: =AF29+AG29 -> -1967920 | AI29: -1837693 | AJ29: 14517 | AK29: =AI29+AJ29 -> -1823176 | AL29: =D29+G29+J29+M29+P29+S29+V29+Y29+AB29+AE29+AH29+AK29 -> -8539251
A30: SWR | B30: -359208 | C30: 65027 | D30: =B30+C30 -> -294181 | E30: =-14560-147589 -> -162149 | F30: =295386+33226 -> 328612 | G30: =E30+F30 -> 166463 | H30: =-49436-745 -> -50181 | I30: =98842+481027 -> 579869 | J30: =H30+I30 -> 529688 | K30: =-4481-180748 -> -185229 | L30: =312013+37806 -> 349819 | M30: =K30+L30 -> 164590 | N30: =-307750-296130 -> -603880 | O30: =50758+11245 -> 62003 | P30: =N30+O30 -> -541877 | Q30: =-634416-614936 -> -1249352 | R30: =24732+87973 -> 112705 | S30: =Q30+R30 -> -1136647 | T30: =-467874-629875 -> -1097749 | U30: =13804+20509 -> 34313 | V30: =T30+U30 -> -1063436 | W30: =-470268-533435 -> -1003703 | X30: =17506+37598 -> 55104 | Y30: =W30+X30 -> -948599 | Z30: =-1118601-617296 -> -1735897 | AA30: =6850+36073 -> 42923 | AB30: =Z30+AA30 -> -1692974 | AC30: =-800200-690528 -> -1490728 | AD30: =21476+13359 -> 34835 | AE30: =AC30+AD30 -> -1455893 | AF30: =-1396718-1188617 -> -2585335 | AG30: =20141+15468 -> 35609 | AH30: =AF30+AG30 -> -2549726 | AI30: =-1687966-1261236 -> -2949202 | AJ30: =49471+11744 -> 61215 | AK30: =AI30+AJ30 -> -2887987 | AL30: =D30+G30+J30+M30+P30+S30+V30+Y30+AB30+AE30+AH30+AK30 -> -11710579
A31: AGRI | B31: -61456 | C31: 21124 | D31: =B31+C31 -> -40332 | E31: =-16122-63162 -> -79284 | F31: =19045+41776 -> 60821 | G31: =E31+F31 -> -18463 | H31: -44389 | I31: 125415 | J31: =H31+I31 -> 81026 | K31: -73654 | L31: 95422 | M31: =K31+L31 -> 21768 | N31: -115282 | O31: 19166 | P31: =N31+O31 -> -96116 | Q31: =-141392-48937 -> -190329 | R31: =2429+2976 -> 5405 | S31: =Q31+R31 -> -184924 | T31: -170765 | U31: 11036 | V31: =T31+U31 -> -159729 | W31: -158476 | X31: 5324 | Y31: =W31+X31 -> -153152 | Z31: -323804 | AA31: 1451 | AB31: =Z31+AA31 -> -322353 | AC31: -379220 | AD31: 15224 | AE31: =AC31+AD31 -> -363996 | AF31: -569567 | AG31: 2138 | AH31: =AF31+AG31 -> -567429 | AI31: -554204 | AJ31: 744 | AK31: =AI31+AJ31 -> -553460 | AL31: =D31+G31+J31+M31+P31+S31+V31+Y31+AB31+AE31+AH31+AK31 -> -2357160
A32: WATER TANK | B32: -244544 | C32: =8316+832 -> 9148 | D32: =B32+C32 -> -235396 | E32: -478076 | F32: 4630 | G32: =E32+F32 -> -473446 | H32: =-444183-1282 -> -445465 | I32: 11480 | J32: =H32+I32 -> -433985 | K32: -266886 | L32: =257654+3864 -> 261518 | M32: =K32+L32 -> -5368 | N32: -87926 | O32: 89331 | P32: =N32+O32 -> 1405 | Q32: -99287 | R32: =222853+2336 -> 225189 | S32: =Q32+R32 -> 125902 | T32: =-344875-5 -> -344880 | U32: =39850+1134 -> 40984 | V32: =T32+U32 -> -303896 | W32: =-59-395591 -> -395650 | X32: =106355+185 -> 106540 | Y32: =W32+X32 -> -289110 | Z32: -342733 | AA32: 152296 | AB32: =Z32+AA32 -> -190437 | AC32: -252704 | AD32: =358078+7796 -> 365874 | AE32: =AC32+AD32 -> 113170 | AF32: -356633 | AG32: =73822+5379 -> 79201 | AH32: =AF32+AG32 -> -277432 | AI32: -529140 | AJ32: =263867+347 -> 264214 | AK32: =AI32+AJ32 -> -264926 | AL32: =D32+G32+J32+M32+P32+S32+V32+Y32+AB32+AE32+AH32+AK32 -> -2233519
A33: HDPE PIPE | D33: =B33+C33 -> 0 | E33: -1207692 | F33: 0 | G33: =E33+F33 -> -1207692 | H33: -5734708 | I33: 0 | J33: =H33+I33 -> -5734708 | K33: -6974092 | L33: 0 | M33: =K33+L33 -> -6974092 | N33: 0 | O33: 354522 | P33: =N33+O33 -> 354522 | Q33: 0 | R33: 250509 | S33: =Q33+R33 -> 250509 | T33: -6249939 | U33: 223548 | V33: =T33+U33 -> -6026391 | W33: 0 | X33: 0 | Y33: =W33+X33 -> 0 | Z33: 0 | AA33: 0 | AB33: =Z33+AA33 -> 0 | AC33: 0 | AD33: -83749 | AE33: =AC33+AD33 -> -83749 | AF33: 0 | AG33: 0 | AH33: =AF33+AG33 -> 0 | AI33: 0 | AJ33: 0 | AK33: =AI33+AJ33 -> 0 | AL33: =D33+G33+J33+M33+P33+S33+V33+Y33+AB33+AE33+AH33+AK33 -> -19421601
A34: GARDEN PIPE | B34: -45082 | C34: 0 | D34: =B34+C34 -> -45082 | E34: -167768 | F34: 1077 | G34: =E34+F34 -> -166691 | H34: -55758 | I34: 140666 | J34: =H34+I34 -> 84908 | K34: -15779 | L34: 33339 | M34: =K34+L34 -> 17560 | N34: -62693 | O34: 578 | P34: =N34+O34 -> -62115 | Q34: -149708 | R34: 91 | S34: =Q34+R34 -> -149617 | T34: -126518 | U34: 0 | V34: =T34+U34 -> -126518 | W34: -250717 | X34: 964 | Y34: =W34+X34 -> -249753 | Z34: -337399 | AA34: 0 | AB34: =Z34+AA34 -> -337399 | AC34: 0 | AD34: -542654 | AE34: =AC34+AD34 -> -542654 | AF34: -525644 | AG34: 41 | AH34: =AF34+AG34 -> -525603 | AI34: -687695 | AJ34: 0 | AK34: =AI34+AJ34 -> -687695 | AL34: =D34+G34+J34+M34+P34+S34+V34+Y34+AB34+AE34+AH34+AK34 -> -2790659
A35: TOTAL | B35: =SUM(B26:B34) -> -1566883 | C35: =SUM(C26:C34) -> 125062 | D35: =B35+C35 -> -1441821 | E35: =SUM(E26:E34) -> -4575328 | F35: =SUM(F26:F34) -> 1124402 | G35: =E35+F35 -> -3450926 | H35: =SUM(H26:H34) -> -7187459 | I35: =SUM(I26:I34) -> 1670279 | J35: =H35+I35 -> -5517180 | K35: =SUM(K26:K34) -> -9014625 | L35: =SUM(L26:L34) -> 1383846 | M35: =K35+L35 -> -7630779 | N35: =SUM(N26:N34) -> -3328038 | O35: =SUM(O26:O34) -> 1083921 | P35: =N35+O35 -> -2244117 | Q35: =SUM(Q26:Q34) -> -3971430 | R35: =SUM(R26:R34) -> 979358 | S35: =Q35+R35 -> -2992072 | T35: =SUM(T26:T34) -> -10169488 | U35: =SUM(U26:U34) -> 541259 | V35: =T35+U35 -> -9628229 | W35: =SUM(W26:W34) -> -4533347 | X35: =SUM(X26:X34) -> 453836 | Y35: =W35+X35 -> -4079511 | Z35: =SUM(Z26:Z34) -> -6060941 | AA35: =SUM(AA26:AA34) -> 489072 | AB35: =Z35+AA35 -> -5571869 | AC35: =SUM(AC26:AC34) -> -5647462 | AD35: =SUM(AD26:AD34) -> 94367 | AE35: =AC35+AD35 -> -5553095 | AF35: =SUM(AF26:AF34) -> -9058984 | AG35: =SUM(AG26:AG34) -> 380818 | AH35: =AF35+AG35 -> -8678166 | AI35: =SUM(AI26:AI34) -> -12005236 | AJ35: =SUM(AJ26:AJ34) -> 832791 | AK35: =AI35+AJ35 -> -11172445 | AL35: =SUM(AL26:AL34) -> -67960210
A38: HARDWARE | B38: -698 | C38: 27992 | D38: =B38+C38 -> 27294 | E38: -14354 | F38: 122253 | G38: =E38+F38 -> 107899 | H38: -21110 | I38: 58944 | J38: =H38+I38 -> 37834 | K38: -2796 | L38: 37115 | M38: =K38+L38 -> 34319 | N38: -61803 | O38: 25620 | P38: =N38+O38 -> -36183 | Q38: -8070 | R38: 23736 | S38: =Q38+R38 -> 15666 | T38: -2658 | U38: 10263 | V38: =T38+U38 -> 7605 | W38: -89750 | X38: 18658 | Y38: =W38+X38 -> -71092 | Z38: -25514 | AA38: 18953 | AB38: =Z38+AA38 -> -6561 | AC38: -90935 | AD38: 3243 | AE38: =AC38+AD38 -> -87692 | AF38: -20327 | AG38: 9166 | AH38: =AF38+AG38 -> -11161 | AI38: -240848 | AJ38: 45674 | AK38: =AI38+AJ38 -> -195174 | AL38: =D38+G38+J38+M38+P38+S38+V38+Y38+AB38+AE38+AH38+AK38 -> -177246
A43: TOTAL | B43: =SUM(B38:B42) -> -698 | C43: =SUM(C38:C42) -> 27992 | D43: =B43+C43 -> 27294 | E43: =SUM(E38:E42) -> -14354 | F43: =SUM(F38:F42) -> 122253 | G43: =E43+F43 -> 107899 | H43: =SUM(H38:H42) -> -21110 | I43: =SUM(I38:I42) -> 58944 | J43: =H43+I43 -> 37834 | K43: =SUM(K38:K42) -> -2796 | L43: =SUM(L38:L42) -> 37115 | M43: =K43+L43 -> 34319 | N43: =SUM(N38:N42) -> -61803 | O43: =SUM(O38:O42) -> 25620 | P43: =N43+O43 -> -36183 | Q43: =SUM(Q38:Q42) -> -8070 | R43: =SUM(R38:R42) -> 23736 | S43: =Q43+R43 -> 15666 | T43: =SUM(T38:T42) -> -2658 | U43: =SUM(U38:U42) -> 10263 | V43: =T43+U43 -> 7605 | W43: =SUM(W38:W42) -> -89750 | X43: =SUM(X38:X42) -> 18658 | Y43: =W43+X43 -> -71092 | Z43: =SUM(Z38:Z42) -> -25514 | AA43: =SUM(AA38:AA42) -> 18953 | AB43: =Z43+AA43 -> -6561 | AC43: =SUM(AC38:AC42) -> -90935 | AD43: =SUM(AD38:AD42) -> 3243 | AE43: =AC43+AD43 -> -87692 | AF43: =SUM(AF38:AF42) -> -20327 | AG43: =SUM(AG38:AG42) -> 9166 | AH43: =AF43+AG43 -> -11161 | AI43: =SUM(AI38:AI42) -> -240848 | AJ43: =SUM(AJ38:AJ42) -> 45674 | AK43: =AI43+AJ43 -> -195174 | AL43: =SUM(AL38:AL42) -> -177246
A45: CONNECTION | B45: -48376 | C45: 11138 | D45: =B45+C45 -> -37238 | E45: -52673 | F45: 6708 | G45: =E45+F45 -> -45965 | H45: -33959 | I45: 10432 | J45: =H45+I45 -> -23527 | K45: -2930 | L45: 275918 | M45: =K45+L45 -> 272988 | N45: -6395 | O45: 252357 | P45: =N45+O45 -> 245962 | Q45: -6526 | R45: 78494 | S45: =Q45+R45 -> 71968 | T45: -1221 | U45: 299739 | V45: =T45+U45 -> 298518 | W45: -1907 | X45: 317799 | Y45: =W45+X45 -> 315892 | Z45: 0 | AA45: 60474 | AB45: =Z45+AA45 -> 60474 | AC45: 0 | AD45: 184117 | AE45: =AC45+AD45 -> 184117 | AF45: 0 | AG45: 255888 | AH45: =AF45+AG45 -> 255888 | AI45: -875 | AJ45: 230689 | AK45: =AI45+AJ45 -> 229814 | AL45: =D45+G45+J45+M45+P45+S45+V45+Y45+AB45+AE45+AH45+AK45 -> 1828891
A46: WASTE-PIPE | B46: -4334 | C46: 9969 | D46: =B46+C46 -> 5635 | E46: -3237 | F46: 48785 | G46: =E46+F46 -> 45548 | H46: -8558 | I46: 9362 | J46: =H46+I46 -> 804 | K46: -45313 | L46: 143997 | M46: =K46+L46 -> 98684 | N46: -41447 | O46: 68763 | P46: =N46+O46 -> 27316 | Q46: -32238 | R46: 33212 | S46: =Q46+R46 -> 974 | T46: -30280 | U46: 69252 | V46: =T46+U46 -> 38972 | W46: -97572 | X46: 71629 | Y46: =W46+X46 -> -25943 | Z46: -130515 | AA46: 30454 | AB46: =Z46+AA46 -> -100061 | AC46: -189905 | AD46: 58587 | AE46: =AC46+AD46 -> -131318 | AF46: -144576 | AG46: 73836 | AH46: =AF46+AG46 -> -70740 | AI46: -392951 | AJ46: 67016 | AK46: =AI46+AJ46 -> -325935 | AL46: =D46+G46+J46+M46+P46+S46+V46+Y46+AB46+AE46+AH46+AK46 -> -436064
A47: TOTAL | B47: =SUM(B45:B46) -> -52710 | C47: =SUM(C45:C46) -> 21107 | D47: =B47+C47 -> -31603 | E47: =SUM(E45:E46) -> -55910 | F47: =SUM(F45:F46) -> 55493 | G47: =E47+F47 -> -417 | H47: =SUM(H45:H46) -> -42517 | I47: =SUM(I45:I46) -> 19794 | J47: =H47+I47 -> -22723 | K47: =SUM(K45:K46) -> -48243 | L47: =SUM(L45:L46) -> 419915 | M47: =K47+L47 -> 371672 | N47: =SUM(N45:N46) -> -47842 | O47: =SUM(O45:O46) -> 321120 | P47: =N47+O47 -> 273278 | Q47: =SUM(Q45:Q46) -> -38764 | R47: =SUM(R45:R46) -> 111706 | S47: =Q47+R47 -> 72942 | T47: =SUM(T45:T46) -> -31501 | U47: =SUM(U45:U46) -> 368991 | V47: =T47+U47 -> 337490 | W47: =SUM(W45:W46) -> -99479 | X47: =SUM(X45:X46) -> 389428 | Y47: =W47+X47 -> 289949 | Z47: =SUM(Z45:Z46) -> -130515 | AA47: =SUM(AA45:AA46) -> 90928 | AB47: =Z47+AA47 -> -39587 | AC47: =SUM(AC45:AC46) -> -189905 | AD47: =SUM(AD45:AD46) -> 242704 | AE47: =AC47+AD47 -> 52799 | AF47: =SUM(AF45:AF46) -> -144576 | AG47: =SUM(AG45:AG46) -> 329724 | AH47: =AF47+AG47 -> 185148 | AI47: =SUM(AI45:AI46) -> -393826 | AJ47: =SUM(AJ45:AJ46) -> 297705 | AK47: =AI47+AJ47 -> -96121 | AL47: =SUM(AL45:AL46) -> 1392827
A49: SANITARYWARE | B49: -33502 | C49: 51499 | D49: =B49+C49 -> 17997 | E49: -131616 | F49: 119439 | G49: =E49+F49 -> -12177 | H49: -298604 | I49: 62095 | J49: =H49+I49 -> -236509 | K49: -181136 | L49: 56348 | M49: =K49+L49 -> -124788 | N49: -224072 | O49: 32701 | P49: =N49+O49 -> -191371 | Q49: -261157 | R49: 43860 | S49: =Q49+R49 -> -217297 | T49: -134606 | U49: 29786 | V49: =T49+U49 -> -104820 | W49: -240682 | X49: 71365 | Y49: =W49+X49 -> -169317 | Z49: -470651 | AA49: 40012 | AB49: =Z49+AA49 -> -430639 | AC49: -415674 | AD49: 25379 | AE49: =AC49+AD49 -> -390295 | AF49: -147499 | AG49: 28919 | AH49: =AF49+AG49 -> -118580 | AI49: -784287 | AJ49: 51348 | AK49: =AI49+AJ49 -> -732939 | AL49: =D49+G49+J49+M49+P49+S49+V49+Y49+AB49+AE49+AH49+AK49 -> -2710735
A51: TOTAL | B51: =SUM(B49:B50) -> -33502 | C51: =SUM(C49:C50) -> 51499 | D51: =B51+C51 -> 17997 | E51: =SUM(E49:E50) -> -131616 | F51: =SUM(F49:F50) -> 119439 | G51: =E51+F51 -> -12177 | H51: =SUM(H49:H50) -> -298604 | I51: =SUM(I49:I50) -> 62095 | J51: =H51+I51 -> -236509 | K51: =SUM(K49:K50) -> -181136 | L51: =SUM(L49:L50) -> 56348 | M51: =K51+L51 -> -124788 | N51: =SUM(N49:N50) -> -224072 | O51: =SUM(O49:O50) -> 32701 | P51: =N51+O51 -> -191371 | Q51: =SUM(Q49:Q50) -> -261157 | R51: =SUM(R49:R50) -> 43860 | S51: =Q51+R51 -> -217297 | T51: =SUM(T49:T50) -> -134606 | U51: =SUM(U49:U50) -> 29786 | V51: =T51+U51 -> -104820 | W51: =SUM(W49:W50) -> -240682 | X51: =SUM(X49:X50) -> 71365 | Y51: =W51+X51 -> -169317 | Z51: =SUM(Z49:Z50) -> -470651 | AA51: =SUM(AA49:AA50) -> 40012 | AB51: =Z51+AA51 -> -430639 | AC51: =SUM(AC49:AC50) -> -415674 | AD51: =SUM(AD49:AD50) -> 25379 | AE51: =AC51+AD51 -> -390295 | AF51: =SUM(AF49:AF50) -> -147499 | AG51: =SUM(AG49:AG50) -> 28919 | AH51: =AF51+AG51 -> -118580 | AI51: =SUM(AI49:AI50) -> -784287 | AJ51: =SUM(AJ49:AJ50) -> 51348 | AK51: =AI51+AJ51 -> -732939 | AL51: =D51+G51+J51+M51+P51+S51+V51+Y51+AB51+AE51+AH51+AK51 -> -2710735
A53: SUBTOTAL | B53: =SUMIF($A$5:$A$52,"TOTAL",B5:B52) -> -3147562 | C53: =SUMIF($A$5:$A$52,"TOTAL",C5:C52) -> 1317621 | D53: =SUMIF($A$5:$A$52,"TOTAL",D5:D52) -> -1829941 | E53: =SUMIF($A$5:$A$52,"TOTAL",E5:E52) -> -7501200 | F53: =SUMIF($A$5:$A$52,"TOTAL",F5:F52) -> 3551295 | G53: =SUMIF($A$5:$A$52,"TOTAL",G5:G52) -> -3949905 | H53: =SUMIF($A$5:$A$52,"TOTAL",H5:H52) -> -9347555 | I53: =SUMIF($A$5:$A$52,"TOTAL",I5:I52) -> 5639400 | ... U53: =SUMIF($A$5:$A$52,"TOTAL",U5:U52) -> 4661083 | V53: =T53+U53 -> -6512761 | W53: =SUMIF($A$5:$A$52,"TOTAL",W5:W52) -> -6253038 | X53: =SUMIF($A$5:$A$52,"TOTAL",X5:X52) -> 5186072 | Y53: =W53+X53 -> -1066966 | Z53: =SUMIF($A$5:$A$52,"TOTAL",Z5:Z52) -> -10809163 | AA53: =SUMIF($A$5:$A$52,"TOTAL",AA5:AA52) -> 3896784 | AB53: =Z53+AA53 -> -6912379 | AC53: =SUMIF($A$5:$A$52,"TOTAL",AC5:AC52) -> -10228573 | AD53: =SUMIF($A$5:$A$52,"TOTAL",AD5:AD52) -> 3070685 | AE53: =AC53+AD53 -> -7157888 | AF53: =SUMIF($A$5:$A$52,"TOTAL",AF5:AF52) -> -14343286 | AG53: =SUMIF($A$5:$A$52,"TOTAL",AG5:AG52) -> 3676295 | AH53: =AF53+AG53 -> -10666991 | AI53: =SUMIF($A$5:$A$52,"TOTAL",AI5:AI52) -> -20342203 | AJ53: =SUMIF($A$5:$A$52,"TOTAL",AJ5:AJ52) -> 6610115 | AK53: =AI53+AJ53 -> -13732088 | AL53: =D53+G53+J53+M53+P53+S53+V53+Y53+AB53+AE53+AH53+AK53 -> -60257475
B55: =B53 -> -3147562 | C55: =C53 -> 1317621 | E55: =E53 -> -7501200 | F55: =F53 -> 3551295 | H55: =H53 -> -9347555 | I55: =I53 -> 5639400 | K55: =K53 -> -10623096 | L55: =L53 -> 5916128 | N55: =N53 -> -5465977 | O55: =O53 -> 6077385 | R55: =R53 -> 5370750 | S55: =S53 -> -624841 | U55: =U53 -> 4661083 | V55: =V53 -> -6512761 | X55: =X53 -> 5186072 | Y55: =Y53 -> -1066966 | AA55: =AA53 -> 3896784 | AB55: =AB53 -> -6912379 | AD55: =AD53 -> 3070685 | AE55: =AE53 -> -7157888 | AG55: =AG53 -> 3676295 | AH55: =AH53 -> -10666991 | AJ55: =AJ53 -> 6610115 | AK55: =AK53 -> -13732088
C57: =B55+C55 -> -1829941 | F57: =E55+F55 -> -3949905 | I57: =H55+I55 -> -3708155 | L57: =K55+L55 -> -4706968 | O57: =N55+O55 -> 611408 | S57: =R55+S55 -> 4745909 | V57: =U55+V55 -> -1851678 | Y57: =X55+Y55 -> 4119106 | AB57: =AA55+AB55 -> -3015595 | AE57: =AD55+AE55 -> -4087203 | AH57: =AG55+AH55 -> -6990696 | AK57: =AJ55+AK55 -> -7121973
P999: =N999+O999 -> 0

Sheet REPORT 1
C1: SALE | G1: Purchase
B2: PTMT | C2: Sale value | D2: Lose | E2: Profit | F2: Sale PL Diff | G2: Purchase value | H2: Lose | I2: Profit | J2: Pur PL Diff | K2: Purchase % | L2: Sale Pur PL Diff
A3: 45383 | B3: =TEXT(A3,"MMM-YY") -> Apr-24 | C3: ='SALE '!C9+'SALE '!C46 -> 47050519 | D3: ='SALE PL'!B11+'SALE PL'!B47 -> -434502 | E3: ='SALE PL'!C11+'SALE PL'!C47 -> 867147 | F3: =D3+E3 -> 432645 | G3: =PURCHASE!C9 -> 14700494 | H3: ='PUR PL'!B10 -> -420293 | I3: ='PUR PL'!C10 -> 580531 | J3: =H3+I3 -> 160238 | K3: =IFERROR(G3/C3,"") -> 0.31244063 | L3: =F3+J3 -> 592883 | Q3: Apr-23 | R3: =SUMIF($B$3:$B$116,$Q3,D$3:D$117) -> 0 | S3: =SUMIF($B$3:$B$116,$Q3,E$3:E$117) -> 0 | T3: =SUMIF($B$3:$B$116,$Q3,F$3:F$117) -> 0 | U3: =SUMIF($B$3:$B$116,$Q3,G$3:G$117) -> 0 | V3: =SUMIF($B$3:$B$116,$Q3,H$3:H$117) -> 0 | W3: =SUMIF($B$3:$B$116,$Q3,I$3:I$117) -> 0
A4: 45413 | B4: =TEXT(A4,"MMM-YY") -> May-24 | C4: ='SALE '!D9+'SALE '!D46 -> 84056269 | D4: ='SALE PL'!E11+'SALE PL'!E47 -> -918219 | E4: ='SALE PL'!F11+'SALE PL'!F47 -> 1639277 | F4: =D4+E4 -> 721058 | G4: =PURCHASE!D9 -> 22208919 | H4: ='PUR PL'!D10 -> -534645 | I4: ='PUR PL'!E10 -> 956408 | J4: =H4+I4 -> 421763 | K4: =IFERROR(G4/C4,"") -> 0.2642149 | L4: =F4+J4 -> 1142821 | Q4: May-23 | R4: =SUMIF($B$3:$B$116,Q4,$D$3:$D$117) -> 0 | S4: =SUMIF($B$3:$B$116,$Q4,E$3:E$117) -> 0 | V4: =SUMIF($B$3:$B$116,$Q4,H$3:H$117) -> 0 | W4: =SUMIF($B$3:$B$116,$Q4,I$3:I$117) -> 0
A5: 45444 | B5: =TEXT(A5,"MMM-YY") -> Jun-24 | C5: ='SALE '!E9+'SALE '!E46 -> 101862964 | D5: ='SALE PL'!H11+'SALE PL'!H47 -> -941917 | E5: ='SALE PL'!I11+'SALE PL'!I47 -> 1750138 | F5: =D5+E5 -> 808221 | G5: 14774062 | H5: ='PUR PL'!F10 -> -620434 | I5: ='PUR PL'!G10 -> 505453 | J5: =H5+I5 -> -114981 | K5: =IFERROR(G5/C5,"") -> 0.1450386 | L5: =F5+J5 -> 693240 | Q5: Jun-23 | R5: =SUMIF($B$3:$B$116,Q5,$D$3:$D$117) -> 0 | S5: =SUMIF($B$3:$B$116,$Q5,E$3:E$117) -> 0 | V5: =SUMIF($B$3:$B$116,$Q5,H$3:H$117) -> 0 | W5: =SUMIF($B$3:$B$116,$Q5,I$3:I$117) -> 0
A6: 45474 | B6: =TEXT(A6,"MMM-YY") -> Jul-24 | C6: ='SALE '!F9+'SALE '!F46 -> 73363323 | D6: ='SALE PL'!K11+'SALE PL'!K47 -> -809545 | E6: ='SALE PL'!L11+'SALE PL'!L47 -> 2321048 | F6: =D6+E6 -> 1511503 | G6: =PURCHASE!F9 -> 24124171 | H6: ='PUR PL'!H10 -> -504160.42 | I6: ='PUR PL'!I10 -> 1650587.7 | J6: =H6+I6 -> 1146427.2 | K6: =IFERROR(G6/C6,"") -> 0.32883149 | L6: =F6+J6 -> 2657930.2 | Q6: Jul-23 | R6: =SUMIF($B$3:$B$116,Q6,$D$3:$D$117) -> 0 | S6: =SUMIF($B$3:$B$116,$Q6,E$3:E$117) -> 0 | V6: =SUMIF($B$3:$B$116,$Q6,H$3:H$117) -> 0 | W6: =SUMIF($B$3:$B$116,$Q6,I$3:I$117) -> 0
A7: 45505 | B7: =TEXT(A7,"MMM-YY") -> Aug-24 | C7: ='SALE '!G9+'SALE '!G46 -> 85769826 | D7: ='SALE PL'!N11+'SALE PL'!N47 -> -1002203 | E7: ='SALE PL'!O11+'SALE PL'!O47 -> 2608427 | F7: =D7+E7 -> 1606224 | G7: =PURCHASE!G9 -> 10096178 | H7: ='PUR PL'!J10 -> -393253 | I7: ='PUR PL'!K10 -> 551843 | J7: =H7+I7 -> 158590 | K7: =IFERROR(G7/C7,"") -> 0.11771247 | L7: =F7+J7 -> 1764814 | Q7: Aug-23 | R7: =SUMIF($B$3:$B$116,Q7,$D$3:$D$117) -> 0 | S7: =SUMIF($B$3:$B$116,$Q7,E$3:E$117) -> 0 | V7: =SUMIF($B$3:$B$116,$Q7,H$3:H$117) -> 0 | W7: =SUMIF($B$3:$B$116,$Q7,I$3:I$117) -> 0
A8: 45536 | B8: =TEXT(A8,"MMM-YY") -> Sep-24 | C8: ='SALE '!H9+'SALE '!H46 -> 77176815 | D8: ='SALE PL'!Q11+'SALE PL'!Q47 -> -748180 | E8: ='SALE PL'!R11+'SALE PL'!R47 -> 2093504 | F8: =D8+E8 -> 1345324 | G8: =PURCHASE!H9 -> 27844295 | H8: ='PUR PL'!L10 -> -770396.62 | I8: ='PUR PL'!M10 -> 1730967 | J8: =H8+I8 -> 960570.38 | K8: =IFERROR(G8/C8,"") -> 0.36078575 | L8: =F8+J8 -> 2305894.4 | Q8: Sep-23 | R8: =SUMIF($B$3:$B$116,Q8,$D$3:$D$117) -> 0 | S8: =SUMIF($B$3:$B$116,$Q8,E$3:E$117) -> 0 | V8: =SUMIF($B$3:$B$116,$Q8,H$3:H$117) -> 0 | W8: =SUMIF($B$3:$B$116,$Q8,I$3:I$117) -> 0
A9: 45566 | B9: =TEXT(A9,"MMM-YY") -> Oct-24 | C9: ='SALE '!I9+'SALE '!I46 -> 65656558 | D9: ='SALE PL'!T11+'SALE PL'!T47 -> -491950 | E9: ='SALE PL'!U11+'SALE PL'!U47 -> 2292470 | F9: =D9+E9 -> 1800520 | G9: =PURCHASE!I9 -> 23220965 | H9: ='PUR PL'!N10 -> -852376 | I9: ='PUR PL'!O10 -> 2143421 | J9: =H9+I9 -> 1291045 | K9: =IFERROR(G9/C9,"") -> 0.3536732 | L9: =F9+J9 -> 3091565 | Q9: Oct-23 | R9: =SUMIF($B$3:$B$116,Q9,$D$3:$D$117) -> 0 | S9: =SUMIF($B$3:$B$116,$Q9,E$3:E$117) -> 0 | V9: =SUMIF($B$3:$B$116,$Q9,H$3:H$117) -> 0 | W9: =SUMIF($B$3:$B$116,$Q9,I$3:I$117) -> 0
A10: 45597 | B10: =TEXT(A10,"MMM-YY") -> Nov-24 | C10: =124666218+9383445 -> 134049663 | D10: ='SALE PL'!W11+'SALE PL'!W47 -> -654591 | E10: ='SALE PL'!X11+'SALE PL'!X47 -> 2281187 | F10: =D10+E10 -> 1626596 | G10: =PURCHASE!J9 -> 19061015 | H10: ='PUR PL'!P10 -> -869245 | I10: ='PUR PL'!Q10 -> 1805817 | J10: =H10+I10 -> 936572 | K10: =IFERROR(G10/C10,"") -> 0.14219368 | L10: =F10+J10 -> 2563168 | Q10: Nov-23 | R10: =SUMIF($B$3:$B$116,Q10,$D$3:$D$117) -> 0 | S10: =SUMIF($B$3:$B$116,$Q10,E$3:E$117) -> 0 | V10: =SUMIF($B$3:$B$116,$Q10,H$3:H$117) -> 0 | W10: =SUMIF($B$3:$B$116,$Q10,I$3:I$117) -> 0
A11: 45627 | B11: =TEXT(A11,"MMM-YY") -> Dec-24 | C11: =115340577+8091764 -> 123432341 | D11: ='SALE PL'!Z11+'SALE PL'!Z47 -> -967580 | E11: ='SALE PL'!AA11+'SALE PL'!AA47 -> 2144830 | F11: =D11+E11 -> 1177250 | G11: =PURCHASE!K9 -> 20105732 | H11: ='PUR PL'!R10 -> -745950 | I11: ='PUR PL'!S10 -> 3769256 | J11: =H11+I11 -> 3023306 | K11: =IFERROR(G11/C11,"") -> 0.16288869 | L11: =F11+J11 -> 4200556 | Q11: Dec-23 | R11: =SUMIF($B$3:$B$116,Q11,$D$3:$D$117) -> 0 | S11: =SUMIF($B$3:$B$116,$Q11,E$3:E$117) -> 0 | V11: =SUMIF($B$3:$B$116,$Q11,H$3:H$117) -> 0 | W11: =SUMIF($B$3:$B$116,$Q11,I$3:I$117) -> 0
A12: 45658 | B12: =TEXT(A12,"MMM-YY") -> Jan-25 | C12: ='SALE '!L9+'SALE '!L46 -> 83965809 | D12: ='SALE PL'!AC11+'SALE PL'!AC47 -> -833773 | E12: ='SALE PL'!AD11+'SALE PL'!AD47 -> 2004189 | F12: =D12+E12 -> 1170416 | G12: =PURCHASE!L9 -> 26654880 | H12: ='PUR PL'!T10 -> -1017569 | I12: ='PUR PL'!U10 -> 2994796 | J12: =H12+I12 -> 1977227 | K12: =IFERROR(G12/C12,"") -> 0.31744921 | L12: =F12+J12 -> 3147643 | Q12: Jan-24 | R12: =SUMIF($B$3:$B$116,Q12,$D$3:$D$117) -> 0 | S12: =SUMIF($B$3:$B$116,$Q12,E$3:E$117) -> 0 | V12: =SUMIF($B$3:$B$116,$Q12,H$3:H$117) -> 0 | W12: =SUMIF($B$3:$B$116,$Q12,I$3:I$117) -> 0
A13: 45689 | B13: =TEXT(A13,"MMM-YY") -> Feb-25 | C13: ='SALE '!M9+'SALE '!M46 -> 100226827 | D13: ='SALE PL'!AF11+'SALE PL'!AF47 -> -926115 | E13: ='SALE PL'!AG11+'SALE PL'!AG47 -> 2224408 | F13: =D13+E13 -> 1298293 | G13: =PURCHASE!M9 -> 23737991 | H13: ='PUR PL'!V10 -> -852856 | I13: ='PUR PL'!W10 -> 2092243 | J13: =H13+I13 -> 1239387 | K13: =IFERROR(G13/C13,"") -> 0.23684269 | L13: =F13+J13 -> 2537680 | Q13: Feb-24 | R13: =SUMIF($B$3:$B$116,Q13,$D$3:$D$117) -> 0 | S13: =SUMIF($B$3:$B$116,$Q13,E$3:E$117) -> 0 | V13: =SUMIF($B$3:$B$116,$Q13,H$3:H$117) -> 0 | W13: =SUMIF($B$3:$B$116,$Q13,I$3:I$117) -> 0
A14: 45717 | B14: =TEXT(A14,"MMM-YY") -> Mar-25 | C14: ='SALE '!N9+'SALE '!N46 -> 158841587 | D14: ='SALE PL'!AI11+'SALE PL'!AI47 -> -1877338 | E14: ='SALE PL'!AJ11+'SALE PL'!AJ47 -> 3234341 | F14: =D14+E14 -> 1357003 | G14: =PURCHASE!N9 -> 29463902 | H14: ='PUR PL'!X10 -> -801516 | I14: ='PUR PL'!Y10 -> 4658053 | J14: =H14+I14 -> 3856537 | K14: =IFERROR(G14/C14,"") -> 0.18549237 | L14: =F14+J14 -> 5213540 | Q14: Mar-24 | R14: =SUMIF($B$3:$B$116,Q14,$D$3:$D$117) -> 0 | S14: =SUMIF($B$3:$B$116,$Q14,E$3:E$117) -> 0 | V14: =SUMIF($B$3:$B$116,$Q14,H$3:H$117) -> 0 | W14: =SUMIF($B$3:$B$116,$Q14,I$3:I$117) -> 0
B15: Total | C15: =SUM(C3:C14) -> 1135452501 | D15: =SUM(D3:D14) -> -10605913 | E15: =SUM(E3:E14) -> 25460966 | F15: =SUM(F3:F14) -> 14855053 | G15: =SUM(G3:G14) -> 255992604 | H15: =SUM(H3:H14) -> -8382694 | I15: =SUM(I3:I14) -> 23439376 | J15: =H15+I15 -> 15056682 | K15: =IFERROR(G15/C15,"") -> 0.22545426 | L15: =F15+J15 -> 29911735
B17: CP | C17: Sale value | D17: Lose | E17: Profit | F17: Sale PL Diff | G17: Purchase value | H17: Lose | I17: Profit | J17: Pur PL Diff | K17: Purchase % | L17: Sale Pur PL Diff
B18: =B3 -> Apr-24 | C18: ='SALE '!C16 -> 28992464 | D18: ='SALE PL'!B18 -> -1014640 | E18: ='SALE PL'!C18 -> 222022 | F18: =D18+E18 -> -792618 | G18: =PURCHASE!C16+PURCHASE!C46+PURCHASE!C52 -> 37676917 | H18: ='PUR PL'!B17 -> -1970798 | I18: ='PUR PL'!C17 -> 216305 | J18: =H18+I18 -> -1754493 | K18: =IFERROR(G18/C18,"") -> 1.2995417 | L18: =F18+J18 -> -2547111
B19: =B4 -> May-24 | C19: ='SALE '!D16 -> 52711962 | D19: ='SALE PL'!E18 -> -1661801 | E19: ='SALE PL'!F18 -> 507988 | F19: =D19+E19 -> -1153813 | G19: =PURCHASE!D16+PURCHASE!D46 -> 37028847 | H19: ='PUR PL'!D17 -> -2747646 | I19: ='PUR PL'!E17 -> 225069 | J19: =H19+I19 -> -2522577 | K19: =IFERROR(G19/C19,"") -> 0.70247522 | L19: =F19+J19 -> -3676390
B20: =B5 -> Jun-24 | C20: ='SALE '!E16 -> 57020281 | D20: ='SALE PL'!H18 -> -792712 | E20: ='SALE PL'!I18 -> 2046126 | F20: =D20+E20 -> 1253414 | G20: 24936608 | H20: ='PUR PL'!F17 -> -1617935 | I20: ='PUR PL'!G17 -> 124339 | J20: =H20+I20 -> -1493596 | K20: =IFERROR(G20/C20,"") -> 0.43732875 | L20: =F20+J20 -> -240182
B21: =B6 -> Jul-24 | C21: ='SALE '!F16 -> 47963115 | D21: ='SALE PL'!K18 -> -572257 | E21: ='SALE PL'!L18 -> 1894186 | F21: =D21+E21 -> 1321929 | G21: =PURCHASE!F16+PURCHASE!F46 -> 35856349 | H21: ='PUR PL'!H17 -> -2223748.3 | I21: ='PUR PL'!I17+'PUR PL'!I45 -> 492515.08 | J21: =H21+I21 -> -1731233.2 | K21: =IFERROR(G21/C21,"") -> 0.74758174 | L21: =F21+J21 -> -409304.25
B22: =B7 -> Aug-24 | C22: ='SALE '!G16 -> 51280011 | D22: ='SALE PL'!N18 -> -811410 | E22: ='SALE PL'!O18 -> 2087117 | F22: =D22+E22 -> 1275707 | G22: =PURCHASE!G16+PURCHASE!G46 -> 19555229 | H22: ='PUR PL'!J17 -> -704708 | I22: ='PUR PL'!K17+'PUR PL'!K47 -> 200802 | J22: =H22+I22 -> -503906 | K22: =IFERROR(G22/C22,"") -> 0.38134214 | L22: =F22+J22 -> 771801
B23: =B8 -> Sep-24 | C23: ='SALE '!H16 -> 63904503 | D23: ='SALE PL'!Q18 -> -922442 | E23: ='SALE PL'!R18 -> 2034403 | F23: =D23+E23 -> 1111961 | G23: =PURCHASE!H16+PURCHASE!H46 -> 35133078 | H23: ='PUR PL'!L17 -> -1369437 | I23: ='PUR PL'!M17+'PUR PL'!M47 -> 615657 | J23: =H23+I23 -> -753780 | K23: =IFERROR(G23/C23,"") -> 0.54977468 | L23: =F23+J23 -> 358181
B24: =B9 -> Oct-24 | C24: ='SALE '!I16 -> 44307725 | D24: ='SALE PL'!T18 -> -326729 | E24: ='SALE PL'!U18 -> 1647288 | F24: =D24+E24 -> 1320559 | G24: =PURCHASE!I16+PURCHASE!I46+PURCHASE!I52 -> 42935713 | H24: ='PUR PL'!N17-1400 -> -2329330 | I24: ='PUR PL'!O17+'PUR PL'!O47 -> 552167 | J24: =H24+I24 -> -1777163 | K24: =IFERROR(G24/C24,"") -> 0.96903447 | L24: =F24+J24 -> -456604
B25: =B10 -> Nov-24 | C25: ='SALE '!J16 -> 103992264 | D25: ='SALE PL'!W18 -> -681001 | E25: ='SALE PL'!X18 -> 2164017 | F25: =D25+E25 -> 1483016 | G25: =PURCHASE!J16+PURCHASE!J46 -> 21851597 | H25: ='PUR PL'!P17 -> -895086 | I25: ='PUR PL'!Q17+'PUR PL'!Q47 -> 462206 | J25: =H25+I25 -> -432880 | K25: =IFERROR(G25/C25,"") -> 0.21012714 | L25: =F25+J25 -> 1050136
B26: =B11 -> Dec-24 | C26: 93242547 | D26: ='SALE PL'!Z18 -> -1855142 | E26: ='SALE PL'!AA18 -> 1163171 | F26: =D26+E26 -> -691971 | G26: =PURCHASE!K16+PURCHASE!K46 -> 35800279 | H26: ='PUR PL'!R17 -> -1303832 | I26: ='PUR PL'!S17+'PUR PL'!S47 -> 403468 | J26: =H26+I26 -> -900364 | K26: =IFERROR(G26/C26,"") -> 0.38394789 | L26: =F26+J26 -> -1592335
B27: =B12 -> Jan-25 | C27: ='SALE '!L16 -> 60380092 | D27: ='SALE PL'!AC18 -> -2082771 | E27: ='SALE PL'!AD18 -> 936704 | F27: =D27+E27 -> -1146067 | G27: =PURCHASE!L16+PURCHASE!L46+PURCHASE!L52 -> 48249949 | H27: ='PUR PL'!T17-12000 -> -1896281 | I27: ='PUR PL'!U17+'PUR PL'!U47 -> 687097 | J27: =H27+I27 -> -1209184 | K27: =IFERROR(G27/C27,"") -> 0.7991036 | L27: =F27+J27 -> -2355251
B28: =B13 -> Feb-25 | C28: ='SALE '!M16 -> 67812350 | D28: ='SALE PL'!AF18 -> -2958234 | E28: ='SALE PL'!AG18 -> 975826 | F28: =D28+E28 -> -1982408 | G28: =PURCHASE!M16+PURCHASE!M46+PURCHASE!M52 -> 40767835 | H28: ='PUR PL'!V17+'PUR PL'!V51 -> -2013862 | I28: ='PUR PL'!W17+'PUR PL'!W47 -> 788256 | J28: =H28+I28 -> -1225606 | K28: =IFERROR(G28/C28,"") -> 0.60118599 | L28: =F28+J28 -> -3208014
B29: =B14 -> Mar-25 | C29: ='SALE '!N16 -> 130835407 | D29: ='SALE PL'!AI18 -> -3719896 | E29: ='SALE PL'!AJ18 -> 2362829 | F29: =D29+E29 -> -1357067 | G29: =PURCHASE!N16+PURCHASE!N44 -> 50468922 | H29: ='PUR PL'!X17+'PUR PL'!X47 -> -3429428 | I29: ='PUR PL'!Y17+'PUR PL'!Y47 -> 724191 | J29: =H29+I29 -> -2705237 | K29: =IFERROR(G29/C29,"") -> 0.38574361 | L29: =F29+J29 -> -4062304
B30: Total | C30: =SUM(C18:C29) -> 802442721 | D30: =sum(D18:D29) -> -17399035 | E30: =sum(E18:E29) -> 18041677 | F30: =sum(F18:F29) -> 642642 | G30: =sum(G18:G29) -> 430261323 | H30: =sum(H18:H29) -> -22502091 | I30: =sum(I18:I29) -> 5492072.1 | J30: =H30+I30 -> -17010019 | K30: =IFERROR(G30/C30,"") -> 0.53618945 | L30: =F30+J30 -> -16367377
B32: SINK | C32: Sale value | D32: Lose | E32: Profit | F32: Sale PL Diff | G32: Purchase value | H32: Lose | I32: Profit | J32: Pur PL Diff | K32: Purchase % | L32: Sale Pur PL Diff
B33: =B18 -> Apr-24 | C33: ='SALE '!C22 -> 5482175 | D33: ='SALE PL'!B24 -> -97337 | E33: ='SALE PL'!C24 -> 23899 | F33: =D33+E33 -> -73438 | G33: =PURCHASE!C23 -> 5761589 | H33: ='PUR PL'!B24 -> -24532 | I33: ='PUR PL'!C24 -> 128115 | J33: =H33+I33 -> 103583 | K33: =IFERROR(G33/C33,"") -> 1.0509677 | L33: =F33+J33 -> 30145
B34: =B19 -> May-24 | C34: ='SALE '!D22 -> 13403356 | D34: ='SALE PL'!E24 -> -199882 | E34: ='SALE PL'!F24 -> 37936 | F34: =D34+E34 -> -161946 | G34: =PURCHASE!D23 -> 7440270 | H34: ='PUR PL'!D24 -> -23514 | I34: ='PUR PL'!E24 -> 102470 | J34: =H34+I34 -> 78956 | K34: =IFERROR(G34/C34,"") -> 0.55510501 | L34: =F34+J34 -> -82990
B35: =B20 -> Jun-24 | C35: ='SALE '!E22 -> 10193424 | D35: ='SALE PL'!H24 -> -105753 | E35: ='SALE PL'!I24 -> 51818 | F35: =D35+E35 -> -53935 | G35: 6816998 | H35: ='PUR PL'!F24 -> -86348 | I35: ='PUR PL'!G24 -> 95848 | J35: =H35+I35 -> 9500 | K35: =IFERROR(G35/C35,"") -> 0.66876429 | L35: =F35+J35 -> -44435
B36: =B21 -> Jul-24 | C36: ='SALE '!F22 -> 9922288 | D36: ='SALE PL'!K24 -> -42737 | E36: ='SALE PL'!L24 -> 223585 | F36: =D36+E36 -> 180848 | G36: =PURCHASE!F23 -> 6071099 | H36: ='PUR PL'!H24 -> -36346.44 | I36: ='PUR PL'!I24 -> 70215.68 | J36: =H36+I36 -> 33869.24 | K36: =IFERROR(G36/C36,"") -> 0.61186482 | L36: =F36+J36 -> 214717.24
B37: =B22 -> Aug-24 | C37: ='SALE '!G22 -> 10744147 | D37: ='SALE PL'!N24 -> -38451 | E37: ='SALE PL'!O24 -> 239599 | F37: =D37+E37 -> 201148 | G37: =PURCHASE!G23 -> 5002135 | H37: ='PUR PL'!J24 -> -46480 | I37: ='PUR PL'!K24 -> 307151 | J37: =H37+I37 -> 260671 | K37: =IFERROR(G37/C37,"") -> 0.46556837 | L37: =F37+J37 -> 461819
B38: =B23 -> Sep-24 | C38: ='SALE '!H22 -> 12032078 | D38: ='SALE PL'!Q24 -> -84312 | E38: ='SALE PL'!R24 -> 195889 | F38: =D38+E38 -> 111577 | G38: =PURCHASE!H23 -> 6589509 | H38: ='PUR PL'!L24 -> -110435 | I38: ='PUR PL'!M24 -> 18106 | J38: =H38+I38 -> -92329 | K38: =IFERROR(G38/C38,"") -> 0.54766176 | L38: =F38+J38 -> 19248
B39: =B24 -> Oct-24 | C39: ='SALE '!I22 -> 7582888 | D39: ='SALE PL'!T24 -> -48413 | E39: ='SALE PL'!U24 -> 140017 | F39: =D39+E39 -> 91604 | G39: =PURCHASE!I23 -> 10012295 | H39: ='PUR PL'!N24 -> -148290 | I39: ='PUR PL'!O24 -> 290305 | J39: =H39+I39 -> 142015 | K39: =IFERROR(G39/C39,"") -> 1.3203802 | L39: =F39+J39 -> 233619
B40: =B25 -> Nov-24 | C40: ='SALE '!J22 -> 14725964 | D40: ='SALE PL'!W24 -> -53667 | E40: ='SALE PL'!X24 -> 197009 | F40: =D40+E40 -> 143342 | G40: =PURCHASE!J23 -> 2426372 | H40: ='PUR PL'!P24 -> -69983 | I40: ='PUR PL'!Q24 -> 115964 | J40: =H40+I40 -> 45981 | K40: =IFERROR(G40/C40,"") -> 0.1647683 | L40: =F40+J40 -> 189323
B41: =B26 -> Dec-24 | C41: 13822066 | D41: ='SALE PL'!Z24 -> -1429335 | E41: ='SALE PL'!AA24 -> 40746 | F41: =D41+E41 -> -1388589 | G41: =PURCHASE!K23 -> 7854918 | H41: ='PUR PL'!R24 -> -99902 | I41: ='PUR PL'!S24 -> 71981 | J41: =H41+I41 -> -27921 | K41: =IFERROR(G41/C41,"") -> 0.56828827 | L41: =F41+J41 -> -1416510
B42: =B27 -> Jan-25 | C42: ='SALE '!L22 -> 9582705 | D42: ='SALE PL'!AC24 -> -1157958 | E42: ='SALE PL'!AD24 -> 6803 | F42: =D42+E42 -> -1151155 | G42: =PURCHASE!L23 -> 6425939 | H42: ='PUR PL'!T24 -> -97359 | I42: ='PUR PL'!U24 -> 159235 | J42: =H42+I42 -> 61876 | K42: =IFERROR(G42/C42,"") -> 0.67057673 | L42: =F42+J42 -> -1089279
...

Sheet SALE 
B1: SALE 2024-25
C2: APR | D2: MAY | E2: JUNE | F2: JULY | G2: AUG | H2: SEP | I2: OCT | J2: NOV | K2: DEC | L2: JAN | M2: FEB | N2: MAR
A3: PTMT | B3: PTMT | C3: 36842697 | D3: 65626335 | E3: 79724796 | F3: 56110277 | G3: 67602553 | H3: 59159975 | I3: 50105539 | J3: 113909741 | K3: 105230893 | L3: 65670079 | M3: 81149771 | N3: 130813916
A4: CISTERN | B4: CISTERN | C4: 4544055 | D4: 7966786 | E4: 9010156 | F4: 6355172 | G4: 6735272 | H4: 8179138 | I4: 6919065 | J4: 8222733 | K4: 7118211 | L4: 6454390 | M4: 7427036 | N4: 10829677
A5: CABINET | B5: CABINET | C5: 324851 | D5: 805589 | E5: 967546 | F5: 1453508 | G5: 929075 | H5: 1313360 | I5: 1132851 | J5: 955454 | K5: 1328775 | L5: 1507022 | M5: 1255488 | N5: 1155094
A6: SEAT COVER | B6: SEAT COVER | C6: 1342320 | D6: 1327082 | E6: 2385237 | F6: 1468745 | G6: 1381740 | H6: 1412044 | I6: 1188348 | J6: 1558403 | K6: 1541356 | L6: 1733587 | M6: 1336967 | N6: 2202681
A7: QUAA | B7: QUAA | C7: 18286 | D7: 88809 | F7: 125337 | G7: 34918 | H7: 67374 | I7: 1555 | J7: 19887 | K7: 121342 | L7: 8892 | M7: 6257 | N7: 65567
A9: =SUM(C9:N9) -> 1034273610 | B9: TOTAL | C9: 43072209 | D9: =SUM(D3:D7) -> 75814601 | E9: =SUM(E3:E7) -> 92087735 | F9: 65513039 | G9: =SUM(G3:G7) -> 76683558 | H9: =SUM(H3:H7) -> 70131891 | I9: =SUM(I3:I7) -> 59347358 | J9: =SUM(J3:J7) -> 124666218 | K9: =SUM(K3:K7) -> 115340577 | L9: =SUM(L3:L7) -> 75373970 | M9: =SUM(M3:M7) -> 91175519 | N9: =SUM(N3:N7) -> 145066935
B10: =sum(C9:N9) -> 1034273610
A11: C P FITTING | B11: CP | C11: 23543970 | D11: 40135349 | E11: 46323099 | F11: 37545714 | G11: 40563973 | H11: 51477504 | I11: 35316630 | J11: 89853164 | K11: 77886718 | L11: 45422022 | M11: 51147190 | N11: 107601316
A12: CP ACCESSORIES | B12: CP ACCESSORIES | C12: 4793190 | D12: 11228251 | E12: 9772975 | F12: 9378282 | G12: 9846591 | H12: 11261889 | I12: 7800924 | J12: 13206362 | K12: 12950502 | L12: 14219880 | M12: 15272826 | N12: 21732338
A13: GLASS | B13: GLASS | D13: 0 | E13: 15166 | F13: 0 | G13: 0 | H13: 0 | I13: 0 | J13: 0 | K13: 0 | L13: 0 | M13: 0 | N13: 0
A14: TEFELON TAPE | B14: TEFLON TAPE | C14: 445722 | D14: 1348362 | E14: 909041 | F14: 1039119 | G14: 762020 | H14: 737992 | I14: 752872 | J14: 388741 | K14: 1065662 | L14: 681351 | M14: 1392334 | N14: 1453910
A15: GEYSER | B15: GEYSER | C15: 209582 | D15: 0 | E15: 0 | F15: 0 | G15: 107427 | H15: 427118 | I15: 437299 | J15: 543997 | K15: 1339665 | L15: 56839 | M15: 0 | N15: 47843
A16: =SUM(C16:N16) -> 802442721 | B16: TOTAL | C16: 28992464 | D16: =SUM(D11:D15) -> 52711962 | E16: =SUM(E11:E15) -> 57020281 | F16: 47963115 | G16: =SUM(G11:G15) -> 51280011 | H16: =SUM(H11:H15) -> 63904503 | I16: =SUM(I11:I15) -> 44307725 | J16: =SUM(J11:J15) -> 103992264 | K16: =SUM(K11:K15) -> 93242547 | L16: =SUM(L11:L15) -> 60380092 | M16: =SUM(M11:M15) -> 67812350 | N16: =SUM(N11:N15) -> 130835407
B17: =sum(C16:N16) -> 802442721
A18: SINK | B18: SINK | C18: 4917073 | D18: 12817200 | E18: 9416652 | F18: 8869897 | G18: 9624863 | H18: 10441429 | I18: 6391331 | J18: 13001573 | K18: 11353127 | L18: 8160108 | M18: 11436588 | N18: 15960124
A19: FLOOR TRAP | B19: JALI | C19: 165531 | D19: 419283 | E19: 393186 | F19: 490367 | G19: 744177 | H19: 776647 | I19: 657097 | J19: 586563 | K19: 613013 | L19: 539527 | M19: 658915 | N19: 916779
A20: PLATE RACK | B20: P-RACK | C20: 399571 | D20: 166873 | E20: 383586 | F20: 562024 | G20: 375107 | H20: 814002 | I20: 534460 | J20: 1137828 | K20: 1855926 | L20: 883070 | M20: 2505352 | N20: 3761532
A22: =SUM(C22:N22) -> 142730381 | B22: TOTAL | C22: 5482175 | D22: =SUM(D18:D20) -> 13403356 | E22: =SUM(E18:E20) -> 10193424 | F22: 9922288 | G22: =SUM(G18:G20) -> 10744147 | H22: =SUM(H18:H20) -> 12032078 | I22: =SUM(I18:I20) -> 7582888 | J22: =SUM(J18:J20) -> 14725964 | K22: =SUM(K18:K20) -> 13822066 | L22: =SUM(L18:L20) -> 9582705 | M22: =SUM(M18:M20) -> 14600855 | N22: =SUM(N18:N20) -> 20638435
B23: =sum(C22:N22) -> 142730381
A24: CPVC FITTING | B24: CPVC | C24: 6117070 | D24: 15496135 | E24: 9666589 | F24: 14204258 | G24: 18482892 | H24: 10005819 | I24: 10021119 | J24: 11467264 | K24: 13211505 | L24: 33066792 | M24: 22475295 | N24: 29714464
A25: CPVC PIPE | B25: CPVC PIPE | C25: 5651931 | D25: 14831072 | E25: 8420427 | F25: 11889066 | G25: 18055874 | H25: 10275997 | I25: 10353651 | J25: 10947742 | K25: 11631260 | L25: 35345323 | M25: 38825890 | N25: 36840689
A26: UPVC FITTING | B26: UPVC | C26: 4154323 | D26: 9503493 | E26: 6456936 | F26: 5861284 | G26: 6235383 | H26: 6119786 | I26: 3789628 | J26: 6573969 | K26: 6205234 | L26: 7205124 | M26: 7913456 | N26: 14215727
A27: UPVC PIPE | B27: UPVC PIPE | C27: 3727425 | D27: 15099719 | E27: 10670290 | F27: 5205006 | G27: 6830420 | H27: 9003867 | I27: 7452625 | J27: 7559688 | K27: 9343253 | L27: 8477036 | M27: 17688832 | N27: 17925754
A28: SWR | B28: SWR | C28: 10834553 | D28: 19902769 | E28: 13277076 | F28: 13305459 | G28: 13129133 | H28: 4703535 | I28: 14267271 | J28: 13969701 | K28: 15771854 | L28: 15488122 | M28: 22710909 | N28: 27148185
A29: AGRI | B29: AGRI | C29: 2229134 | D29: 4516570 | E29: 3299701 | F29: 4999255 | G29: 3538050 | H29: 19973789 | I29: 4175277 | J29: 3314605 | K29: 3828160 | L29: 4554583 | M29: 5820676 | N29: 6174214
