Workbook

Sheet Sheet1
A1: 300005 | B1: 45770 | C1: GULATI TRADERS | D1: GP-345-MW | E1: 45772 | F1: 36 | G1: 365.07 | H1: 12879.67 | I1: GARDEN PIPE | J1: UTTAM NAGAR | K1: DELHI A | L1: ANANT SINGH | M1: PLUMBING GROUP | N1: FY-2025-26 | O1: {=IF(E1:E16335="","",VLOOKUP(E1:E16335,Sheet2!B3:C26,2,0))} -> FY-2025-26
A2: 300005 | B2: 45770 | C2: GULATI TRADERS | D2: GP-364-MW | E2: 45772 | F2: 42 | G2: 730.07 | H2: 30049.68 | I2: GARDEN PIPE | J2: UTTAM NAGAR | K2: DELHI A | L2: ANANT SINGH | M2: PLUMBING GROUP | N2: FY-2025-26 | O2: FY-2025-26
A3: 300005 | B3: 45770 | C3: GULATI TRADERS | D3: GP-346-MW | E3: 45772 | F3: 24 | G3: 540.13 | H3: 12703.86 | I3: GARDEN PIPE | J3: UTTAM NAGAR | K3: DELHI A | L3: ANANT SINGH | M3: PLUMBING GROUP | N3: FY-2025-26 | O3: FY-2025-26
A4: 300005 | B4: 45770 | C4: GULATI TRADERS | D4: GP-367-MW | E4: 45772 | F4: 4 | G4: 1130.32 | H4: 4430.85 | I4: GARDEN PIPE | J4: UTTAM NAGAR | K4: DELHI A | L4: ANANT SINGH | M4: PLUMBING GROUP | N4: FY-2025-26 | O4: FY-2025-26
A5: 300007 | B5: 45770 | C5: LOHIA & SONS (GHAZIABAD) | D5: GP-345-MW | E5: 45772 | F5: 36 | G5: 365.07 | H5: 13142.52 | I5: GARDEN PIPE | J5: SAHIBABAD | K5: UP ( A ) | L5: ANANT SINGH | M5: PLUMBING GROUP | N5: FY-2025-26 | O5: FY-2025-26
A6: 300007 | B6: 45770 | C6: LOHIA & SONS (GHAZIABAD) | D6: GP-346-MW | E6: 45772 | F6: 8 | G6: 540.13 | H6: 4321.04 | I6: GARDEN PIPE | J6: SAHIBABAD | K6: UP ( A ) | L6: ANANT SINGH | M6: PLUMBING GROUP | N6: FY-2025-26 | O6: FY-2025-26
A7: 300007 | B7: 45770 | C7: LOHIA & SONS (GHAZIABAD) | D7: GP-364-MO | E7: 45772 | F7: 12 | G7: 730.07 | H7: 8760.84 | I7: GARDEN PIPE | J7: SAHIBABAD | K7: UP ( A ) | L7: ANANT SINGH | M7: PLUMBING GROUP | N7: FY-2025-26 | O7: FY-2025-26
A8: 300007 | B8: 45770 | C8: LOHIA & SONS (GHAZIABAD) | D8: GP-345-MG | E8: 45772 | F8: 36 | G8: 365.07 | H8: 13142.52 | I8: GARDEN PIPE | J8: SAHIBABAD | K8: UP ( A ) | L8: ANANT SINGH | M8: PLUMBING GROUP | N8: FY-2025-26 | O8: FY-2025-26
A9: 300007 | B9: 45770 | C9: LOHIA & SONS (GHAZIABAD) | D9: GP-364-MW | E9: 45772 | F9: 18 | G9: 730.07 | H9: 13141.26 | I9: GARDEN PIPE | J9: SAHIBABAD | K9: UP ( A ) | L9: ANANT SINGH | M9: PLUMBING GROUP | N9: FY-2025-26 | O9: FY-2025-26
A10: 300007 | B10: 45770 | C10: LOHIA & SONS (GHAZIABAD) | D10: GP-367-MW | E10: 45772 | F10: 4 | G10: 1130.32 | H10: 4521.28 | I10: GARDEN PIPE | J10: SAHIBABAD | K10: UP ( A ) | L10: ANANT SINGH | M10: PLUMBING GROUP | N10: FY-2025-26 | O10: FY-2025-26
A11: 300007 | B11: 45770 | C11: LOHIA & SONS (GHAZIABAD) | D11: GP-345-MO | E11: 45772 | F11: 36 | G11: 365.07 | H11: 13142.52 | I11: GARDEN PIPE | J11: SAHIBABAD | K11: UP ( A ) | L11: ANANT SINGH | M11: PLUMBING GROUP | N11: FY-2025-26 | O11: FY-2025-26
A12: 300007 | B12: 45770 | C12: LOHIA & SONS (GHAZIABAD) | D12: GP-364-MB | E12: 45772 | F12: 18 | G12: 730.07 | H12: 13141.26 | I12: GARDEN PIPE | J12: SAHIBABAD | K12: UP ( A ) | L12: ANANT SINGH | M12: PLUMBING GROUP | N12: FY-2025-26 | O12: FY-2025-26
A13: 300007 | B13: 45770 | C13: LOHIA & SONS (GHAZIABAD) | D13: GP-345-MB | E13: 45772 | F13: 36 | G13: 365.07 | H13: 13142.52 | I13: GARDEN PIPE | J13: SAHIBABAD | K13: UP ( A ) | L13: ANANT SINGH | M13: PLUMBING GROUP | N13: FY-2025-26 | O13: FY-2025-26
A14: 300007 | B14: 45770 | C14: LOHIA & SONS (GHAZIABAD) | D14: GP-364-MG | E14: 45772 | F14: 18 | G14: 730.07 | H14: 13141.26 | I14: GARDEN PIPE | J14: SAHIBABAD | K14: UP ( A ) | L14: ANANT SINGH | M14: PLUMBING GROUP | N14: FY-2025-26 | O14: FY-2025-26
A15: 100166 | B15: 45772 | C15: CHATTAR BHOJ AND SONS (KAROL BAGH) | D15: 103 | E15: 45772 | F15: 108 | G15: 55.68 | H15: 5894.88 | I15: PTMT | J15: DELHI | K15: DELHI A | L15: ANANT SINGH | M15: PTMT GROUP | N15: FY-2025-26 | O15: FY-2025-26
A16: 100166 | B16: 45772 | C16: CHATTAR BHOJ AND SONS (KAROL BAGH) | D16: 187 | E16: 45772 | F16: 66 | G16: 243.84 | H16: 15773.28 | I16: PTMT | J16: DELHI | K16: DELHI A | L16: ANANT SINGH | M16: PTMT GROUP | N16: FY-2025-26 | O16: FY-2025-26
A17: 100166 | B17: 45772 | C17: CHATTAR BHOJ AND SONS (KAROL BAGH) | D17: 121 | E17: 45772 | F17: 216 | G17: 95.52 | H17: 20221.38 | I17: PTMT | J17: DELHI | K17: DELHI A | L17: ANANT SINGH | M17: PTMT GROUP | N17: FY-2025-26 | O17: FY-2025-26
A18: 100167 | B18: 45772 | C18: CHATTAR BHOJ AND SONS (KAROL BAGH) | D18: 190 | E18: 45772 | F18: 56 | G18: 191.04 | H18: 10485.88 | I18: PTMT | J18: DELHI | K18: DELHI A | L18: ANANT SINGH | M18: PTMT GROUP | N18: FY-2025-26 | O18: FY-2025-26
A19: 100167 | B19: 45772 | C19: CHATTAR BHOJ AND SONS (KAROL BAGH) | D19: 187 | E19: 45772 | F19: 66 | G19: 243.84 | H19: 15773.17 | I19: PTMT | J19: DELHI | K19: DELHI A | L19: ANANT SINGH | M19: PTMT GROUP | N19: FY-2025-26 | O19: FY-2025-26
A20: 100167 | B20: 45772 | C20: CHATTAR BHOJ AND SONS (KAROL BAGH) | D20: 121 | E20: 45772 | F20: 216 | G20: 95.52 | H20: 20221.28 | I20: PTMT | J20: DELHI | K20: DELHI A | L20: ANANT SINGH | M20: PTMT GROUP | N20: FY-2025-26 | O20: FY-2025-26
A21: 100167 | B21: 45772 | C21: CHATTAR BHOJ AND SONS (KAROL BAGH) | D21: 103 | E21: 45772 | F21: 108 | G21: 55.68 | H21: 5894.77 | I21: PTMT | J21: DELHI | K21: DELHI A | L21: ANANT SINGH | M21: PTMT GROUP | N21: FY-2025-26 | O21: FY-2025-26
A22: 100255 | B22: 45775 | C22: S S SANITATAION | D22: BEA-88B | E22: 45772 | F22: 120 | G22: 340.4 | H22: 40035.94 | I22: CP ACCESSORIES | J22: NOIDA | K22: DELHI NCR | L22: ANANT SINGH | M22: C P GROUP | N22: FY-2025-26 | O22: FY-2025-26
A23: 100269 | B23: 45775 | C23: SUMIT PAINT AND HARDWARE | D23: 1375-S | E23: 45772 | F23: 6 | G23: 719.04 | H23: 4316.14 | I23: PTMT | J23: NEW DELHI | K23: DELHI A | L23: ANANT SINGH | M23: PTMT GROUP | N23: FY-2025-26 | O23: FY-2025-26
A24: 100269 | B24: 45775 | C24: SUMIT PAINT AND HARDWARE | D24: 124 | E24: 45772 | F24: 92 | G24: 126.72 | H24: 11660.14 | I24: PTMT | J24: NEW DELHI | K24: DELHI A | L24: ANANT SINGH | M24: PTMT GROUP | N24: FY-2025-26 | O24: FY-2025-26
A25: 100269 | B25: 45775 | C25: SUMIT PAINT AND HARDWARE | D25: 151 | E25: 45772 | F25: 70 | G25: 298 | H25: 20861.9 | I25: PTMT | J25: NEW DELHI | K25: DELHI A | L25: ANANT SINGH | M25: PTMT GROUP | N25: FY-2025-26 | O25: FY-2025-26
A26: 100269 | B26: 45775 | C26: SUMIT PAINT AND HARDWARE | D26: 152 | E26: 45772 | F26: 66 | G26: 215.04 | H26: 14194.54 | I26: PTMT | J26: NEW DELHI | K26: DELHI A | L26: ANANT SINGH | M26: PTMT GROUP | N26: FY-2025-26 | O26: FY-2025-26
A27: 100269 | B27: 45775 | C27: SUMIT PAINT AND HARDWARE | D27: 324 | E27: 45772 | F27: 300 | G27: 51.84 | H27: 15553.9 | I27: CONNECTION | J27: NEW DELHI | K27: DELHI A | L27: ANANT SINGH | M27: PTMT GROUP | N27: FY-2025-26 | O27: FY-2025-26
A28: 100269 | B28: 45775 | C28: SUMIT PAINT AND HARDWARE | D28: 129 | E28: 45772 | F28: 24 | G28: 226.56 | H28: 5439.34 | I28: PTMT | J28: NEW DELHI | K28: DELHI A | L28: ANANT SINGH | M28: PTMT GROUP | N28: FY-2025-26 | O28: FY-2025-26
A29: 100269 | B29: 45775 | C29: SUMIT PAINT AND HARDWARE | D29: 132-T | E29: 45772 | F29: 30 | G29: 275.52 | H29: 8267.5 | I29: PTMT | J29: NEW DELHI | K29: DELHI A | L29: ANANT SINGH | M29: PTMT GROUP | N29: FY-2025-26 | O29: FY-2025-26
A30: 100269 | B30: 45775 | C30: SUMIT PAINT AND HARDWARE | D30: 187 | E30: 45772 | F30: 154 | G30: 243.84 | H30: 37553.26 | I30: PTMT | J30: NEW DELHI | K30: DELHI A | L30: ANANT SINGH | M30: PTMT GROUP | N30: FY-2025-26 | O30: FY-2025-26
A31: 100269 | B31: 45775 | C31: SUMIT PAINT AND HARDWARE | D31: 144 | E31: 45772 | F31: 270 | G31: 93.6 | H31: 25273.9 | I31: PTMT | J31: NEW DELHI | K31: DELHI A | L31: ANANT SINGH | M31: PTMT GROUP | N31: FY-2025-26 | O31: FY-2025-26
A32: 100269 | B32: 45775 | C32: SUMIT PAINT AND HARDWARE | D32: 147 | E32: 45772 | F32: 30 | G32: 285.12 | H32: 8555.5 | I32: PTMT | J32: NEW DELHI | K32: DELHI A | L32: ANANT SINGH | M32: PTMT GROUP | N32: FY-2025-26 | O32: FY-2025-26
A33: 100269 | B33: 45775 | C33: SUMIT PAINT AND HARDWARE | D33: 153 | E33: 45772 | F33: 75 | G33: 395.52 | H33: 29665.9 | I33: PTMT | J33: NEW DELHI | K33: DELHI A | L33: ANANT SINGH | M33: PTMT GROUP | N33: FY-2025-26 | O33: FY-2025-26
A34: 100269 | B34: 45775 | C34: SUMIT PAINT AND HARDWARE | D34: 150 | E34: 45772 | F34: 14 | G34: 614.4 | H34: 8603.5 | I34: PTMT | J34: NEW DELHI | K34: DELHI A | L34: ANANT SINGH | M34: PTMT GROUP | N34: FY-2025-26 | O34: FY-2025-26
A35: 100278 | B35: 45775 | C35: S S SANITATAION | D35: 144-QR | E35: 45772 | F35: 66 | G35: 152.64 | H35: 9873.93 | I35: PTMT | J35: NOIDA | K35: DELHI NCR | L35: ANANT SINGH | M35: PTMT GROUP | N35: FY-2025-26 | O35: FY-2025-26
A36: 100278 | B36: 45775 | C36: S S SANITATAION | D36: 144-Q | E36: 45772 | F36: 66 | G36: 143.04 | H36: 9253 | I36: PTMT | J36: NOIDA | K36: DELHI NCR | L36: ANANT SINGH | M36: PTMT GROUP | N36: FY-2025-26 | O36: FY-2025-26
A37: 100280 | B37: 45775 | C37: S S SANITATAION | D37: 123-QR | E37: 45772 | F37: 99 | G37: 156.48 | H37: 15182.81 | I37: PTMT | J37: NOIDA | K37: DELHI NCR | L37: ANANT SINGH | M37: PTMT GROUP | N37: FY-2025-26 | O37: FY-2025-26
A38: 100280 | B38: 45775 | C38: S S SANITATAION | D38: 124 | E38: 45772 | F38: 92 | G38: 126.72 | H38: 11426.19 | I38: PTMT | J38: NOIDA | K38: DELHI NCR | L38: ANANT SINGH | M38: PTMT GROUP | N38: FY-2025-26 | O38: FY-2025-26
A39: 100280 | B39: 45775 | C39: S S SANITATAION | D39: 5211 | E39: 45772 | F39: 26 | G39: 147.84 | H39: 3768.08 | I39: PTMT | J39: NOIDA | K39: DELHI NCR | L39: ANANT SINGH | M39: PTMT GROUP | N39: FY-2025-26 | O39: FY-2025-26
A40: 100280 | B40: 45775 | C40: S S SANITATAION | D40: 1817-C | E40: 45772 | F40: 30 | G40: 218.88 | H40: 6436.19 | I40: PTMT | J40: NOIDA | K40: DELHI NCR | L40: ANANT SINGH | M40: PTMT GROUP | N40: FY-2025-26 | O40: FY-2025-26
...

Sheet Sale & Collection 
B2: =sum(B4:B28) -> 30335607 | C2: =sum(C4:C28) -> 31530001
A3: Month | B3: Sale With Gst | C3: Collection
A4: 46138 | B4: =sumif(Sheet1!E:E,A4,Sheet1!H:H)+sumif(Sheet1!E:E,A4,Sheet1!H:H)*18% -> 854372.66 | C4: =sumif(Sheet2!X:X,A4,Sheet2!W:W) -> 6313539
A6: 46168 | B6: =sumif(Sheet1!E:E,A6,Sheet1!H:H)+sumif(Sheet1!E:E,A6,Sheet1!H:H)*18% -> 15384793 | C6: =sumif(Sheet2!X:X,A6,Sheet2!W:W) -> 10250015
A8: 46199 | B8: =sumif(Sheet1!E:E,A8,Sheet1!H:H)+sumif(Sheet1!E:E,A8,Sheet1!H:H)*18% -> 13902461 | C8: =sumif(Sheet2!X:X,A8,Sheet2!W:W) -> 12393967
A10: 46229 | B10: =sumif(Sheet1!E:E,A10,Sheet1!H:H)+sumif(Sheet1!E:E,A10,Sheet1!H:H)*18% -> 193980.81 | C10: =sumif(Sheet2!X:X,A10,Sheet2!W:W) -> 2572480
A12: 46260 | B12: =sumif(Sheet1!E:E,A12,Sheet1!H:H)+sumif(Sheet1!E:E,A12,Sheet1!H:H)*18% -> 0 | C12: =sumif(Sheet2!X:X,A12,Sheet2!W:W) -> 0
A14: 46291 | B14: =sumif(Sheet1!E:E,A14,Sheet1!H:H)+sumif(Sheet1!E:E,A14,Sheet1!H:H)*18% -> 0 | C14: =sumif(Sheet2!X:X,A14,Sheet2!W:W) -> 0
A16: 46321 | B16: =sumif(Sheet1!E:E,A16,Sheet1!H:H)+sumif(Sheet1!E:E,A16,Sheet1!H:H)*18% -> 0 | C16: =sumif(Sheet2!X:X,A16,Sheet2!W:W) -> 0
A18: 46352 | B18: =sumif(Sheet1!E:E,A18,Sheet1!H:H)+sumif(Sheet1!E:E,A18,Sheet1!H:H)*18% -> 0 | C18: =sumif(Sheet2!X:X,A18,Sheet2!W:W) -> 0
A20: 46382 | B20: =sumif(Sheet1!E:E,A20,Sheet1!H:H)+sumif(Sheet1!E:E,A20,Sheet1!H:H)*18% -> 0 | C20: =sumif(Sheet2!X:X,A20,Sheet2!W:W) -> 0
A22: 46414 | B22: =sumif(Sheet1!E:E,A22,Sheet1!H:H)+sumif(Sheet1!E:E,A22,Sheet1!H:H)*18% -> 0 | C22: =sumif(Sheet2!X:X,A22,Sheet2!W:W) -> 0
A24: 46445 | B24: =sumif(Sheet1!E:E,A24,Sheet1!H:H)+sumif(Sheet1!E:E,A24,Sheet1!H:H)*18% -> 0 | C24: =sumif(Sheet2!X:X,A24,Sheet2!W:W) -> 0
A26: 46473 | B26: =sumif(Sheet1!E:E,A26,Sheet1!H:H)+sumif(Sheet1!E:E,A26,Sheet1!H:H)*18% -> 0 | C26: =sumif(Sheet2!X:X,A26,Sheet2!W:W) -> 0

Sheet Report 1
C3: =SUM(C5:C1000) -> 23066986 | D3: =SUM(D5:D1000) -> 25708142 | E3: =D3-C3 -> 2641155.8 | F3: =(D3-C3)/C3 -> 0.11449939 | G3: =SUM(G5:G1000) -> 1 | J3: UP ( A ) | K3: Total | L3: =sum(L5:L1000) -> 13402370 | M3: =sum(M5:M1000) -> 13045514 | N3: =M3-L3 -> -356855.76 | O3: =IF(K3="","",IF(M3="","-100%",(M3-L3)/L3)) -> -0.026626317 | P3: =sum(P5:P1000) -> 1
B4: =IFERROR(__xludf.DUMMYFUNCTION("QUERY(Sheet1!A1:O1000,""SELECT K,SUM(H) WHERE O IS NOT NULL GROUP BY K PIVOT N LABEL K 'STATE', SUM(H) 'Sale' FORMAT SUM(H) '##'"")"),"STATE") -> STATE | C4: =IFERROR(__xludf.DUMMYFUNCTION("""COMPUTED_VALUE"""),"FY-2025-26 Sale") -> FY-2025-26 Sale | D4: =IFERROR(__xludf.DUMMYFUNCTION("""COMPUTED_VALUE"""),"FY-2026-27 Sale") -> FY-2026-27 Sale | E4: Difference | F4: Growth % | G4: Share % | K4: =IFERROR(__xludf.DUMMYFUNCTION("SORT(QUERY(Sheet1!A1:O1000,""SELECT C,SUM(H) WHERE O IS NOT NULL AND K CONTAINS '""&J3&""' GROUP BY C PIVOT N LABEL C 'Party' , SUM(H) 'Sale' FORMAT SUM(H) '##' ""),3,0)"),"Party") -> Party | L4: =IFERROR(__xludf.DUMMYFUNCTION("""COMPUTED_VALUE"""),"FY-2025-26 Sale") -> FY-2025-26 Sale | M4: =IFERROR(__xludf.DUMMYFUNCTION("""COMPUTED_VALUE"""),"FY-2026-27 Sale") -> FY-2026-27 Sale
B5: =IFERROR(__xludf.DUMMYFUNCTION("""COMPUTED_VALUE"""),"DELHI A") -> DELHI A | C5: =IFERROR(__xludf.DUMMYFUNCTION("""COMPUTED_VALUE"""),4057826.140000001) -> 4057826.1 | D5: =IFERROR(__xludf.DUMMYFUNCTION("""COMPUTED_VALUE"""),3806216.71) -> 3806216.7 | E5: =IF(D5="","",D5-C5) -> -251609.43 | F5: =IFERROR((D5-C5)/C5,"") -> -0.062005966 | G5: =IF(D5="","",D5/D$3) -> 0.14805491 | J5: =IFERROR(__xludf.DUMMYFUNCTION("ArrayFormula(IF(K5:K1000="""","""",VLOOKUP(K5:K1000,IMPORTRANGE(""https://docs.google.com/spreadsheets/d/1njO-srsS29qiE4t45-zr5njbB7R2Zb-oSnv2NL1ONY4/edit?gid=63200363#gid=63200363"",""Sheet2!A2:D""),2,0)))"),"MATHURA") -> MATHURA | K5: =IFERROR(__xludf.DUMMYFUNCTION("""COMPUTED_VALUE"""),"NITIN TRADERS") -> NITIN TRADERS | L5: =IFERROR(__xludf.DUMMYFUNCTION("""COMPUTED_VALUE"""),2917384.4299999997) -> 2917384.4 | M5: =IFERROR(__xludf.DUMMYFUNCTION("""COMPUTED_VALUE"""),3037012.0) -> 3037012 | N5: =IF(K5="","",M5-L5) -> 119627.57 | O5: =IFERROR(IF(K5="","",IF(M5="","-100%",(M5-L5)/L5)),100%) -> 0.041005076 | P5: =IF(K5="","",M5/$M$3) -> 0.23280125
B6: =IFERROR(__xludf.DUMMYFUNCTION("""COMPUTED_VALUE"""),"DELHI NCR") -> DELHI NCR | C6: =IFERROR(__xludf.DUMMYFUNCTION("""COMPUTED_VALUE"""),2408782.1000000006) -> 2408782.1 | D6: =IFERROR(__xludf.DUMMYFUNCTION("""COMPUTED_VALUE"""),2215644.0) -> 2215644 | E6: =IF(D6="","",D6-C6) -> -193138.1 | F6: =IFERROR((D6-C6)/C6,"") -> -0.08018081 | G6: =IF(D6="","",D6/D$3) -> 0.086184526 | J6: =IFERROR(__xludf.DUMMYFUNCTION("""COMPUTED_VALUE"""),"Aligarh") -> Aligarh | K6: =IFERROR(__xludf.DUMMYFUNCTION("""COMPUTED_VALUE"""),"Vidhya Sales") -> Vidhya Sales | L6: =IFERROR(__xludf.DUMMYFUNCTION("""COMPUTED_VALUE"""),624826.2999999999) -> 624826.3 | M6: =IFERROR(__xludf.DUMMYFUNCTION("""COMPUTED_VALUE"""),2530306.41) -> 2530306.4 | N6: =IF(K6="","",M6-L6) -> 1905480.1 | O6: =IFERROR(IF(K6="","",IF(M6="","-100%",(M6-L6)/L6)),100%) -> 3.0496157 | P6: =IF(K6="","",M6/$M$3) -> 0.19395988
B7: =IFERROR(__xludf.DUMMYFUNCTION("""COMPUTED_VALUE"""),"UP ( A )") -> UP ( A ) | C7: =IFERROR(__xludf.DUMMYFUNCTION("""COMPUTED_VALUE"""),1.3402370129999992E7) -> 13402370 | D7: =IFERROR(__xludf.DUMMYFUNCTION("""COMPUTED_VALUE"""),1.3045514370000001E7) -> 13045514 | E7: =IF(D7="","",D7-C7) -> -356855.76 | F7: =IFERROR((D7-C7)/C7,"") -> -0.026626317 | G7: =IF(D7="","",D7/D$3) -> 0.5074468 | J7: =IFERROR(__xludf.DUMMYFUNCTION("""COMPUTED_VALUE"""),"SAHIBABAD") -> SAHIBABAD | K7: =IFERROR(__xludf.DUMMYFUNCTION("""COMPUTED_VALUE"""),"LOHIA & SONS (GHAZIABAD)") -> LOHIA & SONS (GHAZIABAD) | L7: =IFERROR(__xludf.DUMMYFUNCTION("""COMPUTED_VALUE"""),5487212.180000002) -> 5487212.2 | M7: =IFERROR(__xludf.DUMMYFUNCTION("""COMPUTED_VALUE"""),2515196.0) -> 2515196 | N7: =IF(K7="","",M7-L7) -> -2972016.2 | O7: =IFERROR(IF(K7="","",IF(M7="","-100%",(M7-L7)/L7)),100%) -> -0.54162589 | P7: =IF(K7="","",M7/$M$3) -> 0.1928016
B8: =IFERROR(__xludf.DUMMYFUNCTION("""COMPUTED_VALUE"""),"Uttarakhand") -> Uttarakhand | C8: =IFERROR(__xludf.DUMMYFUNCTION("""COMPUTED_VALUE"""),3198007.619999999) -> 3198007.6 | D8: =IFERROR(__xludf.DUMMYFUNCTION("""COMPUTED_VALUE"""),6640766.660000001) -> 6640766.7 | E8: =IF(D8="","",D8-C8) -> 3442759 | F8: =IFERROR((D8-C8)/C8,"") -> 1.0765325 | G8: =IF(D8="","",D8/D$3) -> 0.25831376 | J8: =IFERROR(__xludf.DUMMYFUNCTION("""COMPUTED_VALUE"""),"MORADABAD") -> MORADABAD | K8: =IFERROR(__xludf.DUMMYFUNCTION("""COMPUTED_VALUE"""),"AVANTI SALES & AGENCIES(MORADABAD)") -> AVANTI SALES & AGENCIES(MORADABAD) | L8: =IFERROR(__xludf.DUMMYFUNCTION("""COMPUTED_VALUE"""),1796357.4499999993) -> 1796357.4 | M8: =IFERROR(__xludf.DUMMYFUNCTION("""COMPUTED_VALUE"""),2333239.2) -> 2333239.2 | N8: =IF(K8="","",M8-L8) -> 536881.75 | O8: =IFERROR(IF(K8="","",IF(M8="","-100%",(M8-L8)/L8)),100%) -> 0.29887245 | P8: =IF(K8="","",M8/$M$3) -> 0.17885375
E9: =IF(D9="","",D9-C9) | F9: =IFERROR((D9-C9)/C9,"") | G9: =IF(D9="","",D9/D$3) | J9: =IFERROR(__xludf.DUMMYFUNCTION("""COMPUTED_VALUE"""),"MEERUT") -> MEERUT | K9: =IFERROR(__xludf.DUMMYFUNCTION("""COMPUTED_VALUE"""),"SUNITA ENTERPRISES") -> SUNITA ENTERPRISES | M9: =IFERROR(__xludf.DUMMYFUNCTION("""COMPUTED_VALUE"""),1554643.7599999998) -> 1554643.8 | N9: =IF(K9="","",M9-L9) -> 1554643.8 | O9: =IFERROR(IF(K9="","",IF(M9="","-100%",(M9-L9)/L9)),100%) -> 1 | P9: =IF(K9="","",M9/$M$3) -> 0.11917075
E10: =IF(D10="","",D10-C10) | F10: =IFERROR((D10-C10)/C10,"") | G10: =IF(D10="","",D10/D$3) | J10: =IFERROR(__xludf.DUMMYFUNCTION("""COMPUTED_VALUE"""),"MATHURA") -> MATHURA | K10: =IFERROR(__xludf.DUMMYFUNCTION("""COMPUTED_VALUE"""),"HARSH TRADING COMPANY") -> HARSH TRADING COMPANY | M10: =IFERROR(__xludf.DUMMYFUNCTION("""COMPUTED_VALUE"""),373800.0) -> 373800 | N10: =IF(K10="","",M10-L10) -> 373800 | O10: =IFERROR(IF(K10="","",IF(M10="","-100%",(M10-L10)/L10)),100%) -> 1 | P10: =IF(K10="","",M10/$M$3) -> 0.028653527
E11: =IF(D11="","",D11-C11) | F11: =IFERROR((D11-C11)/C11,"") | G11: =IF(D11="","",D11/D$3) | J11: =IFERROR(__xludf.DUMMYFUNCTION("""COMPUTED_VALUE"""),"GHAZIABAD") -> GHAZIABAD | K11: =IFERROR(__xludf.DUMMYFUNCTION("""COMPUTED_VALUE"""),"MANSI TRADING COMPANY(UP)") -> MANSI TRADING COMPANY(UP) | M11: =IFERROR(__xludf.DUMMYFUNCTION("""COMPUTED_VALUE"""),291072.0) -> 291072 | N11: =IF(K11="","",M11-L11) -> 291072 | O11: =IFERROR(IF(K11="","",IF(M11="","-100%",(M11-L11)/L11)),100%) -> 1 | P11: =IF(K11="","",M11/$M$3) -> 0.022312037
E12: =IF(D12="","",D12-C12) | F12: =IFERROR((D12-C12)/C12,"") | G12: =IF(D12="","",D12/D$3) | J12: =IFERROR(__xludf.DUMMYFUNCTION("""COMPUTED_VALUE"""),"AGRA") -> AGRA | K12: =IFERROR(__xludf.DUMMYFUNCTION("""COMPUTED_VALUE"""),"VINOD TRADERS") -> VINOD TRADERS | M12: =IFERROR(__xludf.DUMMYFUNCTION("""COMPUTED_VALUE"""),238481.0) -> 238481 | N12: =IF(K12="","",M12-L12) -> 238481 | O12: =IFERROR(IF(K12="","",IF(M12="","-100%",(M12-L12)/L12)),100%) -> 1 | P12: =IF(K12="","",M12/$M$3) -> 0.01828069
E13: =IF(D13="","",D13-C13) | F13: =IFERROR((D13-C13)/C13,"") | G13: =IF(D13="","",D13/D$3) | J13: =IFERROR(__xludf.DUMMYFUNCTION("""COMPUTED_VALUE"""),"GHAZIABAD") -> GHAZIABAD | K13: =IFERROR(__xludf.DUMMYFUNCTION("""COMPUTED_VALUE"""),"AMAN TRADERS") -> AMAN TRADERS | M13: =IFERROR(__xludf.DUMMYFUNCTION("""COMPUTED_VALUE"""),171764.0) -> 171764 | N13: =IF(K13="","",M13-L13) -> 171764 | O13: =IFERROR(IF(K13="","",IF(M13="","-100%",(M13-L13)/L13)),100%) -> 1 | P13: =IF(K13="","",M13/$M$3) -> 0.013166518
E14: =IF(D14="","",D14-C14) | F14: =IFERROR((D14-C14)/C14,"") | G14: =IF(D14="","",D14/D$3) | J14: =IFERROR(__xludf.DUMMYFUNCTION("""COMPUTED_VALUE"""),"MEERUT") -> MEERUT | K14: =IFERROR(__xludf.DUMMYFUNCTION("""COMPUTED_VALUE"""),"DEEPAK SANITORY & ELECTRIC STORE") -> DEEPAK SANITORY & ELECTRIC STORE | L14: =IFERROR(__xludf.DUMMYFUNCTION("""COMPUTED_VALUE"""),374039.0) -> 374039 | N14: =IF(K14="","",M14-L14) -> -374039 | O14: =IFERROR(IF(K14="","",IF(M14="","-100%",(M14-L14)/L14)),100%) -> -100% | P14: =IF(K14="","",M14/$M$3) -> 0
E15: =IF(D15="","",D15-C15) | F15: =IFERROR((D15-C15)/C15,"") | G15: =IF(D15="","",D15/D$3) | J15: =IFERROR(__xludf.DUMMYFUNCTION("""COMPUTED_VALUE"""),"SAHARANPUR") -> SAHARANPUR | K15: =IFERROR(__xludf.DUMMYFUNCTION("""COMPUTED_VALUE"""),"DELUXE SANITARY STORE") -> DELUXE SANITARY STORE | L15: =IFERROR(__xludf.DUMMYFUNCTION("""COMPUTED_VALUE"""),91422.88999999998) -> 91422.89 | N15: =IF(K15="","",M15-L15) -> -91422.89 | O15: =IFERROR(IF(K15="","",IF(M15="","-100%",(M15-L15)/L15)),100%) -> -100% | P15: =IF(K15="","",M15/$M$3) -> 0
E16: =IF(D16="","",D16-C16) | G16: =IF(D16="","",D16/D$3) | J16: =IFERROR(__xludf.DUMMYFUNCTION("""COMPUTED_VALUE"""),"MATHURA") -> MATHURA | K16: =IFERROR(__xludf.DUMMYFUNCTION("""COMPUTED_VALUE"""),"HINDUSTAN SANITARY STORES") -> HINDUSTAN SANITARY STORES | L16: =IFERROR(__xludf.DUMMYFUNCTION("""COMPUTED_VALUE"""),74058.5) -> 74058.5 | N16: =IF(K16="","",M16-L16) -> -74058.5 | O16: =IFERROR(IF(K16="","",IF(M16="","-100%",(M16-L16)/L16)),100%) -> -100% | P16: =IF(K16="","",M16/$M$3) -> 0
G17: =IF(D17="","",D17/D$3) | J17: =IFERROR(__xludf.DUMMYFUNCTION("""COMPUTED_VALUE"""),"MORADABAD") -> MORADABAD | K17: =IFERROR(__xludf.DUMMYFUNCTION("""COMPUTED_VALUE"""),"INDIAN TRADERS") -> INDIAN TRADERS | L17: =IFERROR(__xludf.DUMMYFUNCTION("""COMPUTED_VALUE"""),61490.04) -> 61490.04 | N17: =IF(K17="","",M17-L17) -> -61490.04 | O17: =IFERROR(IF(K17="","",IF(M17="","-100%",(M17-L17)/L17)),100%) -> -100% | P17: =IF(K17="","",M17/$M$3) -> 0
J18: =IFERROR(__xludf.DUMMYFUNCTION("""COMPUTED_VALUE"""),"Rampur") -> Rampur | K18: =IFERROR(__xludf.DUMMYFUNCTION("""COMPUTED_VALUE"""),"JAIN TRADERS") -> JAIN TRADERS | L18: =IFERROR(__xludf.DUMMYFUNCTION("""COMPUTED_VALUE"""),71275.0) -> 71275 | N18: =IF(K18="","",M18-L18) -> -71275 | O18: =IFERROR(IF(K18="","",IF(M18="","-100%",(M18-L18)/L18)),100%) -> -100% | P18: =IF(K18="","",M18/$M$3) -> 0
J19: =IFERROR(__xludf.DUMMYFUNCTION("""COMPUTED_VALUE"""),"AMROHA") -> AMROHA | K19: =IFERROR(__xludf.DUMMYFUNCTION("""COMPUTED_VALUE"""),"KULDEEP AGRICULTURE STORE") -> KULDEEP AGRICULTURE STORE | L19: =IFERROR(__xludf.DUMMYFUNCTION("""COMPUTED_VALUE"""),62021.12) -> 62021.12 | N19: =IF(K19="","",M19-L19) -> -62021.12 | O19: =IFERROR(IF(K19="","",IF(M19="","-100%",(M19-L19)/L19)),100%) -> -100% | P19: =IF(K19="","",M19/$M$3) -> 0
J20: =IFERROR(__xludf.DUMMYFUNCTION("""COMPUTED_VALUE"""),"AMROHA") -> AMROHA | K20: =IFERROR(__xludf.DUMMYFUNCTION("""COMPUTED_VALUE"""),"KUMAR PIPE AND HARDWARE STORE") -> KUMAR PIPE AND HARDWARE STORE | L20: =IFERROR(__xludf.DUMMYFUNCTION("""COMPUTED_VALUE"""),164411.38) -> 164411.38 | N20: =IF(K20="","",M20-L20) -> -164411.38 | O20: =IFERROR(IF(K20="","",IF(M20="","-100%",(M20-L20)/L20)),100%) -> -100% | P20: =IF(K20="","",M20/$M$3) -> 0
J21: =IFERROR(__xludf.DUMMYFUNCTION("""COMPUTED_VALUE"""),"MEERUT") -> MEERUT | K21: =IFERROR(__xludf.DUMMYFUNCTION("""COMPUTED_VALUE"""),"MAHAVEER SANITARY WARE & HARDWARE STORE") -> MAHAVEER SANITARY WARE & HARDWARE STORE | L21: =IFERROR(__xludf.DUMMYFUNCTION("""COMPUTED_VALUE"""),99770.0) -> 99770 | N21: =IF(K21="","",M21-L21) -> -99770 | O21: =IFERROR(IF(K21="","",IF(M21="","-100%",(M21-L21)/L21)),100%) -> -100% | P21: =IF(K21="","",M21/$M$3) -> 0
J22: =IFERROR(__xludf.DUMMYFUNCTION("""COMPUTED_VALUE"""),"MATHURA") -> MATHURA | K22: =IFERROR(__xludf.DUMMYFUNCTION("""COMPUTED_VALUE"""),"RAJENDRA PRASAD & CO.") -> RAJENDRA PRASAD & CO. | L22: =IFERROR(__xludf.DUMMYFUNCTION("""COMPUTED_VALUE"""),353465.16) -> 353465.16 | N22: =IF(K22="","",M22-L22) -> -353465.16 | O22: =IFERROR(IF(K22="","",IF(M22="","-100%",(M22-L22)/L22)),100%) -> -100% | P22: =IF(K22="","",M22/$M$3) -> 0
J23: =IFERROR(__xludf.DUMMYFUNCTION("""COMPUTED_VALUE"""),"Hathras") -> Hathras | K23: =IFERROR(__xludf.DUMMYFUNCTION("""COMPUTED_VALUE"""),"RATHI SALES CORP.") -> RATHI SALES CORP. | L23: =IFERROR(__xludf.DUMMYFUNCTION("""COMPUTED_VALUE"""),673174.05) -> 673174.05 | N23: =IF(K23="","",M23-L23) -> -673174.05 | O23: =IFERROR(IF(K23="","",IF(M23="","-100%",(M23-L23)/L23)),100%) -> -100% | P23: =IF(K23="","",M23/$M$3) -> 0
J24: =IFERROR(__xludf.DUMMYFUNCTION("""COMPUTED_VALUE"""),"Baghpat") -> Baghpat | K24: =IFERROR(__xludf.DUMMYFUNCTION("""COMPUTED_VALUE"""),"SAURABH SANITARY STORE") -> SAURABH SANITARY STORE | L24: =IFERROR(__xludf.DUMMYFUNCTION("""COMPUTED_VALUE"""),246298.55) -> 246298.55 | N24: =IF(K24="","",M24-L24) -> -246298.55 | O24: =IFERROR(IF(K24="","",IF(M24="","-100%",(M24-L24)/L24)),100%) -> -100% | P24: =IF(K24="","",M24/$M$3) -> 0
J25: =IFERROR(__xludf.DUMMYFUNCTION("""COMPUTED_VALUE"""),"MATHURA") -> MATHURA | K25: =IFERROR(__xludf.DUMMYFUNCTION("""COMPUTED_VALUE"""),"SHARMA PIPE FITTINGS & SANITARY STORE") -> SHARMA PIPE FITTINGS & SANITARY STORE | L25: =IFERROR(__xludf.DUMMYFUNCTION("""COMPUTED_VALUE"""),213226.08000000002) -> 213226.08 | N25: =IF(K25="","",M25-L25) -> -213226.08 | O25: =IFERROR(IF(K25="","",IF(M25="","-100%",(M25-L25)/L25)),100%) -> -100% | P25: =IF(K25="","",M25/$M$3) -> 0
J26: =IFERROR(__xludf.DUMMYFUNCTION("""COMPUTED_VALUE"""),"Bulandshahr") -> Bulandshahr | K26: =IFERROR(__xludf.DUMMYFUNCTION("""COMPUTED_VALUE"""),"Vihan Marbles & Tiles") -> Vihan Marbles & Tiles | L26: =IFERROR(__xludf.DUMMYFUNCTION("""COMPUTED_VALUE"""),91938.0) -> 91938 | N26: =IF(K26="","",M26-L26) -> -91938 | O26: =IFERROR(IF(K26="","",IF(M26="","-100%",(M26-L26)/L26)),100%) -> -100% | P26: =IF(K26="","",M26/$M$3) -> 0
J27: =IFERROR(__xludf.DUMMYFUNCTION("""COMPUTED_VALUE"""),"") | N27: =IF(K27="","",M27-L27) | O27: =IFERROR(IF(K27="","",IF(M27="","-100%",(M27-L27)/L27)),100%) | P27: =IF(K27="","",M27/$M$3)
J28: =IFERROR(__xludf.DUMMYFUNCTION("""COMPUTED_VALUE"""),"") | N28: =IF(K28="","",M28-L28) | O28: =IFERROR(IF(K28="","",IF(M28="","-100%",(M28-L28)/L28)),100%) | P28: =IF(K28="","",M28/$M$3)
J29: =IFERROR(__xludf.DUMMYFUNCTION("""COMPUTED_VALUE"""),"") | N29: =IF(K29="","",M29-L29) | O29: =IFERROR(IF(K29="","",IF(M29="","-100%",(M29-L29)/L29)),100%) | P29: =IF(K29="","",M29/$M$3)
J30: =IFERROR(__xludf.DUMMYFUNCTION("""COMPUTED_VALUE"""),"") | N30: =IF(K30="","",M30-L30) | O30: =IFERROR(IF(K30="","",IF(M30="","-100%",(M30-L30)/L30)),100%) | P30: =IF(K30="","",M30/$M$3)
J31: =IFERROR(__xludf.DUMMYFUNCTION("""COMPUTED_VALUE"""),"") | N31: =IF(K31="","",M31-L31) | O31: =IFERROR(IF(K31="","",IF(M31="","-100%",(M31-L31)/L31)),100%) | P31: =IF(K31="","",M31/$M$3)
J32: =IFERROR(__xludf.DUMMYFUNCTION("""COMPUTED_VALUE"""),"") | N32: =IF(K32="","",M32-L32) | O32: =IFERROR(IF(K32="","",IF(M32="","-100%",(M32-L32)/L32)),100%) | P32: =IF(K32="","",M32/$M$3)
J33: =IFERROR(__xludf.DUMMYFUNCTION("""COMPUTED_VALUE"""),"") | N33: =IF(K33="","",M33-L33) | O33: =IFERROR(IF(K33="","",IF(M33="","-100%",(M33-L33)/L33)),100%) | P33: =IF(K33="","",M33/$M$3)
J34: =IFERROR(__xludf.DUMMYFUNCTION("""COMPUTED_VALUE"""),"") | N34: =IF(K34="","",M34-L34) | O34: =IFERROR(IF(K34="","",IF(M34="","-100%",(M34-L34)/L34)),100%) | P34: =IF(K34="","",M34/$M$3)
J35: =IFERROR(__xludf.DUMMYFUNCTION("""COMPUTED_VALUE"""),"") | N35: =IF(K35="","",M35-L35) | O35: =IFERROR(IF(K35="","",IF(M35="","-100%",(M35-L35)/L35)),100%) | P35: =IF(K35="","",M35/$M$3)
J36: =IFERROR(__xludf.DUMMYFUNCTION("""COMPUTED_VALUE"""),"") | N36: =IF(K36="","",M36-L36) | O36: =IFERROR(IF(K36="","",IF(M36="","-100%",(M36-L36)/L36)),100%) | P36: =IF(K36="","",M36/$M$3)
J37: =IFERROR(__xludf.DUMMYFUNCTION("""COMPUTED_VALUE"""),"") | N37: =IF(K37="","",M37-L37) | O37: =IFERROR(IF(K37="","",IF(M37="","-100%",(M37-L37)/L37)),100%) | P37: =IF(K37="","",M37/$M$3)
J38: =IFERROR(__xludf.DUMMYFUNCTION("""COMPUTED_VALUE"""),"") | N38: =IF(K38="","",M38-L38) | O38: =IFERROR(IF(K38="","",IF(M38="","-100%",(M38-L38)/L38)),100%) | P38: =IF(K38="","",M38/$M$3)
... J47: =IFERROR(__xludf.DUMMYFUNCTION("""COMPUTED_VALUE"""),"") | N47: =IF(K47="","",M47-L47) | O47: =IFERROR(IF(K47="","",IF(M47="","-100%",(M47-L47)/L47)),100%) | P47: =IF(K47="","",M47/$M$3)
J48: =IFERROR(__xludf.DUMMYFUNCTION("""COMPUTED_VALUE"""),"")
J49: =IFERROR(__xludf.DUMMYFUNCTION("""COMPUTED_VALUE"""),"")
J50: =IFERROR(__xludf.DUMMYFUNCTION("""COMPUTED_VALUE"""),"")
...

Sheet Report 2
C2: =SUM(C4:C34619) -> 110736294 | D2: =SUM(D4:D34619) -> 23066986 | E2: =SUM(E4:E34619) -> 25708142 | F2: =SUM(F4:F34619) -> 2641155.8 | G2: =IFERROR((E2-D2)/D2,"") -> 0.11449939 | H2: =SUM(H4:H34619) -> 1 | L2: =SUM(L4:L10) -> 5250452.2 | M2: =SUM(M4:M10) -> 724044.63 | N2: =IFERROR((M2-L2)/L2,"") -> -0.86209861 | O2: =SUM(O4:O10) -> 12163461 | P2: =SUM(P4:P10) -> 13037960 | Q2: =IFERROR((P2-O2)/O2,"") -> 0.071895565 | R2: =SUM(R4:R10) -> 5653072.8 | S2: =SUM(S4:S10) -> 11781747 | T2: =IFERROR((S2-R2)/R2,"") -> 1.0841314 | U2: =SUM(U4:U10) -> 11444745 | V2: =SUM(V4:V10) -> 0 | W2: =IFERROR((V2-U2)/U2,"") -> -1 | X2: =SUM(X4:X10) -> 9016596.6 | Y2: =SUM(Y4:Y10) -> 0 | Z2: =IFERROR((Y2-X2)/X2,"") -> -1 | AA2: =SUM(AA4:AA10) -> 9337245.2 | AB2: =SUM(AB4:AB10) -> 0 | AC2: =IFERROR((AB2-AA2)/AA2,"") -> -1 | AD2: =SUM(AD4:AD10) -> 5890747.2 | AE2: =SUM(AE4:AE10) -> 0 | AF2: =IFERROR((AE2-AD2)/AD2,"") -> -1 | AG2: =SUM(AG4:AG10) -> 10463644 | AH2: =SUM(AH4:AH10) -> 0 | AI2: =IFERROR((AH2-AG2)/AG2,"") -> -1 | AJ2: =SUM(AJ4:AJ10) -> 9276350.7 | AK2: =SUM(AK4:AK10) -> 0 | AL2: =IFERROR((AK2-AJ2)/AJ2,"") -> -1 | AM2: =SUM(AM4:AM10) -> 10039760 | AN2: =SUM(AN4:AN10) -> 0 | AO2: =IFERROR((AN2-AM2)/AM2,"") -> -1 | AP2: =SUM(AP4:AP10) -> 7629005.9 | AQ2: =SUM(AQ4:AQ10) -> 0 | AR2: =IFERROR((AQ2-AP2)/AP2,"") -> -1 | AS2: =SUM(AS4:AS10) -> 14571213 | AT2: =SUM(AT4:AT10) -> 0 | AU2: =IFERROR((AT2-AS2)/AS2,"") -> -1
B3: =IFERROR(__xludf.DUMMYFUNCTION("QUERY(Sheet1!A1:O34619,""SELECT K,SUM(H) WHERE N LIKE 'FY-2025-26' GROUP BY K ORDER BY SUM(H) DESC LABEL K 'State', SUM(H) 'Sale Value FY-2025-26' FORMAT SUM(H) '##'"")"),"State") -> State | C3: =IFERROR(__xludf.DUMMYFUNCTION("""COMPUTED_VALUE"""),"Sale Value FY-2025-26") -> Sale Value FY-2025-26 | D3: Last Year Till Month Sale | E3: This Year Till Month Sale | F3: Difference | G3: Growth % | H3: Share % | K3: =B3 -> State | L3: 45772 | M3: 46138 | N3: Growth % | O3: 45802 | P3: 46168 | Q3: Growth % | R3: 45833 | S3: 46199 | T3: Growth % | U3: 45863 | V3: 46229 | W3: Growth % | X3: 45894 | Y3: 46260 | Z3: Growth % | AA3: 45925 | AB3: 46291 | AC3: Growth % | AD3: 45955 | AE3: 46321 | AF3: Growth % | AG3: 45986 | AH3: 46352 | AI3: Growth % | AJ3: 46016 | AK3: 46382 | AL3: Growth % | AM3: 46048 | AN3: 46413 | AO3: Growth % | AP3: 46079 | AQ3: 46444 | AR3: Growth % | AS3: 46107 | AT3: 46472 | AU3: Growth %
B4: =IFERROR(__xludf.DUMMYFUNCTION("""COMPUTED_VALUE"""),"UP ( A )") -> UP ( A ) | C4: =IFERROR(__xludf.DUMMYFUNCTION("""COMPUTED_VALUE"""),6.2969206799999975E7) -> 62969207 | D4: =sumifs(Sheet1!H:H,Sheet1!K:K,B4,Sheet1!O:O,"FY-2025-26") -> 13402370 | E4: =sumifs(Sheet1!H:H,Sheet1!K:K,B4,Sheet1!O:O,"FY-2026-27") -> 13045514 | F4: =E4-D4 -> -356855.76 | G4: =IFERROR((E4-D4)/D4,"") -> -0.026626317 | H4: =E4/E$2 -> 0.5074468 | K4: =B4 -> UP ( A ) | L4: =SUMIFS(Sheet1!$H:$H,Sheet1!$K:$K,$K4,Sheet1!$E:$E,L$3) -> 3012559.5 | M4: =SUMIFS(Sheet1!$H:$H,Sheet1!$K:$K,$K4,Sheet1!$E:$E,M$3) -> 49900 | N4: =IFERROR((M4-L4)/L4,"") -> -0.98343601 | O4: =SUMIFS(Sheet1!$H:$H,Sheet1!$K:$K,$K4,Sheet1!$E:$E,O$3) -> 7378758.7 | P4: =SUMIFS(Sheet1!$H:$H,Sheet1!$K:$K,$K4,Sheet1!$E:$E,P$3) -> 7365341 | Q4: =IFERROR((P4-O4)/O4,"") -> -0.0018184265 | R4: =SUMIFS(Sheet1!$H:$H,Sheet1!$K:$K,$K4,Sheet1!$E:$E,R$3) -> 3011052 | S4: =SUMIFS(Sheet1!$H:$H,Sheet1!$K:$K,$K4,Sheet1!$E:$E,S$3) -> 5630273.4 | T4: =IFERROR((S4-R4)/R4,"") -> 0.86986921 | U4: =SUMIFS(Sheet1!$H:$H,Sheet1!$K:$K,$K4,Sheet1!$E:$E,U$3) -> 5740467.6 | V4: =SUMIFS(Sheet1!$H:$H,Sheet1!$K:$K,$K4,Sheet1!$E:$E,V$3) -> 0 | W4: =IFERROR((V4-U4)/U4,"") -> -1 | X4: =SUMIFS(Sheet1!$H:$H,Sheet1!$K:$K,$K4,Sheet1!$E:$E,X$3) -> 4794170.9 | Y4: =SUMIFS(Sheet1!$H:$H,Sheet1!$K:$K,$K4,Sheet1!$E:$E,Y$3) -> 0 | Z4: =IFERROR((Y4-X4)/X4,"") -> -1 | AA4: =SUMIFS(Sheet1!$H:$H,Sheet1!$K:$K,$K4,Sheet1!$E:$E,AA$3) -> 5094534 | AB4: =SUMIFS(Sheet1!$H:$H,Sheet1!$K:$K,$K4,Sheet1!$E:$E,AB$3) -> 0 | AC4: =IFERROR((AB4-AA4)/AA4,"") -> -1 | AD4: =SUMIFS(Sheet1!$H:$H,Sheet1!$K:$K,$K4,Sheet1!$E:$E,AD$3) -> 3004367.2 | AE4: =SUMIFS(Sheet1!$H:$H,Sheet1!$K:$K,$K4,Sheet1!$E:$E,AE$3) -> 0 | AF4: =IFERROR((AE4-AD4)/AD4,"") -> -1 | AG4: =SUMIFS(Sheet1!$H:$H,Sheet1!$K:$K,$K4,Sheet1!$E:$E,AG$3) -> 6403013.3 | AH4: =SUMIFS(Sheet1!$H:$H,Sheet1!$K:$K,$K4,Sheet1!$E:$E,AH$3) -> 0 | AI4: =IFERROR((AH4-AG4)/AG4,"") -> -1 | AJ4: =SUMIFS(Sheet1!$H:$H,Sheet1!$K:$K,$K4,Sheet1!$E:$E,AJ$3) -> 5051391.6 | AK4: =SUMIFS(Sheet1!$H:$H,Sheet1!$K:$K,$K4,Sheet1!$E:$E,AK$3) -> 0 | AL4: =IFERROR((AK4-AJ4)/AJ4,"") -> -1 | AM4: =SUMIFS(Sheet1!$H:$H,Sheet1!$K:$K,$K4,Sheet1!$E:$E,AM$3) -> 5630977.6 | AN4: =SUMIFS(Sheet1!$H:$H,Sheet1!$K:$K,$K4,Sheet1!$E:$E,AN$3) -> 0 | AO4: =IFERROR((AN4-AM4)/AM4,"") -> -1 | AP4: =SUMIFS(Sheet1!$H:$H,Sheet1!$K:$K,$K4,Sheet1!$E:$E,AP$3) -> 3514045.5 | AQ4: =SUMIFS(Sheet1!$H:$H,Sheet1!$K:$K,$K4,Sheet1!$E:$E,AQ$3) -> 0 | AR4: =IFERROR((AQ4-AP4)/AP4,"") -> -1 | AS4: =SUMIFS(Sheet1!$H:$H,Sheet1!$K:$K,$K4,Sheet1!$E:$E,AS$3) -> 10333869 | AT4: =SUMIFS(Sheet1!$H:$H,Sheet1!$K:$K,$K4,Sheet1!$E:$E,AT$3) -> 0 | AU4: =IFERROR((AT4-AS4)/AS4,"") -> -1
B5: =IFERROR(__xludf.DUMMYFUNCTION("""COMPUTED_VALUE"""),"Uttarakhand") -> Uttarakhand | C5: =IFERROR(__xludf.DUMMYFUNCTION("""COMPUTED_VALUE"""),2.0075689249999996E7) -> 20075689 | D5: =sumifs(Sheet1!H:H,Sheet1!K:K,B5,Sheet1!O:O,"FY-2025-26") -> 3198007.6 | E5: =sumifs(Sheet1!H:H,Sheet1!K:K,B5,Sheet1!O:O,"FY-2026-27") -> 6640766.7 | F5: =E5-D5 -> 3442759 | G5: =IFERROR((E5-D5)/D5,"") -> 1.0765325 | H5: =E5/E$2 -> 0.25831376 | K5: =B5 -> Uttarakhand | L5: =SUMIFS(Sheet1!$H:$H,Sheet1!$K:$K,$K5,Sheet1!$E:$E,L$3) -> 183667.49 | M5: =SUMIFS(Sheet1!$H:$H,Sheet1!$K:$K,$K5,Sheet1!$E:$E,M$3) -> 64994 | N5: =IFERROR((M5-L5)/L5,"") -> -0.64613226 | O5: =SUMIFS(Sheet1!$H:$H,Sheet1!$K:$K,$K5,Sheet1!$E:$E,O$3) -> 1876624.3 | P5: =SUMIFS(Sheet1!$H:$H,Sheet1!$K:$K,$K5,Sheet1!$E:$E,P$3) -> 4008538.4 | Q5: =IFERROR((P5-O5)/O5,"") -> 1.1360367 | R5: =SUMIFS(Sheet1!$H:$H,Sheet1!$K:$K,$K5,Sheet1!$E:$E,R$3) -> 1137715.8 | S5: =SUMIFS(Sheet1!$H:$H,Sheet1!$K:$K,$K5,Sheet1!$E:$E,S$3) -> 2402843.7 | T5: =IFERROR((S5-R5)/R5,"") -> 1.1119893 | U5: =SUMIFS(Sheet1!$H:$H,Sheet1!$K:$K,$K5,Sheet1!$E:$E,U$3) -> 2889144.3 | V5: =SUMIFS(Sheet1!$F:$F,Sheet1!$I:$I,$K5,Sheet1!$C:$C,V$3) -> 0 | W5: =IFERROR((V5-U5)/U5,"") -> -1 | X5: =SUMIFS(Sheet1!$H:$H,Sheet1!$K:$K,$K5,Sheet1!$E:$E,X$3) -> 1744088.5 | Y5: =SUMIFS(Sheet1!$F:$F,Sheet1!$I:$I,$K5,Sheet1!$C:$C,Y$3) -> 0 | Z5: =IFERROR((Y5-X5)/X5,"") -> -1 | AA5: =SUMIFS(Sheet1!$H:$H,Sheet1!$K:$K,$K5,Sheet1!$E:$E,AA$3) -> 795491 | AB5: =SUMIFS(Sheet1!$F:$F,Sheet1!$I:$I,$K5,Sheet1!$C:$C,AB$3) -> 0 | AC5: =IFERROR((AB5-AA5)/AA5,"") -> -1 | AD5: =SUMIFS(Sheet1!$H:$H,Sheet1!$K:$K,$K5,Sheet1!$E:$E,AD$3) -> 1807383 | AE5: =SUMIFS(Sheet1!$F:$F,Sheet1!$I:$I,$K5,Sheet1!$C:$C,AE$3) -> 0 | AF5: =IFERROR((AE5-AD5)/AD5,"") -> -1 | AG5: =SUMIFS(Sheet1!$H:$H,Sheet1!$K:$K,$K5,Sheet1!$E:$E,AG$3) -> 1057606.9 | AH5: =SUMIFS(Sheet1!$F:$F,Sheet1!$I:$I,$K5,Sheet1!$C:$C,AH$3) -> 0 | AI5: =IFERROR((AH5-AG5)/AG5,"") -> -1 | AJ5: =SUMIFS(Sheet1!$H:$H,Sheet1!$K:$K,$K5,Sheet1!$E:$E,AJ$3) -> 2338282 | AK5: =SUMIFS(Sheet1!$F:$F,Sheet1!$I:$I,$K5,Sheet1!$C:$C,AK$3) -> 0 | AL5: =IFERROR((AK5-AJ5)/AJ5,"") -> -1 | AM5: =SUMIFS(Sheet1!$H:$H,Sheet1!$K:$K,$K5,Sheet1!$E:$E,AM$3) -> 2075241 | AN5: =SUMIFS(Sheet1!$F:$F,Sheet1!$I:$I,$K5,Sheet1!$C:$C,AN$3) -> 0 | AO5: =IFERROR((AN5-AM5)/AM5,"") -> -1 | AP5: =SUMIFS(Sheet1!$H:$H,Sheet1!$K:$K,$K5,Sheet1!$E:$E,AP$3) -> 2143058.9 | AQ5: =SUMIFS(Sheet1!$F:$F,Sheet1!$I:$I,$K5,Sheet1!$C:$C,AQ$3) -> 0 | AR5: =IFERROR((AQ5-AP5)/AP5,"") -> -1 | AS5: =SUMIFS(Sheet1!$H:$H,Sheet1!$K:$K,$K5,Sheet1!$E:$E,AS$3) -> 2027386.1 | AT5: =SUMIFS(Sheet1!$F:$F,Sheet1!$I:$I,$K5,Sheet1!$C:$C,AT$3) -> 0 | AU5: =IFERROR((AT5-AS5)/AS5,"") -> -1
B6: =IFERROR(__xludf.DUMMYFUNCTION("""COMPUTED_VALUE"""),"DELHI A") -> DELHI A | C6: =IFERROR(__xludf.DUMMYFUNCTION("""COMPUTED_VALUE"""),1.693441684000001E7) -> 16934417 | D6: =sumifs(Sheet1!H:H,Sheet1!K:K,B6,Sheet1!O:O,"FY-2025-26") -> 4057826.1 | E6: =sumifs(Sheet1!H:H,Sheet1!K:K,B6,Sheet1!O:O,"FY-2026-27") -> 3806216.7 | F6: =E6-D6 -> -251609.43 | G6: =IFERROR((E6-D6)/D6,"") -> -0.062005966 | H6: =E6/E$2 -> 0.14805491 | K6: =B6 -> DELHI A | L6: =SUMIFS(Sheet1!$H:$H,Sheet1!$K:$K,$K6,Sheet1!$E:$E,L$3) -> 1894229.4 | M6: =SUMIFS(Sheet1!$H:$H,Sheet1!$K:$K,$K6,Sheet1!$E:$E,M$3) -> 294989.63 | N6: =IFERROR((M6-L6)/L6,"") -> -0.84426932 | O6: =SUMIFS(Sheet1!$H:$H,Sheet1!$K:$K,$K6,Sheet1!$E:$E,O$3) -> 1500603.8 | P6: =SUMIFS(Sheet1!$H:$H,Sheet1!$K:$K,$K6,Sheet1!$E:$E,P$3) -> 1330932.6 | Q6: =IFERROR((P6-O6)/O6,"") -> -0.11306863 | R6: =SUMIFS(Sheet1!$H:$H,Sheet1!$K:$K,$K6,Sheet1!$E:$E,R$3) -> 662992.93 | S6: =SUMIFS(Sheet1!$H:$H,Sheet1!$K:$K,$K6,Sheet1!$E:$E,S$3) -> 2180294.5 | T6: =IFERROR((S6-R6)/R6,"") -> 2.2885637 | U6: =SUMIFS(Sheet1!$H:$H,Sheet1!$K:$K,$K6,Sheet1!$E:$E,U$3) -> 1565819.6 | V6: =SUMIFS(Sheet1!$F:$F,Sheet1!$I:$I,$K6,Sheet1!$C:$C,V$3) -> 0 | W6: =IFERROR((V6-U6)/U6,"") -> -1 | X6: =SUMIFS(Sheet1!$H:$H,Sheet1!$K:$K,$K6,Sheet1!$E:$E,X$3) -> 1826658 | Y6: =SUMIFS(Sheet1!$F:$F,Sheet1!$I:$I,$K6,Sheet1!$C:$C,Y$3) -> 0 | Z6: =IFERROR((Y6-X6)/X6,"") -> -1 | AA6: =SUMIFS(Sheet1!$H:$H,Sheet1!$K:$K,$K6,Sheet1!$E:$E,AA$3) -> 2064462.3 | AB6: =SUMIFS(Sheet1!$F:$F,Sheet1!$I:$I,$K6,Sheet1!$C:$C,AB$3) -> 0 | AC6: =IFERROR((AB6-AA6)/AA6,"") -> -1 | AD6: =SUMIFS(Sheet1!$H:$H,Sheet1!$K:$K,$K6,Sheet1!$E:$E,AD$3) -> 856754 | AE6: =SUMIFS(Sheet1!$F:$F,Sheet1!$I:$I,$K6,Sheet1!$C:$C,AE$3) -> 0 | AF6: =IFERROR((AE6-AD6)/AD6,"") -> -1 | AG6: =SUMIFS(Sheet1!$H:$H,Sheet1!$K:$K,$K6,Sheet1!$E:$E,AG$3) -> 1690168.1 | AH6: =SUMIFS(Sheet1!$F:$F,Sheet1!$I:$I,$K6,Sheet1!$C:$C,AH$3) -> 0 | AI6: =IFERROR((AH6-AG6)/AG6,"") -> -1 | AJ6: =SUMIFS(Sheet1!$H:$H,Sheet1!$K:$K,$K6,Sheet1!$E:$E,AJ$3) -> 925450.05 | AK6: =SUMIFS(Sheet1!$F:$F,Sheet1!$I:$I,$K6,Sheet1!$C:$C,AK$3) -> 0 | AL6: =IFERROR((AK6-AJ6)/AJ6,"") -> -1 | AM6: =SUMIFS(Sheet1!$H:$H,Sheet1!$K:$K,$K6,Sheet1!$E:$E,AM$3) -> 1412645.5 | AN6: =SUMIFS(Sheet1!$F:$F,Sheet1!$I:$I,$K6,Sheet1!$C:$C,AN$3) -> 0 | AO6: =IFERROR((AN6-AM6)/AM6,"") -> -1 | AP6: =SUMIFS(Sheet1!$H:$H,Sheet1!$K:$K,$K6,Sheet1!$E:$E,AP$3) -> 1377741.3 | AQ6: =SUMIFS(Sheet1!$F:$F,Sheet1!$I:$I,$K6,Sheet1!$C:$C,AQ$3) -> 0 | AR6: =IFERROR((AQ6-AP6)/AP6,"") -> -1 | AS6: =SUMIFS(Sheet1!$H:$H,Sheet1!$K:$K,$K6,Sheet1!$E:$E,AS$3) -> 1156891.9 | AT6: =SUMIFS(Sheet1!$F:$F,Sheet1!$I:$I,$K6,Sheet1!$C:$C,AT$3) -> 0 | AU6: =IFERROR((AT6-AS6)/AS6,"") -> -1
B7: =IFERROR(__xludf.DUMMYFUNCTION("""COMPUTED_VALUE"""),"DELHI NCR") -> DELHI NCR | C7: =IFERROR(__xludf.DUMMYFUNCTION("""COMPUTED_VALUE"""),1.0756981070000002E7) -> 10756981 | D7: =sumifs(Sheet1!H:H,Sheet1!K:K,B7,Sheet1!O:O,"FY-2025-26") -> 2408782.1 | E7: =sumifs(Sheet1!H:H,Sheet1!K:K,B7,Sheet1!O:O,"FY-2026-27") -> 2215644 | F7: =E7-D7 -> -193138.1 | G7: =IFERROR((E7-D7)/D7,"") -> -0.08018081 | H7: =E7/E$2 -> 0.086184526 | K7: =B7 -> DELHI NCR | L7: =SUMIFS(Sheet1!$H:$H,Sheet1!$K:$K,$K7,Sheet1!$E:$E,L$3) -> 159995.82 | M7: =SUMIFS(Sheet1!$H:$H,Sheet1!$K:$K,$K7,Sheet1!$E:$E,M$3) -> 314161 | N7: =IFERROR((M7-L7)/L7,"") -> 0.96355755 | O7: =SUMIFS(Sheet1!$H:$H,Sheet1!$K:$K,$K7,Sheet1!$E:$E,O$3) -> 1407474.3 | P7: =SUMIFS(Sheet1!$H:$H,Sheet1!$K:$K,$K7,Sheet1!$E:$E,P$3) -> 333148 | Q7: =IFERROR((P7-O7)/O7,"") -> -0.76330083 | R7: =SUMIFS(Sheet1!$H:$H,Sheet1!$K:$K,$K7,Sheet1!$E:$E,R$3) -> 841312 | S7: =SUMIFS(Sheet1!$H:$H,Sheet1!$K:$K,$K7,Sheet1!$E:$E,S$3) -> 1568335 | T7: =IFERROR((S7-R7)/R7,"") -> 0.86415385 | U7: =SUMIFS(Sheet1!$H:$H,Sheet1!$K:$K,$K7,Sheet1!$E:$E,U$3) -> 1249313.6 | V7: =SUMIFS(Sheet1!$F:$F,Sheet1!$I:$I,$K7,Sheet1!$C:$C,V$3) -> 0 | W7: =IFERROR((V7-U7)/U7,"") -> -1 | X7: =SUMIFS(Sheet1!$H:$H,Sheet1!$K:$K,$K7,Sheet1!$E:$E,X$3) -> 651679.18 | Y7: =SUMIFS(Sheet1!$F:$F,Sheet1!$I:$I,$K7,Sheet1!$C:$C,Y$3) -> 0 | Z7: =IFERROR((Y7-X7)/X7,"") -> -1 | AA7: =SUMIFS(Sheet1!$H:$H,Sheet1!$K:$K,$K7,Sheet1!$E:$E,AA$3) -> 1382758 | AB7: =SUMIFS(Sheet1!$F:$F,Sheet1!$I:$I,$K7,Sheet1!$C:$C,AB$3) -> 0 | AC7: =IFERROR((AB7-AA7)/AA7,"") -> -1 | AD7: =SUMIFS(Sheet1!$H:$H,Sheet1!$K:$K,$K7,Sheet1!$E:$E,AD$3) -> 222243 | AE7: =SUMIFS(Sheet1!$F:$F,Sheet1!$I:$I,$K7,Sheet1!$C:$C,AE$3) -> 0 | AF7: =IFERROR((AE7-AD7)/AD7,"") -> -1 | AG7: =SUMIFS(Sheet1!$H:$H,Sheet1!$K:$K,$K7,Sheet1!$E:$E,AG$3) -> 1312856 | AH7: =SUMIFS(Sheet1!$F:$F,Sheet1!$I:$I,$K7,Sheet1!$C:$C,AH$3) -> 0 | AI7: =IFERROR((AH7-AG7)/AG7,"") -> -1 | AJ7: =SUMIFS(Sheet1!$H:$H,Sheet1!$K:$K,$K7,Sheet1!$E:$E,AJ$3) -> 961227 | AK7: =SUMIFS(Sheet1!$F:$F,Sheet1!$I:$I,$K7,Sheet1!$C:$C,AK$3) -> 0 | AL7: =IFERROR((AK7-AJ7)/AJ7,"") -> -1 | AM7: =SUMIFS(Sheet1!$H:$H,Sheet1!$K:$K,$K7,Sheet1!$E:$E,AM$3) -> 920896 | AN7: =SUMIFS(Sheet1!$F:$F,Sheet1!$I:$I,$K7,Sheet1!$C:$C,AN$3) -> 0 | AO7: =IFERROR((AN7-AM7)/AM7,"") -> -1 | AP7: =SUMIFS(Sheet1!$H:$H,Sheet1!$K:$K,$K7,Sheet1!$E:$E,AP$3) -> 594160.17 | AQ7: =SUMIFS(Sheet1!$F:$F,Sheet1!$I:$I,$K7,Sheet1!$C:$C,AQ$3) -> 0 | AR7: =IFERROR((AQ7-AP7)/AP7,"") -> -1 | AS7: =SUMIFS(Sheet1!$H:$H,Sheet1!$K:$K,$K7,Sheet1!$E:$E,AS$3) -> 1053066 | AT7: =SUMIFS(Sheet1!$F:$F,Sheet1!$I:$I,$K7,Sheet1!$C:$C,AT$3) -> 0 | AU7: =IFERROR((AT7-AS7)/AS7,"") -> -1
D8: =sumifs(Sheet1!H:H,Sheet1!K:K,B8,Sheet1!O:O,"FY-2025-26") -> 0 | E8: =sumifs(Sheet1!F:F,Sheet1!I:I,B8,Sheet1!M:M,"FY-2025-26") -> 0 | F8: =E8-D8 -> 0 | G8: =IFERROR((E8-D8)/D8,"") | K8: =B8 | L8: =SUMIFS(Sheet1!$H:$H,Sheet1!$K:$K,$K8,Sheet1!$E:$E,L$3) -> 0 | M8: =SUMIFS(Sheet1!$H:$H,Sheet1!$K:$K,$K8,Sheet1!$E:$E,M$3) -> 0 | N8: =IFERROR((M8-L8)/L8,"") | O8: =SUMIFS(Sheet1!$H:$H,Sheet1!$K:$K,$K8,Sheet1!$E:$E,O$3) -> 0 | P8: =SUMIFS(Sheet1!$H:$H,Sheet1!$K:$K,$K8,Sheet1!$E:$E,P$3) -> 0 | Q8: =IFERROR((P8-O8)/O8,"") | R8: =SUMIFS(Sheet1!$H:$H,Sheet1!$K:$K,$K8,Sheet1!$E:$E,R$3) -> 0 | S8: =SUMIFS(Sheet1!$H:$H,Sheet1!$K:$K,$K8,Sheet1!$E:$E,S$3) -> 0 | T8: =IFERROR((S8-R8)/R8,"") | U8: =SUMIFS(Sheet1!$H:$H,Sheet1!$K:$K,$K8,Sheet1!$E:$E,U$3) -> 0 | V8: =SUMIFS(Sheet1!$F:$F,Sheet1!$I:$I,$K8,Sheet1!$C:$C,V$3) -> 0 | W8: =IFERROR((V8-U8)/U8,"") | X8: =SUMIFS(Sheet1!$H:$H,Sheet1!$K:$K,$K8,Sheet1!$E:$E,X$3) -> 0 | Y8: =SUMIFS(Sheet1!$F:$F,Sheet1!$I:$I,$K8,Sheet1!$C:$C,Y$3) -> 0 | Z8: =IFERROR((Y8-X8)/X8,"") | AA8: =SUMIFS(Sheet1!$H:$H,Sheet1!$K:$K,$K8,Sheet1!$E:$E,AA$3) -> 0 | AB8: =SUMIFS(Sheet1!$F:$F,Sheet1!$I:$I,$K8,Sheet1!$C:$C,AB$3) -> 0 | AC8: =IFERROR((AB8-AA8)/AA8,"") | AD8: =SUMIFS(Sheet1!$H:$H,Sheet1!$K:$K,$K8,Sheet1!$E:$E,AD$3) -> 0 | AE8: =SUMIFS(Sheet1!$F:$F,Sheet1!$I:$I,$K8,Sheet1!$C:$C,AE$3) -> 0 | AF8: =IFERROR((AE8-AD8)/AD8,"") | AG8: =SUMIFS(Sheet1!$H:$H,Sheet1!$K:$K,$K8,Sheet1!$E:$E,AG$3) -> 0 | AH8: =SUMIFS(Sheet1!$F:$F,Sheet1!$I:$I,$K8,Sheet1!$C:$C,AH$3) -> 0 | AI8: =IFERROR((AH8-AG8)/AG8,"") | AJ8: =SUMIFS(Sheet1!$H:$H,Sheet1!$K:$K,$K8,Sheet1!$E:$E,AJ$3) -> 0 | AK8: =SUMIFS(Sheet1!$F:$F,Sheet1!$I:$I,$K8,Sheet1!$C:$C,AK$3) -> 0 | AL8: =IFERROR((AK8-AJ8)/AJ8,"") | AM8: =SUMIFS(Sheet1!$H:$H,Sheet1!$K:$K,$K8,Sheet1!$E:$E,AM$3) -> 0 | AN8: =SUMIFS(Sheet1!$F:$F,Sheet1!$I:$I,$K8,Sheet1!$C:$C,AN$3) -> 0 | AO8: =IFERROR((AN8-AM8)/AM8,"") | AP8: =SUMIFS(Sheet1!$H:$H,Sheet1!$K:$K,$K8,Sheet1!$E:$E,AP$3) -> 0 | AQ8: =SUMIFS(Sheet1!$F:$F,Sheet1!$I:$I,$K8,Sheet1!$C:$C,AQ$3) -> 0 | AR8: =IFERROR((AQ8-AP8)/AP8,"") | AS8: =SUMIFS(Sheet1!$H:$H,Sheet1!$K:$K,$K8,Sheet1!$E:$E,AS$3) -> 0 | AT8: =SUMIFS(Sheet1!$F:$F,Sheet1!$I:$I,$K8,Sheet1!$C:$C,AT$3) -> 0 | AU8: =IFERROR((AT8-AS8)/AS8,"")
D9: =sumifs(Sheet1!H:H,Sheet1!K:K,B9,Sheet1!O:O,"FY-2025-26") -> 0 | E9: =sumifs(Sheet1!F:F,Sheet1!I:I,B9,Sheet1!M:M,"FY-2025-26") -> 0 | F9: =E9-D9 -> 0 | G9: =IFERROR((E9-D9)/D9,"") | K9: =B9 | L9: =SUMIFS(Sheet1!$H:$H,Sheet1!$K:$K,$K9,Sheet1!$E:$E,L$3) -> 0 | M9: =SUMIFS(Sheet1!$H:$H,Sheet1!$K:$K,$K9,Sheet1!$E:$E,M$3) -> 0 | N9: =IFERROR((M9-L9)/L9,"") | O9: =SUMIFS(Sheet1!$H:$H,Sheet1!$K:$K,$K9,Sheet1!$E:$E,O$3) -> 0 | P9: =SUMIFS(Sheet1!$F:$F,Sheet1!$I:$I,$K9,Sheet1!$C:$C,P$3) -> 0 | Q9: =IFERROR((P9-O9)/O9,"") | R9: =SUMIFS(Sheet1!$H:$H,Sheet1!$K:$K,$K9,Sheet1!$E:$E,R$3) -> 0 | S9: =SUMIFS(Sheet1!$H:$H,Sheet1!$K:$K,$K9,Sheet1!$E:$E,S$3) -> 0 | T9: =IFERROR((S9-R9)/R9,"") | U9: =SUMIFS(Sheet1!$H:$H,Sheet1!$K:$K,$K9,Sheet1!$E:$E,U$3) -> 0 | V9: =SUMIFS(Sheet1!$F:$F,Sheet1!$I:$I,$K9,Sheet1!$C:$C,V$3) -> 0 | W9: =IFERROR((V9-U9)/U9,"") | X9: =SUMIFS(Sheet1!$H:$H,Sheet1!$K:$K,$K9,Sheet1!$E:$E,X$3) -> 0 | Y9: =SUMIFS(Sheet1!$F:$F,Sheet1!$I:$I,$K9,Sheet1!$C:$C,Y$3) -> 0 | Z9: =IFERROR((Y9-X9)/X9,"") | AA9: =SUMIFS(Sheet1!$H:$H,Sheet1!$K:$K,$K9,Sheet1!$E:$E,AA$3) -> 0 | AB9: =SUMIFS(Sheet1!$F:$F,Sheet1!$I:$I,$K9,Sheet1!$C:$C,AB$3) -> 0 | AC9: =IFERROR((AB9-AA9)/AA9,"") | AD9: =SUMIFS(Sheet1!$H:$H,Sheet1!$K:$K,$K9,Sheet1!$E:$E,AD$3) -> 0 | AE9: =SUMIFS(Sheet1!$F:$F,Sheet1!$I:$I,$K9,Sheet1!$C:$C,AE$3) -> 0 | AF9: =IFERROR((AE9-AD9)/AD9,"") | AG9: =SUMIFS(Sheet1!$H:$H,Sheet1!$K:$K,$K9,Sheet1!$E:$E,AG$3) -> 0 | AH9: =SUMIFS(Sheet1!$F:$F,Sheet1!$I:$I,$K9,Sheet1!$C:$C,AH$3) -> 0 | AI9: =IFERROR((AH9-AG9)/AG9,"") | AJ9: =SUMIFS(Sheet1!$H:$H,Sheet1!$K:$K,$K9,Sheet1!$E:$E,AJ$3) -> 0 | AK9: =SUMIFS(Sheet1!$F:$F,Sheet1!$I:$I,$K9,Sheet1!$C:$C,AK$3) -> 0 | AL9: =IFERROR((AK9-AJ9)/AJ9,"") | AM9: =SUMIFS(Sheet1!$H:$H,Sheet1!$K:$K,$K9,Sheet1!$E:$E,AM$3) -> 0 | AN9: =SUMIFS(Sheet1!$F:$F,Sheet1!$I:$I,$K9,Sheet1!$C:$C,AN$3) -> 0 | AO9: =IFERROR((AN9-AM9)/AM9,"") | AP9: =SUMIFS(Sheet1!$F:$F,Sheet1!$I:$I,$K9,Sheet1!$C:$C,AP$3) -> 0 | AQ9: =SUMIFS(Sheet1!$F:$F,Sheet1!$I:$I,$K9,Sheet1!$C:$C,AQ$3) -> 0 | AR9: =IFERROR((AQ9-AP9)/AP9,"") | AS9: =SUMIFS(Sheet1!$F:$F,Sheet1!$I:$I,$K9,Sheet1!$C:$C,AS$3) -> 0 | AT9: =SUMIFS(Sheet1!$F:$F,Sheet1!$I:$I,$K9,Sheet1!$C:$C,AT$3) -> 0 | AU9: =IFERROR((AT9-AS9)/AS9,"")
D10: =sumifs(Sheet1!H:H,Sheet1!K:K,B10,Sheet1!O:O,"FY-2025-26") -> 0 | E10: =sumifs(Sheet1!F:F,Sheet1!I:I,B10,Sheet1!M:M,"FY-2025-26") -> 0 | F10: =E10-D10 -> 0 | G10: =IFERROR((E10-D10)/D10,"") | K10: =B10 | L10: =SUMIFS(Sheet1!$H:$H,Sheet1!$K:$K,$K10,Sheet1!$E:$E,L$3) -> 0 | M10: =SUMIFS(Sheet1!$F:$F,Sheet1!$I:$I,$K10,Sheet1!$C:$C,M$3) -> 0 | N10: =IFERROR((M10-L10)/L10,"") | O10: =SUMIFS(Sheet1!$H:$H,Sheet1!$K:$K,$K10,Sheet1!$E:$E,O$3) -> 0 | P10: =SUMIFS(Sheet1!$F:$F,Sheet1!$I:$I,$K10,Sheet1!$C:$C,P$3) -> 0 | Q10: =IFERROR((P10-O10)/O10,"") | R10: =SUMIFS(Sheet1!$H:$H,Sheet1!$K:$K,$K10,Sheet1!$E:$E,R$3) -> 0 | S10: =SUMIFS(Sheet1!$H:$H,Sheet1!$K:$K,$K10,Sheet1!$E:$E,S$3) -> 0 | T10: =IFERROR((S10-R10)/R10,"") | U10: =SUMIFS(Sheet1!$H:$H,Sheet1!$K:$K,$K10,Sheet1!$E:$E,U$3) -> 0 | V10: =SUMIFS(Sheet1!$F:$F,Sheet1!$I:$I,$K10,Sheet1!$C:$C,V$3) -> 0 | W10: =IFERROR((V10-U10)/U10,"") | X10: =SUMIFS(Sheet1!$F:$F,Sheet1!$I:$I,$K10,Sheet1!$C:$C,X$3) -> 0 | Y10: =SUMIFS(Sheet1!$F:$F,Sheet1!$I:$I,$K10,Sheet1!$C:$C,Y$3) -> 0 | Z10: =IFERROR((Y10-X10)/X10,"") | AA10: =SUMIFS(Sheet1!$H:$H,Sheet1!$K:$K,$K10,Sheet1!$E:$E,AA$3) -> 0 | AB10: =SUMIFS(Sheet1!$F:$F,Sheet1!$I:$I,$K10,Sheet1!$C:$C,AB$3) -> 0 | AC10: =IFERROR((AB10-AA10)/AA10,"") | AD10: =SUMIFS(Sheet1!$F:$F,Sheet1!$I:$I,$K10,Sheet1!$C:$C,AD$3) -> 0 | AE10: =SUMIFS(Sheet1!$F:$F,Sheet1!$I:$I,$K10,Sheet1!$C:$C,AE$3) -> 0 | AF10: =IFERROR((AE10-AD10)/AD10,"") | AG10: =SUMIFS(Sheet1!$H:$H,Sheet1!$K:$K,$K10,Sheet1!$E:$E,AG$3) -> 0 | AH10: =SUMIFS(Sheet1!$F:$F,Sheet1!$I:$I,$K10,Sheet1!$C:$C,AH$3) -> 0 | AI10: =IFERROR((AH10-AG10)/AG10,"") | AJ10: =SUMIFS(Sheet1!$H:$H,Sheet1!$K:$K,$K10,Sheet1!$E:$E,AJ$3) -> 0 | AK10: =SUMIFS(Sheet1!$F:$F,Sheet1!$I:$I,$K10,Sheet1!$C:$C,AK$3) -> 0 | AL10: =IFERROR((AK10-AJ10)/AJ10,"") | AM10: =SUMIFS(Sheet1!$F:$F,Sheet1!$I:$I,$K10,Sheet1!$C:$C,AM$3) -> 0 | AN10: =SUMIFS(Sheet1!$F:$F,Sheet1!$I:$I,$K10,Sheet1!$C:$C,AN$3) -> 0 | AO10: =IFERROR((AN10-AM10)/AM10,"") | AP10: =SUMIFS(Sheet1!$F:$F,Sheet1!$I:$I,$K10,Sheet1!$C:$C,AP$3) -> 0 | AQ10: =SUMIFS(Sheet1!$F:$F,Sheet1!$I:$I,$K10,Sheet1!$C:$C,AQ$3) -> 0 | AR10: =IFERROR((AQ10-AP10)/AP10,"") | AS10: =SUMIFS(Sheet1!$F:$F,Sheet1!$I:$I,$K10,Sheet1!$C:$C,AS$3) -> 0 | AT10: =SUMIFS(Sheet1!$F:$F,Sheet1!$I:$I,$K10,Sheet1!$C:$C,AT$3) -> 0 | AU10: =IFERROR((AT10-AS10)/AS10,"")
D11: =sumifs(Sheet1!F:F,Sheet1!I:I,B11,Sheet1!M:M,"FY-2024-25") -> 0 | E11: =sumifs(Sheet1!F:F,Sheet1!I:I,B11,Sheet1!M:M,"FY-2025-26") -> 0
D12: =sumifs(Sheet1!F:F,Sheet1!I:I,B12,Sheet1!M:M,"FY-2024-25") -> 0 | E12: =sumifs(Sheet1!F:F,Sheet1!I:I,B12,Sheet1!M:M,"FY-2025-26") -> 0
E13: =sumifs(Sheet1!F:F,Sheet1!I:I,B13,Sheet1!M:M,"FY-2025-26") -> 0
E14: =sumifs(Sheet1!F:F,Sheet1!I:I,B14,Sheet1!M:M,"FY-2025-26") -> 0
J15: Select State
J16: DELHI NCR | L16: =SUM(L18:L34619) -> 159995.82 | M16: =SUM(M18:M34619) -> 314161 | N16: =IFERROR((M16-L16)/L16,"") -> 0.96355755 | O16: =SUM(O18:O34619) -> 1407474.3 | P16: =SUM(P18:P34619) -> 333148 | Q16: =IFERROR((P16-O16)/O16,"") -> -0.76330083 | R16: =SUM(R18:R34619) -> 841312 | S16: =SUM(S18:S34619) -> 1568335 | T16: =IFERROR((S16-R16)/R16,"") -> 0.86415385 | U16: =SUM(U18:U34619) -> 1249313.6 | V16: =SUM(V18:V34619) -> 0 | W16: =IFERROR((V16-U16)/U16,"") -> -1 | X16: =SUM(X18:X34619) -> 651679.18 | Y16: =SUM(Y18:Y34619) -> 0 | Z16: =IFERROR((Y16-X16)/X16,"") -> -1 | AA16: =SUM(AA18:AA34619) -> 1382758 | AB16: =SUM(AB18:AB34619) -> 0 | AC16: =IFERROR((AB16-AA16)/AA16,"") -> -1 | AD16: =SUM(AD18:AD34619) -> 222243 | AE16: =SUM(AE18:AE34619) -> 0 | AF16: =IFERROR((AE16-AD16)/AD16,"") -> -1 | AG16: =SUM(AG18:AG34619) -> 1312856 | AH16: =SUM(AH18:AH34619) -> 0 | AI16: =IFERROR((AH16-AG16)/AG16,"") -> -1 | AJ16: =SUM(AJ18:AJ34619) -> 961227 | AK16: =SUM(AK18:AK34619) -> 0 | AL16: =IFERROR((AK16-AJ16)/AJ16,"") -> -1 | AM16: =SUM(AM18:AM34619) -> 920896 | AN16: =SUM(AN18:AN34619) -> 0 | AO16: =IFERROR((AN16-AM16)/AM16,"") -> -1 | AP16: =SUM(AP18:AP34619) -> 594160.17 | AQ16: =SUM(AQ18:AQ34619) -> 0 | AR16: =IFERROR((AQ16-AP16)/AP16,"") -> -1 | AS16: =SUM(AS18:AS34619) -> 1053066 | AT16: =SUM(AT18:AT34619) -> 0 | AU16: =IFERROR((AT16-AS16)/AS16,"") -> -1
J17: =IFERROR(__xludf.DUMMYFUNCTION("UNIQUE(QUERY(Sheet1!A1:O34619,""SELECT SUM(H),C WHERE K CONTAINS '""&J16&""' GROUP BY C ORDER BY SUM(H) DESC LABEL SUM(H) '' ,C 'Party Name'""))"),"") | K17: =IFERROR(__xludf.DUMMYFUNCTION("""COMPUTED_VALUE"""),"Party Name") -> Party Name | L17: 45772 | M17: 46138 | N17: Growth % | O17: 45802 | P17: 46168 | Q17: Growth % | R17: 45833 | S17: 46199 | T17: Growth % | U17: 45863 | V17: 46229 | W17: Growth % | X17: 45894 | Y17: 46260 | Z17: Growth % | AA17: 45925 | AB17: 46291 | AC17: Growth % | AD17: 45955 | AE17: 46321 | AF17: Growth % | AG17: 45986 | AH17: 46352 | AI17: Growth % | AJ17: 46016 | AK17: 46382 | AL17: Growth % | AM17: 46048 | AN17: 46413 | AO17: Growth % | AP17: 46079 | AQ17: 46444 | AR17: Growth % | AS17: 46107 | AT17: 46472 | AU17: Growth %
J18: =IFERROR(__xludf.DUMMYFUNCTION("""COMPUTED_VALUE"""),5731076.120000001) -> 5731076.1 | K18: =IFERROR(__xludf.DUMMYFUNCTION("""COMPUTED_VALUE"""),"S S SANITATAION") -> S S SANITATAION | L18: =SUMIFS(Sheet1!$H:$H,Sheet1!$C:$C,$K18,Sheet1!$E:$E,L$3) -> 159995.82 | M18: =SUMIFS(Sheet1!$H:$H,Sheet1!$C:$C,$K18,Sheet1!$E:$E,M$3) -> 0 | N18: =IFERROR((M18-L18)/L18,"") -> -1 | O18: =SUMIFS(Sheet1!$H:$H,Sheet1!$C:$C,$K18,Sheet1!$E:$E,O$3) -> 364588.2 | P18: =SUMIFS(Sheet1!$H:$H,Sheet1!$C:$C,$K18,Sheet1!$E:$E,P$3) -> 0 | Q18: =IFERROR((P18-O18)/O18,"") -> -1 | R18: =SUMIFS(Sheet1!$H:$H,Sheet1!$C:$C,$K18,Sheet1!$E:$E,R$3) -> 197337 | S18: =SUMIFS(Sheet1!$H:$H,Sheet1!$C:$C,$K18,Sheet1!$E:$E,S$3) -> 0 | T18: =IFERROR((S18-R18)/R18,"") -> -1 | U18: =SUMIFS(Sheet1!$H:$H,Sheet1!$C:$C,$K18,Sheet1!$E:$E,U$3) -> 991671.66 | V18: =SUMIFS(Sheet1!$H:$H,Sheet1!$C:$C,$K18,Sheet1!$E:$E,V$3) -> 0 | W18: =IFERROR((V18-U18)/U18,"") -> -1 | X18: =SUMIFS(Sheet1!$H:$H,Sheet1!$C:$C,$K18,Sheet1!$E:$E,X$3) -> 126959.27 | Y18: =SUMIFS(Sheet1!$H:$H,Sheet1!$C:$C,$K18,Sheet1!$E:$E,Y$3) -> 0 | Z18: =IFERROR((Y18-X18)/X18,"") -> -1 | AA18: =SUMIFS(Sheet1!$H:$H,Sheet1!$C:$C,$K18,Sheet1!$E:$E,AA$3) -> 744326 | AB18: =SUMIFS(Sheet1!$H:$H,Sheet1!$C:$C,$K18,Sheet1!$E:$E,AB$3) -> 0 | AC18: =IFERROR((AB18-AA18)/AA18,"") -> -1 | AD18: =SUMIFS(Sheet1!$H:$H,Sheet1!$C:$C,$K18,Sheet1!$E:$E,AD$3) -> 99871 | AE18: =SUMIFS(Sheet1!$H:$H,Sheet1!$C:$C,$K18,Sheet1!$E:$E,AE$3) -> 0 | AF18: =IFERROR((AE18-AD18)/AD18,"") -> -1 | AG18: =SUMIFS(Sheet1!$H:$H,Sheet1!$C:$C,$K18,Sheet1!$E:$E,AG$3) -> 605555 | AH18: =SUMIFS(Sheet1!$H:$H,Sheet1!$C:$C,$K18,Sheet1!$E:$E,AH$3) -> 0 | AI18: =IFERROR((AH18-AG18)/AG18,"") -> -1 | AJ18: =SUMIFS(Sheet1!$H:$H,Sheet1!$C:$C,$K18,Sheet1!$E:$E,AJ$3) -> 457868 | AK18: =SUMIFS(Sheet1!$H:$H,Sheet1!$C:$C,$K18,Sheet1!$E:$E,AK$3) -> 0 | AL18: =IFERROR((AK18-AJ18)/AJ18,"") -> -1 | AM18: =SUMIFS(Sheet1!$H:$H,Sheet1!$C:$C,$K18,Sheet1!$E:$E,AM$3) -> 476841 | AN18: =SUMIFS(Sheet1!$H:$H,Sheet1!$C:$C,$K18,Sheet1!$E:$E,AN$3) -> 0 | AO18: =IFERROR((AN18-AM18)/AM18,"") -> -1 | AP18: =SUMIFS(Sheet1!$H:$H,Sheet1!$C:$C,$K18,Sheet1!$E:$E,AP$3) -> 452997.17 | AQ18: =SUMIFS(Sheet1!$H:$H,Sheet1!$C:$C,$K18,Sheet1!$E:$E,AQ$3) -> 0 | AR18: =IFERROR((AQ18-AP18)/AP18,"") -> -1 | AS18: =SUMIFS(Sheet1!$H:$H,Sheet1!$C:$C,$K18,Sheet1!$E:$E,AS$3) -> 1053066 | AT18: =SUMIFS(Sheet1!$H:$H,Sheet1!$C:$C,$K18,Sheet1!$E:$E,AT$3) -> 0 | AU18: =IFERROR((AT18-AS18)/AS18,"") -> -1
J19: =IFERROR(__xludf.DUMMYFUNCTION("""COMPUTED_VALUE"""),4161744.0300000007) -> 4161744 | K19: =IFERROR(__xludf.DUMMYFUNCTION("""COMPUTED_VALUE"""),"ANIK TRADERS") -> ANIK TRADERS | L19: =SUMIFS(Sheet1!$H:$H,Sheet1!$C:$C,$K19,Sheet1!$E:$E,L$3) -> 0 | M19: =SUMIFS(Sheet1!$H:$H,Sheet1!$C:$C,$K19,Sheet1!$E:$E,M$3) -> 0 | N19: =IFERROR((M19-L19)/L19,"") | O19: =SUMIFS(Sheet1!$H:$H,Sheet1!$C:$C,$K19,Sheet1!$E:$E,O$3) -> 952233.16 | P19: =SUMIFS(Sheet1!$H:$H,Sheet1!$C:$C,$K19,Sheet1!$E:$E,P$3) -> 0 | Q19: =IFERROR((P19-O19)/O19,"") -> -1 | R19: =SUMIFS(Sheet1!$H:$H,Sheet1!$C:$C,$K19,Sheet1!$E:$E,R$3) -> 551834 | S19: =SUMIFS(Sheet1!$H:$H,Sheet1!$C:$C,$K19,Sheet1!$E:$E,S$3) -> 0 | T19: =IFERROR((S19-R19)/R19,"") -> -1 | U19: =SUMIFS(Sheet1!$H:$H,Sheet1!$C:$C,$K19,Sheet1!$E:$E,U$3) -> 257641.96 | V19: =SUMIFS(Sheet1!$H:$H,Sheet1!$C:$C,$K19,Sheet1!$E:$E,V$3) -> 0 | W19: =IFERROR((V19-U19)/U19,"") -> -1 | X19: =SUMIFS(Sheet1!$H:$H,Sheet1!$C:$C,$K19,Sheet1!$E:$E,X$3) -> 524719.91 | Y19: =SUMIFS(Sheet1!$H:$H,Sheet1!$C:$C,$K19,Sheet1!$E:$E,Y$3) -> 0 | Z19: =IFERROR((Y19-X19)/X19,"") -> -1 | AA19: =SUMIFS(Sheet1!$H:$H,Sheet1!$C:$C,$K19,Sheet1!$E:$E,AA$3) -> 600953 | AB19: =SUMIFS(Sheet1!$H:$H,Sheet1!$C:$C,$K19,Sheet1!$E:$E,AB$3) -> 0 | AC19: =IFERROR((AB19-AA19)/AA19,"") -> -1 | AD19: =SUMIFS(Sheet1!$H:$H,Sheet1!$C:$C,$K19,Sheet1!$E:$E,AD$3) -> 103632 | AE19: =SUMIFS(Sheet1!$H:$H,Sheet1!$C:$C,$K19,Sheet1!$E:$E,AE$3) -> 0 | AF19: =IFERROR((AE19-AD19)/AD19,"") -> -1 | AG19: =SUMIFS(Sheet1!$H:$H,Sheet1!$C:$C,$K19,Sheet1!$E:$E,AG$3) -> 661664 | AH19: =SUMIFS(Sheet1!$H:$H,Sheet1!$C:$C,$K19,Sheet1!$E:$E,AH$3) -> 0 | AI19: =IFERROR((AH19-AG19)/AG19,"") -> -1 | AJ19: =SUMIFS(Sheet1!$H:$H,Sheet1!$C:$C,$K19,Sheet1!$E:$E,AJ$3) -> 379248 | AK19: =SUMIFS(Sheet1!$H:$H,Sheet1!$C:$C,$K19,Sheet1!$E:$E,AK$3) -> 0 | AL19: =IFERROR((AK19-AJ19)/AJ19,"") -> -1 | AM19: =SUMIFS(Sheet1!$H:$H,Sheet1!$C:$C,$K19,Sheet1!$E:$E,AM$3) -> 129818 | AN19: =SUMIFS(Sheet1!$H:$H,Sheet1!$C:$C,$K19,Sheet1!$E:$E,AN$3) -> 0 | AO19: =IFERROR((AN19-AM19)/AM19,"") -> -1 | AP19: =SUMIFS(Sheet1!$H:$H,Sheet1!$C:$C,$K19,Sheet1!$E:$E,AP$3) -> 0 | AQ19: =SUMIFS(Sheet1!$H:$H,Sheet1!$C:$C,$K19,Sheet1!$E:$E,AQ$3) -> 0 | AR19: =IFERROR((AQ19-AP19)/AP19,"") | AS19: =SUMIFS(Sheet1!$H:$H,Sheet1!$C:$C,$K19,Sheet1!$E:$E,AS$3) -> 0 | AT19: =SUMIFS(Sheet1!$H:$H,Sheet1!$C:$C,$K19,Sheet1!$E:$E,AT$3) -> 0 | AU19: =IFERROR((AT19-AS19)/AS19,"")
J20: =IFERROR(__xludf.DUMMYFUNCTION("""COMPUTED_VALUE"""),1022204.0) -> 1022204 | K20: =IFERROR(__xludf.DUMMYFUNCTION("""COMPUTED_VALUE"""),"HYDURE PIPE FITTING COMPANY (HR)") -> HYDURE PIPE FITTING COMPANY (HR) | L20: =SUMIFS(Sheet1!$H:$H,Sheet1!$C:$C,$K20,Sheet1!$E:$E,L$3) -> 0 | M20: =SUMIFS(Sheet1!$H:$H,Sheet1!$C:$C,$K20,Sheet1!$E:$E,M$3) -> 0 | N20: =IFERROR((M20-L20)/L20,"") | O20: =SUMIFS(Sheet1!$H:$H,Sheet1!$C:$C,$K20,Sheet1!$E:$E,O$3) -> 0 | P20: =SUMIFS(Sheet1!$H:$H,Sheet1!$C:$C,$K20,Sheet1!$E:$E,P$3) -> 0 | Q20: =IFERROR((P20-O20)/O20,"") | R20: =SUMIFS(Sheet1!$H:$H,Sheet1!$C:$C,$K20,Sheet1!$E:$E,R$3) -> 0 | S20: =SUMIFS(Sheet1!$H:$H,Sheet1!$C:$C,$K20,Sheet1!$E:$E,S$3) -> 1022204 | T20: =IFERROR((S20-R20)/R20,"") | U20: =SUMIFS(Sheet1!$H:$H,Sheet1!$C:$C,$K20,Sheet1!$E:$E,U$3) -> 0 | V20: =SUMIFS(Sheet1!$H:$H,Sheet1!$C:$C,$K20,Sheet1!$E:$E,V$3) -> 0 | W20: =IFERROR((V20-U20)/U20,"") | X20: =SUMIFS(Sheet1!$H:$H,Sheet1!$C:$C,$K20,Sheet1!$E:$E,X$3) -> 0 | Y20: =SUMIFS(Sheet1!$H:$H,Sheet1!$C:$C,$K20,Sheet1!$E:$E,Y$3) -> 0 | Z20: =IFERROR((Y20-X20)/X20,"") | AA20: =SUMIFS(Sheet1!$H:$H,Sheet1!$C:$C,$K20,Sheet1!$E:$E,AA$3) -> 0 | AB20: =SUMIFS(Sheet1!$H:$H,Sheet1!$C:$C,$K20,Sheet1!$E:$E,AB$3) -> 0 | AC20: =IFERROR((AB20-AA20)/AA20,"") | AD20: =SUMIFS(Sheet1!$H:$H,Sheet1!$C:$C,$K20,Sheet1!$E:$E,AD$3) -> 0 | AE20: =SUMIFS(Sheet1!$H:$H,Sheet1!$C:$C,$K20,Sheet1!$E:$E,AE$3) -> 0 | AF20: =IFERROR((AE20-AD20)/AD20,"") | AG20: =SUMIFS(Sheet1!$H:$H,Sheet1!$C:$C,$K20,Sheet1!$E:$E,AG$3) -> 0 | AH20: =SUMIFS(Sheet1!$H:$H,Sheet1!$C:$C,$K20,Sheet1!$E:$E,AH$3) -> 0 | AI20: =IFERROR((AH20-AG20)/AG20,"") | AJ20: =SUMIFS(Sheet1!$H:$H,Sheet1!$C:$C,$K20,Sheet1!$E:$E,AJ$3) -> 0 | AK20: =SUMIFS(Sheet1!$H:$H,Sheet1!$C:$C,$K20,Sheet1!$E:$E,AK$3) -> 0 | AL20: =IFERROR((AK20-AJ20)/AJ20,"") | AM20: =SUMIFS(Sheet1!$H:$H,Sheet1!$C:$C,$K20,Sheet1!$E:$E,AM$3) -> 0 | AN20: =SUMIFS(Sheet1!$H:$H,Sheet1!$C:$C,$K20,Sheet1!$E:$E,AN$3) -> 0 | AO20: =IFERROR((AN20-AM20)/AM20,"") | AP20: =SUMIFS(Sheet1!$H:$H,Sheet1!$C:$C,$K20,Sheet1!$E:$E,AP$3) -> 0 | AQ20: =SUMIFS(Sheet1!$H:$H,Sheet1!$C:$C,$K20,Sheet1!$E:$E,AQ$3) -> 0 | AR20: =IFERROR((AQ20-AP20)/AP20,"") | AS20: =SUMIFS(Sheet1!$H:$H,Sheet1!$C:$C,$K20,Sheet1!$E:$E,AS$3) -> 0 | AT20: =SUMIFS(Sheet1!$H:$H,Sheet1!$C:$C,$K20,Sheet1!$E:$E,AT$3) -> 0 | AU20: =IFERROR((AT20-AS20)/AS20,"")
J21: =IFERROR(__xludf.DUMMYFUNCTION("""COMPUTED_VALUE"""),1015488.0) -> 1015488 | K21: =IFERROR(__xludf.DUMMYFUNCTION("""COMPUTED_VALUE"""),"JULUCK ENTERPRISES") -> JULUCK ENTERPRISES | L21: =SUMIFS(Sheet1!$H:$H,Sheet1!$C:$C,$K21,Sheet1!$E:$E,L$3) -> 0 | M21: =SUMIFS(Sheet1!$H:$H,Sheet1!$C:$C,$K21,Sheet1!$E:$E,M$3) -> 314161 | N21: =IFERROR((M21-L21)/L21,"") | O21: =SUMIFS(Sheet1!$H:$H,Sheet1!$C:$C,$K21,Sheet1!$E:$E,O$3) -> 0 | P21: =SUMIFS(Sheet1!$H:$H,Sheet1!$C:$C,$K21,Sheet1!$E:$E,P$3) -> 333148 | Q21: =IFERROR((P21-O21)/O21,"") | R21: =SUMIFS(Sheet1!$H:$H,Sheet1!$C:$C,$K21,Sheet1!$E:$E,R$3) -> 0 | S21: =SUMIFS(Sheet1!$H:$H,Sheet1!$C:$C,$K21,Sheet1!$E:$E,S$3) -> 368179 | T21: =IFERROR((S21-R21)/R21,"") | U21: =SUMIFS(Sheet1!$H:$H,Sheet1!$C:$C,$K21,Sheet1!$E:$E,U$3) -> 0 | V21: =SUMIFS(Sheet1!$H:$H,Sheet1!$C:$C,$K21,Sheet1!$E:$E,V$3) -> 0 | W21: =IFERROR((V21-U21)/U21,"") | X21: =SUMIFS(Sheet1!$H:$H,Sheet1!$C:$C,$K21,Sheet1!$E:$E,X$3) -> 0 | Y21: =SUMIFS(Sheet1!$H:$H,Sheet1!$C:$C,$K21,Sheet1!$E:$E,Y$3) -> 0 | Z21: =IFERROR((Y21-X21)/X21,"") | AA21: =SUMIFS(Sheet1!$H:$H,Sheet1!$C:$C,$K21,Sheet1!$E:$E,AA$3) -> 0 | AB21: =SUMIFS(Sheet1!$H:$H,Sheet1!$C:$C,$K21,Sheet1!$E:$E,AB$3) -> 0 | AC21: =IFERROR((AB21-AA21)/AA21,"") | AD21: =SUMIFS(Sheet1!$H:$H,Sheet1!$C:$C,$K21,Sheet1!$E:$E,AD$3) -> 0 | AE21: =SUMIFS(Sheet1!$H:$H,Sheet1!$C:$C,$K21,Sheet1!$E:$E,AE$3) -> 0 | AF21: =IFERROR((AE21-AD21)/AD21,"") | AG21: =SUMIFS(Sheet1!$H:$H,Sheet1!$C:$C,$K21,Sheet1!$E:$E,AG$3) -> 0 | AH21: =SUMIFS(Sheet1!$H:$H,Sheet1!$C:$C,$K21,Sheet1!$E:$E,AH$3) -> 0 | AI21: =IFERROR((AH21-AG21)/AG21,"") | AJ21: =SUMIFS(Sheet1!$H:$H,Sheet1!$C:$C,$K21,Sheet1!$E:$E,AJ$3) -> 0 | AK21: =SUMIFS(Sheet1!$H:$H,Sheet1!$C:$C,$K21,Sheet1!$E:$E,AK$3) -> 0 | AL21: =IFERROR((AK21-AJ21)/AJ21,"") | AM21: =SUMIFS(Sheet1!$H:$H,Sheet1!$C:$C,$K21,Sheet1!$E:$E,AM$3) -> 0 | AN21: =SUMIFS(Sheet1!$H:$H,Sheet1!$C:$C,$K21,Sheet1!$E:$E,AN$3) -> 0 | AO21: =IFERROR((AN21-AM21)/AM21,"") | AP21: =SUMIFS(Sheet1!$H:$H,Sheet1!$C:$C,$K21,Sheet1!$E:$E,AP$3) -> 0 | AQ21: =SUMIFS(Sheet1!$H:$H,Sheet1!$C:$C,$K21,Sheet1!$E:$E,AQ$3) -> 0 | AR21: =IFERROR((AQ21-AP21)/AP21,"") | AS21: =SUMIFS(Sheet1!$H:$H,Sheet1!$C:$C,$K21,Sheet1!$E:$E,AS$3) -> 0 | AT21: =SUMIFS(Sheet1!$H:$H,Sheet1!$C:$C,$K21,Sheet1!$E:$E,AT$3) -> 0 | AU21: =IFERROR((AT21-AS21)/AS21,"")
