Workbook

Sheet Head_Summary
A1: August 2026 order booking by state head — roster-based attribution
A2: Every CRM sales user mapped to a head using the STATE HEAD DASHBOARD 2026-27 roster first, then the CRM reporting-manager chain. Source: Aug_month_order_booking.xlsx, September_Order_Booking.xlsx (1–17 Sep).
A4: State head | B4: Aug value — roster-based (Rs) | C4: Aug value — app today, Product-Wise by person (Rs) | D4: Difference (Rs) | E4: secondary_head_month ordered, Aug (Rs) | F4: Roster-based vs head_month (Rs) | G4: Sep 1–17 value — roster-based (Rs)
A5: Sandeep Dadheech | B5: =SUMIFS(User_to_Head!$K$2:$K$153,User_to_Head!$C$2:$C$153,A5) -> 123742880 | C5: 91774735 | D5: =B5-C5 -> 31968145 | E5: 1.1041785e+08 | F5: =B5-E5 -> 13325027 | G5: =SUMIFS(User_to_Head!$L$2:$L$153,User_to_Head!$C$2:$C$153,A5) -> 41382251
A6: Syed Aqil Rizvi | B6: =SUMIFS(User_to_Head!$K$2:$K$153,User_to_Head!$C$2:$C$153,A6) -> 37557506 | C6: 29558636 | D6: =B6-C6 -> 7998870 | E6: 13040396 | F6: =B6-E6 -> 24517110 | G6: =SUMIFS(User_to_Head!$L$2:$L$153,User_to_Head!$C$2:$C$153,A6) -> 7785866
A7: Lalan Kumar | B7: =SUMIFS(User_to_Head!$K$2:$K$153,User_to_Head!$C$2:$C$153,A7) -> 11240415 | C7: 8645386 | D7: =B7-C7 -> 2595029 | E7: 8322015.5 | F7: =B7-E7 -> 2918399.5 | G7: =SUMIFS(User_to_Head!$L$2:$L$153,User_to_Head!$C$2:$C$153,A7) -> 2006801
A8: Anant Singh | B8: =SUMIFS(User_to_Head!$K$2:$K$153,User_to_Head!$C$2:$C$153,A8) -> 8646568 | C8: 5286655 | D8: =B8-C8 -> 3359913 | E8: 6385850.3 | F8: =B8-E8 -> 2260717.7 | G8: =SUMIFS(User_to_Head!$L$2:$L$153,User_to_Head!$C$2:$C$153,A8) -> 3336577
A9: Biju C.O | B9: =SUMIFS(User_to_Head!$K$2:$K$153,User_to_Head!$C$2:$C$153,A9) -> 6725577 | C9: 5049235 | D9: =B9-C9 -> 1676342 | E9: 3635465.2 | F9: =B9-E9 -> 3090111.8 | G9: =SUMIFS(User_to_Head!$L$2:$L$153,User_to_Head!$C$2:$C$153,A9) -> 2260578
A10: Pawan Kumar Sharma | B10: =SUMIFS(User_to_Head!$K$2:$K$153,User_to_Head!$C$2:$C$153,A10) -> 3511104 | C10: 2957156 | D10: =B10-C10 -> 553948 | E10: 995810.26 | F10: =B10-E10 -> 2515293.7 | G10: =SUMIFS(User_to_Head!$L$2:$L$153,User_to_Head!$C$2:$C$153,A10) -> 2175556
A11: Sunil Patel | B11: =SUMIFS(User_to_Head!$K$2:$K$153,User_to_Head!$C$2:$C$153,A11) -> 1722676 | C11: 9722299 | D11: =B11-C11 -> -7999623 | E11: 1253434 | F11: =B11-E11 -> 469241.98 | G11: =SUMIFS(User_to_Head!$L$2:$L$153,User_to_Head!$C$2:$C$153,A11) -> 731842
A12: Sulinder Pal | B12: =SUMIFS(User_to_Head!$K$2:$K$153,User_to_Head!$C$2:$C$153,A12) -> 1404844 | C12: 748919 | D12: =B12-C12 -> 655925 | E12: 1290551.9 | F12: =B12-E12 -> 114292.06 | G12: =SUMIFS(User_to_Head!$L$2:$L$153,User_to_Head!$C$2:$C$153,A12) -> 520711
A13: Nasir Hussain Khan | B13: =SUMIFS(User_to_Head!$K$2:$K$153,User_to_Head!$C$2:$C$153,A13) -> 1236719 | C13: 197314 | D13: =B13-C13 -> 1039405 | E13: 668308.1 | F13: =B13-E13 -> 568410.9 | G13: =SUMIFS(User_to_Head!$L$2:$L$153,User_to_Head!$C$2:$C$153,A13) -> 1105629
A14: Not attributed to any head (app today) | B14: 0 | C14: =195788289-SUM(C5:C13) -> 41847954 | D14: =B14-C14 -> -41847954 | E14: 0 | F14: =B14-E14 -> 0 | G14: 0
A15: Total | B15: =SUM(B5:B14) -> 195788289 | C15: =SUM(C5:C14) -> 195788289 | D15: =SUM(D5:D14) -> 0 | E15: =SUM(E5:E14) -> 1.4600968e+08 | F15: =SUM(F5:F14) -> 49778604 | G15: =SUM(G5:G14) -> 61305811
A17: Notes
A18: Column C = figures the app reported on 19 Sep (Prompt 119 E table) via person_registry; it leaves Rs 4.19 Cr with no head.
A19: Column E = secondary_head_month ordered after the 19 Sep 11:11 UTC reload (run 381): Pawan +Rs 9,95,810.26 (Vikash Gour), Biju +Rs 8,67,880.20 (J. Suresh Kumar). Source: Replit report 19 Sep.
A20: Roster-based attribution places 100% of August value (Rs 19,57,88,289) with a named head: 144 of 152 users by exact roster name, 8 by the CRM reporting-manager chain.
A21: Sunil Patel: the roster team is Gujarat only (Devdutt Joshi, Dhaval Parmar, Rathod Vijaybhai). The app gives him about Rs 80 L more; the same amount is missing from Syed Aqil Rizvi.
A22: Two roster heads are spelled two ways (Sulindar/Sulinder Pal; Biju C.O/Biju CO) and treated as one here.

Sheet User_to_Head
A1: CRM Sales User Name | B1: Employee ID | C1: Proposed state head | D1: Basis | E1: Roster head (STATE HEAD DASHBOARD 2026-27) | F1: CRM reporting manager | G1: CRM chain to head | H1: Main states | I1: Aug rows | J1: Sep rows (1-17) | K1: Aug value (Rs ex-GST) | L1: Sep value 1-17 (Rs ex-GST) | M1: Note
A2: RAVINDER PURI | B2: PRG-361 | C2: Anant Singh | D2: Roster (exact name) | E2: Anant Singh | F2: ANANT SINGH | G2: ANANT SINGH | H2: UTTAR PRADESH | I2: 407 | J2: 105 | K2: 1770801 | L2: 439943
A3: SHIVAM CHAUHAN | B3: PRG-056 | C3: Anant Singh | D3: Roster (exact name) | E3: Anant Singh | F3: ANANT SINGH | G3: ANANT SINGH | H3: UTTARAKHAND, UTTAR PRADESH | I3: 153 | J3: 135 | K3: 1223544 | L3: 543081
A4: RINKU | B4: PRG-124 | C4: Anant Singh | D4: Roster (exact name) | E4: Anant Singh | F4: ANANT SINGH | G4: ANANT SINGH | H4: UTTAR PRADESH | I4: 135 | J4: 0 | K4: 959597 | L4: 0
A5: TARUN GIRI | B5: PRG-029 | C5: Anant Singh | D5: Roster (exact name) | E5: Anant Singh | F5: ANANT SINGH | G5: ANANT SINGH | H5: UTTAR PRADESH | I5: 155 | J5: 115 | K5: 949948 | L5: 643954
A6: MANISH GUPTA | B6: PRG-128 | C6: Anant Singh | D6: Roster (exact name) | E6: Anant Singh | F6: ANANT SINGH | G6: ANANT SINGH | H6: UTTAR PRADESH, DELHI | I6: 243 | J6: 141 | K6: 916901 | L6: 691968
A7: PRASUN CHATTERJEE | B7: PRG-354 | C7: Anant Singh | D7: Roster (exact name) | E7: Anant Singh | F7: ANANT SINGH | G7: ANANT SINGH | H7: DELHI | I7: 28 | J7: 0 | K7: 761005 | L7: 0
A8: RAHUL SINGH | B8: PRG-001 | C8: Anant Singh | D8: Roster (exact name) | E8: Anant Singh | F8: ANANT SINGH | G8: ANANT SINGH | H8: UTTAR PRADESH | I8: 115 | J8: 68 | K8: 737716 | L8: 285048
A9: ASHUTOSH KUMAR (RUDRAPUR) | B9: PRG-102 | C9: Anant Singh | D9: CRM chain | E9: Anant Singh / Sandeep Dadheech | F9: ANANT SINGH | G9: ANANT SINGH | H9: UTTARAKHAND | I9: 121 | J9: 34 | K9: 722410 | L9: 439058 | M9: Two Ashutosh Kumar in roster. This one sells in Uttarakhand and reports to Anant.
A10: ANKIT KUMAR | B10: PRG-036 | C10: Anant Singh | D10: Roster (exact name) | E10: Anant Singh | F10: ANANT SINGH | G10: ANANT SINGH | H10: UTTAR PRADESH, WEST U.P | I10: 82 | J10: 53 | K10: 604646 | L10: 293525
A11: K.V.THAMIZHSELVAN | B11: PRG-341 | C11: Biju C.O | D11: Roster (exact name) | E11: Biju C.O | F11: BIJU C.O | G11: BIJU C.O | H11: TAMIL NADU, ANDHRA PRADESH | I11: 353 | J11: 129 | K11: 1370253 | L11: 489184
A12: SAIBULLA S. | B12: PRG-112 | C12: Biju C.O | D12: Roster (exact name) | E12: Biju C.O | F12: BIJU C.O | G12: BIJU C.O | H12: TAMIL NADU | I12: 168 | J12: 6 | K12: 903787 | L12: 23887
A13: J.SURESH KUMAR | B13: PRG-338 | C13: Biju C.O | D13: Roster (exact name) | E13: Biju C.O | F13: BIJU C.O | G13: BIJU C.O | H13: TAMIL NADU, PUDUCHERRY | I13: 157 | J13: 59 | K13: 867882 | L13: 287471
A14: K SURESH KUMAR | B14: PRG-028 | C14: Biju C.O | D14: Roster (exact name) | E14: Biju C.O | F14: BIJU C.O | G14: BIJU C.O | H14: TAMIL NADU | I14: 185 | J14: 73 | K14: 759158 | L14: 275693
A15: GIRISH B | B15: PRG-149 | C15: Biju C.O | D15: Roster (exact name) | E15: Biju C.O | F15: BIJU C.O | G15: BIJU C.O | H15: KERALA | I15: 117 | J15: 110 | K15: 638179 | L15: 541986
A16: AMEERALI EK (OFF ROLL) | B16: PRG-095 | C16: Biju C.O | D16: Roster (exact name) | E16: Biju C.O | F16: BIJU C.O | G16: BIJU C.O | H16: KERALA | I16: 84 | J16: 8 | K16: 613655 | L16: 72888
A17: RIYAS V | B17: PRG-082 | C17: Biju C.O | D17: Roster (exact name) | E17: Biju C.O | F17: BIJU C.O | G17: BIJU C.O | H17: KERALA | I17: 69 | J17: 90 | K17: 527216 | L17: 449016
A18: PRATHEESH CC | B18: PRG-355 | C18: Biju C.O | D18: Roster (exact name) | E18: Biju C.O | F18: BIJU C.O | G18: BIJU C.O | H18: KERALA | I18: 60 | J18: 0 | K18: 452594 | L18: 0
A19: PRATHAM KYASTI | B19: PRG-014 | C19: Biju C.O | D19: Roster (exact name) | E19: Biju C.O | F19: PRASHANT ONAM NAIK | G19: PRASHANT ONAM NAIK | H19: KARNATAKA | I19: 118 | J19: 16 | K19: 275044 | L19: 37352
A20: ABHISHEK RAVINDRA PADADAR | B20: PRG-008 | C20: Biju C.O | D20: Roster (exact name) | E20: Biju C.O | F20: PRASHANTHA M | G20: PRASHANTHA M(roster) | H20: KARNATAKA | I20: 87 | J20: 44 | K20: 224885 | L20: 83101 | M20: Roster says Biju C.O; CRM manager Prashantha M is Sandeep primary team. Roster kept.
A21: MILIND ASHOK SADANAND | B21: PRG-031 | C21: Biju C.O | D21: Roster (exact name) | E21: Biju C.O | F21: PRASHANT ONAM NAIK | G21: PRASHANT ONAM NAIK | H21: KARNATAKA | I21: 22 | J21: 0 | K21: 41651 | L21: 0
A22: ABHISHEKGOUD .K. PATIL | B22: NJ-7 | C22: Biju C.O | D22: CRM chain | F22: MILIND ASHOK SADANAND | G22: MILIND ASHOK SADANAND(roster) | H22: KARNATAKA | I22: 3 | J22: 0 | K22: 23170 | L22: 0 | M22: Not in roster. Manager Milind Ashok Sadanand is in Biju roster (Hubli).
A23: HARSHA K RAO | B23: PRG-021 | C23: Biju C.O | D23: Roster (exact name) | E23: Biju C.O | F23: PRASHANT ONAM NAIK | G23: PRASHANT ONAM NAIK | H23: KARNATAKA | I23: 17 | J23: 0 | K23: 22739 | L23: 0
A24: KRISHNA KUMAR K | B24: NJ-5 | C24: Biju C.O | D24: CRM chain | F24: BIJU C.O | G24: BIJU C.O | H24: KERALA | I24: 1 | J24: 0 | K24: 5364 | L24: 0
A25: AMEY DEODHAR | B25: PRG-323 | C25: Lalan Kumar | D25: Roster (exact name) | E25: Lalan Kumar | F25: LALAN KUMAR | G25: LALAN KUMAR | H25: MAHARASHTRA | I25: 145 | J25: 8 | K25: 1825278 | L25: 115126
A26: TEJAS LUNAWAT | B26: PRG-430 | C26: Lalan Kumar | D26: Roster (exact name) | E26: Lalan Kumar | F26: LALAN KUMAR | G26: LALAN KUMAR | H26: MAHARASHTRA | I26: 40 | J26: 0 | K26: 1131452 | L26: 0
A27: SANDEEP AMRUT SONAWANE | B27: PRG-377 | C27: Lalan Kumar | D27: Roster (exact name) | E27: Lalan Kumar | F27: TEJAS LUNAWAT | G27: TEJAS LUNAWAT(roster) | H27: MAHARASHTRA | I27: 145 | J27: 36 | K27: 1056280 | L27: 431321
A28: UNMESH DILIP THAKAR | B28: PRG-016 | C28: Lalan Kumar | D28: Roster (exact name) | E28: Lalan Kumar | F28: AMEY DEODHAR | G28: AMEY DEODHAR(roster) | H28: MAHARASHTRA | I28: 197 | J28: 3 | K28: 954040 | L28: 40395
A29: AMIT DAMODHAR JADHAV | B29: PRG-324 | C29: Lalan Kumar | D29: Roster (exact name) | E29: Lalan Kumar | F29: LALAN KUMAR | G29: LALAN KUMAR | H29: MAHARASHTRA | I29: 136 | J29: 37 | K29: 939289 | L29: 217983
A30: VIJAY DNYANESHWAR | B30: PRG-242 | C30: Lalan Kumar | D30: Roster (exact name) | E30: Lalan Kumar | F30: LALAN KUMAR | G30: LALAN KUMAR | H30: MAHARASHTRA | I30: 175 | J30: 31 | K30: 919531 | L30: 158279
A31: CHANDRAKANT MANDAVE | B31: PRG-330 | C31: Lalan Kumar | D31: Roster (exact name) | E31: Lalan Kumar | F31: LALAN KUMAR | G31: LALAN KUMAR | H31: MAHARASHTRA | I31: 132 | J31: 20 | K31: 787879 | L31: 194413
A32: VAIBHAV BAPURAO WAGHE | B32: PRG-007 | C32: Lalan Kumar | D32: Roster (exact name) | E32: Lalan Kumar | F32: TEJAS LUNAWAT | G32: TEJAS LUNAWAT(roster) | H32: MAHARASHTRA | I32: 126 | J32: 19 | K32: 639346 | L32: 47071
A33: TUSHAR RAVINDRA KANTHALE | B33: PRG-321 | C33: Lalan Kumar | D33: Roster (exact name) | E33: Lalan Kumar | F33: TEJAS LUNAWAT | G33: TEJAS LUNAWAT(roster) | H33: MAHARASHTRA | I33: 125 | J33: 0 | K33: 590932 | L33: 0
A34: KUNAL SANJAY SASANE | B34: PRG-133 | C34: Lalan Kumar | D34: Roster (exact name) | E34: Lalan Kumar | F34: AMEY DEODHAR | G34: AMEY DEODHAR(roster) | H34: MAHARASHTRA | I34: 161 | J34: 0 | K34: 483995 | L34: 0
A35: PRASAD PUNDALIK YEDGE | B35: PRG-013 | C35: Lalan Kumar | D35: Roster (exact name) | E35: Lalan Kumar | F35: LALAN KUMAR | G35: LALAN KUMAR | H35: MAHARASHTRA | I35: 195 | J35: 22 | K35: 426405 | L35: 43883
A36: SYED SOHEL HASHMI | B36: PRG-155 | C36: Lalan Kumar | D36: Roster (exact name) | E36: Lalan Kumar | F36: TEJAS LUNAWAT | G36: TEJAS LUNAWAT(roster) | H36: MAHARASHTRA | I36: 77 | J36: 103 | K36: 410026 | L36: 458050
... A40: PAWAN KUMAR | B40: PRG-350 | C40: Nasir Hussain Khan | D40: Roster (exact name) | E40: Nasir Hussain Khan | F40: NASIR HUSSAIN KHAN | G40: NASIR HUSSAIN KHAN | H40: JAMMU AND KASHMIR | I40: 66 | J40: 11 | K40: 469566 | L40: 1105629
A41: BASHARAT MAJEED MAGLOO | B41: NJ-6 | C41: Nasir Hussain Khan | D41: CRM chain | F41: NASIR HUSSAIN KHAN | G41: NASIR HUSSAIN KHAN | H41: JAMMU AND KASHMIR | I41: 31 | J41: 0 | K41: 444284 | L41: 0
A42: TAFAZUL NAZIR | B42: PRG-278 | C42: Nasir Hussain Khan | D42: Roster (exact name) | E42: Nasir Hussain Khan | F42: NASIR HUSSAIN KHAN | G42: NASIR HUSSAIN KHAN | H42: JAMMU AND KASHMIR | I42: 13 | J42: 0 | K42: 125555 | L42: 0
A43: DEEP KUMAR | B43: PRG-027 | C43: Nasir Hussain Khan | D43: Roster (exact name) | E43: Nasir Hussain Khan | F43: NASIR HUSSAIN KHAN | G43: NASIR HUSSAIN KHAN | H43: JAMMU AND KASHMIR | I43: 25 | J43: 0 | K43: 101416 | L43: 0
...
