Workbook

Sheet ORDER BOOKING REPORT 2025-26
B1: ORDER BOOKING REPORT 2025-26 | M1: =sum(M3,N1)-sum('Summary 25-26'!M5:N5) -> 2309013868 | N1: 2735023
C3: TOTAL | I3: =SUM(I7:I225) -> 7860770 | J3: =SUM(J7:J225) -> 3.6643401e+08 | K3: =SUM(K7:K225) -> 17273 | L3: =SUM(L7:L225) -> 3797511503 | M3: =SUM(M7:M225) -> 2344243214 | N3: =iferror(O3/L3,"") -> 0.63235699 | O3: =SUM(O7:O225) -> 2401382930 | P3: =SUM(P7:P225) -> 2.6491977e+08 | Q3: =SUM(Q7:Q225) -> 7200 | R3: =SUM(R7:R225) -> 1.3199116e+08 | S3: =SUM(S7:S225) -> 2590 | T3: =iferror(R3/P3,"") -> 0.4982307 | U3: =SUM(U7:U225) -> 143975271 | V3: =SUM(V7:V225) -> 2877 | W3: =SUM(W7:W225) -> 2.7900015e+08 | X3: =SUM(X7:X225) -> 7448 | Y3: =SUM(Y7:Y225) -> 1.8800099e+08 | Z3: =SUM(Z7:Z225) -> 3118 | AA3: =iferror(Y3/W3,"") -> 0.67383832 | AB3: =SUM(AB7:AB225) -> 1.9194412e+08 | AC3: =SUM(AC7:AC225) -> 3405 | AD3: =SUM(AD7:AD225) -> 3.007814e+08 | AE3: =SUM(AE7:AE225) -> 7743 | AF3: =SUM(AF7:AF225) -> 2.0909692e+08 | AG3: =SUM(AG7:AG225) -> 3019 | AH3: =iferror(AF3/AD3,"") -> 0.69517902 | AI3: =SUM(AI7:AI225) -> 2.1790106e+08 | AJ3: =SUM(AJ7:AJ225) -> 3220 | AK3: =SUM(AK7:AK225) -> 2.9376451e+08 | AL3: =SUM(AL7:AL225) -> 7782 | AM3: =SUM(AM7:AM225) -> 1.9449774e+08 | AN3: =SUM(AN7:AN225) -> 3266 | AO3: =iferror(AM3/AK3,"") -> 0.66208726 | AP3: =SUM(AP7:AP225) -> 1.9185567e+08 | AQ3: =SUM(AQ7:AQ225) -> 3310 | AR3: =SUM(AR7:AR225) -> 2.8231115e+08 | AS3: =SUM(AS7:AS225) -> 7887 | AT3: =SUM(AT7:AT225) -> 1.9327481e+08 | AU3: =SUM(AU7:AU225) -> 3120 | AV3: =iferror(AT3/AR3,"") -> 0.68461629 | AW3: =SUM(AW7:AW225) -> 1.9483789e+08 | AX3: =SUM(AX7:AX225) -> 3260 | AY3: =SUM(AY7:AY225) -> 3.0258034e+08 | AZ3: =SUM(AZ7:AZ225) -> 8074 | BA3: =SUM(BA7:BA225) -> 2.0462143e+08 | BB3: =SUM(BB7:BB225) -> 3326 | BC3: =iferror(BA3/AY3,"") -> 0.67625487 | BD3: =SUM(BD7:BD225) -> 2.0385066e+08 | BE3: =SUM(BE7:BE225) -> 3424 | BF3: =SUM(BF7:BF225) -> 2.8846526e+08 | BG3: =SUM(BG7:BG225) -> 7874 | BH3: =SUM(BH7:BH225) -> 1.7662105e+08 | BI3: =SUM(BI7:BI225) -> 2886 | BJ3: =iferror(BH3/BF3,"") -> 0.6122784 | BK3: =SUM(BK7:BK225) -> 1.8054222e+08 | BL3: =SUM(BL7:BL225) -> 3087 | BM3: =SUM(BM7:BM225) -> 2.9090573e+08 | BN3: =SUM(BN7:BN225) -> 7908 | BO3: =SUM(BO7:BO225) -> 1.7189559e+08 | BP3: =SUM(BP7:BP225) -> 3005 | BQ3: =iferror(BO3/BM3,"") -> 0.5908979 | BR3: =SUM(BR7:BR225) -> 1.7585819e+08 | BS3: =SUM(BS7:BS225) -> 3146 | BT3: =SUM(BT7:BT225) -> 3.2391346e+08 | BU3: =SUM(BU7:BU225) -> 8155 | BV3: =SUM(BV7:BV225) -> 2.0831272e+08 | BW3: =SUM(BW7:BW225) -> 3245 | BX3: =iferror(BV3/BT3,"") -> 0.64311226 | BY3: =SUM(BY7:BY225) -> 2.1256178e+08 | BZ3: =SUM(BZ7:BZ225) -> 3440 | CA3: =SUM(CA7:CA225) -> 2.8735403e+08 | CB3: =SUM(CB7:CB225) -> 7878 | CC3: =SUM(CC7:CC225) -> 2.0746012e+08 | CD3: =SUM(CD7:CD225) -> 3107 | CE3: =iferror(CC3/CA3,"") -> 0.72196699 | CF3: =SUM(CF7:CF225) -> 2.0719789e+08 | CG3: =SUM(CG7:CG225) -> 3392 | CH3: =SUM(CH7:CH225) -> 2.9736784e+08 | CI3: =SUM(CI7:CI225) -> 7731 | CJ3: =SUM(CJ7:CJ225) -> 1.9305124e+08 | CK3: =SUM(CK7:CK225) -> 3001 | CL3: =iferror(CJ3/CH3,"") -> 0.64920012 | CM3: =SUM(CM7:CM225) -> 2.0244648e+08 | CN3: =SUM(CN7:CN225) -> 3331 | CO3: =SUM(CO7:CO225) -> 3.1409766e+08 | CP3: =SUM(CP7:CP225) -> 7531 | CQ3: =SUM(CQ7:CQ225) -> 2.6541946e+08 | CR3: =SUM(CR7:CR225) -> 2970 | CS3: =iferror(CQ3/CO3,"") -> 0.84502209 | CT3: =SUM(CT7:CT225) -> 2.784117e+08 | CU3: =SUM(CU7:CU225) -> 3167
B4: State Head | C4: Team Member | D4: H.Q | E4: Contact Number | F4: DOJ | G4: Week Off | H4: Market Hours | I4: Monthly CTC 25-26 | J4: Monthly Target 25-26 | K4: Total Dealer 25-26 | L4: Business Plan 25-26 | M4: Order Booked 25-26 | N4: Final Achievement | O4: Sales 25-26 | P4: 45748 | W4: 45778 | AD4: 45809 | AK4: 45839 | AR4: 45870 | AY4: 45901 | BF4: 45931 | BM4: 45962 | BT4: 45992 | CA4: 46023 | CH4: 46054 | CO4: 46082
P5: Plan | R5: Order Booked | T5: % of Achievement | U5: Sales Received | W5: Plan | Y5: Order Booked | AA5: % of Achievement | AB5: Sales Received | AD5: Plan | AF5: Order Booked | AH5: % of Achievement | AI5: Sales Received | AK5: Plan | AM5: Order Booked | AO5: % of Achievement | AP5: Sales Received | AR5: Plan | AT5: Order Booked | AV5: % of Achievement | AW5: Sales Received | AY5: Plan | BA5: Order Booked | BC5: % of Achievement | BD5: Sales Received | BF5: Plan | BH5: Order Booked | BJ5: % of Achievement | BK5: Sales Received | BM5: Plan | BO5: Order Booked | BQ5: % of Achievement | BR5: Sales Received | BT5: Plan | BV5: Order Booked | BX5: % of Achievement | BY5: Sales Received | CA5: Plan | CC5: Order Booked | CE5: % of Achievement | CF5: Sales Received | CH5: Plan | CJ5: Order Booked | CL5: % of Achievement | CM5: Sales Received | CO5: Plan | CQ5: Order Booked | CS5: % of Achievement | CT5: Sales Received
P6: Amount | Q6: Count | R6: Amount | S6: Count | U6: Amount | V6: Count | W6: Amount | X6: Count | Y6: Amount | Z6: Count | AB6: Amount | AC6: Count | AD6: Amount | AE6: Count | AF6: Amount | AG6: Count | AI6: Amount | AJ6: Count | AK6: Amount | AL6: Count | AM6: Amount | AN6: Count | AP6: Amount | AQ6: Count | AR6: Amount | AS6: Count | AT6: Amount | AU6: Count | AW6: Amount | AX6: Count | AY6: Amount | AZ6: Count | BA6: Amount | BB6: Count | BD6: Amount | BE6: Count | BF6: Amount | BG6: Count | BH6: Amount | BI6: Count | BK6: Amount | BL6: Count | BM6: Amount | BN6: Count | BO6: Amount | BP6: Count | BR6: Amount | BS6: Count | BT6: Amount | BU6: Count | BV6: Amount | BW6: Count | BY6: Amount | BZ6: Count | CA6: Amount | CB6: Count | CC6: Amount | CD6: Count | CF6: Amount | CG6: Count | CH6: Amount | CI6: Count | CJ6: Amount | CK6: Count | CM6: Amount | CN6: Count | CO6: Amount | CP6: Count | CQ6: Amount | CR6: Count | CT6: Amount | CU6: Count
A7: Anant Singh | B7: Anant Singh | C7: Ravinder Puri | D7: Ghaziabad | E7: 8802898600 | F7: 44809 | I7: =VLOOKUP($C7,Data!$C:$BV,72,0) -> 32910 | J7: 1800000 | K7: =IFERROR(__xludf.DUMMYFUNCTION("IMPORTRANGE(""1WowgCGTCOMmqanUXVQIbYWHbXi0cuGFxvrPe3CdSDpA"",""2025-26!A3"")"),106.0) -> 106 | L7: =IFERROR(__xludf.DUMMYFUNCTION("IMPORTRANGE(""1WowgCGTCOMmqanUXVQIbYWHbXi0cuGFxvrPe3CdSDpA"",""2025-26!G4"")"),2.13E7) -> 21300000 | M7: =R7+Y7+AF7+AM7+AT7+BA7+BH7+BO7+BV7+CC7+CJ7+CQ7 -> 20551333 | N7: =O7/L7 -> 1.0528726 | O7: =U7+AB7+AI7+AP7+AW7+BD7+BK7+BR7+BY7+CF7+CM7+CT7 -> 22426186 | P7: =IFERROR(__xludf.DUMMYFUNCTION("IMPORTRANGE(""1WowgCGTCOMmqanUXVQIbYWHbXi0cuGFxvrPe3CdSDpA"",""2025-26!J4"")"),1650000.0) -> 1650000 | Q7: =IFERROR(__xludf.DUMMYFUNCTION("IMPORTRANGE(""1WowgCGTCOMmqanUXVQIbYWHbXi0cuGFxvrPe3CdSDpA"",""2025-26!J3"")"),80.0) -> 80 | R7: =IFERROR(__xludf.DUMMYFUNCTION("IMPORTRANGE(""1WowgCGTCOMmqanUXVQIbYWHbXi0cuGFxvrPe3CdSDpA"",""2025-26!K4"")"),1636412.13) -> 1636412.1 | S7: =IFERROR(__xludf.DUMMYFUNCTION("IMPORTRANGE(""1WowgCGTCOMmqanUXVQIbYWHbXi0cuGFxvrPe3CdSDpA"",""2025-26!K3"")"),40.0) -> 40 | T7: =IFERROR((U7/P7),"") -> 1.0851794 | U7: =IFERROR(__xludf.DUMMYFUNCTION("IMPORTRANGE(""1WowgCGTCOMmqanUXVQIbYWHbXi0cuGFxvrPe3CdSDpA"",""2025-26!L4"")"),1790546.0) -> 1790546 | V7: =IFERROR(__xludf.DUMMYFUNCTION("IMPORTRANGE(""1WowgCGTCOMmqanUXVQIbYWHbXi0cuGFxvrPe3CdSDpA"",""2025-26!L3"")"),43.0) -> 43 | W7: =IFERROR(__xludf.DUMMYFUNCTION("IMPORTRANGE(""1WowgCGTCOMmqanUXVQIbYWHbXi0cuGFxvrPe3CdSDpA"",""2025-26!m4"")"),1800000.0) -> 1800000 | X7: =IFERROR(__xludf.DUMMYFUNCTION("IMPORTRANGE(""1WowgCGTCOMmqanUXVQIbYWHbXi0cuGFxvrPe3CdSDpA"",""2025-26!m3"")"),57.0) -> 57 | Y7: =IFERROR(__xludf.DUMMYFUNCTION("IMPORTRANGE(""1WowgCGTCOMmqanUXVQIbYWHbXi0cuGFxvrPe3CdSDpA"",""2025-26!N4"")"),1767294.6600000001) -> 1767294.7 | Z7: =IFERROR(__xludf.DUMMYFUNCTION("IMPORTRANGE(""1WowgCGTCOMmqanUXVQIbYWHbXi0cuGFxvrPe3CdSDpA"",""2025-26!N3"")"),56.0) -> 56 | AA7: =IFERROR((AB7/W7),"") -> 1.0165478 | AB7: =IFERROR(__xludf.DUMMYFUNCTION("IMPORTRANGE(""1WowgCGTCOMmqanUXVQIbYWHbXi0cuGFxvrPe3CdSDpA"",""2025-26!O4"")"),1829786.0) -> 1829786 | AC7: =IFERROR(__xludf.DUMMYFUNCTION("IMPORTRANGE(""1WowgCGTCOMmqanUXVQIbYWHbXi0cuGFxvrPe3CdSDpA"",""2025-26!O3"")"),60.0) -> 60 | AD7: =IFERROR(__xludf.DUMMYFUNCTION("IMPORTRANGE(""1WowgCGTCOMmqanUXVQIbYWHbXi0cuGFxvrPe3CdSDpA"",""2025-26!P4"")"),1800000.0) -> 1800000 | AE7: =IFERROR(__xludf.DUMMYFUNCTION("IMPORTRANGE(""1WowgCGTCOMmqanUXVQIbYWHbXi0cuGFxvrPe3CdSDpA"",""2025-26!P3"")"),92.0) -> 92 | AF7: =IFERROR(__xludf.DUMMYFUNCTION("IMPORTRANGE(""1WowgCGTCOMmqanUXVQIbYWHbXi0cuGFxvrPe3CdSDpA"",""2025-26!Q4"")"),1692838.3799999994) -> 1692838.4 | AG7: =IFERROR(__xludf.DUMMYFUNCTION("IMPORTRANGE(""1WowgCGTCOMmqanUXVQIbYWHbXi0cuGFxvrPe3CdSDpA"",""2025-26!Q3"")"),40.0) -> 40 | AH7: =IFERROR((AI7/AD7),"") -> 1.0018522 | AI7: =IFERROR(__xludf.DUMMYFUNCTION("IMPORTRANGE(""1WowgCGTCOMmqanUXVQIbYWHbXi0cuGFxvrPe3CdSDpA"",""2025-26!R4"")"),1803334.0) -> 1803334 | AJ7: =IFERROR(__xludf.DUMMYFUNCTION("IMPORTRANGE(""1WowgCGTCOMmqanUXVQIbYWHbXi0cuGFxvrPe3CdSDpA"",""2025-26!R3"")"),47.0) -> 47 | AK7: =IFERROR(__xludf.DUMMYFUNCTION("IMPORTRANGE(""1WowgCGTCOMmqanUXVQIbYWHbXi0cuGFxvrPe3CdSDpA"",""2025-26!S4"")"),1800000.0) -> 1800000 | AL7: =IFERROR(__xludf.DUMMYFUNCTION("IMPORTRANGE(""1WowgCGTCOMmqanUXVQIbYWHbXi0cuGFxvrPe3CdSDpA"",""2025-26!S3"")"),97.0) -> 97 | AM7: =IFERROR(__xludf.DUMMYFUNCTION("IMPORTRANGE(""1WowgCGTCOMmqanUXVQIbYWHbXi0cuGFxvrPe3CdSDpA"",""2025-26!T4"")"),1278357.0399999998) -> 1278357 | AN7: =IFERROR(__xludf.DUMMYFUNCTION("IMPORTRANGE(""1WowgCGTCOMmqanUXVQIbYWHbXi0cuGFxvrPe3CdSDpA"",""2025-26!T3"")"),37.0) -> 37 | AO7: =IFERROR((AP7/AK7),"") -> 0.74253333 | AP7: =IFERROR(__xludf.DUMMYFUNCTION("IMPORTRANGE(""1WowgCGTCOMmqanUXVQIbYWHbXi0cuGFxvrPe3CdSDpA"",""2025-26!U4"")"),1336560.0) -> 1336560 | AQ7: =IFERROR(__xludf.DUMMYFUNCTION("IMPORTRANGE(""1WowgCGTCOMmqanUXVQIbYWHbXi0cuGFxvrPe3CdSDpA"",""2025-26!U3"")"),39.0) -> 39 | AR7: =IFERROR(__xludf.DUMMYFUNCTION("IMPORTRANGE(""1WowgCGTCOMmqanUXVQIbYWHbXi0cuGFxvrPe3CdSDpA"",""2025-26!V4"")"),1800000.0) -> 1800000 | AS7: =IFERROR(__xludf.DUMMYFUNCTION("IMPORTRANGE(""1WowgCGTCOMmqanUXVQIbYWHbXi0cuGFxvrPe3CdSDpA"",""2025-26!V3"")"),92.0) -> 92 | AT7: =IFERROR(__xludf.DUMMYFUNCTION("IMPORTRANGE(""1WowgCGTCOMmqanUXVQIbYWHbXi0cuGFxvrPe3CdSDpA"",""2025-26!W4"")"),1498904.2899999998) -> 1498904.3 | AU7: =IFERROR(__xludf.DUMMYFUNCTION("IMPORTRANGE(""1WowgCGTCOMmqanUXVQIbYWHbXi0cuGFxvrPe3CdSDpA"",""2025-26!W3"")"),40.0) -> 40 | AV7: =IFERROR((AW7/AR7),"") -> 1.0169083 | AW7: =IFERROR(__xludf.DUMMYFUNCTION("IMPORTRANGE(""1WowgCGTCOMmqanUXVQIbYWHbXi0cuGFxvrPe3CdSDpA"",""2025-26!X4"")"),1830435.0) -> 1830435 | AX7: =IFERROR(__xludf.DUMMYFUNCTION("IMPORTRANGE(""1WowgCGTCOMmqanUXVQIbYWHbXi0cuGFxvrPe3CdSDpA"",""2025-26!X3"")"),55.0) -> 55 | AY7: =IFERROR(__xludf.DUMMYFUNCTION("IMPORTRANGE(""1WowgCGTCOMmqanUXVQIbYWHbXi0cuGFxvrPe3CdSDpA"",""2025-26!Y4"")"),1800000.0) -> 1800000 | AZ7: =IFERROR(__xludf.DUMMYFUNCTION("IMPORTRANGE(""1WowgCGTCOMmqanUXVQIbYWHbXi0cuGFxvrPe3CdSDpA"",""2025-26!Y3"")"),90.0) -> 90 | BA7: =IFERROR(__xludf.DUMMYFUNCTION("IMPORTRANGE(""1WowgCGTCOMmqanUXVQIbYWHbXi0cuGFxvrPe3CdSDpA"",""2025-26!Z4"")"),2039934.8599999999) -> 2039934.9 | BB7: =IFERROR(__xludf.DUMMYFUNCTION("IMPORTRANGE(""1WowgCGTCOMmqanUXVQIbYWHbXi0cuGFxvrPe3CdSDpA"",""2025-26!Z3"")"),48.0) -> 48 | BC7: =IFERROR((BD7/AY7),"") -> 1.2881567 | BD7: =IFERROR(__xludf.DUMMYFUNCTION("IMPORTRANGE(""1WowgCGTCOMmqanUXVQIbYWHbXi0cuGFxvrPe3CdSDpA"",""2025-26!AA4"")"),2318682.0) -> 2318682 | BE7: =IFERROR(__xludf.DUMMYFUNCTION("IMPORTRANGE(""1WowgCGTCOMmqanUXVQIbYWHbXi0cuGFxvrPe3CdSDpA"",""2025-26!AA3"")"),55.0) -> 55 | BF7: =IFERROR(__xludf.DUMMYFUNCTION("IMPORTRANGE(""1WowgCGTCOMmqanUXVQIbYWHbXi0cuGFxvrPe3CdSDpA"",""2025-26!AB4"")"),1800000.0) -> 1800000 | BG7: =IFERROR(__xludf.DUMMYFUNCTION("IMPORTRANGE(""1WowgCGTCOMmqanUXVQIbYWHbXi0cuGFxvrPe3CdSDpA"",""2025-26!AB3"")"),90.0) -> 90 | BH7: =IFERROR(__xludf.DUMMYFUNCTION("IMPORTRANGE(""1WowgCGTCOMmqanUXVQIbYWHbXi0cuGFxvrPe3CdSDpA"",""2025-26!AC4"")"),1299667.7899999996) -> 1299667.8 | BI7: =IFERROR(__xludf.DUMMYFUNCTION("IMPORTRANGE(""1WowgCGTCOMmqanUXVQIbYWHbXi0cuGFxvrPe3CdSDpA"",""2025-26!AC3"")"),44.0) -> 44 | BJ7: =IFERROR((BK7/BF7),"") -> 0.82467667 | BK7: =IFERROR(__xludf.DUMMYFUNCTION("IMPORTRANGE(""1WowgCGTCOMmqanUXVQIbYWHbXi0cuGFxvrPe3CdSDpA"",""2025-26!AD4"")"),1484418.0) -> 1484418 | BL7: =IFERROR(__xludf.DUMMYFUNCTION("IMPORTRANGE(""1WowgCGTCOMmqanUXVQIbYWHbXi0cuGFxvrPe3CdSDpA"",""2025-26!AD3"")"),44.0) -> 44 | BM7: =IFERROR(__xludf.DUMMYFUNCTION("IMPORTRANGE(""1WowgCGTCOMmqanUXVQIbYWHbXi0cuGFxvrPe3CdSDpA"",""2025-26!AE4"")"),1800000.0) -> 1800000 | BN7: =IFERROR(__xludf.DUMMYFUNCTION("IMPORTRANGE(""1WowgCGTCOMmqanUXVQIbYWHbXi0cuGFxvrPe3CdSDpA"",""2025-26!AE3"")"),91.0) -> 91 | BO7: =IFERROR(__xludf.DUMMYFUNCTION("IMPORTRANGE(""1WowgCGTCOMmqanUXVQIbYWHbXi0cuGFxvrPe3CdSDpA"",""2025-26!AF4"")"),1749611.6400000004) -> 1749611.6 | BP7: =IFERROR(__xludf.DUMMYFUNCTION("IMPORTRANGE(""1WowgCGTCOMmqanUXVQIbYWHbXi0cuGFxvrPe3CdSDpA"",""2025-26!AF3"")"),44.0) -> 44 | BQ7: =IFERROR((BR7/BM7),"") -> 1.2408344 | BR7: =IFERROR(__xludf.DUMMYFUNCTION("IMPORTRANGE(""1WowgCGTCOMmqanUXVQIbYWHbXi0cuGFxvrPe3CdSDpA"",""2025-26!AG4"")"),2233502.0) -> 2233502 | BS7: =IFERROR(__xludf.DUMMYFUNCTION("IMPORTRANGE(""1WowgCGTCOMmqanUXVQIbYWHbXi0cuGFxvrPe3CdSDpA"",""2025-26!AG3"")"),55.0) -> 55 | BT7: =IFERROR(__xludf.DUMMYFUNCTION("IMPORTRANGE(""1WowgCGTCOMmqanUXVQIbYWHbXi0cuGFxvrPe3CdSDpA"",""2025-26!AH4"")"),1800000.0) -> 1800000 | BU7: =IFERROR(__xludf.DUMMYFUNCTION("IMPORTRANGE(""1WowgCGTCOMmqanUXVQIbYWHbXi0cuGFxvrPe3CdSDpA"",""2025-26!AH3"")"),89.0) -> 89 | BV7: =IFERROR(__xludf.DUMMYFUNCTION("IMPORTRANGE(""1WowgCGTCOMmqanUXVQIbYWHbXi0cuGFxvrPe3CdSDpA"",""2025-26!AI4"")"),2078025.1699999997) -> 2078025.2 | BW7: =IFERROR(__xludf.DUMMYFUNCTION("IMPORTRANGE(""1WowgCGTCOMmqanUXVQIbYWHbXi0cuGFxvrPe3CdSDpA"",""2025-26!AI3"")"),54.0) -> 54 | BX7: =IFERROR((BY7/BT7),"") -> 1.1865744 | BY7: =IFERROR(__xludf.DUMMYFUNCTION("IMPORTRANGE(""1WowgCGTCOMmqanUXVQIbYWHbXi0cuGFxvrPe3CdSDpA"",""2025-26!AJ4"")"),2135834.0) -> 2135834 | BZ7: =IFERROR(__xludf.DUMMYFUNCTION("IMPORTRANGE(""1WowgCGTCOMmqanUXVQIbYWHbXi0cuGFxvrPe3CdSDpA"",""2025-26!AJ3"")"),55.0) -> 55 | CA7: =IFERROR(__xludf.DUMMYFUNCTION("IMPORTRANGE(""1WowgCGTCOMmqanUXVQIbYWHbXi0cuGFxvrPe3CdSDpA"",""2025-26!AK4"")"),1800000.0) -> 1800000 | CB7: =IFERROR(__xludf.DUMMYFUNCTION("IMPORTRANGE(""1WowgCGTCOMmqanUXVQIbYWHbXi0cuGFxvrPe3CdSDpA"",""2025-26!AK3"")"),90.0) -> 90 | CC7: =IFERROR(__xludf.DUMMYFUNCTION("IMPORTRANGE(""1WowgCGTCOMmqanUXVQIbYWHbXi0cuGFxvrPe3CdSDpA"",""2025-26!AL4"")"),1892383.69) -> 1892383.7 | CD7: =IFERROR(__xludf.DUMMYFUNCTION("IMPORTRANGE(""1WowgCGTCOMmqanUXVQIbYWHbXi0cuGFxvrPe3CdSDpA"",""2025-26!AL3"")"),45.0) -> 45 | CE7: =IFERROR((CF7/CA7),"") -> 1.0655617 | CF7: =IFERROR(__xludf.DUMMYFUNCTION("IMPORTRANGE(""1WowgCGTCOMmqanUXVQIbYWHbXi0cuGFxvrPe3CdSDpA"",""2025-26!AM4"")"),1918011.0) -> 1918011 | CG7: =IFERROR(__xludf.DUMMYFUNCTION("IMPORTRANGE(""1WowgCGTCOMmqanUXVQIbYWHbXi0cuGFxvrPe3CdSDpA"",""2025-26!AM3"")"),49.0) -> 49 | CH7: =IFERROR(__xludf.DUMMYFUNCTION("IMPORTRANGE(""1WowgCGTCOMmqanUXVQIbYWHbXi0cuGFxvrPe3CdSDpA"",""2025-26!AN4"")"),1800000.0) -> 1800000 | CI7: =IFERROR(__xludf.DUMMYFUNCTION("IMPORTRANGE(""1WowgCGTCOMmqanUXVQIbYWHbXi0cuGFxvrPe3CdSDpA"",""2025-26!AN3"")"),92.0) -> 92 | CJ7: =IFERROR(__xludf.DUMMYFUNCTION("IMPORTRANGE(""1WowgCGTCOMmqanUXVQIbYWHbXi0cuGFxvrPe3CdSDpA"",""2025-26!AO4"")"),1669928.2499999998) -> 1669928.2 | CK7: =IFERROR(__xludf.DUMMYFUNCTION("IMPORTRANGE(""1WowgCGTCOMmqanUXVQIbYWHbXi0cuGFxvrPe3CdSDpA"",""2025-26!AO3"")"),43.0) -> 43 | CL7: =IFERROR((CM7/CH7),"") -> 0.94717 | CM7: =IFERROR(__xludf.DUMMYFUNCTION("IMPORTRANGE(""1WowgCGTCOMmqanUXVQIbYWHbXi0cuGFxvrPe3CdSDpA"",""2025-26!AP4"")"),1704906.0) -> 1704906 | CN7: =IFERROR(__xludf.DUMMYFUNCTION("IMPORTRANGE(""1WowgCGTCOMmqanUXVQIbYWHbXi0cuGFxvrPe3CdSDpA"",""2025-26!AP3"")"),46.0) -> 46 | CO7: =IFERROR(__xludf.DUMMYFUNCTION("IMPORTRANGE(""1WowgCGTCOMmqanUXVQIbYWHbXi0cuGFxvrPe3CdSDpA"",""2025-26!AQ4"")"),1800000.0) -> 1800000 | CP7: =IFERROR(__xludf.DUMMYFUNCTION("IMPORTRANGE(""1WowgCGTCOMmqanUXVQIbYWHbXi0cuGFxvrPe3CdSDpA"",""2025-26!AQ3"")"),95.0) -> 95 | CQ7: =IFERROR(__xludf.DUMMYFUNCTION("IMPORTRANGE(""1WowgCGTCOMmqanUXVQIbYWHbXi0cuGFxvrPe3CdSDpA"",""2025-26!AR4"")"),1947975.5199999998) -> 1947975.5 | CR7: =IFERROR(__xludf.DUMMYFUNCTION("IMPORTRANGE(""1WowgCGTCOMmqanUXVQIbYWHbXi0cuGFxvrPe3CdSDpA"",""2025-26!AR3"")"),40.0) -> 40 | CS7: =IFERROR((CT7/CO7),"") -> 1.1334289 | CT7: =IFERROR(__xludf.DUMMYFUNCTION("IMPORTRANGE(""1WowgCGTCOMmqanUXVQIbYWHbXi0cuGFxvrPe3CdSDpA"",""2025-26!AS4"")"),2040172.0) -> 2040172 | CU7: =IFERROR(__xludf.DUMMYFUNCTION("IMPORTRANGE(""1WowgCGTCOMmqanUXVQIbYWHbXi0cuGFxvrPe3CdSDpA"",""2025-26!AS3"")"),42.0) -> 42 | CV7: {=vlookup(C7:C225,{Data!C:C,Data!B:B},2,0)} -> West U.P
A8: Anant Singh | C8: PRASUN CHATTERJEE | D8: Delhi | E8: 9810268300 | F8: 44994 | I8: =VLOOKUP($C8,Data!$C:$BV,72,0) -> 46390 | J8: =1500000+200000 -> 1700000 | K8: =IFERROR(__xludf.DUMMYFUNCTION("IMPORTRANGE(""1UEZK2L9OACV3t606hu8vkTn-5ekPDyqCYSBS2X6A5Jc"",""2025-26!A3"")"),94.0) -> 94 | L8: =IFERROR(__xludf.DUMMYFUNCTION("IMPORTRANGE(""1UEZK2L9OACV3t606hu8vkTn-5ekPDyqCYSBS2X6A5Jc"",""2025-26!G4"")"),1.74E7) -> 17400000 | M8: =R8+Y8+AF8+AM8+AT8+BA8+BH8+BO8+BV8+CC8+CJ8+CQ8 -> 9670433.2 | N8: =O8/L8 -> 0.5315596 | O8: =U8+AB8+AI8+AP8+AW8+BD8+BK8+BR8+BY8+CF8+CM8+CT8 -> 9249137 | P8: =IFERROR(__xludf.DUMMYFUNCTION("IMPORTRANGE(""1UEZK2L9OACV3t606hu8vkTn-5ekPDyqCYSBS2X6A5Jc"",""2025-26!J4"")"),1600000.0) -> 1600000 | Q8: =IFERROR(__xludf.DUMMYFUNCTION("IMPORTRANGE(""1UEZK2L9OACV3t606hu8vkTn-5ekPDyqCYSBS2X6A5Jc"",""2025-26!J3"")"),90.0) -> 90 | R8: =IFERROR(__xludf.DUMMYFUNCTION("IMPORTRANGE(""1UEZK2L9OACV3t606hu8vkTn-5ekPDyqCYSBS2X6A5Jc"",""2025-26!K4"")"),1462179.0) -> 1462179 | S8: =IFERROR(__xludf.DUMMYFUNCTION("IMPORTRANGE(""1UEZK2L9OACV3t606hu8vkTn-5ekPDyqCYSBS2X6A5Jc"",""2025-26!K3"")"),28.0) -> 28 | T8: =IFERROR((U8/P8),"") -> 0.99004313 | U8: =IFERROR(__xludf.DUMMYFUNCTION("IMPORTRANGE(""1UEZK2L9OACV3t606hu8vkTn-5ekPDyqCYSBS2X6A5Jc"",""2025-26!L4"")"),1584069.0) -> 1584069 | V8: =IFERROR(__xludf.DUMMYFUNCTION("IMPORTRANGE(""1UEZK2L9OACV3t606hu8vkTn-5ekPDyqCYSBS2X6A5Jc"",""2025-26!L3"")"),27.0) -> 27 | W8: =IFERROR(__xludf.DUMMYFUNCTION("IMPORTRANGE(""1UEZK2L9OACV3t606hu8vkTn-5ekPDyqCYSBS2X6A5Jc"",""2025-26!m4"")"),1590000.0) -> 1590000 | X8: =IFERROR(__xludf.DUMMYFUNCTION("IMPORTRANGE(""1UEZK2L9OACV3t606hu8vkTn-5ekPDyqCYSBS2X6A5Jc"",""2025-26!m3"")"),89.0) -> 89 | Y8: =IFERROR(__xludf.DUMMYFUNCTION("IMPORTRANGE(""1UEZK2L9OACV3t606hu8vkTn-5ekPDyqCYSBS2X6A5Jc"",""2025-26!N4"")"),1185329.9999999998) -> 1185330 | Z8: =IFERROR(__xludf.DUMMYFUNCTION("IMPORTRANGE(""1UEZK2L9OACV3t606hu8vkTn-5ekPDyqCYSBS2X6A5Jc"",""2025-26!N3"")"),29.0) -> 29 | AA8: =IFERROR((AB8/W8),"") -> 0.81574465 | AB8: =IFERROR(__xludf.DUMMYFUNCTION("IMPORTRANGE(""1UEZK2L9OACV3t606hu8vkTn-5ekPDyqCYSBS2X6A5Jc"",""2025-26!O4"")"),1297034.0) -> 1297034 | AC8: =IFERROR(__xludf.DUMMYFUNCTION("IMPORTRANGE(""1UEZK2L9OACV3t606hu8vkTn-5ekPDyqCYSBS2X6A5Jc"",""2025-26!O3"")"),29.0) -> 29 | AD8: =IFERROR(__xludf.DUMMYFUNCTION("IMPORTRANGE(""1UEZK2L9OACV3t606hu8vkTn-5ekPDyqCYSBS2X6A5Jc"",""2025-26!P4"")"),1590000.0) -> 1590000 | AE8: =IFERROR(__xludf.DUMMYFUNCTION("IMPORTRANGE(""1UEZK2L9OACV3t606hu8vkTn-5ekPDyqCYSBS2X6A5Jc"",""2025-26!P3"")"),89.0) -> 89 | AF8: =IFERROR(__xludf.DUMMYFUNCTION("IMPORTRANGE(""1UEZK2L9OACV3t606hu8vkTn-5ekPDyqCYSBS2X6A5Jc"",""2025-26!Q4"")"),778565.4) -> 778565.4 | AG8: =IFERROR(__xludf.DUMMYFUNCTION("IMPORTRANGE(""1UEZK2L9OACV3t606hu8vkTn-5ekPDyqCYSBS2X6A5Jc"",""2025-26!Q3"")"),23.0) -> 23 | AH8: =IFERROR((AI8/AD8),"") -> 0.50446415 | AI8: =IFERROR(__xludf.DUMMYFUNCTION("IMPORTRANGE(""1UEZK2L9OACV3t606hu8vkTn-5ekPDyqCYSBS2X6A5Jc"",""2025-26!R4"")"),802098.0) -> 802098 | AJ8: =IFERROR(__xludf.DUMMYFUNCTION("IMPORTRANGE(""1UEZK2L9OACV3t606hu8vkTn-5ekPDyqCYSBS2X6A5Jc"",""2025-26!R3"")"),23.0) -> 23 | AK8: =IFERROR(__xludf.DUMMYFUNCTION("IMPORTRANGE(""1UEZK2L9OACV3t606hu8vkTn-5ekPDyqCYSBS2X6A5Jc"",""2025-26!S4"")"),1590000.0) -> 1590000 | AL8: =IFERROR(__xludf.DUMMYFUNCTION("IMPORTRANGE(""1UEZK2L9OACV3t606hu8vkTn-5ekPDyqCYSBS2X6A5Jc"",""2025-26!S3"")"),89.0) -> 89 | AM8: =IFERROR(__xludf.DUMMYFUNCTION("IMPORTRANGE(""1UEZK2L9OACV3t606hu8vkTn-5ekPDyqCYSBS2X6A5Jc"",""2025-26!T4"")"),936504.3500000001) -> 936504.35 | AN8: =IFERROR(__xludf.DUMMYFUNCTION("IMPORTRANGE(""1UEZK2L9OACV3t606hu8vkTn-5ekPDyqCYSBS2X6A5Jc"",""2025-26!T3"")"),27.0) -> 27 | AO8: =IFERROR((AP8/AK8),"") -> 0.60073333 | AP8: =IFERROR(__xludf.DUMMYFUNCTION("IMPORTRANGE(""1UEZK2L9OACV3t606hu8vkTn-5ekPDyqCYSBS2X6A5Jc"",""2025-26!U4"")"),955166.0) -> 955166 | AQ8: =IFERROR(__xludf.DUMMYFUNCTION("IMPORTRANGE(""1UEZK2L9OACV3t606hu8vkTn-5ekPDyqCYSBS2X6A5Jc"",""2025-26!U3"")"),28.0) -> 28 | AR8: =IFERROR(__xludf.DUMMYFUNCTION("IMPORTRANGE(""1UEZK2L9OACV3t606hu8vkTn-5ekPDyqCYSBS2X6A5Jc"",""2025-26!V4"")"),1590000.0) -> 1590000 | AS8: =IFERROR(__xludf.DUMMYFUNCTION("IMPORTRANGE(""1UEZK2L9OACV3t606hu8vkTn-5ekPDyqCYSBS2X6A5Jc"",""2025-26!V3"")"),89.0) -> 89 | AT8: =IFERROR(__xludf.DUMMYFUNCTION("IMPORTRANGE(""1UEZK2L9OACV3t606hu8vkTn-5ekPDyqCYSBS2X6A5Jc"",""2025-26!W4"")"),955602.7500000001) -> 955602.75 | AU8: =IFERROR(__xludf.DUMMYFUNCTION("IMPORTRANGE(""1UEZK2L9OACV3t606hu8vkTn-5ekPDyqCYSBS2X6A5Jc"",""2025-26!W3"")"),29.0) -> 29 | AV8: =IFERROR((AW8/AR8),"") -> 0.55920566 | AW8: =IFERROR(__xludf.DUMMYFUNCTION("IMPORTRANGE(""1UEZK2L9OACV3t606hu8vkTn-5ekPDyqCYSBS2X6A5Jc"",""2025-26!X4"")"),889137.0) -> 889137 | AX8: =IFERROR(__xludf.DUMMYFUNCTION("IMPORTRANGE(""1UEZK2L9OACV3t606hu8vkTn-5ekPDyqCYSBS2X6A5Jc"",""2025-26!X3"")"),28.0) -> 28 | AY8: =IFERROR(__xludf.DUMMYFUNCTION("IMPORTRANGE(""1UEZK2L9OACV3t606hu8vkTn-5ekPDyqCYSBS2X6A5Jc"",""2025-26!Y4"")"),1590000.0) -> 1590000 | AZ8: =IFERROR(__xludf.DUMMYFUNCTION("IMPORTRANGE(""1UEZK2L9OACV3t606hu8vkTn-5ekPDyqCYSBS2X6A5Jc"",""2025-26!Y3"")"),89.0) -> 89 | BA8: =IFERROR(__xludf.DUMMYFUNCTION("IMPORTRANGE(""1UEZK2L9OACV3t606hu8vkTn-5ekPDyqCYSBS2X6A5Jc"",""2025-26!Z4"")"),906875.4299999999) -> 906875.43 | BB8: =IFERROR(__xludf.DUMMYFUNCTION("IMPORTRANGE(""1UEZK2L9OACV3t606hu8vkTn-5ekPDyqCYSBS2X6A5Jc"",""2025-26!Z3"")"),25.0) -> 25 | BC8: =IFERROR((BD8/AY8),"") -> 0.57211195 | BD8: =IFERROR(__xludf.DUMMYFUNCTION("IMPORTRANGE(""1UEZK2L9OACV3t606hu8vkTn-5ekPDyqCYSBS2X6A5Jc"",""2025-26!AA4"")"),909658.0) -> 909658 | BE8: =IFERROR(__xludf.DUMMYFUNCTION("IMPORTRANGE(""1UEZK2L9OACV3t606hu8vkTn-5ekPDyqCYSBS2X6A5Jc"",""2025-26!AA3"")"),25.0) -> 25 | BF8: =IFERROR(__xludf.DUMMYFUNCTION("IMPORTRANGE(""1UEZK2L9OACV3t606hu8vkTn-5ekPDyqCYSBS2X6A5Jc"",""2025-26!AB4"")"),1511000.0) -> 1511000 | BG8: =IFERROR(__xludf.DUMMYFUNCTION("IMPORTRANGE(""1UEZK2L9OACV3t606hu8vkTn-5ekPDyqCYSBS2X6A5Jc"",""2025-26!AB3"")"),67.0) -> 67 | BH8: =IFERROR(__xludf.DUMMYFUNCTION("IMPORTRANGE(""1UEZK2L9OACV3t606hu8vkTn-5ekPDyqCYSBS2X6A5Jc"",""2025-26!AC4"")"),844005.05) -> 844005.05 | BI8: =IFERROR(__xludf.DUMMYFUNCTION("IMPORTRANGE(""1UEZK2L9OACV3t606hu8vkTn-5ekPDyqCYSBS2X6A5Jc"",""2025-26!AC3"")"),18.0) -> 18 | BJ8: =IFERROR((BK8/BF8),"") -> 0.51032958 | BK8: =IFERROR(__xludf.DUMMYFUNCTION("IMPORTRANGE(""1UEZK2L9OACV3t606hu8vkTn-5ekPDyqCYSBS2X6A5Jc"",""2025-26!AD4"")"),771108.0) -> 771108 | BL8: =IFERROR(__xludf.DUMMYFUNCTION("IMPORTRANGE(""1UEZK2L9OACV3t606hu8vkTn-5ekPDyqCYSBS2X6A5Jc"",""2025-26!AD3"")"),17.0) -> 17 | BM8: =IFERROR(__xludf.DUMMYFUNCTION("IMPORTRANGE(""1UEZK2L9OACV3t606hu8vkTn-5ekPDyqCYSBS2X6A5Jc"",""2025-26!AE4"")"),1511000.0) -> 1511000 | BN8: =IFERROR(__xludf.DUMMYFUNCTION("IMPORTRANGE(""1UEZK2L9OACV3t606hu8vkTn-5ekPDyqCYSBS2X6A5Jc"",""2025-26!AE3"")"),67.0) -> 67 | BO8: =IFERROR(__xludf.DUMMYFUNCTION("IMPORTRANGE(""1UEZK2L9OACV3t606hu8vkTn-5ekPDyqCYSBS2X6A5Jc"",""2025-26!AF4"")"),322651.9) -> 322651.9 | BP8: =IFERROR(__xludf.DUMMYFUNCTION("IMPORTRANGE(""1UEZK2L9OACV3t606hu8vkTn-5ekPDyqCYSBS2X6A5Jc"",""2025-26!AF3"")"),12.0) -> 12 | BQ8: =IFERROR((BR8/BM8),"") -> 0.21962343 | BR8: =IFERROR(__xludf.DUMMYFUNCTION("IMPORTRANGE(""1UEZK2L9OACV3t606hu8vkTn-5ekPDyqCYSBS2X6A5Jc"",""2025-26!AG4"")"),331851.0) -> 331851 | BS8: =IFERROR(__xludf.DUMMYFUNCTION("IMPORTRANGE(""1UEZK2L9OACV3t606hu8vkTn-5ekPDyqCYSBS2X6A5Jc"",""2025-26!AG3"")"),12.0) -> 12 | BT8: =IFERROR(__xludf.DUMMYFUNCTION("IMPORTRANGE(""1UEZK2L9OACV3t606hu8vkTn-5ekPDyqCYSBS2X6A5Jc"",""2025-26!AH4"")"),1511000.0) -> 1511000 | BU8: =IFERROR(__xludf.DUMMYFUNCTION("IMPORTRANGE(""1UEZK2L9OACV3t606hu8vkTn-5ekPDyqCYSBS2X6A5Jc"",""2025-26!AH3"")"),67.0) -> 67 | BV8: =IFERROR(__xludf.DUMMYFUNCTION("IMPORTRANGE(""1UEZK2L9OACV3t606hu8vkTn-5ekPDyqCYSBS2X6A5Jc"",""2025-26!AI4"")"),537682.4) -> 537682.4 | BW8: =IFERROR(__xludf.DUMMYFUNCTION("IMPORTRANGE(""1UEZK2L9OACV3t606hu8vkTn-5ekPDyqCYSBS2X6A5Jc"",""2025-26!AI3"")"),21.0) -> 21 | BX8: =IFERROR((BY8/BT8),"") -> 0.36031635 | BY8: =IFERROR(__xludf.DUMMYFUNCTION("IMPORTRANGE(""1UEZK2L9OACV3t606hu8vkTn-5ekPDyqCYSBS2X6A5Jc"",""2025-26!AJ4"")"),544438.0) -> 544438 | BZ8: =IFERROR(__xludf.DUMMYFUNCTION("IMPORTRANGE(""1UEZK2L9OACV3t606hu8vkTn-5ekPDyqCYSBS2X6A5Jc"",""2025-26!AJ3"")"),21.0) -> 21 | CA8: =IFERROR(__xludf.DUMMYFUNCTION("IMPORTRANGE(""1UEZK2L9OACV3t606hu8vkTn-5ekPDyqCYSBS2X6A5Jc"",""2025-26!AK4"")"),1656000.0) -> 1656000 | CB8: =IFERROR(__xludf.DUMMYFUNCTION("IMPORTRANGE(""1UEZK2L9OACV3t606hu8vkTn-5ekPDyqCYSBS2X6A5Jc"",""2025-26!AK3"")"),72.0) -> 72 | CC8: =IFERROR(__xludf.DUMMYFUNCTION("IMPORTRANGE(""1UEZK2L9OACV3t606hu8vkTn-5ekPDyqCYSBS2X6A5Jc"",""2025-26!AL4"")"),563550.7) -> 563550.7 | CD8: =IFERROR(__xludf.DUMMYFUNCTION("IMPORTRANGE(""1UEZK2L9OACV3t606hu8vkTn-5ekPDyqCYSBS2X6A5Jc"",""2025-26!AL3"")"),21.0) -> 21 | CE8: =IFERROR((CF8/CA8),"") -> 0.33966546 | CF8: =IFERROR(__xludf.DUMMYFUNCTION("IMPORTRANGE(""1UEZK2L9OACV3t606hu8vkTn-5ekPDyqCYSBS2X6A5Jc"",""2025-26!AM4"")"),562486.0) -> 562486 | CG8: =IFERROR(__xludf.DUMMYFUNCTION("IMPORTRANGE(""1UEZK2L9OACV3t606hu8vkTn-5ekPDyqCYSBS2X6A5Jc"",""2025-26!AM3"")"),21.0) -> 21 | CH8: =IFERROR(__xludf.DUMMYFUNCTION("IMPORTRANGE(""1UEZK2L9OACV3t606hu8vkTn-5ekPDyqCYSBS2X6A5Jc"",""2025-26!AN4"")"),1656000.0) -> 1656000 | CI8: =IFERROR(__xludf.DUMMYFUNCTION("IMPORTRANGE(""1UEZK2L9OACV3t606hu8vkTn-5ekPDyqCYSBS2X6A5Jc"",""2025-26!AN3"")"),72.0) -> 72 | CJ8: =IFERROR(__xludf.DUMMYFUNCTION("IMPORTRANGE(""1UEZK2L9OACV3t606hu8vkTn-5ekPDyqCYSBS2X6A5Jc"",""2025-26!AO4"")"),463732.5) -> 463732.5 | CK8: =IFERROR(__xludf.DUMMYFUNCTION("IMPORTRANGE(""1UEZK2L9OACV3t606hu8vkTn-5ekPDyqCYSBS2X6A5Jc"",""2025-26!AO3"")"),21.0) -> 21 | CL8: =IFERROR((CM8/CH8),"") -> 0.30358937 | CM8: =IFERROR(__xludf.DUMMYFUNCTION("IMPORTRANGE(""1UEZK2L9OACV3t606hu8vkTn-5ekPDyqCYSBS2X6A5Jc"",""2025-26!AP4"")"),502744.0) -> 502744 | CN8: =IFERROR(__xludf.DUMMYFUNCTION("IMPORTRANGE(""1UEZK2L9OACV3t606hu8vkTn-5ekPDyqCYSBS2X6A5Jc"",""2025-26!AP3"")"),22.0) -> 22 | CO8: =IFERROR(__xludf.DUMMYFUNCTION("IMPORTRANGE(""1UEZK2L9OACV3t606hu8vkTn-5ekPDyqCYSBS2X6A5Jc"",""2025-26!AQ4"")"),1656000.0) -> 1656000 | CP8: =IFERROR(__xludf.DUMMYFUNCTION("IMPORTRANGE(""1UEZK2L9OACV3t606hu8vkTn-5ekPDyqCYSBS2X6A5Jc"",""2025-26!AQ3"")"),72.0) -> 72 | CQ8: =IFERROR(__xludf.DUMMYFUNCTION("IMPORTRANGE(""1UEZK2L9OACV3t606hu8vkTn-5ekPDyqCYSBS2X6A5Jc"",""2025-26!AR4"")"),713753.75) -> 713753.75 | CR8: =IFERROR(__xludf.DUMMYFUNCTION("IMPORTRANGE(""1UEZK2L9OACV3t606hu8vkTn-5ekPDyqCYSBS2X6A5Jc"",""2025-26!AR3"")"),21.0) -> 21 | CS8: =IFERROR((CT8/CO8),"") -> 0.059992754 | CT8: =IFERROR(__xludf.DUMMYFUNCTION("IMPORTRANGE(""1UEZK2L9OACV3t606hu8vkTn-5ekPDyqCYSBS2X6A5Jc"",""2025-26!AS4"")"),99348.0) -> 99348 | CU8: =IFERROR(__xludf.DUMMYFUNCTION("IMPORTRANGE(""1UEZK2L9OACV3t606hu8vkTn-5ekPDyqCYSBS2X6A5Jc"",""2025-26!AS3"")"),7.0) -> 7 | CV8: Delhi
A9: Anant Singh | C9: Jagdev | D9: Mathura | E9: 8448288693 | F9: 45261 | I9: =VLOOKUP($C9,Data!$C:$BV,72,0) -> 29360 | J9: =1200000+200000 -> 1400000 | K9: =IFERROR(__xludf.DUMMYFUNCTION("IMPORTRANGE(""1FQCfm55A8B3_aOo8e1xPQEUbQHYH85diG24OUoTRqnY"",""2025-26!A3"")"),105.0) -> 105 | L9: =IFERROR(__xludf.DUMMYFUNCTION("IMPORTRANGE(""1FQCfm55A8B3_aOo8e1xPQEUbQHYH85diG24OUoTRqnY"",""2025-26!G4"")"),1.6E7) -> 16000000 | M9: =R9+Y9+AF9+AM9+AT9+BA9+BH9+BO9+BV9+CC9+CJ9+CQ9 -> 12136399 | N9: =O9/L9 -> 0.77128669 | O9: =U9+AB9+AI9+AP9+AW9+BD9+BK9+BR9+BY9+CF9+CM9+CT9 -> 12340587 | P9: =IFERROR(__xludf.DUMMYFUNCTION("IMPORTRANGE(""1FQCfm55A8B3_aOo8e1xPQEUbQHYH85diG24OUoTRqnY"",""2025-26!J4"")"),1095310.0) -> 1095310 | Q9: =IFERROR(__xludf.DUMMYFUNCTION("IMPORTRANGE(""1FQCfm55A8B3_aOo8e1xPQEUbQHYH85diG24OUoTRqnY"",""2025-26!J3"")"),68.0) -> 68 | R9: =IFERROR(__xludf.DUMMYFUNCTION("IMPORTRANGE(""1FQCfm55A8B3_aOo8e1xPQEUbQHYH85diG24OUoTRqnY"",""2025-26!K4"")"),974002.74) -> 974002.74 | S9: =IFERROR(__xludf.DUMMYFUNCTION("IMPORTRANGE(""1FQCfm55A8B3_aOo8e1xPQEUbQHYH85diG24OUoTRqnY"",""2025-26!K3"")"),17.0) -> 17 | T9: =IFERROR((U9/P9),"") -> 0.90698889 | U9: =IFERROR(__xludf.DUMMYFUNCTION("IMPORTRANGE(""1FQCfm55A8B3_aOo8e1xPQEUbQHYH85diG24OUoTRqnY"",""2025-26!L4"")"),993434.0) -> 993434 | V9: =IFERROR(__xludf.DUMMYFUNCTION("IMPORTRANGE(""1FQCfm55A8B3_aOo8e1xPQEUbQHYH85diG24OUoTRqnY"",""2025-26!L3"")"),17.0) -> 17 | W9: =IFERROR(__xludf.DUMMYFUNCTION("IMPORTRANGE(""1FQCfm55A8B3_aOo8e1xPQEUbQHYH85diG24OUoTRqnY"",""2025-26!m4"")"),1069978.0) -> 1069978 | X9: =IFERROR(__xludf.DUMMYFUNCTION("IMPORTRANGE(""1FQCfm55A8B3_aOo8e1xPQEUbQHYH85diG24OUoTRqnY"",""2025-26!m3"")"),68.0) -> 68 | Y9: =IFERROR(__xludf.DUMMYFUNCTION("IMPORTRANGE(""1FQCfm55A8B3_aOo8e1xPQEUbQHYH85diG24OUoTRqnY"",""2025-26!N4"")"),1039828.85) -> 1039828.8 | Z9: =IFERROR(__xludf.DUMMYFUNCTION("IMPORTRANGE(""1FQCfm55A8B3_aOo8e1xPQEUbQHYH85diG24OUoTRqnY"",""2025-26!N3"")"),22.0) -> 22 | AA9: =IFERROR((AB9/W9),"") -> 0.99852707 | AB9: =IFERROR(__xludf.DUMMYFUNCTION("IMPORTRANGE(""1FQCfm55A8B3_aOo8e1xPQEUbQHYH85diG24OUoTRqnY"",""2025-26!O4"")"),1068402.0) -> 1068402 | AC9: =IFERROR(__xludf.DUMMYFUNCTION("IMPORTRANGE(""1FQCfm55A8B3_aOo8e1xPQEUbQHYH85diG24OUoTRqnY"",""2025-26!O3"")"),22.0) -> 22 | AD9: =IFERROR(__xludf.DUMMYFUNCTION("IMPORTRANGE(""1FQCfm55A8B3_aOo8e1xPQEUbQHYH85diG24OUoTRqnY"",""2025-26!P4"")"),1107000.0) -> 1107000 | AE9: =IFERROR(__xludf.DUMMYFUNCTION("IMPORTRANGE(""1FQCfm55A8B3_aOo8e1xPQEUbQHYH85diG24OUoTRqnY"",""2025-26!P3"")"),68.0) -> 68 | AF9: =IFERROR(__xludf.DUMMYFUNCTION("IMPORTRANGE(""1FQCfm55A8B3_aOo8e1xPQEUbQHYH85diG24OUoTRqnY"",""2025-26!Q4"")"),1124766.61) -> 1124766.6 | AG9: =IFERROR(__xludf.DUMMYFUNCTION("IMPORTRANGE(""1FQCfm55A8B3_aOo8e1xPQEUbQHYH85diG24OUoTRqnY"",""2025-26!Q3"")"),21.0) -> 21 | AH9: =IFERROR((AI9/AD9),"") -> 1.0365808 | AI9: =IFERROR(__xludf.DUMMYFUNCTION("IMPORTRANGE(""1FQCfm55A8B3_aOo8e1xPQEUbQHYH85diG24OUoTRqnY"",""2025-26!R4"")"),1147495.0) -> 1147495 | AJ9: =IFERROR(__xludf.DUMMYFUNCTION("IMPORTRANGE(""1FQCfm55A8B3_aOo8e1xPQEUbQHYH85diG24OUoTRqnY"",""2025-26!R3"")"),21.0) -> 21 | AK9: =IFERROR(__xludf.DUMMYFUNCTION("IMPORTRANGE(""1FQCfm55A8B3_aOo8e1xPQEUbQHYH85diG24OUoTRqnY"",""2025-26!S4"")"),1304000.0) -> 1304000 | AL9: =IFERROR(__xludf.DUMMYFUNCTION("IMPORTRANGE(""1FQCfm55A8B3_aOo8e1xPQEUbQHYH85diG24OUoTRqnY"",""2025-26!S3"")"),85.0) -> 85 | AM9: =IFERROR(__xludf.DUMMYFUNCTION("IMPORTRANGE(""1FQCfm55A8B3_aOo8e1xPQEUbQHYH85diG24OUoTRqnY"",""2025-26!T4"")"),1293629.32) -> 1293629.3 | AN9: =IFERROR(__xludf.DUMMYFUNCTION("IMPORTRANGE(""1FQCfm55A8B3_aOo8e1xPQEUbQHYH85diG24OUoTRqnY"",""2025-26!T3"")"),26.0) -> 26 | AO9: =IFERROR((AP9/AK9),"") -> 1.0053758 | AP9: =IFERROR(__xludf.DUMMYFUNCTION("IMPORTRANGE(""1FQCfm55A8B3_aOo8e1xPQEUbQHYH85diG24OUoTRqnY"",""2025-26!U4"")"),1311010.0) -> 1311010 | AQ9: =IFERROR(__xludf.DUMMYFUNCTION("IMPORTRANGE(""1FQCfm55A8B3_aOo8e1xPQEUbQHYH85diG24OUoTRqnY"",""2025-26!U3"")"),26.0) -> 26 | AR9: =IFERROR(__xludf.DUMMYFUNCTION("IMPORTRANGE(""1FQCfm55A8B3_aOo8e1xPQEUbQHYH85diG24OUoTRqnY"",""2025-26!V4"")"),1336000.0) -> 1336000 | AS9: =IFERROR(__xludf.DUMMYFUNCTION("IMPORTRANGE(""1FQCfm55A8B3_aOo8e1xPQEUbQHYH85diG24OUoTRqnY"",""2025-26!V3"")"),85.0) -> 85 | AT9: =IFERROR(__xludf.DUMMYFUNCTION("IMPORTRANGE(""1FQCfm55A8B3_aOo8e1xPQEUbQHYH85diG24OUoTRqnY"",""2025-26!W4"")"),1242011.89) -> 1242011.9 | AU9: =IFERROR(__xludf.DUMMYFUNCTION("IMPORTRANGE(""1FQCfm55A8B3_aOo8e1xPQEUbQHYH85diG24OUoTRqnY"",""2025-26!W3"")"),24.0) -> 24 | AV9: =IFERROR((AW9/AR9),"") -> 0.9320232 | AW9: =IFERROR(__xludf.DUMMYFUNCTION("IMPORTRANGE(""1FQCfm55A8B3_aOo8e1xPQEUbQHYH85diG24OUoTRqnY"",""2025-26!X4"")"),1245183.0) -> 1245183 | AX9: =IFERROR(__xludf.DUMMYFUNCTION("IMPORTRANGE(""1FQCfm55A8B3_aOo8e1xPQEUbQHYH85diG24OUoTRqnY"",""2025-26!X3"")"),24.0) -> 24 | AY9: =IFERROR(__xludf.DUMMYFUNCTION("IMPORTRANGE(""1FQCfm55A8B3_aOo8e1xPQEUbQHYH85diG24OUoTRqnY"",""2025-26!Y4"")"),1249000.0) -> 1249000 | AZ9: =IFERROR(__xludf.DUMMYFUNCTION("IMPORTRANGE(""1FQCfm55A8B3_aOo8e1xPQEUbQHYH85diG24OUoTRqnY"",""2025-26!Y3"")"),83.0) -> 83 | BA9: =IFERROR(__xludf.DUMMYFUNCTION("IMPORTRANGE(""1FQCfm55A8B3_aOo8e1xPQEUbQHYH85diG24OUoTRqnY"",""2025-26!Z4"")"),953132.9799999999) -> 953132.98 | BB9: =IFERROR(__xludf.DUMMYFUNCTION("IMPORTRANGE(""1FQCfm55A8B3_aOo8e1xPQEUbQHYH85diG24OUoTRqnY"",""2025-26!Z3"")"),34.0) -> 34 | BC9: =IFERROR((BD9/AY9),"") -> 0.76533707 | BD9: =IFERROR(__xludf.DUMMYFUNCTION("IMPORTRANGE(""1FQCfm55A8B3_aOo8e1xPQEUbQHYH85diG24OUoTRqnY"",""2025-26!AA4"")"),955906.0) -> 955906 | BE9: =IFERROR(__xludf.DUMMYFUNCTION("IMPORTRANGE(""1FQCfm55A8B3_aOo8e1xPQEUbQHYH85diG24OUoTRqnY"",""2025-26!AA3"")"),34.0) -> 34 | BF9: =IFERROR(__xludf.DUMMYFUNCTION("IMPORTRANGE(""1FQCfm55A8B3_aOo8e1xPQEUbQHYH85diG24OUoTRqnY"",""2025-26!AB4"")"),1360000.0) -> 1360000 | BG9: =IFERROR(__xludf.DUMMYFUNCTION("IMPORTRANGE(""1FQCfm55A8B3_aOo8e1xPQEUbQHYH85diG24OUoTRqnY"",""2025-26!AB3"")"),85.0) -> 85 | BH9: =IFERROR(__xludf.DUMMYFUNCTION("IMPORTRANGE(""1FQCfm55A8B3_aOo8e1xPQEUbQHYH85diG24OUoTRqnY"",""2025-26!AC4"")"),907255.3400000001) -> 907255.34 | BI9: =IFERROR(__xludf.DUMMYFUNCTION("IMPORTRANGE(""1FQCfm55A8B3_aOo8e1xPQEUbQHYH85diG24OUoTRqnY"",""2025-26!AC3"")"),22.0) -> 22 | BJ9: =IFERROR((BK9/BF9),"") -> 0.66986176 | BK9: =IFERROR(__xludf.DUMMYFUNCTION("IMPORTRANGE(""1FQCfm55A8B3_aOo8e1xPQEUbQHYH85diG24OUoTRqnY"",""2025-26!AD4"")"),911012.0) -> 911012 | BL9: =IFERROR(__xludf.DUMMYFUNCTION("IMPORTRANGE(""1FQCfm55A8B3_aOo8e1xPQEUbQHYH85diG24OUoTRqnY"",""2025-26!AD3"")"),22.0) -> 22 | BM9: =IFERROR(__xludf.DUMMYFUNCTION("IMPORTRANGE(""1FQCfm55A8B3_aOo8e1xPQEUbQHYH85diG24OUoTRqnY"",""2025-26!AE4"")"),1269000.0) -> 1269000 | BN9: =IFERROR(__xludf.DUMMYFUNCTION("IMPORTRANGE(""1FQCfm55A8B3_aOo8e1xPQEUbQHYH85diG24OUoTRqnY"",""2025-26!AE3"")"),85.0) -> 85 | BO9: =IFERROR(__xludf.DUMMYFUNCTION("IMPORTRANGE(""1FQCfm55A8B3_aOo8e1xPQEUbQHYH85diG24OUoTRqnY"",""2025-26!AF4"")"),1007490.22) -> 1007490.2 | BP9: =IFERROR(__xludf.DUMMYFUNCTION("IMPORTRANGE(""1FQCfm55A8B3_aOo8e1xPQEUbQHYH85diG24OUoTRqnY"",""2025-26!AF3"")"),31.0) -> 31 | BQ9: =IFERROR((BR9/BM9),"") -> 0.81714342 | BR9: =IFERROR(__xludf.DUMMYFUNCTION("IMPORTRANGE(""1FQCfm55A8B3_aOo8e1xPQEUbQHYH85diG24OUoTRqnY"",""2025-26!AG4"")"),1036955.0) -> 1036955 | BS9: =IFERROR(__xludf.DUMMYFUNCTION("IMPORTRANGE(""1FQCfm55A8B3_aOo8e1xPQEUbQHYH85diG24OUoTRqnY"",""2025-26!AG3"")"),33.0) -> 33 | BT9: =IFERROR(__xludf.DUMMYFUNCTION("IMPORTRANGE(""1FQCfm55A8B3_aOo8e1xPQEUbQHYH85diG24OUoTRqnY"",""2025-26!AH4"")"),1357000.0) -> 1357000 | BU9: =IFERROR(__xludf.DUMMYFUNCTION("IMPORTRANGE(""1FQCfm55A8B3_aOo8e1xPQEUbQHYH85diG24OUoTRqnY"",""2025-26!AH3"")"),99.0) -> 99 | BV9: =IFERROR(__xludf.DUMMYFUNCTION("IMPORTRANGE(""1FQCfm55A8B3_aOo8e1xPQEUbQHYH85diG24OUoTRqnY"",""2025-26!AI4"")"),906093.8200000001) -> 906093.82 | BW9: =IFERROR(__xludf.DUMMYFUNCTION("IMPORTRANGE(""1FQCfm55A8B3_aOo8e1xPQEUbQHYH85diG24OUoTRqnY"",""2025-26!AI3"")"),28.0) -> 28 | BX9: =IFERROR((BY9/BT9),"") -> 0.66091304 | BY9: =IFERROR(__xludf.DUMMYFUNCTION("IMPORTRANGE(""1FQCfm55A8B3_aOo8e1xPQEUbQHYH85diG24OUoTRqnY"",""2025-26!AJ4"")"),896859.0) -> 896859 | BZ9: =IFERROR(__xludf.DUMMYFUNCTION("IMPORTRANGE(""1FQCfm55A8B3_aOo8e1xPQEUbQHYH85diG24OUoTRqnY"",""2025-26!AJ3"")"),27.0) -> 27 | CA9: =IFERROR(__xludf.DUMMYFUNCTION("IMPORTRANGE(""1FQCfm55A8B3_aOo8e1xPQEUbQHYH85diG24OUoTRqnY"",""2025-26!AK4"")"),1321000.0) -> 1321000 | CB9: =IFERROR(__xludf.DUMMYFUNCTION("IMPORTRANGE(""1FQCfm55A8B3_aOo8e1xPQEUbQHYH85diG24OUoTRqnY"",""2025-26!AK3"")"),99.0) -> 99 | CC9: =IFERROR(__xludf.DUMMYFUNCTION("IMPORTRANGE(""1FQCfm55A8B3_aOo8e1xPQEUbQHYH85diG24OUoTRqnY"",""2025-26!AL4"")"),1006623.01) -> 1006623 | CD9: =IFERROR(__xludf.DUMMYFUNCTION("IMPORTRANGE(""1FQCfm55A8B3_aOo8e1xPQEUbQHYH85diG24OUoTRqnY"",""2025-26!AL3"")"),27.0) -> 27 | CE9: =IFERROR((CF9/CA9),"") -> 0.78368887 | CF9: =IFERROR(__xludf.DUMMYFUNCTION("IMPORTRANGE(""1FQCfm55A8B3_aOo8e1xPQEUbQHYH85diG24OUoTRqnY"",""2025-26!AM4"")"),1035253.0) -> 1035253 | CG9: =IFERROR(__xludf.DUMMYFUNCTION("IMPORTRANGE(""1FQCfm55A8B3_aOo8e1xPQEUbQHYH85diG24OUoTRqnY"",""2025-26!AM3"")"),27.0) -> 27 | CH9: =IFERROR(__xludf.DUMMYFUNCTION("IMPORTRANGE(""1FQCfm55A8B3_aOo8e1xPQEUbQHYH85diG24OUoTRqnY"",""2025-26!AN4"")"),1314000.0) -> 1314000 | CI9: =IFERROR(__xludf.DUMMYFUNCTION("IMPORTRANGE(""1FQCfm55A8B3_aOo8e1xPQEUbQHYH85diG24OUoTRqnY"",""2025-26!AN3"")"),99.0) -> 99 | CJ9: =IFERROR(__xludf.DUMMYFUNCTION("IMPORTRANGE(""1FQCfm55A8B3_aOo8e1xPQEUbQHYH85diG24OUoTRqnY"",""2025-26!AO4"")"),732687.57) -> 732687.57 | CK9: =IFERROR(__xludf.DUMMYFUNCTION("IMPORTRANGE(""1FQCfm55A8B3_aOo8e1xPQEUbQHYH85diG24OUoTRqnY"",""2025-26!AO3"")"),26.0) -> 26 | CL9: =IFERROR((CM9/CH9),"") -> 0.577293 | CM9: =IFERROR(__xludf.DUMMYFUNCTION("IMPORTRANGE(""1FQCfm55A8B3_aOo8e1xPQEUbQHYH85diG24OUoTRqnY"",""2025-26!AP4"")"),758563.0) -> 758563 | CN9: =IFERROR(__xludf.DUMMYFUNCTION("IMPORTRANGE(""1FQCfm55A8B3_aOo8e1xPQEUbQHYH85diG24OUoTRqnY"",""2025-26!AP3"")"),26.0) -> 26 | CO9: =IFERROR(__xludf.DUMMYFUNCTION("IMPORTRANGE(""1FQCfm55A8B3_aOo8e1xPQEUbQHYH85diG24OUoTRqnY"",""2025-26!AQ4"")"),1375000.0) -> 1375000 | CP9: =IFERROR(__xludf.DUMMYFUNCTION("IMPORTRANGE(""1FQCfm55A8B3_aOo8e1xPQEUbQHYH85diG24OUoTRqnY"",""2025-26!AQ3"")"),99.0) -> 99 | CQ9: =IFERROR(__xludf.DUMMYFUNCTION("IMPORTRANGE(""1FQCfm55A8B3_aOo8e1xPQEUbQHYH85diG24OUoTRqnY"",""2025-26!AR4"")"),948876.5699999998) -> 948876.57 | CR9: =IFERROR(__xludf.DUMMYFUNCTION("IMPORTRANGE(""1FQCfm55A8B3_aOo8e1xPQEUbQHYH85diG24OUoTRqnY"",""2025-26!AR3"")"),23.0) -> 23 | CS9: =IFERROR((CT9/CO9),"") -> 0.71310182 | CT9: =IFERROR(__xludf.DUMMYFUNCTION("IMPORTRANGE(""1FQCfm55A8B3_aOo8e1xPQEUbQHYH85diG24OUoTRqnY"",""2025-26!AS4"")"),980515.0) -> 980515 | CU9: =IFERROR(__xludf.DUMMYFUNCTION("IMPORTRANGE(""1FQCfm55A8B3_aOo8e1xPQEUbQHYH85diG24OUoTRqnY"",""2025-26!AS3"")"),23.0) -> 23 | CV9: West U.P
A10: Anant Singh | C10: Manish Gupta | D10: South East Delhi | E10: 9891552205 | F10: 45551 | I10: =VLOOKUP($C10,Data!$C:$BV,72,0) -> 28310 | J10: 1300000 | K10: =IFERROR(__xludf.DUMMYFUNCTION("IMPORTRANGE(""1Oujo8vUnwFLr-WkmYYfJwaGjmRsDy-q2Aq0vU4BlykA"",""2025-26!A3"")"),125.0) -> 125 | L10: =IFERROR(__xludf.DUMMYFUNCTION("IMPORTRANGE(""1Oujo8vUnwFLr-WkmYYfJwaGjmRsDy-q2Aq0vU4BlykA"",""2025-26!G4"")"),1.5445E7) -> 15445000 | M10: =R10+Y10+AF10+AM10+AT10+BA10+BH10+BO10+BV10+CC10+CJ10+CQ10 -> 11338113 | N10: =O10/L10 -> 0.73676536 | O10: =U10+AB10+AI10+AP10+AW10+BD10+BK10+BR10+BY10+CF10+CM10+CT10 -> 11379341 | P10: =IFERROR(__xludf.DUMMYFUNCTION("IMPORTRANGE(""1Oujo8vUnwFLr-WkmYYfJwaGjmRsDy-q2Aq0vU4BlykA"",""2025-26!J4"")"),1232000.0) -> 1232000 | Q10: =IFERROR(__xludf.DUMMYFUNCTION("IMPORTRANGE(""1Oujo8vUnwFLr-WkmYYfJwaGjmRsDy-q2Aq0vU4BlykA"",""2025-26!J3"")"),114.0) -> 114 | R10: =IFERROR(__xludf.DUMMYFUNCTION("IMPORTRANGE(""1Oujo8vUnwFLr-WkmYYfJwaGjmRsDy-q2Aq0vU4BlykA"",""2025-26!K4"")"),846489.8100000002) -> 846489.81 | S10: =IFERROR(__xludf.DUMMYFUNCTION("IMPORTRANGE(""1Oujo8vUnwFLr-WkmYYfJwaGjmRsDy-q2Aq0vU4BlykA"",""2025-26!K3"")"),43.0) -> 43 | T10: =IFERROR((U10/P10),"") -> 0.7011333 | U10: =IFERROR(__xludf.DUMMYFUNCTION("IMPORTRANGE(""1Oujo8vUnwFLr-WkmYYfJwaGjmRsDy-q2Aq0vU4BlykA"",""2025-26!L4"")"),863796.22) -> 863796.22 | V10: =IFERROR(__xludf.DUMMYFUNCTION("IMPORTRANGE(""1Oujo8vUnwFLr-WkmYYfJwaGjmRsDy-q2Aq0vU4BlykA"",""2025-26!L3"")"),43.0) -> 43 | W10: =IFERROR(__xludf.DUMMYFUNCTION("IMPORTRANGE(""1Oujo8vUnwFLr-WkmYYfJwaGjmRsDy-q2Aq0vU4BlykA"",""2025-26!m4"")"),1214000.0) -> 1214000 | X10: =IFERROR(__xludf.DUMMYFUNCTION("IMPORTRANGE(""1Oujo8vUnwFLr-WkmYYfJwaGjmRsDy-q2Aq0vU4BlykA"",""2025-26!m3"")"),114.0) -> 114 | Y10: =IFERROR(__xludf.DUMMYFUNCTION("IMPORTRANGE(""1Oujo8vUnwFLr-WkmYYfJwaGjmRsDy-q2Aq0vU4BlykA"",""2025-26!N4"")"),926964.65) -> 926964.65 | Z10: =IFERROR(__xludf.DUMMYFUNCTION("IMPORTRANGE(""1Oujo8vUnwFLr-WkmYYfJwaGjmRsDy-q2Aq0vU4BlykA"",""2025-26!N3"")"),42.0) -> 42 | AA10: =IFERROR((AB10/W10),"") -> 0.78115451 | AB10: =IFERROR(__xludf.DUMMYFUNCTION("IMPORTRANGE(""1Oujo8vUnwFLr-WkmYYfJwaGjmRsDy-q2Aq0vU4BlykA"",""2025-26!O4"")"),948321.58) -> 948321.58 | AC10: =IFERROR(__xludf.DUMMYFUNCTION("IMPORTRANGE(""1Oujo8vUnwFLr-WkmYYfJwaGjmRsDy-q2Aq0vU4BlykA"",""2025-26!O3"")"),43.0) -> 43 | AD10: =IFERROR(__xludf.DUMMYFUNCTION("IMPORTRANGE(""1Oujo8vUnwFLr-WkmYYfJwaGjmRsDy-q2Aq0vU4BlykA"",""2025-26!P4"")"),1327000.0) -> 1327000 | AE10: =IFERROR(__xludf.DUMMYFUNCTION("IMPORTRANGE(""1Oujo8vUnwFLr-WkmYYfJwaGjmRsDy-q2Aq0vU4BlykA"",""2025-26!P3"")"),116.0) -> 116 | AF10: =IFERROR(__xludf.DUMMYFUNCTION("IMPORTRANGE(""1Oujo8vUnwFLr-WkmYYfJwaGjmRsDy-q2Aq0vU4BlykA"",""2025-26!Q4"")"),867458.8000000002) -> 867458.8 | AG10: =IFERROR(__xludf.DUMMYFUNCTION("IMPORTRANGE(""1Oujo8vUnwFLr-WkmYYfJwaGjmRsDy-q2Aq0vU4BlykA"",""2025-26!Q3"")"),36.0) -> 36 | AH10: =IFERROR((AI10/AD10),"") -> 0.65871839 | AI10: =IFERROR(__xludf.DUMMYFUNCTION("IMPORTRANGE(""1Oujo8vUnwFLr-WkmYYfJwaGjmRsDy-q2Aq0vU4BlykA"",""2025-26!R4"")"),874119.3099999998) -> 874119.31 | AJ10: =IFERROR(__xludf.DUMMYFUNCTION("IMPORTRANGE(""1Oujo8vUnwFLr-WkmYYfJwaGjmRsDy-q2Aq0vU4BlykA"",""2025-26!R3"")"),36.0) -> 36 | AK10: =IFERROR(__xludf.DUMMYFUNCTION("IMPORTRANGE(""1Oujo8vUnwFLr-WkmYYfJwaGjmRsDy-q2Aq0vU4BlykA"",""2025-26!S4"")"),1312000.0) -> 1312000 | AL10: =IFERROR(__xludf.DUMMYFUNCTION("IMPORTRANGE(""1Oujo8vUnwFLr-WkmYYfJwaGjmRsDy-q2Aq0vU4BlykA"",""2025-26!S3"")"),116.0) -> 116 | AM10: =IFERROR(__xludf.DUMMYFUNCTION("IMPORTRANGE(""1Oujo8vUnwFLr-WkmYYfJwaGjmRsDy-q2Aq0vU4BlykA"",""2025-26!T4"")"),958979.1399999999) -> 958979.14 | AN10: =IFERROR(__xludf.DUMMYFUNCTION("IMPORTRANGE(""1Oujo8vUnwFLr-WkmYYfJwaGjmRsDy-q2Aq0vU4BlykA"",""2025-26!T3"")"),40.0) -> 40 | AO10: =IFERROR((AP10/AK10),"") -> 0.73267927 | AP10: =IFERROR(__xludf.DUMMYFUNCTION("IMPORTRANGE(""1Oujo8vUnwFLr-WkmYYfJwaGjmRsDy-q2Aq0vU4BlykA"",""2025-26!U4"")"),961275.2000000001) -> 961275.2 | AQ10: =IFERROR(__xludf.DUMMYFUNCTION("IMPORTRANGE(""1Oujo8vUnwFLr-WkmYYfJwaGjmRsDy-q2Aq0vU4BlykA"",""2025-26!U3"")"),40.0) -> 40 | AR10: =IFERROR(__xludf.DUMMYFUNCTION("IMPORTRANGE(""1Oujo8vUnwFLr-WkmYYfJwaGjmRsDy-q2Aq0vU4BlykA"",""2025-26!V4"")"),1330000.0) -> 1330000 | AS10: =IFERROR(__xludf.DUMMYFUNCTION("IMPORTRANGE(""1Oujo8vUnwFLr-WkmYYfJwaGjmRsDy-q2Aq0vU4BlykA"",""2025-26!V3"")"),122.0) -> 122 | AT10: =IFERROR(__xludf.DUMMYFUNCTION("IMPORTRANGE(""1Oujo8vUnwFLr-WkmYYfJwaGjmRsDy-q2Aq0vU4BlykA"",""2025-26!W4"")"),811098.1600000004) -> 811098.16 | AU10: =IFERROR(__xludf.DUMMYFUNCTION("IMPORTRANGE(""1Oujo8vUnwFLr-WkmYYfJwaGjmRsDy-q2Aq0vU4BlykA"",""2025-26!W3"")"),45.0) -> 45 | AV10: =IFERROR((AW10/AR10),"") -> 0.6162202 | AW10: =IFERROR(__xludf.DUMMYFUNCTION("IMPORTRANGE(""1Oujo8vUnwFLr-WkmYYfJwaGjmRsDy-q2Aq0vU4BlykA"",""2025-26!X4"")"),819572.8599999999) -> 819572.86 | AX10: =IFERROR(__xludf.DUMMYFUNCTION("IMPORTRANGE(""1Oujo8vUnwFLr-WkmYYfJwaGjmRsDy-q2Aq0vU4BlykA"",""2025-26!X3"")"),45.0) -> 45 | AY10: =IFERROR(__xludf.DUMMYFUNCTION("IMPORTRANGE(""1Oujo8vUnwFLr-WkmYYfJwaGjmRsDy-q2Aq0vU4BlykA"",""2025-26!Y4"")"),1319000.0) -> 1319000 | AZ10: =IFERROR(__xludf.DUMMYFUNCTION("IMPORTRANGE(""1Oujo8vUnwFLr-WkmYYfJwaGjmRsDy-q2Aq0vU4BlykA"",""2025-26!Y3"")"),122.0) -> 122 | BA10: =IFERROR(__xludf.DUMMYFUNCTION("IMPORTRANGE(""1Oujo8vUnwFLr-WkmYYfJwaGjmRsDy-q2Aq0vU4BlykA"",""2025-26!Z4"")"),1184994.7600000002) -> 1184994.8 | BB10: =IFERROR(__xludf.DUMMYFUNCTION("IMPORTRANGE(""1Oujo8vUnwFLr-WkmYYfJwaGjmRsDy-q2Aq0vU4BlykA"",""2025-26!Z3"")"),45.0) -> 45 | BC10: =IFERROR((BD10/AY10),"") -> 0.90426295 | BD10: =IFERROR(__xludf.DUMMYFUNCTION("IMPORTRANGE(""1Oujo8vUnwFLr-WkmYYfJwaGjmRsDy-q2Aq0vU4BlykA"",""2025-26!AA4"")"),1192722.8299999998) -> 1192722.8 | BE10: =IFERROR(__xludf.DUMMYFUNCTION("IMPORTRANGE(""1Oujo8vUnwFLr-WkmYYfJwaGjmRsDy-q2Aq0vU4BlykA"",""2025-26!AA3"")"),45.0) -> 45 | BF10: =IFERROR(__xludf.DUMMYFUNCTION("IMPORTRANGE(""1Oujo8vUnwFLr-WkmYYfJwaGjmRsDy-q2Aq0vU4BlykA"",""2025-26!AB4"")"),1316000.0) -> 1316000 | BG10: =IFERROR(__xludf.DUMMYFUNCTION("IMPORTRANGE(""1Oujo8vUnwFLr-WkmYYfJwaGjmRsDy-q2Aq0vU4BlykA"",""2025-26!AB3"")"),121.0) -> 121 | BH10: =IFERROR(__xludf.DUMMYFUNCTION("IMPORTRANGE(""1Oujo8vUnwFLr-WkmYYfJwaGjmRsDy-q2Aq0vU4BlykA"",""2025-26!AC4"")"),1080876.61) -> 1080876.6 | BI10: =IFERROR(__xludf.DUMMYFUNCTION("IMPORTRANGE(""1Oujo8vUnwFLr-WkmYYfJwaGjmRsDy-q2Aq0vU4BlykA"",""2025-26!AC3"")"),47.0) -> 47 | BJ10: =IFERROR((BK10/BF10),"") -> 0.88111743 | BK10: =IFERROR(__xludf.DUMMYFUNCTION("IMPORTRANGE(""1Oujo8vUnwFLr-WkmYYfJwaGjmRsDy-q2Aq0vU4BlykA"",""2025-26!AD4"")"),1159550.5399999998) -> 1159550.5 | BL10: =IFERROR(__xludf.DUMMYFUNCTION("IMPORTRANGE(""1Oujo8vUnwFLr-WkmYYfJwaGjmRsDy-q2Aq0vU4BlykA"",""2025-26!AD3"")"),48.0) -> 48 | BM10: =IFERROR(__xludf.DUMMYFUNCTION("IMPORTRANGE(""1Oujo8vUnwFLr-WkmYYfJwaGjmRsDy-q2Aq0vU4BlykA"",""2025-26!AE4"")"),1322000.0) -> 1322000 | BN10: =IFERROR(__xludf.DUMMYFUNCTION("IMPORTRANGE(""1Oujo8vUnwFLr-WkmYYfJwaGjmRsDy-q2Aq0vU4BlykA"",""2025-26!AE3"")"),121.0) -> 121 | BO10: =IFERROR(__xludf.DUMMYFUNCTION("IMPORTRANGE(""1Oujo8vUnwFLr-WkmYYfJwaGjmRsDy-q2Aq0vU4BlykA"",""2025-26!AF4"")"),916671.9600000001) -> 916671.96 | BP10: =IFERROR(__xludf.DUMMYFUNCTION("IMPORTRANGE(""1Oujo8vUnwFLr-WkmYYfJwaGjmRsDy-q2Aq0vU4BlykA"",""2025-26!AF3"")"),39.0) -> 39 | BQ10: =IFERROR((BR10/BM10),"") -> 0.64042607 | BR10: =IFERROR(__xludf.DUMMYFUNCTION("IMPORTRANGE(""1Oujo8vUnwFLr-WkmYYfJwaGjmRsDy-q2Aq0vU4BlykA"",""2025-26!AG4"")"),846643.2599999999) -> 846643.26 | BS10: =IFERROR(__xludf.DUMMYFUNCTION("IMPORTRANGE(""1Oujo8vUnwFLr-WkmYYfJwaGjmRsDy-q2Aq0vU4BlykA"",""2025-26!AG3"")"),38.0) -> 38 | BT10: =IFERROR(__xludf.DUMMYFUNCTION("IMPORTRANGE(""1Oujo8vUnwFLr-WkmYYfJwaGjmRsDy-q2Aq0vU4BlykA"",""2025-26!AH4"")"),1332000.0) -> 1332000 | BU10: =IFERROR(__xludf.DUMMYFUNCTION("IMPORTRANGE(""1Oujo8vUnwFLr-WkmYYfJwaGjmRsDy-q2Aq0vU4BlykA"",""2025-26!AH3"")"),104.0) -> 104 | BV10: =IFERROR(__xludf.DUMMYFUNCTION("IMPORTRANGE(""1Oujo8vUnwFLr-WkmYYfJwaGjmRsDy-q2Aq0vU4BlykA"",""2025-26!AI4"")"),942623.2599999997) -> 942623.26 | BW10: =IFERROR(__xludf.DUMMYFUNCTION("IMPORTRANGE(""1Oujo8vUnwFLr-WkmYYfJwaGjmRsDy-q2Aq0vU4BlykA"",""2025-26!AI3"")"),31.0) -> 31 | BX10: =IFERROR((BY10/BT10),"") -> 0.70997222 | BY10: =IFERROR(__xludf.DUMMYFUNCTION("IMPORTRANGE(""1Oujo8vUnwFLr-WkmYYfJwaGjmRsDy-q2Aq0vU4BlykA"",""2025-26!AJ4"")"),945683.0000000002) -> 945683 | BZ10: =IFERROR(__xludf.DUMMYFUNCTION("IMPORTRANGE(""1Oujo8vUnwFLr-WkmYYfJwaGjmRsDy-q2Aq0vU4BlykA"",""2025-26!AJ3"")"),31.0) -> 31 | CA10: =IFERROR(__xludf.DUMMYFUNCTION("IMPORTRANGE(""1Oujo8vUnwFLr-WkmYYfJwaGjmRsDy-q2Aq0vU4BlykA"",""2025-26!AK4"")"),1319000.0) -> 1319000 | CB10: =IFERROR(__xludf.DUMMYFUNCTION("IMPORTRANGE(""1Oujo8vUnwFLr-WkmYYfJwaGjmRsDy-q2Aq0vU4BlykA"",""2025-26!AK3"")"),102.0) -> 102 | CC10: =IFERROR(__xludf.DUMMYFUNCTION("IMPORTRANGE(""1Oujo8vUnwFLr-WkmYYfJwaGjmRsDy-q2Aq0vU4BlykA"",""2025-26!AL4"")"),926198.1900000001) -> 926198.19 | CD10: =IFERROR(__xludf.DUMMYFUNCTION("IMPORTRANGE(""1Oujo8vUnwFLr-WkmYYfJwaGjmRsDy-q2Aq0vU4BlykA"",""2025-26!AL3"")"),39.0) -> 39 | CE10: =IFERROR((CF10/CA10),"") -> 0.67615102 | CF10: =IFERROR(__xludf.DUMMYFUNCTION("IMPORTRANGE(""1Oujo8vUnwFLr-WkmYYfJwaGjmRsDy-q2Aq0vU4BlykA"",""2025-26!AM4"")"),891843.2000000001) -> 891843.2 | CG10: =IFERROR(__xludf.DUMMYFUNCTION("IMPORTRANGE(""1Oujo8vUnwFLr-WkmYYfJwaGjmRsDy-q2Aq0vU4BlykA"",""2025-26!AM3"")"),38.0) -> 38 | CH10: =IFERROR(__xludf.DUMMYFUNCTION("IMPORTRANGE(""1Oujo8vUnwFLr-WkmYYfJwaGjmRsDy-q2Aq0vU4BlykA"",""2025-26!AN4"")"),1323000.0) -> 1323000 | CI10: =IFERROR(__xludf.DUMMYFUNCTION("IMPORTRANGE(""1Oujo8vUnwFLr-WkmYYfJwaGjmRsDy-q2Aq0vU4BlykA"",""2025-26!AN3"")"),102.0) -> 102 | CJ10: =IFERROR(__xludf.DUMMYFUNCTION("IMPORTRANGE(""1Oujo8vUnwFLr-WkmYYfJwaGjmRsDy-q2Aq0vU4BlykA"",""2025-26!AO4"")"),842725.1900000004) -> 842725.19 | CK10: =IFERROR(__xludf.DUMMYFUNCTION("IMPORTRANGE(""1Oujo8vUnwFLr-WkmYYfJwaGjmRsDy-q2Aq0vU4BlykA"",""2025-26!AO3"")"),35.0) -> 35 | CL10: =IFERROR((CM10/CH10),"") -> 0.63824714 | CM10: =IFERROR(__xludf.DUMMYFUNCTION("IMPORTRANGE(""1Oujo8vUnwFLr-WkmYYfJwaGjmRsDy-q2Aq0vU4BlykA"",""2025-26!AP4"")"),844400.9599999998) -> 844400.96 | CN10: =IFERROR(__xludf.DUMMYFUNCTION("IMPORTRANGE(""1Oujo8vUnwFLr-WkmYYfJwaGjmRsDy-q2Aq0vU4BlykA"",""2025-26!AP3"")"),35.0) -> 35 | CO10: =IFERROR(__xludf.DUMMYFUNCTION("IMPORTRANGE(""1Oujo8vUnwFLr-WkmYYfJwaGjmRsDy-q2Aq0vU4BlykA"",""2025-26!AQ4"")"),1314000.0) -> 1314000 | CP10: =IFERROR(__xludf.DUMMYFUNCTION("IMPORTRANGE(""1Oujo8vUnwFLr-WkmYYfJwaGjmRsDy-q2Aq0vU4BlykA"",""2025-26!AQ3"")"),103.0) -> 103 | CQ10: =IFERROR(__xludf.DUMMYFUNCTION("IMPORTRANGE(""1Oujo8vUnwFLr-WkmYYfJwaGjmRsDy-q2Aq0vU4BlykA"",""2025-26!AR4"")"),1033032.84) -> 1033032.8 | CR10: =IFERROR(__xludf.DUMMYFUNCTION("IMPORTRANGE(""1Oujo8vUnwFLr-WkmYYfJwaGjmRsDy-q2Aq0vU4BlykA"",""2025-26!AR3"")"),37.0) -> 37 | CS10: =IFERROR((CT10/CO10),"") -> 0.78494067 | CT10: =IFERROR(__xludf.DUMMYFUNCTION("IMPORTRANGE(""1Oujo8vUnwFLr-WkmYYfJwaGjmRsDy-q2Aq0vU4BlykA"",""2025-26!AS4"")"),1031412.04) -> 1031412 | CU10: =IFERROR(__xludf.DUMMYFUNCTION("IMPORTRANGE(""1Oujo8vUnwFLr-WkmYYfJwaGjmRsDy-q2Aq0vU4BlykA"",""2025-26!AS3"")"),37.0) -> 37 | CV10: Delhi
