Workbook

Sheet SECONDARY ORDER BOOKING REPORT 
B1: SECONDARY ORDER BOOKING REPORT 2026-27
C3: TOTAL | I3: =SUM(I7:I172) -> 5550165 | J3: =SUM(J7:J172) -> 334318616 | K3: =SUM(K7:K172) -> 11536 | L3: =SUM(L7:L172) -> 3619744793 | M3: =SUM(M7:M172) -> 5.779557e+08 | N3: =iferror(O3/L3,"") -> 0.12280843 | O3: =SUM(O7:O172) -> 4.4453518e+08 | P3: =SUM(P7:P172) -> 252592620 | Q3: =SUM(Q7:Q172) -> 6751 | R3: =SUM(R7:R172) -> 1.276113e+08 | S3: =SUM(S7:S172) -> 2213 | T3: =iferror(R3/P3,"") -> 0.50520599 | U3: =SUM(U7:U172) -> 1.3999574e+08 | V3: =SUM(V7:V172) -> 2589 | W3: =SUM(W7:W172) -> 2.8439279e+08 | X3: =SUM(X7:X172) -> 7672 | Y3: =SUM(Y7:Y172) -> 205924259 | Z3: =SUM(Z7:Z172) -> 2975 | AA3: =iferror(Y3/W3,"") -> 0.72408396 | AB3: =SUM(AB7:AB172) -> 2.0272754e+08 | AC3: =SUM(AC7:AC172) -> 3183 | AD3: =SUM(AD7:AD172) -> 2.8477878e+08 | AE3: =SUM(AE7:AE172) -> 7663 | AF3: =SUM(AF7:AF172) -> 2.4442014e+08 | AG3: =SUM(AG7:AG172) -> 3462 | AH3: =iferror(AF3/AD3,"") -> 0.85828074 | AI3: =SUM(AI7:AI172) -> 99094753 | AJ3: =SUM(AJ7:AJ172) -> 1549 | AK3: =SUM(AK7:AK172) -> 2.0852314e+08 | AL3: =SUM(AL7:AL172) -> 4490 | AM3: =SUM(AM7:AM172) -> 0 | AN3: =SUM(AN7:AN172) -> 0 | AO3: =iferror(AM3/AK3,"") -> 0 | AP3: =SUM(AP7:AP172) -> 1823285 | AQ3: =SUM(AQ7:AQ172) -> 59 | AR3: =SUM(AR7:AR172) -> 1.6198663e+08 | AS3: =SUM(AS7:AS172) -> 3443 | AT3: =SUM(AT7:AT172) -> 0 | AU3: =SUM(AU7:AU172) -> 0 | AV3: =iferror(AT3/AR3,"") -> 0 | AW3: =SUM(AW7:AW172) -> 0 | AX3: =SUM(AX7:AX172) -> 0 | AY3: =SUM(AY7:AY172) -> 1.701646e+08 | AZ3: =SUM(AZ7:AZ172) -> 2977 | BA3: =SUM(BA7:BA172) -> 0 | BB3: =SUM(BB7:BB172) -> 0 | BC3: =iferror(BA3/AY3,"") -> 0 | BD3: =SUM(BD7:BD172) -> 0 | BE3: =SUM(BE7:BE172) -> 0 | BF3: =SUM(BF7:BF172) -> 1.5771319e+08 | BG3: =SUM(BG7:BG172) -> 3024 | BH3: =SUM(BH7:BH172) -> 0 | BI3: =SUM(BI7:BI172) -> 0 | BJ3: =iferror(BH3/BF3,"") -> 0 | BK3: =SUM(BK7:BK172) -> 0 | BL3: =SUM(BL7:BL172) -> 0 | BM3: =SUM(BM7:BM172) -> 1.594196e+08 | BN3: =SUM(BN7:BN172) -> 3027 | BO3: =SUM(BO7:BO172) -> 0 | BP3: =SUM(BP7:BP172) -> 0 | BQ3: =iferror(BO3/BM3,"") -> 0 | BR3: =SUM(BR7:BR172) -> 0 | BS3: =SUM(BS7:BS172) -> 0 | BT3: =SUM(BT7:BT172) -> 1.8381142e+08 | BU3: =SUM(BU7:BU172) -> 3060 | BV3: =SUM(BV7:BV172) -> 0 | BW3: =SUM(BW7:BW172) -> 0 | BX3: =iferror(BV3/BT3,"") -> 0 | BY3: =SUM(BY7:BY172) -> 0 | BZ3: =SUM(BZ7:BZ172) -> 0 | CA3: =SUM(CA7:CA172) -> 1.6045965e+08 | CB3: =SUM(CB7:CB172) -> 3012 | CC3: =SUM(CC7:CC172) -> 0 | CD3: =SUM(CD7:CD172) -> 0 | CE3: =iferror(CC3/CA3,"") -> 0 | CF3: =SUM(CF7:CF172) -> 0 | CG3: =SUM(CG7:CG172) -> 0 | CH3: =SUM(CH7:CH172) -> 1.6766664e+08 | CI3: =SUM(CI7:CI172) -> 3022 | CJ3: =SUM(CJ7:CJ172) -> 0 | CK3: =SUM(CK7:CK172) -> 0 | CL3: =iferror(CJ3/CH3,"") -> 0 | CM3: =SUM(CM7:CM172) -> 0 | CN3: =SUM(CN7:CN172) -> 0 | CO3: =SUM(CO7:CO172) -> 1.806421e+08 | CP3: =SUM(CP7:CP172) -> 3074 | CQ3: =SUM(CQ7:CQ172) -> 0 | CR3: =SUM(CR7:CR172) -> 0 | CS3: =iferror(CQ3/CO3,"") -> 0 | CT3: =SUM(CT7:CT172) -> 893855 | CU3: =SUM(CU7:CU172) -> 22
B4: State Head | C4: Team Member | D4: H.Q | E4: Contact Number | F4: DOJ | G4: Week Off | H4: Market Hours | I4: Monthly CTC 25-26 | J4: Monthly Target 26-27 | K4: Total Dealer 26-27 | L4: Business Plan 26-27 | M4: Order Booked 26-27 | N4: Final Achievement | O4: Sales 26-27 | P4: 46113 | W4: 46143 | AD4: 46174 | AK4: 46204 | AR4: 46235 | AY4: 46266 | BF4: 46296 | BM4: 46327 | BT4: 46357 | CA4: 46388 | CH4: 46419 | CO4: 46447
P5: Plan | R5: Order Booked | T5: % of Achievement | U5: Sales Received | W5: Plan | Y5: Order Booked | AA5: % of Achievement | AB5: Sales Received | AD5: Plan | AF5: Order Booked | AH5: % of Achievement | AI5: Sales Received | AK5: Plan | AM5: Order Booked | AO5: % of Achievement | AP5: Sales Received | AR5: Plan | AT5: Order Booked | AV5: % of Achievement | AW5: Sales Received | AY5: Plan | BA5: Order Booked | BC5: % of Achievement | BD5: Sales Received | BF5: Plan | BH5: Order Booked | BJ5: % of Achievement | BK5: Sales Received | BM5: Plan | BO5: Order Booked | BQ5: % of Achievement | BR5: Sales Received | BT5: Plan | BV5: Order Booked | BX5: % of Achievement | BY5: Sales Received | CA5: Plan | CC5: Order Booked | CE5: % of Achievement | CF5: Sales Received | CH5: Plan | CJ5: Order Booked | CL5: % of Achievement | CM5: Sales Received | CO5: Plan | CQ5: Order Booked | CS5: % of Achievement | CT5: Sales Received
P6: Amount | Q6: Count | R6: Amount | S6: Count | U6: Amount | V6: Count | W6: Amount | X6: Count | Y6: Amount | Z6: Count | AB6: Amount | AC6: Count | AD6: Amount | AE6: Count | AF6: Amount | AG6: Count | AI6: Amount | AJ6: Count | AK6: Amount | AL6: Count | AM6: Amount | AN6: Count | AP6: Amount | AQ6: Count | AR6: Amount | AS6: Count | AT6: Amount | AU6: Count | AW6: Amount | AX6: Count | AY6: Amount | AZ6: Count | BA6: Amount | BB6: Count | BD6: Amount | BE6: Count | BF6: Amount | BG6: Count | BH6: Amount | BI6: Count | BK6: Amount | BL6: Count | BM6: Amount | BN6: Count | BO6: Amount | BP6: Count | BR6: Amount | BS6: Count | BT6: Amount | BU6: Count | BV6: Amount | BW6: Count | BY6: Amount | BZ6: Count | CA6: Amount | CB6: Count | CC6: Amount | CD6: Count | CF6: Amount | CG6: Count | CH6: Amount | CI6: Count | CJ6: Amount | CK6: Count | CM6: Amount | CN6: Count | CO6: Amount | CP6: Count | CQ6: Amount | CR6: Count | CT6: Amount | CU6: Count
A7: Anant Singh | B7: Anant Singh | C7: Ravinder Puri | D7: Ghaziabad | E7: 8802898600 | F7: 44809 | I7: 32910 | J7: 1980000 | K7: =IFERROR(__xludf.DUMMYFUNCTION("IMPORTRANGE(""1WowgCGTCOMmqanUXVQIbYWHbXi0cuGFxvrPe3CdSDpA"",""2026-27!A3"")"),96.0) -> 96 | L7: =IFERROR(__xludf.DUMMYFUNCTION("IMPORTRANGE(""1WowgCGTCOMmqanUXVQIbYWHbXi0cuGFxvrPe3CdSDpA"",""2026-27!G4"")"),2.376E7) -> 23760000 | M7: =R7+Y7+AF7+AM7+AT7+BA7+BH7+BO7+BV7+CC7+CJ7+CQ7 -> 5225399.2 | N7: =iferror(O7/L7,"") -> 0.23653455 | O7: =U7+AB7+AI7+AP7+AW7+BD7+BK7+BR7+BY7+CF7+CM7+CT7 -> 5620061 | P7: =IFERROR(__xludf.DUMMYFUNCTION("IMPORTRANGE(""1WowgCGTCOMmqanUXVQIbYWHbXi0cuGFxvrPe3CdSDpA"",""2026-27!J4"")"),1800000.0) -> 1800000 | Q7: =IFERROR(__xludf.DUMMYFUNCTION("IMPORTRANGE(""1WowgCGTCOMmqanUXVQIbYWHbXi0cuGFxvrPe3CdSDpA"",""2026-27!J3"")"),91.0) -> 91 | R7: =IFERROR(__xludf.DUMMYFUNCTION("IMPORTRANGE(""1WowgCGTCOMmqanUXVQIbYWHbXi0cuGFxvrPe3CdSDpA"",""2026-27!K4"")"),1544324.43) -> 1544324.4 | S7: =IFERROR(__xludf.DUMMYFUNCTION("IMPORTRANGE(""1WowgCGTCOMmqanUXVQIbYWHbXi0cuGFxvrPe3CdSDpA"",""2026-27!K3"")"),46.0) -> 46 | T7: =IFERROR((U7/P7),"") -> 0.93006667 | U7: =IFERROR(__xludf.DUMMYFUNCTION("IMPORTRANGE(""1WowgCGTCOMmqanUXVQIbYWHbXi0cuGFxvrPe3CdSDpA"",""2026-27!L4"")"),1674120.0) -> 1674120 | V7: =IFERROR(__xludf.DUMMYFUNCTION("IMPORTRANGE(""1WowgCGTCOMmqanUXVQIbYWHbXi0cuGFxvrPe3CdSDpA"",""2026-27!L3"")"),53.0) -> 53 | W7: =IFERROR(__xludf.DUMMYFUNCTION("IMPORTRANGE(""1WowgCGTCOMmqanUXVQIbYWHbXi0cuGFxvrPe3CdSDpA"",""2026-27!m4"")"),1980000.0) -> 1980000 | X7: =IFERROR(__xludf.DUMMYFUNCTION("IMPORTRANGE(""1WowgCGTCOMmqanUXVQIbYWHbXi0cuGFxvrPe3CdSDpA"",""2026-27!m3"")"),91.0) -> 91 | Y7: =IFERROR(__xludf.DUMMYFUNCTION("IMPORTRANGE(""1WowgCGTCOMmqanUXVQIbYWHbXi0cuGFxvrPe3CdSDpA"",""2026-27!N4"")"),1644028.0999999996) -> 1644028.1 | Z7: =IFERROR(__xludf.DUMMYFUNCTION("IMPORTRANGE(""1WowgCGTCOMmqanUXVQIbYWHbXi0cuGFxvrPe3CdSDpA"",""2026-27!N3"")"),50.0) -> 50 | AA7: =IFERROR((AB7/W7),"") -> 0.87523131 | AB7: =IFERROR(__xludf.DUMMYFUNCTION("IMPORTRANGE(""1WowgCGTCOMmqanUXVQIbYWHbXi0cuGFxvrPe3CdSDpA"",""2026-27!O4"")"),1732958.0) -> 1732958 | AC7: =IFERROR(__xludf.DUMMYFUNCTION("IMPORTRANGE(""1WowgCGTCOMmqanUXVQIbYWHbXi0cuGFxvrPe3CdSDpA"",""2026-27!O3"")"),52.0) -> 52 | AD7: =IFERROR(__xludf.DUMMYFUNCTION("IMPORTRANGE(""1WowgCGTCOMmqanUXVQIbYWHbXi0cuGFxvrPe3CdSDpA"",""2026-27!P4"")"),1980000.0) -> 1980000 | AE7: =IFERROR(__xludf.DUMMYFUNCTION("IMPORTRANGE(""1WowgCGTCOMmqanUXVQIbYWHbXi0cuGFxvrPe3CdSDpA"",""2026-27!P3"")"),94.0) -> 94 | AF7: =IFERROR(__xludf.DUMMYFUNCTION("IMPORTRANGE(""1WowgCGTCOMmqanUXVQIbYWHbXi0cuGFxvrPe3CdSDpA"",""2026-27!Q4"")"),2037046.62) -> 2037046.6 | AG7: =IFERROR(__xludf.DUMMYFUNCTION("IMPORTRANGE(""1WowgCGTCOMmqanUXVQIbYWHbXi0cuGFxvrPe3CdSDpA"",""2026-27!Q3"")"),43.0) -> 43 | AH7: =IFERROR((AI7/AD7),"") -> 1.1176682 | AI7: =IFERROR(__xludf.DUMMYFUNCTION("IMPORTRANGE(""1WowgCGTCOMmqanUXVQIbYWHbXi0cuGFxvrPe3CdSDpA"",""2026-27!R4"")"),2212983.0) -> 2212983 | AJ7: =IFERROR(__xludf.DUMMYFUNCTION("IMPORTRANGE(""1WowgCGTCOMmqanUXVQIbYWHbXi0cuGFxvrPe3CdSDpA"",""2026-27!R3"")"),50.0) -> 50 | AK7: =IFERROR(__xludf.DUMMYFUNCTION("IMPORTRANGE(""1WowgCGTCOMmqanUXVQIbYWHbXi0cuGFxvrPe3CdSDpA"",""2026-27!S4"")"),1980000.0) -> 1980000 | AL7: =IFERROR(__xludf.DUMMYFUNCTION("IMPORTRANGE(""1WowgCGTCOMmqanUXVQIbYWHbXi0cuGFxvrPe3CdSDpA"",""2026-27!S3"")"),95.0) -> 95 | AM7: =IFERROR(__xludf.DUMMYFUNCTION("IMPORTRANGE(""1WowgCGTCOMmqanUXVQIbYWHbXi0cuGFxvrPe3CdSDpA"",""2026-27!T4"")"),0.0) -> 0 | AN7: =IFERROR(__xludf.DUMMYFUNCTION("IMPORTRANGE(""1WowgCGTCOMmqanUXVQIbYWHbXi0cuGFxvrPe3CdSDpA"",""2026-27!T3"")"),0.0) -> 0 | AO7: =IFERROR((AP7/AK7),"") -> 0 | AP7: =IFERROR(__xludf.DUMMYFUNCTION("IMPORTRANGE(""1WowgCGTCOMmqanUXVQIbYWHbXi0cuGFxvrPe3CdSDpA"",""2026-27!U4"")"),0.0) -> 0 | AQ7: =IFERROR(__xludf.DUMMYFUNCTION("IMPORTRANGE(""1WowgCGTCOMmqanUXVQIbYWHbXi0cuGFxvrPe3CdSDpA"",""2026-27!U3"")"),0.0) -> 0 | AR7: =IFERROR(__xludf.DUMMYFUNCTION("IMPORTRANGE(""1WowgCGTCOMmqanUXVQIbYWHbXi0cuGFxvrPe3CdSDpA"",""2026-27!V4"")"),0.0) -> 0 | AS7: =IFERROR(__xludf.DUMMYFUNCTION("IMPORTRANGE(""1WowgCGTCOMmqanUXVQIbYWHbXi0cuGFxvrPe3CdSDpA"",""2026-27!V3"")"),0.0) -> 0 | AT7: =IFERROR(__xludf.DUMMYFUNCTION("IMPORTRANGE(""1WowgCGTCOMmqanUXVQIbYWHbXi0cuGFxvrPe3CdSDpA"",""2026-27!W4"")"),0.0) -> 0 | AU7: =IFERROR(__xludf.DUMMYFUNCTION("IMPORTRANGE(""1WowgCGTCOMmqanUXVQIbYWHbXi0cuGFxvrPe3CdSDpA"",""2026-27!W3"")"),0.0) -> 0 | AV7: =IFERROR((AW7/AR7),"") | AW7: =IFERROR(__xludf.DUMMYFUNCTION("IMPORTRANGE(""1WowgCGTCOMmqanUXVQIbYWHbXi0cuGFxvrPe3CdSDpA"",""2026-27!X4"")"),0.0) -> 0 | AX7: =IFERROR(__xludf.DUMMYFUNCTION("IMPORTRANGE(""1WowgCGTCOMmqanUXVQIbYWHbXi0cuGFxvrPe3CdSDpA"",""2026-27!X3"")"),0.0) -> 0 | AY7: =IFERROR(__xludf.DUMMYFUNCTION("IMPORTRANGE(""1WowgCGTCOMmqanUXVQIbYWHbXi0cuGFxvrPe3CdSDpA"",""2026-27!Y4"")"),0.0) -> 0 | AZ7: =IFERROR(__xludf.DUMMYFUNCTION("IMPORTRANGE(""1WowgCGTCOMmqanUXVQIbYWHbXi0cuGFxvrPe3CdSDpA"",""2026-27!Y3"")"),0.0) -> 0 | BA7: =IFERROR(__xludf.DUMMYFUNCTION("IMPORTRANGE(""1WowgCGTCOMmqanUXVQIbYWHbXi0cuGFxvrPe3CdSDpA"",""2026-27!Z4"")"),0.0) -> 0 | BB7: =IFERROR(__xludf.DUMMYFUNCTION("IMPORTRANGE(""1WowgCGTCOMmqanUXVQIbYWHbXi0cuGFxvrPe3CdSDpA"",""2026-27!Z3"")"),0.0) -> 0 | BC7: =IFERROR((BD7/AY7),"") | BD7: =IFERROR(__xludf.DUMMYFUNCTION("IMPORTRANGE(""1WowgCGTCOMmqanUXVQIbYWHbXi0cuGFxvrPe3CdSDpA"",""2026-27!AA4"")"),0.0) -> 0 | BE7: =IFERROR(__xludf.DUMMYFUNCTION("IMPORTRANGE(""1WowgCGTCOMmqanUXVQIbYWHbXi0cuGFxvrPe3CdSDpA"",""2026-27!AA3"")"),0.0) -> 0 | BF7: =IFERROR(__xludf.DUMMYFUNCTION("IMPORTRANGE(""1WowgCGTCOMmqanUXVQIbYWHbXi0cuGFxvrPe3CdSDpA"",""2026-27!AB4"")"),0.0) -> 0 | BG7: =IFERROR(__xludf.DUMMYFUNCTION("IMPORTRANGE(""1WowgCGTCOMmqanUXVQIbYWHbXi0cuGFxvrPe3CdSDpA"",""2026-27!AB3"")"),0.0) -> 0 | BH7: =IFERROR(__xludf.DUMMYFUNCTION("IMPORTRANGE(""1WowgCGTCOMmqanUXVQIbYWHbXi0cuGFxvrPe3CdSDpA"",""2026-27!AC4"")"),0.0) -> 0 | BI7: =IFERROR(__xludf.DUMMYFUNCTION("IMPORTRANGE(""1WowgCGTCOMmqanUXVQIbYWHbXi0cuGFxvrPe3CdSDpA"",""2026-27!AC3"")"),0.0) -> 0 | BJ7: =IFERROR((BK7/BF7),"") | BK7: =IFERROR(__xludf.DUMMYFUNCTION("IMPORTRANGE(""1WowgCGTCOMmqanUXVQIbYWHbXi0cuGFxvrPe3CdSDpA"",""2026-27!AD4"")"),0.0) -> 0 | BL7: =IFERROR(__xludf.DUMMYFUNCTION("IMPORTRANGE(""1WowgCGTCOMmqanUXVQIbYWHbXi0cuGFxvrPe3CdSDpA"",""2026-27!AD3"")"),0.0) -> 0 | BM7: =IFERROR(__xludf.DUMMYFUNCTION("IMPORTRANGE(""1WowgCGTCOMmqanUXVQIbYWHbXi0cuGFxvrPe3CdSDpA"",""2026-27!AE4"")"),0.0) -> 0 | BN7: =IFERROR(__xludf.DUMMYFUNCTION("IMPORTRANGE(""1WowgCGTCOMmqanUXVQIbYWHbXi0cuGFxvrPe3CdSDpA"",""2026-27!AE3"")"),0.0) -> 0 | BO7: =IFERROR(__xludf.DUMMYFUNCTION("IMPORTRANGE(""1WowgCGTCOMmqanUXVQIbYWHbXi0cuGFxvrPe3CdSDpA"",""2026-27!AF4"")"),0.0) -> 0 | BP7: =IFERROR(__xludf.DUMMYFUNCTION("IMPORTRANGE(""1WowgCGTCOMmqanUXVQIbYWHbXi0cuGFxvrPe3CdSDpA"",""2026-27!AF3"")"),0.0) -> 0 | BQ7: =IFERROR((BR7/BM7),"") | BR7: =IFERROR(__xludf.DUMMYFUNCTION("IMPORTRANGE(""1WowgCGTCOMmqanUXVQIbYWHbXi0cuGFxvrPe3CdSDpA"",""2026-27!AG4"")"),0.0) -> 0 | BS7: =IFERROR(__xludf.DUMMYFUNCTION("IMPORTRANGE(""1WowgCGTCOMmqanUXVQIbYWHbXi0cuGFxvrPe3CdSDpA"",""2026-27!AG3"")"),0.0) -> 0 | BT7: =IFERROR(__xludf.DUMMYFUNCTION("IMPORTRANGE(""1WowgCGTCOMmqanUXVQIbYWHbXi0cuGFxvrPe3CdSDpA"",""2026-27!AH4"")"),0.0) -> 0 | BU7: =IFERROR(__xludf.DUMMYFUNCTION("IMPORTRANGE(""1WowgCGTCOMmqanUXVQIbYWHbXi0cuGFxvrPe3CdSDpA"",""2026-27!AH3"")"),0.0) -> 0 | BV7: =IFERROR(__xludf.DUMMYFUNCTION("IMPORTRANGE(""1WowgCGTCOMmqanUXVQIbYWHbXi0cuGFxvrPe3CdSDpA"",""2026-27!AI4"")"),0.0) -> 0 | BW7: =IFERROR(__xludf.DUMMYFUNCTION("IMPORTRANGE(""1WowgCGTCOMmqanUXVQIbYWHbXi0cuGFxvrPe3CdSDpA"",""2026-27!AI3"")"),0.0) -> 0 | BX7: =IFERROR((BY7/BT7),"") | BY7: =IFERROR(__xludf.DUMMYFUNCTION("IMPORTRANGE(""1WowgCGTCOMmqanUXVQIbYWHbXi0cuGFxvrPe3CdSDpA"",""2026-27!AJ4"")"),0.0) -> 0 | BZ7: =IFERROR(__xludf.DUMMYFUNCTION("IMPORTRANGE(""1WowgCGTCOMmqanUXVQIbYWHbXi0cuGFxvrPe3CdSDpA"",""2026-27!AJ3"")"),0.0) -> 0 | CA7: =IFERROR(__xludf.DUMMYFUNCTION("IMPORTRANGE(""1WowgCGTCOMmqanUXVQIbYWHbXi0cuGFxvrPe3CdSDpA"",""2026-27!AK4"")"),0.0) -> 0 | CB7: =IFERROR(__xludf.DUMMYFUNCTION("IMPORTRANGE(""1WowgCGTCOMmqanUXVQIbYWHbXi0cuGFxvrPe3CdSDpA"",""2026-27!AK3"")"),0.0) -> 0 | CC7: =IFERROR(__xludf.DUMMYFUNCTION("IMPORTRANGE(""1WowgCGTCOMmqanUXVQIbYWHbXi0cuGFxvrPe3CdSDpA"",""2026-27!AL4"")"),0.0) -> 0 | CD7: =IFERROR(__xludf.DUMMYFUNCTION("IMPORTRANGE(""1WowgCGTCOMmqanUXVQIbYWHbXi0cuGFxvrPe3CdSDpA"",""2026-27!AL3"")"),0.0) -> 0 | CE7: =IFERROR((CF7/CA7),"") | CF7: =IFERROR(__xludf.DUMMYFUNCTION("IMPORTRANGE(""1WowgCGTCOMmqanUXVQIbYWHbXi0cuGFxvrPe3CdSDpA"",""2026-27!AM4"")"),0.0) -> 0 | CG7: =IFERROR(__xludf.DUMMYFUNCTION("IMPORTRANGE(""1WowgCGTCOMmqanUXVQIbYWHbXi0cuGFxvrPe3CdSDpA"",""2026-27!AM3"")"),0.0) -> 0 | CH7: =IFERROR(__xludf.DUMMYFUNCTION("IMPORTRANGE(""1WowgCGTCOMmqanUXVQIbYWHbXi0cuGFxvrPe3CdSDpA"",""2026-27!AN4"")"),0.0) -> 0 | CI7: =IFERROR(__xludf.DUMMYFUNCTION("IMPORTRANGE(""1WowgCGTCOMmqanUXVQIbYWHbXi0cuGFxvrPe3CdSDpA"",""2026-27!AN3"")"),0.0) -> 0 | CJ7: =IFERROR(__xludf.DUMMYFUNCTION("IMPORTRANGE(""1WowgCGTCOMmqanUXVQIbYWHbXi0cuGFxvrPe3CdSDpA"",""2026-27!AO4"")"),0.0) -> 0 | CK7: =IFERROR(__xludf.DUMMYFUNCTION("IMPORTRANGE(""1WowgCGTCOMmqanUXVQIbYWHbXi0cuGFxvrPe3CdSDpA"",""2026-27!AO3"")"),0.0) -> 0 | CL7: =IFERROR((CM7/CH7),"") | CM7: =IFERROR(__xludf.DUMMYFUNCTION("IMPORTRANGE(""1WowgCGTCOMmqanUXVQIbYWHbXi0cuGFxvrPe3CdSDpA"",""2026-27!AP4"")"),0.0) -> 0 | CN7: =IFERROR(__xludf.DUMMYFUNCTION("IMPORTRANGE(""1WowgCGTCOMmqanUXVQIbYWHbXi0cuGFxvrPe3CdSDpA"",""2026-27!AP3"")"),0.0) -> 0 | CO7: =IFERROR(__xludf.DUMMYFUNCTION("IMPORTRANGE(""1WowgCGTCOMmqanUXVQIbYWHbXi0cuGFxvrPe3CdSDpA"",""2026-27!AQ4"")"),0.0) -> 0 | CP7: =IFERROR(__xludf.DUMMYFUNCTION("IMPORTRANGE(""1WowgCGTCOMmqanUXVQIbYWHbXi0cuGFxvrPe3CdSDpA"",""2026-27!AQ3"")"),0.0) -> 0 | CQ7: =IFERROR(__xludf.DUMMYFUNCTION("IMPORTRANGE(""1WowgCGTCOMmqanUXVQIbYWHbXi0cuGFxvrPe3CdSDpA"",""2026-27!AR4"")"),0.0) -> 0 | CR7: =IFERROR(__xludf.DUMMYFUNCTION("IMPORTRANGE(""1WowgCGTCOMmqanUXVQIbYWHbXi0cuGFxvrPe3CdSDpA"",""2026-27!AR3"")"),0.0) -> 0 | CS7: =IFERROR((CT7/CO7),"") | CT7: =IFERROR(__xludf.DUMMYFUNCTION("IMPORTRANGE(""1WowgCGTCOMmqanUXVQIbYWHbXi0cuGFxvrPe3CdSDpA"",""2026-27!AS4"")"),0.0) -> 0 | CU7: =IFERROR(__xludf.DUMMYFUNCTION("IMPORTRANGE(""1WowgCGTCOMmqanUXVQIbYWHbXi0cuGFxvrPe3CdSDpA"",""2026-27!AS3"")"),0.0) -> 0
A8: Anant Singh | C8: PRASUN CHATTERJEE | D8: Delhi | E8: 9810268300 | F8: 44994 | I8: 46390 | J8: 1800000 | K8: =IFERROR(__xludf.DUMMYFUNCTION("IMPORTRANGE(""1UEZK2L9OACV3t606hu8vkTn-5ekPDyqCYSBS2X6A5Jc"",""2026-27!A3"")"),73.0) -> 73 | L8: =IFERROR(__xludf.DUMMYFUNCTION("IMPORTRANGE(""1UEZK2L9OACV3t606hu8vkTn-5ekPDyqCYSBS2X6A5Jc"",""2026-27!G4"")"),1.8E7) -> 18000000 | M8: =R8+Y8+AF8+AM8+AT8+BA8+BH8+BO8+BV8+CC8+CJ8+CQ8 -> 2621109.1 | N8: =iferror(O8/L8,"") -> 0.079209278 | O8: =U8+AB8+AI8+AP8+AW8+BD8+BK8+BR8+BY8+CF8+CM8+CT8 -> 1425767 | P8: =IFERROR(__xludf.DUMMYFUNCTION("IMPORTRANGE(""1UEZK2L9OACV3t606hu8vkTn-5ekPDyqCYSBS2X6A5Jc"",""2026-27!J4"")"),1673000.0) -> 1673000 | Q8: =IFERROR(__xludf.DUMMYFUNCTION("IMPORTRANGE(""1UEZK2L9OACV3t606hu8vkTn-5ekPDyqCYSBS2X6A5Jc"",""2026-27!J3"")"),66.0) -> 66 | R8: =IFERROR(__xludf.DUMMYFUNCTION("IMPORTRANGE(""1UEZK2L9OACV3t606hu8vkTn-5ekPDyqCYSBS2X6A5Jc"",""2026-27!K4"")"),415010.95) -> 415010.95 | S8: =IFERROR(__xludf.DUMMYFUNCTION("IMPORTRANGE(""1UEZK2L9OACV3t606hu8vkTn-5ekPDyqCYSBS2X6A5Jc"",""2026-27!K3"")"),20.0) -> 20 | T8: =IFERROR((U8/P8),"") -> 0.24477764 | U8: =IFERROR(__xludf.DUMMYFUNCTION("IMPORTRANGE(""1UEZK2L9OACV3t606hu8vkTn-5ekPDyqCYSBS2X6A5Jc"",""2026-27!L4"")"),409513.0) -> 409513 | V8: =IFERROR(__xludf.DUMMYFUNCTION("IMPORTRANGE(""1UEZK2L9OACV3t606hu8vkTn-5ekPDyqCYSBS2X6A5Jc"",""2026-27!L3"")"),20.0) -> 20 | W8: =IFERROR(__xludf.DUMMYFUNCTION("IMPORTRANGE(""1UEZK2L9OACV3t606hu8vkTn-5ekPDyqCYSBS2X6A5Jc"",""2026-27!m4"")"),1673000.0) -> 1673000 | X8: =IFERROR(__xludf.DUMMYFUNCTION("IMPORTRANGE(""1UEZK2L9OACV3t606hu8vkTn-5ekPDyqCYSBS2X6A5Jc"",""2026-27!m3"")"),66.0) -> 66 | Y8: =IFERROR(__xludf.DUMMYFUNCTION("IMPORTRANGE(""1UEZK2L9OACV3t606hu8vkTn-5ekPDyqCYSBS2X6A5Jc"",""2026-27!N4"")"),945801.1) -> 945801.1 | Z8: =IFERROR(__xludf.DUMMYFUNCTION("IMPORTRANGE(""1UEZK2L9OACV3t606hu8vkTn-5ekPDyqCYSBS2X6A5Jc"",""2026-27!N3"")"),20.0) -> 20 | AA8: =IFERROR((AB8/W8),"") -> 0.60744411 | AB8: =IFERROR(__xludf.DUMMYFUNCTION("IMPORTRANGE(""1UEZK2L9OACV3t606hu8vkTn-5ekPDyqCYSBS2X6A5Jc"",""2026-27!O4"")"),1016254.0) -> 1016254 | AC8: =IFERROR(__xludf.DUMMYFUNCTION("IMPORTRANGE(""1UEZK2L9OACV3t606hu8vkTn-5ekPDyqCYSBS2X6A5Jc"",""2026-27!O3"")"),20.0) -> 20 | AD8: =IFERROR(__xludf.DUMMYFUNCTION("IMPORTRANGE(""1UEZK2L9OACV3t606hu8vkTn-5ekPDyqCYSBS2X6A5Jc"",""2026-27!P4"")"),1673000.0) -> 1673000 | AE8: =IFERROR(__xludf.DUMMYFUNCTION("IMPORTRANGE(""1UEZK2L9OACV3t606hu8vkTn-5ekPDyqCYSBS2X6A5Jc"",""2026-27!P3"")"),66.0) -> 66 | AF8: =IFERROR(__xludf.DUMMYFUNCTION("IMPORTRANGE(""1UEZK2L9OACV3t606hu8vkTn-5ekPDyqCYSBS2X6A5Jc"",""2026-27!Q4"")"),1260297.02) -> 1260297 | AG8: =IFERROR(__xludf.DUMMYFUNCTION("IMPORTRANGE(""1UEZK2L9OACV3t606hu8vkTn-5ekPDyqCYSBS2X6A5Jc"",""2026-27!Q3"")"),21.0) -> 21 | AH8: =IFERROR((AI8/AD8),"") -> 0 | AI8: =IFERROR(__xludf.DUMMYFUNCTION("IMPORTRANGE(""1UEZK2L9OACV3t606hu8vkTn-5ekPDyqCYSBS2X6A5Jc"",""2026-27!R4"")"),0.0) -> 0 | AJ8: =IFERROR(__xludf.DUMMYFUNCTION("IMPORTRANGE(""1UEZK2L9OACV3t606hu8vkTn-5ekPDyqCYSBS2X6A5Jc"",""2026-27!R3"")"),0.0) -> 0 | AK8: =IFERROR(__xludf.DUMMYFUNCTION("IMPORTRANGE(""1UEZK2L9OACV3t606hu8vkTn-5ekPDyqCYSBS2X6A5Jc"",""2026-27!S4"")"),0.0) -> 0 | AL8: =IFERROR(__xludf.DUMMYFUNCTION("IMPORTRANGE(""1UEZK2L9OACV3t606hu8vkTn-5ekPDyqCYSBS2X6A5Jc"",""2026-27!S3"")"),0.0) -> 0 | AM8: =IFERROR(__xludf.DUMMYFUNCTION("IMPORTRANGE(""1UEZK2L9OACV3t606hu8vkTn-5ekPDyqCYSBS2X6A5Jc"",""2026-27!T4"")"),0.0) -> 0 | AN8: =IFERROR(__xludf.DUMMYFUNCTION("IMPORTRANGE(""1UEZK2L9OACV3t606hu8vkTn-5ekPDyqCYSBS2X6A5Jc"",""2026-27!T3"")"),0.0) -> 0 | AO8: =IFERROR((AP8/AK8),"") | AP8: =IFERROR(__xludf.DUMMYFUNCTION("IMPORTRANGE(""1UEZK2L9OACV3t606hu8vkTn-5ekPDyqCYSBS2X6A5Jc"",""2026-27!U4"")"),0.0) -> 0 | AQ8: =IFERROR(__xludf.DUMMYFUNCTION("IMPORTRANGE(""1UEZK2L9OACV3t606hu8vkTn-5ekPDyqCYSBS2X6A5Jc"",""2026-27!U3"")"),0.0) -> 0 | AR8: =IFERROR(__xludf.DUMMYFUNCTION("IMPORTRANGE(""1UEZK2L9OACV3t606hu8vkTn-5ekPDyqCYSBS2X6A5Jc"",""2026-27!V4"")"),0.0) -> 0 | AS8: =IFERROR(__xludf.DUMMYFUNCTION("IMPORTRANGE(""1UEZK2L9OACV3t606hu8vkTn-5ekPDyqCYSBS2X6A5Jc"",""2026-27!V3"")"),0.0) -> 0 | AT8: =IFERROR(__xludf.DUMMYFUNCTION("IMPORTRANGE(""1UEZK2L9OACV3t606hu8vkTn-5ekPDyqCYSBS2X6A5Jc"",""2026-27!W4"")"),0.0) -> 0 | AU8: =IFERROR(__xludf.DUMMYFUNCTION("IMPORTRANGE(""1UEZK2L9OACV3t606hu8vkTn-5ekPDyqCYSBS2X6A5Jc"",""2026-27!W3"")"),0.0) -> 0 | AV8: =IFERROR((AW8/AR8),"") | AW8: =IFERROR(__xludf.DUMMYFUNCTION("IMPORTRANGE(""1UEZK2L9OACV3t606hu8vkTn-5ekPDyqCYSBS2X6A5Jc"",""2026-27!X4"")"),0.0) -> 0 | AX8: =IFERROR(__xludf.DUMMYFUNCTION("IMPORTRANGE(""1UEZK2L9OACV3t606hu8vkTn-5ekPDyqCYSBS2X6A5Jc"",""2026-27!X3"")"),0.0) -> 0 | AY8: =IFERROR(__xludf.DUMMYFUNCTION("IMPORTRANGE(""1UEZK2L9OACV3t606hu8vkTn-5ekPDyqCYSBS2X6A5Jc"",""2026-27!Y4"")"),0.0) -> 0 | AZ8: =IFERROR(__xludf.DUMMYFUNCTION("IMPORTRANGE(""1UEZK2L9OACV3t606hu8vkTn-5ekPDyqCYSBS2X6A5Jc"",""2026-27!Y3"")"),0.0) -> 0 | BA8: =IFERROR(__xludf.DUMMYFUNCTION("IMPORTRANGE(""1UEZK2L9OACV3t606hu8vkTn-5ekPDyqCYSBS2X6A5Jc"",""2026-27!Z4"")"),0.0) -> 0 | BB8: =IFERROR(__xludf.DUMMYFUNCTION("IMPORTRANGE(""1UEZK2L9OACV3t606hu8vkTn-5ekPDyqCYSBS2X6A5Jc"",""2026-27!Z3"")"),0.0) -> 0 | BC8: =IFERROR((BD8/AY8),"") | BD8: =IFERROR(__xludf.DUMMYFUNCTION("IMPORTRANGE(""1UEZK2L9OACV3t606hu8vkTn-5ekPDyqCYSBS2X6A5Jc"",""2026-27!AA4"")"),0.0) -> 0 | BE8: =IFERROR(__xludf.DUMMYFUNCTION("IMPORTRANGE(""1UEZK2L9OACV3t606hu8vkTn-5ekPDyqCYSBS2X6A5Jc"",""2026-27!AA3"")"),0.0) -> 0 | BF8: =IFERROR(__xludf.DUMMYFUNCTION("IMPORTRANGE(""1UEZK2L9OACV3t606hu8vkTn-5ekPDyqCYSBS2X6A5Jc"",""2026-27!AB4"")"),0.0) -> 0 | BG8: =IFERROR(__xludf.DUMMYFUNCTION("IMPORTRANGE(""1UEZK2L9OACV3t606hu8vkTn-5ekPDyqCYSBS2X6A5Jc"",""2026-27!AB3"")"),0.0) -> 0 | BH8: =IFERROR(__xludf.DUMMYFUNCTION("IMPORTRANGE(""1UEZK2L9OACV3t606hu8vkTn-5ekPDyqCYSBS2X6A5Jc"",""2026-27!AC4"")"),0.0) -> 0 | BI8: =IFERROR(__xludf.DUMMYFUNCTION("IMPORTRANGE(""1UEZK2L9OACV3t606hu8vkTn-5ekPDyqCYSBS2X6A5Jc"",""2026-27!AC3"")"),0.0) -> 0 | BJ8: =IFERROR((BK8/BF8),"") | BK8: =IFERROR(__xludf.DUMMYFUNCTION("IMPORTRANGE(""1UEZK2L9OACV3t606hu8vkTn-5ekPDyqCYSBS2X6A5Jc"",""2026-27!AD4"")"),0.0) -> 0 | BL8: =IFERROR(__xludf.DUMMYFUNCTION("IMPORTRANGE(""1UEZK2L9OACV3t606hu8vkTn-5ekPDyqCYSBS2X6A5Jc"",""2026-27!AD3"")"),0.0) -> 0 | BM8: =IFERROR(__xludf.DUMMYFUNCTION("IMPORTRANGE(""1UEZK2L9OACV3t606hu8vkTn-5ekPDyqCYSBS2X6A5Jc"",""2026-27!AE4"")"),0.0) -> 0 | BN8: =IFERROR(__xludf.DUMMYFUNCTION("IMPORTRANGE(""1UEZK2L9OACV3t606hu8vkTn-5ekPDyqCYSBS2X6A5Jc"",""2026-27!AE3"")"),0.0) -> 0 | BO8: =IFERROR(__xludf.DUMMYFUNCTION("IMPORTRANGE(""1UEZK2L9OACV3t606hu8vkTn-5ekPDyqCYSBS2X6A5Jc"",""2026-27!AF4"")"),0.0) -> 0 | BP8: =IFERROR(__xludf.DUMMYFUNCTION("IMPORTRANGE(""1UEZK2L9OACV3t606hu8vkTn-5ekPDyqCYSBS2X6A5Jc"",""2026-27!AF3"")"),0.0) -> 0 | BQ8: =IFERROR((BR8/BM8),"") | BR8: =IFERROR(__xludf.DUMMYFUNCTION("IMPORTRANGE(""1UEZK2L9OACV3t606hu8vkTn-5ekPDyqCYSBS2X6A5Jc"",""2026-27!AG4"")"),0.0) -> 0 | BS8: =IFERROR(__xludf.DUMMYFUNCTION("IMPORTRANGE(""1UEZK2L9OACV3t606hu8vkTn-5ekPDyqCYSBS2X6A5Jc"",""2026-27!AG3"")"),0.0) -> 0 | BT8: =IFERROR(__xludf.DUMMYFUNCTION("IMPORTRANGE(""1UEZK2L9OACV3t606hu8vkTn-5ekPDyqCYSBS2X6A5Jc"",""2026-27!AH4"")"),0.0) -> 0 | BU8: =IFERROR(__xludf.DUMMYFUNCTION("IMPORTRANGE(""1UEZK2L9OACV3t606hu8vkTn-5ekPDyqCYSBS2X6A5Jc"",""2026-27!AH3"")"),0.0) -> 0 | BV8: =IFERROR(__xludf.DUMMYFUNCTION("IMPORTRANGE(""1UEZK2L9OACV3t606hu8vkTn-5ekPDyqCYSBS2X6A5Jc"",""2026-27!AI4"")"),0.0) -> 0 | BW8: =IFERROR(__xludf.DUMMYFUNCTION("IMPORTRANGE(""1UEZK2L9OACV3t606hu8vkTn-5ekPDyqCYSBS2X6A5Jc"",""2026-27!AI3"")"),0.0) -> 0 | BX8: =IFERROR((BY8/BT8),"") | BY8: =IFERROR(__xludf.DUMMYFUNCTION("IMPORTRANGE(""1UEZK2L9OACV3t606hu8vkTn-5ekPDyqCYSBS2X6A5Jc"",""2026-27!AJ4"")"),0.0) -> 0 | BZ8: =IFERROR(__xludf.DUMMYFUNCTION("IMPORTRANGE(""1UEZK2L9OACV3t606hu8vkTn-5ekPDyqCYSBS2X6A5Jc"",""2026-27!AJ3"")"),0.0) -> 0 | CA8: =IFERROR(__xludf.DUMMYFUNCTION("IMPORTRANGE(""1UEZK2L9OACV3t606hu8vkTn-5ekPDyqCYSBS2X6A5Jc"",""2026-27!AK4"")"),0.0) -> 0 | CB8: =IFERROR(__xludf.DUMMYFUNCTION("IMPORTRANGE(""1UEZK2L9OACV3t606hu8vkTn-5ekPDyqCYSBS2X6A5Jc"",""2026-27!AK3"")"),0.0) -> 0 | CC8: =IFERROR(__xludf.DUMMYFUNCTION("IMPORTRANGE(""1UEZK2L9OACV3t606hu8vkTn-5ekPDyqCYSBS2X6A5Jc"",""2026-27!AL4"")"),0.0) -> 0 | CD8: =IFERROR(__xludf.DUMMYFUNCTION("IMPORTRANGE(""1UEZK2L9OACV3t606hu8vkTn-5ekPDyqCYSBS2X6A5Jc"",""2026-27!AL3"")"),0.0) -> 0 | CE8: =IFERROR((CF8/CA8),"") | CF8: =IFERROR(__xludf.DUMMYFUNCTION("IMPORTRANGE(""1UEZK2L9OACV3t606hu8vkTn-5ekPDyqCYSBS2X6A5Jc"",""2026-27!AM4"")"),0.0) -> 0 | CG8: =IFERROR(__xludf.DUMMYFUNCTION("IMPORTRANGE(""1UEZK2L9OACV3t606hu8vkTn-5ekPDyqCYSBS2X6A5Jc"",""2026-27!AM3"")"),0.0) -> 0 | CH8: =IFERROR(__xludf.DUMMYFUNCTION("IMPORTRANGE(""1UEZK2L9OACV3t606hu8vkTn-5ekPDyqCYSBS2X6A5Jc"",""2026-27!AN4"")"),0.0) -> 0 | CI8: =IFERROR(__xludf.DUMMYFUNCTION("IMPORTRANGE(""1UEZK2L9OACV3t606hu8vkTn-5ekPDyqCYSBS2X6A5Jc"",""2026-27!AN3"")"),0.0) -> 0 | CJ8: =IFERROR(__xludf.DUMMYFUNCTION("IMPORTRANGE(""1UEZK2L9OACV3t606hu8vkTn-5ekPDyqCYSBS2X6A5Jc"",""2026-27!AO4"")"),0.0) -> 0 | CK8: =IFERROR(__xludf.DUMMYFUNCTION("IMPORTRANGE(""1UEZK2L9OACV3t606hu8vkTn-5ekPDyqCYSBS2X6A5Jc"",""2026-27!AO3"")"),0.0) -> 0 | CL8: =IFERROR((CM8/CH8),"") | CM8: =IFERROR(__xludf.DUMMYFUNCTION("IMPORTRANGE(""1UEZK2L9OACV3t606hu8vkTn-5ekPDyqCYSBS2X6A5Jc"",""2026-27!AP4"")"),0.0) -> 0 | CN8: =IFERROR(__xludf.DUMMYFUNCTION("IMPORTRANGE(""1UEZK2L9OACV3t606hu8vkTn-5ekPDyqCYSBS2X6A5Jc"",""2026-27!AP3"")"),0.0) -> 0 | CO8: =IFERROR(__xludf.DUMMYFUNCTION("IMPORTRANGE(""1UEZK2L9OACV3t606hu8vkTn-5ekPDyqCYSBS2X6A5Jc"",""2026-27!AQ4"")"),0.0) -> 0 | CP8: =IFERROR(__xludf.DUMMYFUNCTION("IMPORTRANGE(""1UEZK2L9OACV3t606hu8vkTn-5ekPDyqCYSBS2X6A5Jc"",""2026-27!AQ3"")"),0.0) -> 0 | CQ8: =IFERROR(__xludf.DUMMYFUNCTION("IMPORTRANGE(""1UEZK2L9OACV3t606hu8vkTn-5ekPDyqCYSBS2X6A5Jc"",""2026-27!AR4"")"),0.0) -> 0 | CR8: =IFERROR(__xludf.DUMMYFUNCTION("IMPORTRANGE(""1UEZK2L9OACV3t606hu8vkTn-5ekPDyqCYSBS2X6A5Jc"",""2026-27!AR3"")"),0.0) -> 0 | CS8: =IFERROR((CT8/CO8),"") | CT8: =IFERROR(__xludf.DUMMYFUNCTION("IMPORTRANGE(""1UEZK2L9OACV3t606hu8vkTn-5ekPDyqCYSBS2X6A5Jc"",""2026-27!AS4"")"),0.0) -> 0 | CU8: =IFERROR(__xludf.DUMMYFUNCTION("IMPORTRANGE(""1UEZK2L9OACV3t606hu8vkTn-5ekPDyqCYSBS2X6A5Jc"",""2026-27!AS3"")"),0.0) -> 0
A9: Anant Singh | C9: Manish Gupta | D9: South East Delhi | E9: 9891552205 | F9: 45551 | I9: 28310 | J9: 1400000 | K9: =IFERROR(__xludf.DUMMYFUNCTION("IMPORTRANGE(""1Oujo8vUnwFLr-WkmYYfJwaGjmRsDy-q2Aq0vU4BlykA"",""2026-27!A3"")"),94.0) -> 94 | L9: =IFERROR(__xludf.DUMMYFUNCTION("IMPORTRANGE(""1Oujo8vUnwFLr-WkmYYfJwaGjmRsDy-q2Aq0vU4BlykA"",""2026-27!G4"")"),1.565E7) -> 15650000 | M9: =R9+Y9+AF9+AM9+AT9+BA9+BH9+BO9+BV9+CC9+CJ9+CQ9 -> 2657739 | N9: =iferror(O9/L9,"") -> 0.18148371 | O9: =U9+AB9+AI9+AP9+AW9+BD9+BK9+BR9+BY9+CF9+CM9+CT9 -> 2840220 | P9: =IFERROR(__xludf.DUMMYFUNCTION("IMPORTRANGE(""1Oujo8vUnwFLr-WkmYYfJwaGjmRsDy-q2Aq0vU4BlykA"",""2026-27!J4"")"),1357000.0) -> 1357000 | Q9: =IFERROR(__xludf.DUMMYFUNCTION("IMPORTRANGE(""1Oujo8vUnwFLr-WkmYYfJwaGjmRsDy-q2Aq0vU4BlykA"",""2026-27!J3"")"),92.0) -> 92 | R9: =IFERROR(__xludf.DUMMYFUNCTION("IMPORTRANGE(""1Oujo8vUnwFLr-WkmYYfJwaGjmRsDy-q2Aq0vU4BlykA"",""2026-27!K4"")"),821049.6) -> 821049.6 | S9: =IFERROR(__xludf.DUMMYFUNCTION("IMPORTRANGE(""1Oujo8vUnwFLr-WkmYYfJwaGjmRsDy-q2Aq0vU4BlykA"",""2026-27!K3"")"),39.0) -> 39 | T9: =IFERROR((U9/P9),"") -> 0.62064047 | U9: =IFERROR(__xludf.DUMMYFUNCTION("IMPORTRANGE(""1Oujo8vUnwFLr-WkmYYfJwaGjmRsDy-q2Aq0vU4BlykA"",""2026-27!L4"")"),842209.1200000001) -> 842209.12 | V9: =IFERROR(__xludf.DUMMYFUNCTION("IMPORTRANGE(""1Oujo8vUnwFLr-WkmYYfJwaGjmRsDy-q2Aq0vU4BlykA"",""2026-27!L3"")"),39.0) -> 39 | W9: =IFERROR(__xludf.DUMMYFUNCTION("IMPORTRANGE(""1Oujo8vUnwFLr-WkmYYfJwaGjmRsDy-q2Aq0vU4BlykA"",""2026-27!m4"")"),1560000.0) -> 1560000 | X9: =IFERROR(__xludf.DUMMYFUNCTION("IMPORTRANGE(""1Oujo8vUnwFLr-WkmYYfJwaGjmRsDy-q2Aq0vU4BlykA"",""2026-27!m3"")"),92.0) -> 92 | Y9: =IFERROR(__xludf.DUMMYFUNCTION("IMPORTRANGE(""1Oujo8vUnwFLr-WkmYYfJwaGjmRsDy-q2Aq0vU4BlykA"",""2026-27!N4"")"),782770.1200000001) -> 782770.12 | Z9: =IFERROR(__xludf.DUMMYFUNCTION("IMPORTRANGE(""1Oujo8vUnwFLr-WkmYYfJwaGjmRsDy-q2Aq0vU4BlykA"",""2026-27!N3"")"),32.0) -> 32 | AA9: =IFERROR((AB9/W9),"") -> 0.60682735 | AB9: =IFERROR(__xludf.DUMMYFUNCTION("IMPORTRANGE(""1Oujo8vUnwFLr-WkmYYfJwaGjmRsDy-q2Aq0vU4BlykA"",""2026-27!O4"")"),946650.6599999997) -> 946650.66 | AC9: =IFERROR(__xludf.DUMMYFUNCTION("IMPORTRANGE(""1Oujo8vUnwFLr-WkmYYfJwaGjmRsDy-q2Aq0vU4BlykA"",""2026-27!O3"")"),32.0) -> 32 | AD9: =IFERROR(__xludf.DUMMYFUNCTION("IMPORTRANGE(""1Oujo8vUnwFLr-WkmYYfJwaGjmRsDy-q2Aq0vU4BlykA"",""2026-27!P4"")"),1405000.0) -> 1405000 | AE9: =IFERROR(__xludf.DUMMYFUNCTION("IMPORTRANGE(""1Oujo8vUnwFLr-WkmYYfJwaGjmRsDy-q2Aq0vU4BlykA"",""2026-27!P3"")"),92.0) -> 92 | AF9: =IFERROR(__xludf.DUMMYFUNCTION("IMPORTRANGE(""1Oujo8vUnwFLr-WkmYYfJwaGjmRsDy-q2Aq0vU4BlykA"",""2026-27!Q4"")"),1053919.24) -> 1053919.2 | AG9: =IFERROR(__xludf.DUMMYFUNCTION("IMPORTRANGE(""1Oujo8vUnwFLr-WkmYYfJwaGjmRsDy-q2Aq0vU4BlykA"",""2026-27!Q3"")"),40.0) -> 40 | AH9: =IFERROR((AI9/AD9),"") -> 0.7482991 | AI9: =IFERROR(__xludf.DUMMYFUNCTION("IMPORTRANGE(""1Oujo8vUnwFLr-WkmYYfJwaGjmRsDy-q2Aq0vU4BlykA"",""2026-27!R4"")"),1051360.23) -> 1051360.2 | AJ9: =IFERROR(__xludf.DUMMYFUNCTION("IMPORTRANGE(""1Oujo8vUnwFLr-WkmYYfJwaGjmRsDy-q2Aq0vU4BlykA"",""2026-27!R3"")"),39.0) -> 39 | AK9: =IFERROR(__xludf.DUMMYFUNCTION("IMPORTRANGE(""1Oujo8vUnwFLr-WkmYYfJwaGjmRsDy-q2Aq0vU4BlykA"",""2026-27!S4"")"),1408000.0) -> 1408000 | AL9: =IFERROR(__xludf.DUMMYFUNCTION("IMPORTRANGE(""1Oujo8vUnwFLr-WkmYYfJwaGjmRsDy-q2Aq0vU4BlykA"",""2026-27!S3"")"),93.0) -> 93 | AM9: =IFERROR(__xludf.DUMMYFUNCTION("IMPORTRANGE(""1Oujo8vUnwFLr-WkmYYfJwaGjmRsDy-q2Aq0vU4BlykA"",""2026-27!T4"")"),0.0) -> 0 | AN9: =IFERROR(__xludf.DUMMYFUNCTION("IMPORTRANGE(""1Oujo8vUnwFLr-WkmYYfJwaGjmRsDy-q2Aq0vU4BlykA"",""2026-27!T3"")"),0.0) -> 0 | AO9: =IFERROR((AP9/AK9),"") -> 0 | AP9: =IFERROR(__xludf.DUMMYFUNCTION("IMPORTRANGE(""1Oujo8vUnwFLr-WkmYYfJwaGjmRsDy-q2Aq0vU4BlykA"",""2026-27!U4"")"),0.0) -> 0 | AQ9: =IFERROR(__xludf.DUMMYFUNCTION("IMPORTRANGE(""1Oujo8vUnwFLr-WkmYYfJwaGjmRsDy-q2Aq0vU4BlykA"",""2026-27!U3"")"),0.0) -> 0 | AR9: =IFERROR(__xludf.DUMMYFUNCTION("IMPORTRANGE(""1Oujo8vUnwFLr-WkmYYfJwaGjmRsDy-q2Aq0vU4BlykA"",""2026-27!V4"")"),0.0) -> 0 | AS9: =IFERROR(__xludf.DUMMYFUNCTION("IMPORTRANGE(""1Oujo8vUnwFLr-WkmYYfJwaGjmRsDy-q2Aq0vU4BlykA"",""2026-27!V3"")"),0.0) -> 0 | AT9: =IFERROR(__xludf.DUMMYFUNCTION("IMPORTRANGE(""1Oujo8vUnwFLr-WkmYYfJwaGjmRsDy-q2Aq0vU4BlykA"",""2026-27!W4"")"),0.0) -> 0 | AU9: =IFERROR(__xludf.DUMMYFUNCTION("IMPORTRANGE(""1Oujo8vUnwFLr-WkmYYfJwaGjmRsDy-q2Aq0vU4BlykA"",""2026-27!W3"")"),0.0) -> 0 | AV9: =IFERROR((AW9/AR9),"") | AW9: =IFERROR(__xludf.DUMMYFUNCTION("IMPORTRANGE(""1Oujo8vUnwFLr-WkmYYfJwaGjmRsDy-q2Aq0vU4BlykA"",""2026-27!X4"")"),0.0) -> 0 | AX9: =IFERROR(__xludf.DUMMYFUNCTION("IMPORTRANGE(""1Oujo8vUnwFLr-WkmYYfJwaGjmRsDy-q2Aq0vU4BlykA"",""2026-27!X3"")"),0.0) -> 0 | AY9: =IFERROR(__xludf.DUMMYFUNCTION("IMPORTRANGE(""1Oujo8vUnwFLr-WkmYYfJwaGjmRsDy-q2Aq0vU4BlykA"",""2026-27!Y4"")"),0.0) -> 0 | AZ9: =IFERROR(__xludf.DUMMYFUNCTION("IMPORTRANGE(""1Oujo8vUnwFLr-WkmYYfJwaGjmRsDy-q2Aq0vU4BlykA"",""2026-27!Y3"")"),0.0) -> 0 | BA9: =IFERROR(__xludf.DUMMYFUNCTION("IMPORTRANGE(""1Oujo8vUnwFLr-WkmYYfJwaGjmRsDy-q2Aq0vU4BlykA"",""2026-27!Z4"")"),0.0) -> 0 | BB9: =IFERROR(__xludf.DUMMYFUNCTION("IMPORTRANGE(""1Oujo8vUnwFLr-WkmYYfJwaGjmRsDy-q2Aq0vU4BlykA"",""2026-27!Z3"")"),0.0) -> 0 | BC9: =IFERROR((BD9/AY9),"") | BD9: =IFERROR(__xludf.DUMMYFUNCTION("IMPORTRANGE(""1Oujo8vUnwFLr-WkmYYfJwaGjmRsDy-q2Aq0vU4BlykA"",""2026-27!AA4"")"),0.0) -> 0 | BE9: =IFERROR(__xludf.DUMMYFUNCTION("IMPORTRANGE(""1Oujo8vUnwFLr-WkmYYfJwaGjmRsDy-q2Aq0vU4BlykA"",""2026-27!AA3"")"),0.0) -> 0 | BF9: =IFERROR(__xludf.DUMMYFUNCTION("IMPORTRANGE(""1Oujo8vUnwFLr-WkmYYfJwaGjmRsDy-q2Aq0vU4BlykA"",""2026-27!AB4"")"),0.0) -> 0 | BG9: =IFERROR(__xludf.DUMMYFUNCTION("IMPORTRANGE(""1Oujo8vUnwFLr-WkmYYfJwaGjmRsDy-q2Aq0vU4BlykA"",""2026-27!AB3"")"),0.0) -> 0 | BH9: =IFERROR(__xludf.DUMMYFUNCTION("IMPORTRANGE(""1Oujo8vUnwFLr-WkmYYfJwaGjmRsDy-q2Aq0vU4BlykA"",""2026-27!AC4"")"),0.0) -> 0 | BI9: =IFERROR(__xludf.DUMMYFUNCTION("IMPORTRANGE(""1Oujo8vUnwFLr-WkmYYfJwaGjmRsDy-q2Aq0vU4BlykA"",""2026-27!AC3"")"),0.0) -> 0 | BJ9: =IFERROR((BK9/BF9),"") | BK9: =IFERROR(__xludf.DUMMYFUNCTION("IMPORTRANGE(""1Oujo8vUnwFLr-WkmYYfJwaGjmRsDy-q2Aq0vU4BlykA"",""2026-27!AD4"")"),0.0) -> 0 | BL9: =IFERROR(__xludf.DUMMYFUNCTION("IMPORTRANGE(""1Oujo8vUnwFLr-WkmYYfJwaGjmRsDy-q2Aq0vU4BlykA"",""2026-27!AD3"")"),0.0) -> 0 | BM9: =IFERROR(__xludf.DUMMYFUNCTION("IMPORTRANGE(""1Oujo8vUnwFLr-WkmYYfJwaGjmRsDy-q2Aq0vU4BlykA"",""2026-27!AE4"")"),0.0) -> 0 | BN9: =IFERROR(__xludf.DUMMYFUNCTION("IMPORTRANGE(""1Oujo8vUnwFLr-WkmYYfJwaGjmRsDy-q2Aq0vU4BlykA"",""2026-27!AE3"")"),0.0) -> 0 | BO9: =IFERROR(__xludf.DUMMYFUNCTION("IMPORTRANGE(""1Oujo8vUnwFLr-WkmYYfJwaGjmRsDy-q2Aq0vU4BlykA"",""2026-27!AF4"")"),0.0) -> 0 | BP9: =IFERROR(__xludf.DUMMYFUNCTION("IMPORTRANGE(""1Oujo8vUnwFLr-WkmYYfJwaGjmRsDy-q2Aq0vU4BlykA"",""2026-27!AF3"")"),0.0) -> 0 | BQ9: =IFERROR((BR9/BM9),"") | BR9: =IFERROR(__xludf.DUMMYFUNCTION("IMPORTRANGE(""1Oujo8vUnwFLr-WkmYYfJwaGjmRsDy-q2Aq0vU4BlykA"",""2026-27!AG4"")"),0.0) -> 0 | BS9: =IFERROR(__xludf.DUMMYFUNCTION("IMPORTRANGE(""1Oujo8vUnwFLr-WkmYYfJwaGjmRsDy-q2Aq0vU4BlykA"",""2026-27!AG3"")"),0.0) -> 0 | BT9: =IFERROR(__xludf.DUMMYFUNCTION("IMPORTRANGE(""1Oujo8vUnwFLr-WkmYYfJwaGjmRsDy-q2Aq0vU4BlykA"",""2026-27!AH4"")"),0.0) -> 0 | BU9: =IFERROR(__xludf.DUMMYFUNCTION("IMPORTRANGE(""1Oujo8vUnwFLr-WkmYYfJwaGjmRsDy-q2Aq0vU4BlykA"",""2026-27!AH3"")"),0.0) -> 0 | BV9: =IFERROR(__xludf.DUMMYFUNCTION("IMPORTRANGE(""1Oujo8vUnwFLr-WkmYYfJwaGjmRsDy-q2Aq0vU4BlykA"",""2026-27!AI4"")"),0.0) -> 0 | BW9: =IFERROR(__xludf.DUMMYFUNCTION("IMPORTRANGE(""1Oujo8vUnwFLr-WkmYYfJwaGjmRsDy-q2Aq0vU4BlykA"",""2026-27!AI3"")"),0.0) -> 0 | BX9: =IFERROR((BY9/BT9),"") | BY9: =IFERROR(__xludf.DUMMYFUNCTION("IMPORTRANGE(""1Oujo8vUnwFLr-WkmYYfJwaGjmRsDy-q2Aq0vU4BlykA"",""2026-27!AJ4"")"),0.0) -> 0 | BZ9: =IFERROR(__xludf.DUMMYFUNCTION("IMPORTRANGE(""1Oujo8vUnwFLr-WkmYYfJwaGjmRsDy-q2Aq0vU4BlykA"",""2026-27!AJ3"")"),0.0) -> 0 | CA9: =IFERROR(__xludf.DUMMYFUNCTION("IMPORTRANGE(""1Oujo8vUnwFLr-WkmYYfJwaGjmRsDy-q2Aq0vU4BlykA"",""2026-27!AK4"")"),0.0) -> 0 | CB9: =IFERROR(__xludf.DUMMYFUNCTION("IMPORTRANGE(""1Oujo8vUnwFLr-WkmYYfJwaGjmRsDy-q2Aq0vU4BlykA"",""2026-27!AK3"")"),0.0) -> 0 | CC9: =IFERROR(__xludf.DUMMYFUNCTION("IMPORTRANGE(""1Oujo8vUnwFLr-WkmYYfJwaGjmRsDy-q2Aq0vU4BlykA"",""2026-27!AL4"")"),0.0) -> 0 | CD9: =IFERROR(__xludf.DUMMYFUNCTION("IMPORTRANGE(""1Oujo8vUnwFLr-WkmYYfJwaGjmRsDy-q2Aq0vU4BlykA"",""2026-27!AL3"")"),0.0) -> 0 | CE9: =IFERROR((CF9/CA9),"") | CF9: =IFERROR(__xludf.DUMMYFUNCTION("IMPORTRANGE(""1Oujo8vUnwFLr-WkmYYfJwaGjmRsDy-q2Aq0vU4BlykA"",""2026-27!AM4"")"),0.0) -> 0 | CG9: =IFERROR(__xludf.DUMMYFUNCTION("IMPORTRANGE(""1Oujo8vUnwFLr-WkmYYfJwaGjmRsDy-q2Aq0vU4BlykA"",""2026-27!AM3"")"),0.0) -> 0 | CH9: =IFERROR(__xludf.DUMMYFUNCTION("IMPORTRANGE(""1Oujo8vUnwFLr-WkmYYfJwaGjmRsDy-q2Aq0vU4BlykA"",""2026-27!AN4"")"),0.0) -> 0 | CI9: =IFERROR(__xludf.DUMMYFUNCTION("IMPORTRANGE(""1Oujo8vUnwFLr-WkmYYfJwaGjmRsDy-q2Aq0vU4BlykA"",""2026-27!AN3"")"),0.0) -> 0 | CJ9: =IFERROR(__xludf.DUMMYFUNCTION("IMPORTRANGE(""1Oujo8vUnwFLr-WkmYYfJwaGjmRsDy-q2Aq0vU4BlykA"",""2026-27!AO4"")"),0.0) -> 0 | CK9: =IFERROR(__xludf.DUMMYFUNCTION("IMPORTRANGE(""1Oujo8vUnwFLr-WkmYYfJwaGjmRsDy-q2Aq0vU4BlykA"",""2026-27!AO3"")"),0.0) -> 0 | CL9: =IFERROR((CM9/CH9),"") | CM9: =IFERROR(__xludf.DUMMYFUNCTION("IMPORTRANGE(""1Oujo8vUnwFLr-WkmYYfJwaGjmRsDy-q2Aq0vU4BlykA"",""2026-27!AP4"")"),0.0) -> 0 | CN9: =IFERROR(__xludf.DUMMYFUNCTION("IMPORTRANGE(""1Oujo8vUnwFLr-WkmYYfJwaGjmRsDy-q2Aq0vU4BlykA"",""2026-27!AP3"")"),0.0) -> 0 | CO9: =IFERROR(__xludf.DUMMYFUNCTION("IMPORTRANGE(""1Oujo8vUnwFLr-WkmYYfJwaGjmRsDy-q2Aq0vU4BlykA"",""2026-27!AQ4"")"),0.0) -> 0 | CP9: =IFERROR(__xludf.DUMMYFUNCTION("IMPORTRANGE(""1Oujo8vUnwFLr-WkmYYfJwaGjmRsDy-q2Aq0vU4BlykA"",""2026-27!AQ3"")"),0.0) -> 0 | CQ9: =IFERROR(__xludf.DUMMYFUNCTION("IMPORTRANGE(""1Oujo8vUnwFLr-WkmYYfJwaGjmRsDy-q2Aq0vU4BlykA"",""2026-27!AR4"")"),0.0) -> 0 | CR9: =IFERROR(__xludf.DUMMYFUNCTION("IMPORTRANGE(""1Oujo8vUnwFLr-WkmYYfJwaGjmRsDy-q2Aq0vU4BlykA"",""2026-27!AR3"")"),0.0) -> 0 | CS9: =IFERROR((CT9/CO9),"") | CT9: =IFERROR(__xludf.DUMMYFUNCTION("IMPORTRANGE(""1Oujo8vUnwFLr-WkmYYfJwaGjmRsDy-q2Aq0vU4BlykA"",""2026-27!AS4"")"),0.0) -> 0 | CU9: =IFERROR(__xludf.DUMMYFUNCTION("IMPORTRANGE(""1Oujo8vUnwFLr-WkmYYfJwaGjmRsDy-q2Aq0vU4BlykA"",""2026-27!AS3"")"),0.0) -> 0
A10: Anant Singh | C10: Rinku | D10: Moradabad | E10: 6398490183 | F10: 45568 | I10: 30405 | J10: 1400000 | K10: =IFERROR(__xludf.DUMMYFUNCTION("IMPORTRANGE(""1LJGS53NCp-odxIXkmSORKxH8_UeQo5bY4expBVdkFdk"",""2026-27!A3"")"),34.0) -> 34 | L10: =IFERROR(__xludf.DUMMYFUNCTION("IMPORTRANGE(""1LJGS53NCp-odxIXkmSORKxH8_UeQo5bY4expBVdkFdk"",""2026-27!G4"")"),1.777E7) -> 17770000 | M10: =R10+Y10+AF10+AM10+AT10+BA10+BH10+BO10+BV10+CC10+CJ10+CQ10 -> 3015628 | N10: =iferror(O10/L10,"") -> 0.16270698 | O10: =U10+AB10+AI10+AP10+AW10+BD10+BK10+BR10+BY10+CF10+CM10+CT10 -> 2891303 | P10: =IFERROR(__xludf.DUMMYFUNCTION("IMPORTRANGE(""1LJGS53NCp-odxIXkmSORKxH8_UeQo5bY4expBVdkFdk"",""2026-27!J4"")"),1328000.0) -> 1328000 | Q10: =IFERROR(__xludf.DUMMYFUNCTION("IMPORTRANGE(""1LJGS53NCp-odxIXkmSORKxH8_UeQo5bY4expBVdkFdk"",""2026-27!J3"")"),27.0) -> 27 | R10: =IFERROR(__xludf.DUMMYFUNCTION("IMPORTRANGE(""1LJGS53NCp-odxIXkmSORKxH8_UeQo5bY4expBVdkFdk"",""2026-27!K4"")"),674641.1099999999) -> 674641.11 | S10: =IFERROR(__xludf.DUMMYFUNCTION("IMPORTRANGE(""1LJGS53NCp-odxIXkmSORKxH8_UeQo5bY4expBVdkFdk"",""2026-27!K3"")"),10.0) -> 10 | T10: =IFERROR((U10/P10),"") -> 0.45152259 | U10: =IFERROR(__xludf.DUMMYFUNCTION("IMPORTRANGE(""1LJGS53NCp-odxIXkmSORKxH8_UeQo5bY4expBVdkFdk"",""2026-27!L4"")"),599622.0) -> 599622 | V10: =IFERROR(__xludf.DUMMYFUNCTION("IMPORTRANGE(""1LJGS53NCp-odxIXkmSORKxH8_UeQo5bY4expBVdkFdk"",""2026-27!L3"")"),8.0) -> 8 | W10: =IFERROR(__xludf.DUMMYFUNCTION("IMPORTRANGE(""1LJGS53NCp-odxIXkmSORKxH8_UeQo5bY4expBVdkFdk"",""2026-27!m4"")"),1590000.0) -> 1590000 | X10: =IFERROR(__xludf.DUMMYFUNCTION("IMPORTRANGE(""1LJGS53NCp-odxIXkmSORKxH8_UeQo5bY4expBVdkFdk"",""2026-27!m3"")"),29.0) -> 29 | Y10: =IFERROR(__xludf.DUMMYFUNCTION("IMPORTRANGE(""1LJGS53NCp-odxIXkmSORKxH8_UeQo5bY4expBVdkFdk"",""2026-27!N4"")"),1241551.0799999998) -> 1241551.1 | Z10: =IFERROR(__xludf.DUMMYFUNCTION("IMPORTRANGE(""1LJGS53NCp-odxIXkmSORKxH8_UeQo5bY4expBVdkFdk"",""2026-27!N3"")"),17.0) -> 17 | AA10: =IFERROR((AB10/W10),"") -> 0.75457736 | AB10: =IFERROR(__xludf.DUMMYFUNCTION("IMPORTRANGE(""1LJGS53NCp-odxIXkmSORKxH8_UeQo5bY4expBVdkFdk"",""2026-27!O4"")"),1199778.0) -> 1199778 | AC10: =IFERROR(__xludf.DUMMYFUNCTION("IMPORTRANGE(""1LJGS53NCp-odxIXkmSORKxH8_UeQo5bY4expBVdkFdk"",""2026-27!O3"")"),17.0) -> 17 | AD10: =IFERROR(__xludf.DUMMYFUNCTION("IMPORTRANGE(""1LJGS53NCp-odxIXkmSORKxH8_UeQo5bY4expBVdkFdk"",""2026-27!P4"")"),1612000.0) -> 1612000 | AE10: =IFERROR(__xludf.DUMMYFUNCTION("IMPORTRANGE(""1LJGS53NCp-odxIXkmSORKxH8_UeQo5bY4expBVdkFdk"",""2026-27!P3"")"),29.0) -> 29 | AF10: =IFERROR(__xludf.DUMMYFUNCTION("IMPORTRANGE(""1LJGS53NCp-odxIXkmSORKxH8_UeQo5bY4expBVdkFdk"",""2026-27!Q4"")"),1099435.76) -> 1099435.8 | AG10: =IFERROR(__xludf.DUMMYFUNCTION("IMPORTRANGE(""1LJGS53NCp-odxIXkmSORKxH8_UeQo5bY4expBVdkFdk"",""2026-27!Q3"")"),20.0) -> 20 | AH10: =IFERROR((AI10/AD10),"") -> 0.67735918 | AI10: =IFERROR(__xludf.DUMMYFUNCTION("IMPORTRANGE(""1LJGS53NCp-odxIXkmSORKxH8_UeQo5bY4expBVdkFdk"",""2026-27!R4"")"),1091903.0) -> 1091903 | AJ10: =IFERROR(__xludf.DUMMYFUNCTION("IMPORTRANGE(""1LJGS53NCp-odxIXkmSORKxH8_UeQo5bY4expBVdkFdk"",""2026-27!R3"")"),20.0) -> 20 | AK10: =IFERROR(__xludf.DUMMYFUNCTION("IMPORTRANGE(""1LJGS53NCp-odxIXkmSORKxH8_UeQo5bY4expBVdkFdk"",""2026-27!S4"")"),1405000.0) -> 1405000 | AL10: =IFERROR(__xludf.DUMMYFUNCTION("IMPORTRANGE(""1LJGS53NCp-odxIXkmSORKxH8_UeQo5bY4expBVdkFdk"",""2026-27!S3"")"),30.0) -> 30 | AM10: =IFERROR(__xludf.DUMMYFUNCTION("IMPORTRANGE(""1LJGS53NCp-odxIXkmSORKxH8_UeQo5bY4expBVdkFdk"",""2026-27!T4"")"),0.0) -> 0 | AN10: =IFERROR(__xludf.DUMMYFUNCTION("IMPORTRANGE(""1LJGS53NCp-odxIXkmSORKxH8_UeQo5bY4expBVdkFdk"",""2026-27!T3"")"),0.0) -> 0 | AO10: =IFERROR((AP10/AK10),"") -> 0 | AP10: =IFERROR(__xludf.DUMMYFUNCTION("IMPORTRANGE(""1LJGS53NCp-odxIXkmSORKxH8_UeQo5bY4expBVdkFdk"",""2026-27!U4"")"),0.0) -> 0 | AQ10: =IFERROR(__xludf.DUMMYFUNCTION("IMPORTRANGE(""1LJGS53NCp-odxIXkmSORKxH8_UeQo5bY4expBVdkFdk"",""2026-27!U3"")"),0.0) -> 0 | AR10: =IFERROR(__xludf.DUMMYFUNCTION("IMPORTRANGE(""1LJGS53NCp-odxIXkmSORKxH8_UeQo5bY4expBVdkFdk"",""2026-27!V4"")"),1420000.0) -> 1420000 | AS10: =IFERROR(__xludf.DUMMYFUNCTION("IMPORTRANGE(""1LJGS53NCp-odxIXkmSORKxH8_UeQo5bY4expBVdkFdk"",""2026-27!V3"")"),30.0) -> 30 | AT10: =IFERROR(__xludf.DUMMYFUNCTION("IMPORTRANGE(""1LJGS53NCp-odxIXkmSORKxH8_UeQo5bY4expBVdkFdk"",""2026-27!W4"")"),0.0) -> 0 | AU10: =IFERROR(__xludf.DUMMYFUNCTION("IMPORTRANGE(""1LJGS53NCp-odxIXkmSORKxH8_UeQo5bY4expBVdkFdk"",""2026-27!W3"")"),0.0) -> 0 | AV10: =IFERROR((AW10/AR10),"") -> 0 | AW10: =IFERROR(__xludf.DUMMYFUNCTION("IMPORTRANGE(""1LJGS53NCp-odxIXkmSORKxH8_UeQo5bY4expBVdkFdk"",""2026-27!X4"")"),0.0) -> 0 | AX10: =IFERROR(__xludf.DUMMYFUNCTION("IMPORTRANGE(""1LJGS53NCp-odxIXkmSORKxH8_UeQo5bY4expBVdkFdk"",""2026-27!X3"")"),0.0) -> 0 | AY10: =IFERROR(__xludf.DUMMYFUNCTION("IMPORTRANGE(""1LJGS53NCp-odxIXkmSORKxH8_UeQo5bY4expBVdkFdk"",""2026-27!Y4"")"),0.0) -> 0 | AZ10: =IFERROR(__xludf.DUMMYFUNCTION("IMPORTRANGE(""1LJGS53NCp-odxIXkmSORKxH8_UeQo5bY4expBVdkFdk"",""2026-27!Y3"")"),0.0) -> 0 | BA10: =IFERROR(__xludf.DUMMYFUNCTION("IMPORTRANGE(""1LJGS53NCp-odxIXkmSORKxH8_UeQo5bY4expBVdkFdk"",""2026-27!Z4"")"),0.0) -> 0 | BB10: =IFERROR(__xludf.DUMMYFUNCTION("IMPORTRANGE(""1LJGS53NCp-odxIXkmSORKxH8_UeQo5bY4expBVdkFdk"",""2026-27!Z3"")"),0.0) -> 0 | BC10: =IFERROR((BD10/AY10),"") | BD10: =IFERROR(__xludf.DUMMYFUNCTION("IMPORTRANGE(""1LJGS53NCp-odxIXkmSORKxH8_UeQo5bY4expBVdkFdk"",""2026-27!AA4"")"),0.0) -> 0 | BE10: =IFERROR(__xludf.DUMMYFUNCTION("IMPORTRANGE(""1LJGS53NCp-odxIXkmSORKxH8_UeQo5bY4expBVdkFdk"",""2026-27!AA3"")"),0.0) -> 0 | BF10: =IFERROR(__xludf.DUMMYFUNCTION("IMPORTRANGE(""1LJGS53NCp-odxIXkmSORKxH8_UeQo5bY4expBVdkFdk"",""2026-27!AB4"")"),0.0) -> 0 | BG10: =IFERROR(__xludf.DUMMYFUNCTION("IMPORTRANGE(""1LJGS53NCp-odxIXkmSORKxH8_UeQo5bY4expBVdkFdk"",""2026-27!AB3"")"),0.0) -> 0 | BH10: =IFERROR(__xludf.DUMMYFUNCTION("IMPORTRANGE(""1LJGS53NCp-odxIXkmSORKxH8_UeQo5bY4expBVdkFdk"",""2026-27!AC4"")"),0.0) -> 0 | BI10: =IFERROR(__xludf.DUMMYFUNCTION("IMPORTRANGE(""1LJGS53NCp-odxIXkmSORKxH8_UeQo5bY4expBVdkFdk"",""2026-27!AC3"")"),0.0) -> 0 | BJ10: =IFERROR((BK10/BF10),"") | BK10: =IFERROR(__xludf.DUMMYFUNCTION("IMPORTRANGE(""1LJGS53NCp-odxIXkmSORKxH8_UeQo5bY4expBVdkFdk"",""2026-27!AD4"")"),0.0) -> 0 | BL10: =IFERROR(__xludf.DUMMYFUNCTION("IMPORTRANGE(""1LJGS53NCp-odxIXkmSORKxH8_UeQo5bY4expBVdkFdk"",""2026-27!AD3"")"),0.0) -> 0 | BM10: =IFERROR(__xludf.DUMMYFUNCTION("IMPORTRANGE(""1LJGS53NCp-odxIXkmSORKxH8_UeQo5bY4expBVdkFdk"",""2026-27!AE4"")"),0.0) -> 0 | BN10: =IFERROR(__xludf.DUMMYFUNCTION("IMPORTRANGE(""1LJGS53NCp-odxIXkmSORKxH8_UeQo5bY4expBVdkFdk"",""2026-27!AE3"")"),0.0) -> 0 | BO10: =IFERROR(__xludf.DUMMYFUNCTION("IMPORTRANGE(""1LJGS53NCp-odxIXkmSORKxH8_UeQo5bY4expBVdkFdk"",""2026-27!AF4"")"),0.0) -> 0 | BP10: =IFERROR(__xludf.DUMMYFUNCTION("IMPORTRANGE(""1LJGS53NCp-odxIXkmSORKxH8_UeQo5bY4expBVdkFdk"",""2026-27!AF3"")"),0.0) -> 0 | BQ10: =IFERROR((BR10/BM10),"") | BR10: =IFERROR(__xludf.DUMMYFUNCTION("IMPORTRANGE(""1LJGS53NCp-odxIXkmSORKxH8_UeQo5bY4expBVdkFdk"",""2026-27!AG4"")"),0.0) -> 0 | BS10: =IFERROR(__xludf.DUMMYFUNCTION("IMPORTRANGE(""1LJGS53NCp-odxIXkmSORKxH8_UeQo5bY4expBVdkFdk"",""2026-27!AG3"")"),0.0) -> 0 | BT10: =IFERROR(__xludf.DUMMYFUNCTION("IMPORTRANGE(""1LJGS53NCp-odxIXkmSORKxH8_UeQo5bY4expBVdkFdk"",""2026-27!AH4"")"),0.0) -> 0 | BU10: =IFERROR(__xludf.DUMMYFUNCTION("IMPORTRANGE(""1LJGS53NCp-odxIXkmSORKxH8_UeQo5bY4expBVdkFdk"",""2026-27!AH3"")"),0.0) -> 0 | BV10: =IFERROR(__xludf.DUMMYFUNCTION("IMPORTRANGE(""1LJGS53NCp-odxIXkmSORKxH8_UeQo5bY4expBVdkFdk"",""2026-27!AI4"")"),0.0) -> 0 | BW10: =IFERROR(__xludf.DUMMYFUNCTION("IMPORTRANGE(""1LJGS53NCp-odxIXkmSORKxH8_UeQo5bY4expBVdkFdk"",""2026-27!AI3"")"),0.0) -> 0 | BX10: =IFERROR((BY10/BT10),"") | BY10: =IFERROR(__xludf.DUMMYFUNCTION("IMPORTRANGE(""1LJGS53NCp-odxIXkmSORKxH8_UeQo5bY4expBVdkFdk"",""2026-27!AJ4"")"),0.0) -> 0 | BZ10: =IFERROR(__xludf.DUMMYFUNCTION("IMPORTRANGE(""1LJGS53NCp-odxIXkmSORKxH8_UeQo5bY4expBVdkFdk"",""2026-27!AJ3"")"),0.0) -> 0 | CA10: =IFERROR(__xludf.DUMMYFUNCTION("IMPORTRANGE(""1LJGS53NCp-odxIXkmSORKxH8_UeQo5bY4expBVdkFdk"",""2026-27!AK4"")"),0.0) -> 0 | CB10: =IFERROR(__xludf.DUMMYFUNCTION("IMPORTRANGE(""1LJGS53NCp-odxIXkmSORKxH8_UeQo5bY4expBVdkFdk"",""2026-27!AK3"")"),0.0) -> 0 | CC10: =IFERROR(__xludf.DUMMYFUNCTION("IMPORTRANGE(""1LJGS53NCp-odxIXkmSORKxH8_UeQo5bY4expBVdkFdk"",""2026-27!AL4"")"),0.0) -> 0 | CD10: =IFERROR(__xludf.DUMMYFUNCTION("IMPORTRANGE(""1LJGS53NCp-odxIXkmSORKxH8_UeQo5bY4expBVdkFdk"",""2026-27!AL3"")"),0.0) -> 0 | CE10: =IFERROR((CF10/CA10),"") | CF10: =IFERROR(__xludf.DUMMYFUNCTION("IMPORTRANGE(""1LJGS53NCp-odxIXkmSORKxH8_UeQo5bY4expBVdkFdk"",""2026-27!AM4"")"),0.0) -> 0 | CG10: =IFERROR(__xludf.DUMMYFUNCTION("IMPORTRANGE(""1LJGS53NCp-odxIXkmSORKxH8_UeQo5bY4expBVdkFdk"",""2026-27!AM3"")"),0.0) -> 0 | CH10: =IFERROR(__xludf.DUMMYFUNCTION("IMPORTRANGE(""1LJGS53NCp-odxIXkmSORKxH8_UeQo5bY4expBVdkFdk"",""2026-27!AN4"")"),0.0) -> 0 | CI10: =IFERROR(__xludf.DUMMYFUNCTION("IMPORTRANGE(""1LJGS53NCp-odxIXkmSORKxH8_UeQo5bY4expBVdkFdk"",""2026-27!AN3"")"),0.0) -> 0 | CJ10: =IFERROR(__xludf.DUMMYFUNCTION("IMPORTRANGE(""1LJGS53NCp-odxIXkmSORKxH8_UeQo5bY4expBVdkFdk"",""2026-27!AO4"")"),0.0) -> 0 | CK10: =IFERROR(__xludf.DUMMYFUNCTION("IMPORTRANGE(""1LJGS53NCp-odxIXkmSORKxH8_UeQo5bY4expBVdkFdk"",""2026-27!AO3"")"),0.0) -> 0 | CL10: =IFERROR((CM10/CH10),"") | CM10: =IFERROR(__xludf.DUMMYFUNCTION("IMPORTRANGE(""1LJGS53NCp-odxIXkmSORKxH8_UeQo5bY4expBVdkFdk"",""2026-27!AP4"")"),0.0) -> 0 | CN10: =IFERROR(__xludf.DUMMYFUNCTION("IMPORTRANGE(""1LJGS53NCp-odxIXkmSORKxH8_UeQo5bY4expBVdkFdk"",""2026-27!AP3"")"),0.0) -> 0 | CO10: =IFERROR(__xludf.DUMMYFUNCTION("IMPORTRANGE(""1LJGS53NCp-odxIXkmSORKxH8_UeQo5bY4expBVdkFdk"",""2026-27!AQ4"")"),0.0) -> 0 | CP10: =IFERROR(__xludf.DUMMYFUNCTION("IMPORTRANGE(""1LJGS53NCp-odxIXkmSORKxH8_UeQo5bY4expBVdkFdk"",""2026-27!AQ3"")"),0.0) -> 0 | CQ10: =IFERROR(__xludf.DUMMYFUNCTION("IMPORTRANGE(""1LJGS53NCp-odxIXkmSORKxH8_UeQo5bY4expBVdkFdk"",""2026-27!AR4"")"),0.0) -> 0 | CR10: =IFERROR(__xludf.DUMMYFUNCTION("IMPORTRANGE(""1LJGS53NCp-odxIXkmSORKxH8_UeQo5bY4expBVdkFdk"",""2026-27!AR3"")"),0.0) -> 0 | CS10: =IFERROR((CT10/CO10),"") | CT10: =IFERROR(__xludf.DUMMYFUNCTION("IMPORTRANGE(""1LJGS53NCp-odxIXkmSORKxH8_UeQo5bY4expBVdkFdk"",""2026-27!AS4"")"),0.0) -> 0 | CU10: =IFERROR(__xludf.DUMMYFUNCTION("IMPORTRANGE(""1LJGS53NCp-odxIXkmSORKxH8_UeQo5bY4expBVdkFdk"",""2026-27!AS3"")"),0.0) -> 0
A11: Anant Singh | C11: Ashutosh Kumar (Rudrapur) | D11: Rudrapur | E11: 9319865478 | F11: 45658 | I11: 31455 | J11: 1400000 | K11: =IFERROR(__xludf.DUMMYFUNCTION("IMPORTRANGE(""13EYfcAewqPPQ83PA3ta2L46h2GIwi9k-mw8zx8HuEws"",""2026-27!A3"")"),100.0) -> 100 | L11: =IFERROR(__xludf.DUMMYFUNCTION("IMPORTRANGE(""13EYfcAewqPPQ83PA3ta2L46h2GIwi9k-mw8zx8HuEws"",""2026-27!G4"")"),1.735E7) -> 17350000 | M11: =R11+Y11+AF11+AM11+AT11+BA11+BH11+BO11+BV11+CC11+CJ11+CQ11 -> 2124687.9 | N11: =iferror(O11/L11,"") -> 0.13429297 | O11: =U11+AB11+AI11+AP11+AW11+BD11+BK11+BR11+BY11+CF11+CM11+CT11 -> 2329983 | P11: =IFERROR(__xludf.DUMMYFUNCTION("IMPORTRANGE(""13EYfcAewqPPQ83PA3ta2L46h2GIwi9k-mw8zx8HuEws"",""2026-27!J4"")"),1500000.0) -> 1500000 | Q11: =IFERROR(__xludf.DUMMYFUNCTION("IMPORTRANGE(""13EYfcAewqPPQ83PA3ta2L46h2GIwi9k-mw8zx8HuEws"",""2026-27!J3"")"),86.0) -> 86 | R11: =IFERROR(__xludf.DUMMYFUNCTION("IMPORTRANGE(""13EYfcAewqPPQ83PA3ta2L46h2GIwi9k-mw8zx8HuEws"",""2026-27!K4"")"),231251.31999999998) -> 231251.32 | S11: =IFERROR(__xludf.DUMMYFUNCTION("IMPORTRANGE(""13EYfcAewqPPQ83PA3ta2L46h2GIwi9k-mw8zx8HuEws"",""2026-27!K3"")"),15.0) -> 15 | T11: =IFERROR((U11/P11),"") -> 0.17681 | U11: =IFERROR(__xludf.DUMMYFUNCTION("IMPORTRANGE(""13EYfcAewqPPQ83PA3ta2L46h2GIwi9k-mw8zx8HuEws"",""2026-27!L4"")"),265215.0) -> 265215 | V11: =IFERROR(__xludf.DUMMYFUNCTION("IMPORTRANGE(""13EYfcAewqPPQ83PA3ta2L46h2GIwi9k-mw8zx8HuEws"",""2026-27!L3"")"),17.0) -> 17 | W11: =IFERROR(__xludf.DUMMYFUNCTION("IMPORTRANGE(""13EYfcAewqPPQ83PA3ta2L46h2GIwi9k-mw8zx8HuEws"",""2026-27!m4"")"),1425000.0) -> 1425000 | X11: =IFERROR(__xludf.DUMMYFUNCTION("IMPORTRANGE(""13EYfcAewqPPQ83PA3ta2L46h2GIwi9k-mw8zx8HuEws"",""2026-27!m3"")"),86.0) -> 86 | Y11: =IFERROR(__xludf.DUMMYFUNCTION("IMPORTRANGE(""13EYfcAewqPPQ83PA3ta2L46h2GIwi9k-mw8zx8HuEws"",""2026-27!N4"")"),1088919.99) -> 1088920 | Z11: =IFERROR(__xludf.DUMMYFUNCTION("IMPORTRANGE(""13EYfcAewqPPQ83PA3ta2L46h2GIwi9k-mw8zx8HuEws"",""2026-27!N3"")"),22.0) -> 22 | AA11: =IFERROR((AB11/W11),"") -> 0.85945754 | AB11: =IFERROR(__xludf.DUMMYFUNCTION("IMPORTRANGE(""13EYfcAewqPPQ83PA3ta2L46h2GIwi9k-mw8zx8HuEws"",""2026-27!O4"")"),1224727.0) -> 1224727 | AC11: =IFERROR(__xludf.DUMMYFUNCTION("IMPORTRANGE(""13EYfcAewqPPQ83PA3ta2L46h2GIwi9k-mw8zx8HuEws"",""2026-27!O3"")"),22.0) -> 22 | AD11: =IFERROR(__xludf.DUMMYFUNCTION("IMPORTRANGE(""13EYfcAewqPPQ83PA3ta2L46h2GIwi9k-mw8zx8HuEws"",""2026-27!P4"")"),1400000.0) -> 1400000 | AE11: =IFERROR(__xludf.DUMMYFUNCTION("IMPORTRANGE(""13EYfcAewqPPQ83PA3ta2L46h2GIwi9k-mw8zx8HuEws"",""2026-27!P3"")"),95.0) -> 95 | AF11: =IFERROR(__xludf.DUMMYFUNCTION("IMPORTRANGE(""13EYfcAewqPPQ83PA3ta2L46h2GIwi9k-mw8zx8HuEws"",""2026-27!Q4"")"),804516.6100000001) -> 804516.61 | AG11: =IFERROR(__xludf.DUMMYFUNCTION("IMPORTRANGE(""13EYfcAewqPPQ83PA3ta2L46h2GIwi9k-mw8zx8HuEws"",""2026-27!Q3"")"),23.0) -> 23 | AH11: =IFERROR((AI11/AD11),"") -> 0.60002929 | AI11: =IFERROR(__xludf.DUMMYFUNCTION("IMPORTRANGE(""13EYfcAewqPPQ83PA3ta2L46h2GIwi9k-mw8zx8HuEws"",""2026-27!R4"")"),840041.0) -> 840041 | AJ11: =IFERROR(__xludf.DUMMYFUNCTION("IMPORTRANGE(""13EYfcAewqPPQ83PA3ta2L46h2GIwi9k-mw8zx8HuEws"",""2026-27!R3"")"),24.0) -> 24 | AK11: =IFERROR(__xludf.DUMMYFUNCTION("IMPORTRANGE(""13EYfcAewqPPQ83PA3ta2L46h2GIwi9k-mw8zx8HuEws"",""2026-27!S4"")"),0.0) -> 0 | AL11: =IFERROR(__xludf.DUMMYFUNCTION("IMPORTRANGE(""13EYfcAewqPPQ83PA3ta2L46h2GIwi9k-mw8zx8HuEws"",""2026-27!S3"")"),0.0) -> 0 | AM11: =IFERROR(__xludf.DUMMYFUNCTION("IMPORTRANGE(""13EYfcAewqPPQ83PA3ta2L46h2GIwi9k-mw8zx8HuEws"",""2026-27!T4"")"),0.0) -> 0 | AN11: =IFERROR(__xludf.DUMMYFUNCTION("IMPORTRANGE(""13EYfcAewqPPQ83PA3ta2L46h2GIwi9k-mw8zx8HuEws"",""2026-27!T3"")"),0.0) -> 0 | AO11: =IFERROR((AP11/AK11),"") | AP11: =IFERROR(__xludf.DUMMYFUNCTION("IMPORTRANGE(""13EYfcAewqPPQ83PA3ta2L46h2GIwi9k-mw8zx8HuEws"",""2026-27!U4"")"),0.0) -> 0 | AQ11: =IFERROR(__xludf.DUMMYFUNCTION("IMPORTRANGE(""13EYfcAewqPPQ83PA3ta2L46h2GIwi9k-mw8zx8HuEws"",""2026-27!U3"")"),0.0) -> 0 | AR11: =IFERROR(__xludf.DUMMYFUNCTION("IMPORTRANGE(""13EYfcAewqPPQ83PA3ta2L46h2GIwi9k-mw8zx8HuEws"",""2026-27!V4"")"),0.0) -> 0 | AS11: =IFERROR(__xludf.DUMMYFUNCTION("IMPORTRANGE(""13EYfcAewqPPQ83PA3ta2L46h2GIwi9k-mw8zx8HuEws"",""2026-27!V3"")"),0.0) -> 0 | AT11: =IFERROR(__xludf.DUMMYFUNCTION("IMPORTRANGE(""13EYfcAewqPPQ83PA3ta2L46h2GIwi9k-mw8zx8HuEws"",""2026-27!W4"")"),0.0) -> 0 | AU11: =IFERROR(__xludf.DUMMYFUNCTION("IMPORTRANGE(""13EYfcAewqPPQ83PA3ta2L46h2GIwi9k-mw8zx8HuEws"",""2026-27!W3"")"),0.0) -> 0 | AV11: =IFERROR((AW11/AR11),"") | AW11: =IFERROR(__xludf.DUMMYFUNCTION("IMPORTRANGE(""13EYfcAewqPPQ83PA3ta2L46h2GIwi9k-mw8zx8HuEws"",""2026-27!X4"")"),0.0) -> 0 | AX11: =IFERROR(__xludf.DUMMYFUNCTION("IMPORTRANGE(""13EYfcAewqPPQ83PA3ta2L46h2GIwi9k-mw8zx8HuEws"",""2026-27!X3"")"),0.0) -> 0 | AY11: =IFERROR(__xludf.DUMMYFUNCTION("IMPORTRANGE(""13EYfcAewqPPQ83PA3ta2L46h2GIwi9k-mw8zx8HuEws"",""2026-27!Y4"")"),0.0) -> 0 | AZ11: =IFERROR(__xludf.DUMMYFUNCTION("IMPORTRANGE(""13EYfcAewqPPQ83PA3ta2L46h2GIwi9k-mw8zx8HuEws"",""2026-27!Y3"")"),0.0) -> 0 | BA11: =IFERROR(__xludf.DUMMYFUNCTION("IMPORTRANGE(""13EYfcAewqPPQ83PA3ta2L46h2GIwi9k-mw8zx8HuEws"",""2026-27!Z4"")"),0.0) -> 0 | BB11: =IFERROR(__xludf.DUMMYFUNCTION("IMPORTRANGE(""13EYfcAewqPPQ83PA3ta2L46h2GIwi9k-mw8zx8HuEws"",""2026-27!Z3"")"),0.0) -> 0 | BC11: =IFERROR((BD11/AY11),"") | BD11: =IFERROR(__xludf.DUMMYFUNCTION("IMPORTRANGE(""13EYfcAewqPPQ83PA3ta2L46h2GIwi9k-mw8zx8HuEws"",""2026-27!AA4"")"),0.0) -> 0 | BE11: =IFERROR(__xludf.DUMMYFUNCTION("IMPORTRANGE(""13EYfcAewqPPQ83PA3ta2L46h2GIwi9k-mw8zx8HuEws"",""2026-27!AA3"")"),0.0) -> 0 | BF11: =IFERROR(__xludf.DUMMYFUNCTION("IMPORTRANGE(""13EYfcAewqPPQ83PA3ta2L46h2GIwi9k-mw8zx8HuEws"",""2026-27!AB4"")"),0.0) -> 0 | BG11: =IFERROR(__xludf.DUMMYFUNCTION("IMPORTRANGE(""13EYfcAewqPPQ83PA3ta2L46h2GIwi9k-mw8zx8HuEws"",""2026-27!AB3"")"),0.0) -> 0 | BH11: =IFERROR(__xludf.DUMMYFUNCTION("IMPORTRANGE(""13EYfcAewqPPQ83PA3ta2L46h2GIwi9k-mw8zx8HuEws"",""2026-27!AC4"")"),0.0) -> 0 | BI11: =IFERROR(__xludf.DUMMYFUNCTION("IMPORTRANGE(""13EYfcAewqPPQ83PA3ta2L46h2GIwi9k-mw8zx8HuEws"",""2026-27!AC3"")"),0.0) -> 0 | BJ11: =IFERROR((BK11/BF11),"") | BK11: =IFERROR(__xludf.DUMMYFUNCTION("IMPORTRANGE(""13EYfcAewqPPQ83PA3ta2L46h2GIwi9k-mw8zx8HuEws"",""2026-27!AD4"")"),0.0) -> 0 | BL11: =IFERROR(__xludf.DUMMYFUNCTION("IMPORTRANGE(""13EYfcAewqPPQ83PA3ta2L46h2GIwi9k-mw8zx8HuEws"",""2026-27!AD3"")"),0.0) -> 0 | BM11: =IFERROR(__xludf.DUMMYFUNCTION("IMPORTRANGE(""13EYfcAewqPPQ83PA3ta2L46h2GIwi9k-mw8zx8HuEws"",""2026-27!AE4"")"),0.0) -> 0 | BN11: =IFERROR(__xludf.DUMMYFUNCTION("IMPORTRANGE(""13EYfcAewqPPQ83PA3ta2L46h2GIwi9k-mw8zx8HuEws"",""2026-27!AE3"")"),0.0) -> 0 | BO11: =IFERROR(__xludf.DUMMYFUNCTION("IMPORTRANGE(""13EYfcAewqPPQ83PA3ta2L46h2GIwi9k-mw8zx8HuEws"",""2026-27!AF4"")"),0.0) -> 0 | BP11: =IFERROR(__xludf.DUMMYFUNCTION("IMPORTRANGE(""13EYfcAewqPPQ83PA3ta2L46h2GIwi9k-mw8zx8HuEws"",""2026-27!AF3"")"),0.0) -> 0 | BQ11: =IFERROR((BR11/BM11),"") | BR11: =IFERROR(__xludf.DUMMYFUNCTION("IMPORTRANGE(""13EYfcAewqPPQ83PA3ta2L46h2GIwi9k-mw8zx8HuEws"",""2026-27!AG4"")"),0.0) -> 0 | BS11: =IFERROR(__xludf.DUMMYFUNCTION("IMPORTRANGE(""13EYfcAewqPPQ83PA3ta2L46h2GIwi9k-mw8zx8HuEws"",""2026-27!AG3"")"),0.0) -> 0 | BT11: =IFERROR(__xludf.DUMMYFUNCTION("IMPORTRANGE(""13EYfcAewqPPQ83PA3ta2L46h2GIwi9k-mw8zx8HuEws"",""2026-27!AH4"")"),0.0) -> 0 | BU11: =IFERROR(__xludf.DUMMYFUNCTION("IMPORTRANGE(""13EYfcAewqPPQ83PA3ta2L46h2GIwi9k-mw8zx8HuEws"",""2026-27!AH3"")"),0.0) -> 0 | BV11: =IFERROR(__xludf.DUMMYFUNCTION("IMPORTRANGE(""13EYfcAewqPPQ83PA3ta2L46h2GIwi9k-mw8zx8HuEws"",""2026-27!AI4"")"),0.0) -> 0 | BW11: =IFERROR(__xludf.DUMMYFUNCTION("IMPORTRANGE(""13EYfcAewqPPQ83PA3ta2L46h2GIwi9k-mw8zx8HuEws"",""2026-27!AI3"")"),0.0) -> 0 | BX11: =IFERROR((BY11/BT11),"") | BY11: =IFERROR(__xludf.DUMMYFUNCTION("IMPORTRANGE(""13EYfcAewqPPQ83PA3ta2L46h2GIwi9k-mw8zx8HuEws"",""2026-27!AJ4"")"),0.0) -> 0 | BZ11: =IFERROR(__xludf.DUMMYFUNCTION("IMPORTRANGE(""13EYfcAewqPPQ83PA3ta2L46h2GIwi9k-mw8zx8HuEws"",""2026-27!AJ3"")"),0.0) -> 0 | CA11: =IFERROR(__xludf.DUMMYFUNCTION("IMPORTRANGE(""13EYfcAewqPPQ83PA3ta2L46h2GIwi9k-mw8zx8HuEws"",""2026-27!AK4"")"),0.0) -> 0 | CB11: =IFERROR(__xludf.DUMMYFUNCTION("IMPORTRANGE(""13EYfcAewqPPQ83PA3ta2L46h2GIwi9k-mw8zx8HuEws"",""2026-27!AK3"")"),0.0) -> 0 | CC11: =IFERROR(__xludf.DUMMYFUNCTION("IMPORTRANGE(""13EYfcAewqPPQ83PA3ta2L46h2GIwi9k-mw8zx8HuEws"",""2026-27!AL4"")"),0.0) -> 0 | CD11: =IFERROR(__xludf.DUMMYFUNCTION("IMPORTRANGE(""13EYfcAewqPPQ83PA3ta2L46h2GIwi9k-mw8zx8HuEws"",""2026-27!AL3"")"),0.0) -> 0 | CE11: =IFERROR((CF11/CA11),"") | CF11: =IFERROR(__xludf.DUMMYFUNCTION("IMPORTRANGE(""13EYfcAewqPPQ83PA3ta2L46h2GIwi9k-mw8zx8HuEws"",""2026-27!AM4"")"),0.0) -> 0 | CG11: =IFERROR(__xludf.DUMMYFUNCTION("IMPORTRANGE(""13EYfcAewqPPQ83PA3ta2L46h2GIwi9k-mw8zx8HuEws"",""2026-27!AM3"")"),0.0) -> 0 | CH11: =IFERROR(__xludf.DUMMYFUNCTION("IMPORTRANGE(""13EYfcAewqPPQ83PA3ta2L46h2GIwi9k-mw8zx8HuEws"",""2026-27!AN4"")"),0.0) -> 0 | CI11: =IFERROR(__xludf.DUMMYFUNCTION("IMPORTRANGE(""13EYfcAewqPPQ83PA3ta2L46h2GIwi9k-mw8zx8HuEws"",""2026-27!AN3"")"),0.0) -> 0 | CJ11: =IFERROR(__xludf.DUMMYFUNCTION("IMPORTRANGE(""13EYfcAewqPPQ83PA3ta2L46h2GIwi9k-mw8zx8HuEws"",""2026-27!AO4"")"),0.0) -> 0 | CK11: =IFERROR(__xludf.DUMMYFUNCTION("IMPORTRANGE(""13EYfcAewqPPQ83PA3ta2L46h2GIwi9k-mw8zx8HuEws"",""2026-27!AO3"")"),0.0) -> 0 | CL11: =IFERROR((CM11/CH11),"") | CM11: =IFERROR(__xludf.DUMMYFUNCTION("IMPORTRANGE(""13EYfcAewqPPQ83PA3ta2L46h2GIwi9k-mw8zx8HuEws"",""2026-27!AP4"")"),0.0) -> 0 | CN11: =IFERROR(__xludf.DUMMYFUNCTION("IMPORTRANGE(""13EYfcAewqPPQ83PA3ta2L46h2GIwi9k-mw8zx8HuEws"",""2026-27!AP3"")"),0.0) -> 0 | CO11: =IFERROR(__xludf.DUMMYFUNCTION("IMPORTRANGE(""13EYfcAewqPPQ83PA3ta2L46h2GIwi9k-mw8zx8HuEws"",""2026-27!AQ4"")"),0.0) -> 0 | CP11: =IFERROR(__xludf.DUMMYFUNCTION("IMPORTRANGE(""13EYfcAewqPPQ83PA3ta2L46h2GIwi9k-mw8zx8HuEws"",""2026-27!AQ3"")"),0.0) -> 0 | CQ11: =IFERROR(__xludf.DUMMYFUNCTION("IMPORTRANGE(""13EYfcAewqPPQ83PA3ta2L46h2GIwi9k-mw8zx8HuEws"",""2026-27!AR4"")"),0.0) -> 0 | CR11: =IFERROR(__xludf.DUMMYFUNCTION("IMPORTRANGE(""13EYfcAewqPPQ83PA3ta2L46h2GIwi9k-mw8zx8HuEws"",""2026-27!AR3"")"),0.0) -> 0 | CS11: =IFERROR((CT11/CO11),"") | CT11: =IFERROR(__xludf.DUMMYFUNCTION("IMPORTRANGE(""13EYfcAewqPPQ83PA3ta2L46h2GIwi9k-mw8zx8HuEws"",""2026-27!AS4"")"),0.0) -> 0 | CU11: =IFERROR(__xludf.DUMMYFUNCTION("IMPORTRANGE(""13EYfcAewqPPQ83PA3ta2L46h2GIwi9k-mw8zx8HuEws"",""2026-27!AS3"")"),0.0) -> 0
