Workbook

Sheet Data
A1: =((1200000/30)*14)+1200000 -> 1760000 | B1: =12/30 -> 0.4 | C1: =10/31 -> 0.32258065 | D1: 2 | E1: 3 | G1: 5 | H1: 6 | I1: 7 | J1: 8 | K1: 9 | L1: 10 | M1: 11 | N1: 12 | O1: 13 | P1: 14 | Q1: 15 | R1: 16 | S1: 17 | T1: 18 | U1: 19 | V1: 20 | W1: 21 | X1: 22 | Y1: 23 | Z1: 24 | AA1: 25 | AB1: 26 | AC1: 27 | AD1: 28 | AE1: 29 | AF1: 30 | AG1: 31 | AH1: 32 | AI1: 33 | AJ1: 34 | AK1: 35 | AL1: 36 | AM1: 37 | AN1: 38 | AO1: 39 | AP1: 39 | AQ1: 41 | AR1: 42 | AS1: 43 | AT1: 44 | AU1: 45 | AY1: 46 | AZ1: 47 | BB1: 45747 | BD1: Salary month / target count | BI1: =BE160*3 -> #VALUE! | BO1: Order Booking 2024-2025 | CM1: =COUNTIF(CM3:CM243,">0") -> 26 | CQ1: =SUM(CQ3:CQ29) -> 148 | CR1: =SUM(CR3:CR29) -> 12
A2: State Head | B2: State | C2: Name | D2: Working State | E2: Headquarter | F2: D.O.J | G2: Primary Target | H2: Target | I2: Achievement | J2: Direct Dealers order | K2: Total Old Retailers | L2: Visited in a Month | M2: New Retailers | N2: Total Retailers | O2: Non Visited Retailers | P2: Old Party Business Order Booking | Q2: New Party Order Booking | R2: Business Achived By No. of Old Parties | S2: Business Achived By No. of New Parties | T2: Business Achieved By | U2: Business Achieved By Direct Dealer | V2: Total Lead Counters | W2: Total Lead Visits | X2: Total Non Lead Visits | Y2: Distributor Counter | Z2: Distributor Visits | AA2: Direct Dealer Counter | AB2: Direct Dealer Visits | AC2: Distributor/Direct Dealer Lead Counter | AD2: Distributor/Direct Dealer Lead Visits | AE2: Active Parties Visits | AF2: Total Visits | AG2: Working Days | AH2: Average Sales Per Day | AI2: Average Visit Per Day | AJ2: CTC Monthly | AK2: CTC | AL2: T.A. Bill ST. Cost | AM2: Cost Ratio (%) | AN2: Business Per Retailer | AO2: Target Achievement (%) | AP2: Direct Dealer/Primary target achievement (%) | AQ2: No of Orders | AR2: Total Working Hours | AS2: Total GPS KM | AT2: New Party Orders | AU2: Avg Distance (KM) | AV2: Business Received Parties Visits | AW2: Visited But No Business Received | AX2: No Visit No Business Received | AY2: Sale Report 25-26 | AZ2: Left Date | BA2: Active/ Left | BB2: old new | BC2: Target range | BD2: mar | BE2: Target monthly | BG2: Secondary / Primary | BH2: Sale 24-25 | BI2: Total Order 24-25 | BJ2: days calculation | BK2: Monthy Direct Dealer Primary Target | BL2: Direct Dealer Primary Target | BM2: Total target | BN2: rEMARKS | BO2: q1 | BP2: q2 | BQ2: q3 | BR2: q4 | BS2: Target Achievement (%) (Sale) | BT2: Cost Ratio (%)Sale | BV2: ctc 2025 | BW2: designation | BX2: emp code | CB2: Old | CC2: New | CD2: Left | CE2: Total | CG2: BELOW 60 DEALER | CH2: BUSINESS Achieved 50% AND ABOVE | CJ2: BUSINESS RECEIVED TOTAL VISITS | CK2: VISITED BUT BUSINESS NOT RECEIVED TOTAL VISITS | CL2: PARTIES NOT VISITED | CM2: Varitaion | CN2: Remarks | CO2: State Head | CP2: State | CQ2: Secon | CR2: prima
A3: Sandeep Dadheech | B3: West Bengal | C3: Monmon Paul | D3: WEST BENGAL | E3: KOLKATA | F3: 39859 | G3: 0 | H3: 0 | I3: 1199546.8 | J3: 0 | K3: 194 | L3: 185 | M3: 11 | N3: 205 | O3: 20 | P3: 1199546.8 | Q3: 0 | R3: 12 | S3: 0 | T3: 12 | U3: 0 | V3: 13 | W3: 19 | X3: 75 | Y3: 10 | Z3: 228 | AA3: 1 | AB3: 34 | AC3: 1 | AD3: 16 | AE3: 862 | AF3: 1159 | AG3: 297 | AH3: =IFERROR(SUM(I3:J3)/AG3,"") -> 4038.8782 | AI3: =IFERROR(AF3/AG3,"") -> 3.9023569 | AJ3: 70400 | AK3: =AJ3*BD3 -> 844800 | AL3: 263642 | AM3: =IFERROR(SUM(AK3:AL3)/SUM(I3:J3),"") -> 0.92405063 | AN3: =IFERROR(I3/T3,"") -> 99962.235 | AO3: No Target | AP3: 0 | AQ3: 21 | AR3: 3515 | AS3: 4573.56 | AT3: 0 | AU3: 25 | AV3: 12 | AW3: 173 | AX3: 20 | AY3: =IFERROR(VLOOKUP(C3,#REF!,13,0),"") | BA3: =IF(ISBLANK(AZ3),"Active","LEFT" ) -> Active | BB3: =_xludf.ifs(F3<$BB$1,"Old",F3>$BB$1,"New") -> #NAME? | BC3: No Target | BD3: =MATCH($BD$2,{"Apr","May","Jun","Jul","Aug","Sep","Oct","Nov","Dec","Jan","Feb","Mar"},0) -> 12 | BE3: {=IFERROR(VLOOKUP($C$3:$C243,#REF!,8,0),"")} | BF3: =M3-AT3 -> 11 | BG3: Primary | BH3: =IFERROR(__xludf.DUMMYFUNCTION("iferror(ArrayFormula(VLOOKUP($C$3:$C243,importrange(""1MwNMVzWE3QBVOyJjKr3eFX-Sq1Ng0Q1sghWJbgbE_8g"",""ORDER BOOKING REPORT 2024-25!C:O""),13,0)))"),28690782.84) -> 28690783 | BI3: =IFERROR(__xludf.DUMMYFUNCTION("iferror(ArrayFormula(VLOOKUP($C$3:$C243,importrange(""1MwNMVzWE3QBVOyJjKr3eFX-Sq1Ng0Q1sghWJbgbE_8g"",""ORDER BOOKING REPORT 2024-25!C:O""),11,0)))"),32790753.08) -> 32790753 | BL3: =BK3*BD3 -> 0 | BM3: =H3+BL3 -> 0 | BO3: =IFERROR(__xludf.DUMMYFUNCTION("IFERROR(ArrayFormula(SUM(VLOOKUP($C3,importrange(""1MwNMVzWE3QBVOyJjKr3eFX-Sq1Ng0Q1sghWJbgbE_8g"",""ORDER BOOKING REPORT 2024-25!C:CV""),{16,23,30},0))))"),6963375.6) -> 6963375.6 | BP3: =IFERROR(__xludf.DUMMYFUNCTION("IFERROR(ArrayFormula(SUM(VLOOKUP($C3,importrange(""1MwNMVzWE3QBVOyJjKr3eFX-Sq1Ng0Q1sghWJbgbE_8g"",""ORDER BOOKING REPORT 2024-25!C:CV""),{37,44,51},0))))"),9095913.7) -> 9095913.7 | BQ3: =IFERROR(__xludf.DUMMYFUNCTION("IFERROR(ArrayFormula(SUM(VLOOKUP($C3,importrange(""1MwNMVzWE3QBVOyJjKr3eFX-Sq1Ng0Q1sghWJbgbE_8g"",""ORDER BOOKING REPORT 2024-25!C:CV""),{58,65,72},0))))"),7698254.58) -> 7698254.6 | BR3: =IFERROR(__xludf.DUMMYFUNCTION("IFERROR(ArrayFormula(SUM(VLOOKUP($C3,importrange(""1MwNMVzWE3QBVOyJjKr3eFX-Sq1Ng0Q1sghWJbgbE_8g"",""ORDER BOOKING REPORT 2024-25!C:CV""),{79,86,93},0))))"),9033209.2) -> 9033209.2 | BS3: =IFERROR(AY3/BM3,"") | BT3: =IFERROR(SUM(AK3:AL3)/AY3,"") | BU3: =BL3-G3 -> 0 | BV3: 70400 | BW3: Sr. Area Sales Manager | BX3: 535 | BY3: =BV3-AJ3 -> 0 | CA3: Apr | CB3: =COUNTIF($F:$F, "<=" & DATE(2025,3,30)) -> 170 | CC3: =COUNTIFS(F:F, ">=" & DATE(2025,4,1), F:F, "<=" & DATE(2025,4,30)) -> 4 | CD3: =COUNTIFS(AZ:AZ, ">=" & DATE(2025,4,1), AZ:AZ, "<=" & DATE(2025,4,30)) -> 7 | CE3: =CB3+CC3 -> 174 | CF3: =SUM(CB3:CD3) -> 181 | CG3: =IF(N3<60,"Below 60"," ") | CH3: =IF(T3 = 0, "Not 50%", IF(T3 >= 0.5 * N3, "Business Achieved EXACT 50%", "Not 50%")) -> Not 50% | CI3: =IFERROR((T3/N3),) -> 0.058536585 | CJ3: =IFERROR(__xludf.DUMMYFUNCTION("IFERROR(ArrayFormula(VLOOKUP($C$3:$C243,IMPORTRANGE(""https://docs.google.com/spreadsheets/d/1OkdrCquHuVNXRsEZ16AzawxA5ZUvzmc454rG7C6Xzg0/edit?gid=548125645#gid=548125645"",""Sheet8!B:U""),{6,8,10},0)))"),100) -> 100 | CK3: =IFERROR(__xludf.DUMMYFUNCTION("""COMPUTED_VALUE"""),743) -> 743 | CL3: =IFERROR(__xludf.DUMMYFUNCTION("""COMPUTED_VALUE"""),0) -> 0 | CM3: =AE3-SUM(CJ3:CL3) -> 19 | CN3: =IFERROR(__xludf.DUMMYFUNCTION("IFERROR(ArrayFormula(VLOOKUP($C$3:$C243,IMPORTRANGE(""https://docs.google.com/spreadsheets/d/1OkdrCquHuVNXRsEZ16AzawxA5ZUvzmc454rG7C6Xzg0/edit?gid=548125645#gid=548125645"",""Sheet8!B:U""),20,0)))"),"") | CP3: Andhra Pradesh | CQ3: =COUNTIFS($B:$B,$CP3,$BG:$BG,"Secondary",$BA:$BA,"Active") -> 3 | CR3: =COUNTIFS($B:$B,$CP3,$BG:$BG,"Primary",$BA:$BA,"Active") -> 0 | CS3: {=_xludf.UNIQUE(A3:A243)} -> #NAME? | CT3: =COUNTIFS(A:A,CS3,BA:BA,"Active") -> 0
A4: Sandeep Dadheech | B4: West Bengal | C4: Sujan Ghata | D4: WEST BENGAL | E4: KOLKATA | F4: 39859 | G4: 0 | H4: 60600000 | I4: 41352930 | J4: 0 | K4: 111 | L4: 106 | M4: 13 | N4: 124 | O4: 18 | P4: 36872573 | Q4: 4480356.8 | R4: 85 | S4: 11 | T4: 96 | U4: 0 | V4: 9 | W4: 9 | X4: 79 | Y4: 9 | Z4: 121 | AA4: 0 | AB4: 0 | AC4: 0 | AD4: 0 | AE4: 1023 | AF4: 1153 | AG4: 291 | AH4: =IFERROR(SUM(I4:J4)/AG4,"") -> 142106.29 | AI4: =IFERROR(AF4/AG4,"") -> 3.9621993 | AJ4: 60500 | AK4: =AJ4*BD4 -> 726000 | AL4: 91425 | AM4: =IFERROR(SUM(AK4:AL4)/SUM(I4:J4),"") -> 0.01976704 | AN4: =IFERROR(I4/T4,"") -> 430759.68 | AO4: =IFERROR(SUM(I4:J4)/SUM(G4:H4),"") -> 0.68239158 | AP4: 0 | AQ4: 466 | AR4: 3035 | AS4: 4088.66 | AT4: 11 | AU4: 39 | AV4: 96 | AW4: 19 | AX4: 9 | AY4: =IFERROR(VLOOKUP(C4,#REF!,13,0),"") | BA4: =IF(ISBLANK(AZ4),"Active","LEFT" ) -> Active | BB4: =_xludf.ifs(F4<$BB$1,"Old",F4>$BB$1,"New") -> #NAME? | BC4: =_xludf.ifs(AO4<50%,"Below 50%",AO4<70%,"50%-70%",AO4<90%,"70%-90%",AO4<100%,"90%-100%",AO4>100%,"Above 100%") -> #NAME? | BD4: =MATCH($BD$2,{"Apr","May","Jun","Jul","Aug","Sep","Oct","Nov","Dec","Jan","Feb","Mar"},0) -> 12 | BF4: =M4-AT4 -> 2 | BG4: Secondary | BH4: =IFERROR(__xludf.DUMMYFUNCTION("""COMPUTED_VALUE"""),38475930.54) -> 38475931 | BI4: =IFERROR(__xludf.DUMMYFUNCTION("""COMPUTED_VALUE"""),37705783.88) -> 37705784 | BL4: =BK4*BD4 -> 0 | BM4: =H4+BL4 -> 60600000 | BO4: =IFERROR(__xludf.DUMMYFUNCTION("IFERROR(ArrayFormula(SUM(VLOOKUP($C4,importrange(""1MwNMVzWE3QBVOyJjKr3eFX-Sq1Ng0Q1sghWJbgbE_8g"",""ORDER BOOKING REPORT 2024-25!C:CV""),{16,23,30},0))))"),7373008.92) -> 7373008.9 | BP4: =IFERROR(__xludf.DUMMYFUNCTION("IFERROR(ArrayFormula(SUM(VLOOKUP($C4,importrange(""1MwNMVzWE3QBVOyJjKr3eFX-Sq1Ng0Q1sghWJbgbE_8g"",""ORDER BOOKING REPORT 2024-25!C:CV""),{37,44,51},0))))"),9026880) -> 9026880 | BQ4: =IFERROR(__xludf.DUMMYFUNCTION("IFERROR(ArrayFormula(SUM(VLOOKUP($C4,importrange(""1MwNMVzWE3QBVOyJjKr3eFX-Sq1Ng0Q1sghWJbgbE_8g"",""ORDER BOOKING REPORT 2024-25!C:CV""),{58,65,72},0))))"),8248527.6) -> 8248527.6 | BR4: =IFERROR(__xludf.DUMMYFUNCTION("IFERROR(ArrayFormula(SUM(VLOOKUP($C4,importrange(""1MwNMVzWE3QBVOyJjKr3eFX-Sq1Ng0Q1sghWJbgbE_8g"",""ORDER BOOKING REPORT 2024-25!C:CV""),{79,86,93},0))))"),13057367.36) -> 13057367 | BS4: =IFERROR(AY4/BM4,"") | BT4: =IFERROR(SUM(AK4:AL4)/AY4,"") | BU4: =BL4-G4 -> 0 | BV4: 60500 | BW4: Area Sales Manager | BX4: 536 | BY4: =BV4-AJ4 -> 0 | CA4: May | CB4: =COUNTIF($F:$F, "<=" & DATE(2025,4,30))-COUNTIFS(AZ:AZ, ">=" & DATE(2025,4,1), AZ:AZ, "<=" & DATE(2025,4,30)) -> 167 | CC4: =COUNTIFS(F:F, ">=" & DATE(2025,5,1), F:F, "<=" & DATE(2025,5,31)) -> 9 | CD4: =COUNTIFS(AZ:AZ, ">=" & DATE(2025,5,1), AZ:AZ, "<=" & DATE(2025,5,31)) -> 5 | CE4: =CB4+CC4 -> 176 | CF4: =SUM(CB4:CD4) -> 181 | CG4: =IF(N4<60,"Below 60"," ") | CH4: =IF(T4 = 0, "Not 50%", IF(T4 >= 0.5 * N4, "Business Achieved 50%", "Not 50%")) -> Business Achieved 50% | CI4: =IFERROR((T4/N4),) -> 0.77419355 | CJ4: =IFERROR(__xludf.DUMMYFUNCTION("""COMPUTED_VALUE"""),955) -> 955 | CK4: =IFERROR(__xludf.DUMMYFUNCTION("""COMPUTED_VALUE"""),68) -> 68 | CL4: =IFERROR(__xludf.DUMMYFUNCTION("""COMPUTED_VALUE"""),0) -> 0 | CM4: =AE4-SUM(CJ4:CL4) -> 0 | CP4: Bihar | CQ4: =COUNTIFS($B:$B,$CP4,$BG:$BG,"Secondary",$BA:$BA,"Active") -> 8 | CR4: =COUNTIFS($B:$B,$CP4,$BG:$BG,"Primary",$BA:$BA,"Active") -> 1 | CS4: #NAME? | CT4: =COUNTIFS(A:A,CS4,BA:BA,"Active") -> 0
A5: Syed Aqil Rizvi | B5: East U.P | C5: Rajan Srivastava | D5: East U.P, MADHYA PRADESH | E5: Varanasi | F5: 41004 | G5: 3600000 | H5: 46400004 | I5: 39826983 | J5: 3804037.1 | K5: 59 | L5: 70 | M5: 15 | N5: 74 | O5: 4 | P5: 32519279 | Q5: 7307704 | R5: 41 | S5: 11 | T5: 52 | U5: 8 | V5: 14 | W5: 21 | X5: 19 | Y5: 11 | Z5: 408 | AA5: 9 | AB5: 118 | AC5: 3 | AD5: 6 | AE5: 619 | AF5: 1172 | AG5: 254 | AH5: =IFERROR(SUM(I5:J5)/AG5,"") -> 171775.67 | AI5: =IFERROR(AF5/AG5,"") -> 4.6141732 | AJ5: =BV5 -> 95834 | AK5: =AJ5*BD5 -> 1150008 | AL5: 239916 | AM5: =IFERROR(SUM(AK5:AL5)/SUM(I5:J5),"") -> 0.031856326 | AN5: =IFERROR(I5/T5,"") -> 765903.53 | AO5: =IFERROR(SUM(I5:J5)/SUM(G5:H5),"") -> 0.87262034 | AP5: 1.06 | AQ5: 578 | AR5: 1986 | AS5: 2254.73 | AT5: 11 | AU5: 32 | AV5: 52 | AW5: 18 | AX5: 4 | AY5: =IFERROR(VLOOKUP(C5,#REF!,13,0),"") | BA5: =IF(ISBLANK(AZ5),"Active","LEFT" ) -> Active | BB5: =_xludf.ifs(F5<$BB$1,"Old",F5>$BB$1,"New") -> #NAME? | BC5: =_xludf.ifs(AO5<50%,"Below 50%",AO5<70%,"50%-70%",AO5<90%,"70%-90%",AO5<100%,"90%-100%",AO5>100%,"Above 100%") -> #NAME? | BD5: =MATCH($BD$2,{"Apr","May","Jun","Jul","Aug","Sep","Oct","Nov","Dec","Jan","Feb","Mar"},0) -> 12 | BF5: =M5-AT5 -> 4 | BG5: Secondary | BH5: =IFERROR(__xludf.DUMMYFUNCTION("""COMPUTED_VALUE"""),45381670) -> 45381670 | BI5: =IFERROR(__xludf.DUMMYFUNCTION("""COMPUTED_VALUE"""),44623264.94) -> 44623265 | BK5: 300000 | BL5: =BK5*BD5 -> 3600000 | BM5: =H5+BL5 -> 50000004 | BO5: =IFERROR(__xludf.DUMMYFUNCTION("IFERROR(ArrayFormula(SUM(VLOOKUP($C5,importrange(""1MwNMVzWE3QBVOyJjKr3eFX-Sq1Ng0Q1sghWJbgbE_8g"",""ORDER BOOKING REPORT 2024-25!C:CV""),{16,23,30},0))))"),13609862.56) -> 13609863 | BP5: =IFERROR(__xludf.DUMMYFUNCTION("IFERROR(ArrayFormula(SUM(VLOOKUP($C5,importrange(""1MwNMVzWE3QBVOyJjKr3eFX-Sq1Ng0Q1sghWJbgbE_8g"",""ORDER BOOKING REPORT 2024-25!C:CV""),{37,44,51},0))))"),7145309.5) -> 7145309.5 | BQ5: =IFERROR(__xludf.DUMMYFUNCTION("IFERROR(ArrayFormula(SUM(VLOOKUP($C5,importrange(""1MwNMVzWE3QBVOyJjKr3eFX-Sq1Ng0Q1sghWJbgbE_8g"",""ORDER BOOKING REPORT 2024-25!C:CV""),{58,65,72},0))))"),11508289.34) -> 11508289 | BR5: =IFERROR(__xludf.DUMMYFUNCTION("IFERROR(ArrayFormula(SUM(VLOOKUP($C5,importrange(""1MwNMVzWE3QBVOyJjKr3eFX-Sq1Ng0Q1sghWJbgbE_8g"",""ORDER BOOKING REPORT 2024-25!C:CV""),{79,86,93},0))))"),12359803.54) -> 12359804 | BS5: =IFERROR(AY5/BM5,"") | BT5: =IFERROR(SUM(AK5:AL5)/AY5,"") | BU5: =BL5-G5 -> 0 | BV5: 95834 | BW5: Regional Sales Manager | BX5: 15 | BY5: =BV5-AJ5 -> 0 | CA5: Jun | CB5: =COUNTIF($F:$F, "<=" & DATE(2025,5,31))-COUNTIFS(AZ:AZ, ">=" & DATE(2025,4,1), AZ:AZ, "<=" & DATE(2025,5,31)) -> 171 | CC5: =COUNTIFS(F:F, ">=" & DATE(2025,6,1), F:F, "<=" & DATE(2025,6,30)) -> 9 | CD5: =COUNTIFS(AZ:AZ, ">=" & DATE(2025,6,1), AZ:AZ, "<=" & DATE(2025,6,30)) -> 4 | CE5: =CB5+CC5 -> 180 | CF5: =SUM(CB5:CD5) -> 184 | CG5: =IF(N5<60,"Below 60"," ") | CH5: =IF(T5 = 0, "Not 50%", IF(T5 >= 0.5 * N5, "Business Achieved 50%", "Not 50%")) -> Business Achieved 50% | CI5: =IFERROR((T5/N5),) -> 0.7027027 | CJ5: =IFERROR(__xludf.DUMMYFUNCTION("""COMPUTED_VALUE"""),590) -> 590 | CK5: =IFERROR(__xludf.DUMMYFUNCTION("""COMPUTED_VALUE"""),28) -> 28 | CL5: =IFERROR(__xludf.DUMMYFUNCTION("""COMPUTED_VALUE"""),0) -> 0 | CM5: =AE5-SUM(CJ5:CL5) -> 1 | CN5: =IFERROR(__xludf.DUMMYFUNCTION("""COMPUTED_VALUE"""),"Retailer Convert as a direct dealer") -> Retailer Convert as a direct dealer | CP5: Chattisgarh | CQ5: =COUNTIFS($B:$B,$CP5,$BG:$BG,"Secondary",$BA:$BA,"Active") -> 2 | CR5: =COUNTIFS($B:$B,$CP5,$BG:$BG,"Primary",$BA:$BA,"Active") -> 0 | CS5: #NAME? | CT5: =COUNTIFS(A:A,CS5,BA:BA,"Active") -> 0
A6: Sandeep Dadheech | B6: West Bengal | C6: Surojit Mondal | D6: WEST BENGAL | E6: ANDAL | F6: 41159 | G6: 0 | H6: 81999996 | I6: 34910047 | J6: 0 | K6: 149 | L6: 143 | M6: 4 | N6: 153 | O6: 10 | P6: 33231270 | Q6: 1678777.6 | R6: 78 | S6: 3 | T6: 81 | U6: 0 | V6: 51 | W6: 124 | X6: 22 | Y6: 3 | Z6: 37 | AA6: 0 | AB6: 0 | AC6: 0 | AD6: 0 | AE6: 1386 | AF6: 1547 | AG6: 301 | AH6: =IFERROR(SUM(I6:J6)/AG6,"") -> 115980.22 | AI6: =IFERROR(AF6/AG6,"") -> 5.1395349 | AJ6: 78125 | AK6: =AJ6*BD6 -> 937500 | AL6: 243987 | AM6: =IFERROR(SUM(AK6:AL6)/SUM(I6:J6),"") -> 0.033843752 | AN6: =IFERROR(I6/T6,"") -> 430988.24 | AO6: =IFERROR(SUM(I6:J6)/SUM(G6:H6),"") -> 0.42573231 | AP6: 0 | AQ6: 306 | AR6: 3433 | AS6: 1481.26 | AT6: 3 | AU6: 10 | AV6: 81 | AW6: 62 | AX6: 10 | AY6: =IFERROR(VLOOKUP(C6,#REF!,13,0),"") | BA6: =IF(ISBLANK(AZ6),"Active","LEFT" ) -> Active | BB6: =_xludf.ifs(F6<$BB$1,"Old",F6>$BB$1,"New") -> #NAME? | BC6: =_xludf.ifs(AO6<50%,"Below 50%",AO6<70%,"50%-70%",AO6<90%,"70%-90%",AO6<100%,"90%-100%",AO6>100%,"Above 100%") -> #NAME? | BD6: =MATCH($BD$2,{"Apr","May","Jun","Jul","Aug","Sep","Oct","Nov","Dec","Jan","Feb","Mar"},0) -> 12 | BF6: =M6-AT6 -> 1 | BG6: Secondary | BH6: =IFERROR(__xludf.DUMMYFUNCTION("""COMPUTED_VALUE"""),63090460) -> 63090460 | BI6: =IFERROR(__xludf.DUMMYFUNCTION("""COMPUTED_VALUE"""),63695685.6) -> 63695686 | BL6: =BK6*BD6 -> 0 | BM6: =H6+BL6 -> 81999996 | BO6: =IFERROR(__xludf.DUMMYFUNCTION("IFERROR(ArrayFormula(SUM(VLOOKUP($C6,importrange(""1MwNMVzWE3QBVOyJjKr3eFX-Sq1Ng0Q1sghWJbgbE_8g"",""ORDER BOOKING REPORT 2024-25!C:CV""),{16,23,30},0))))"),15537153.4) -> 15537153 | BP6: =IFERROR(__xludf.DUMMYFUNCTION("IFERROR(ArrayFormula(SUM(VLOOKUP($C6,importrange(""1MwNMVzWE3QBVOyJjKr3eFX-Sq1Ng0Q1sghWJbgbE_8g"",""ORDER BOOKING REPORT 2024-25!C:CV""),{37,44,51},0))))"),13951117.7) -> 13951118 | BQ6: =IFERROR(__xludf.DUMMYFUNCTION("IFERROR(ArrayFormula(SUM(VLOOKUP($C6,importrange(""1MwNMVzWE3QBVOyJjKr3eFX-Sq1Ng0Q1sghWJbgbE_8g"",""ORDER BOOKING REPORT 2024-25!C:CV""),{58,65,72},0))))"),18425749.8) -> 18425750 | BR6: =IFERROR(__xludf.DUMMYFUNCTION("IFERROR(ArrayFormula(SUM(VLOOKUP($C6,importrange(""1MwNMVzWE3QBVOyJjKr3eFX-Sq1Ng0Q1sghWJbgbE_8g"",""ORDER BOOKING REPORT 2024-25!C:CV""),{79,86,93},0))))"),15781664.7) -> 15781665 | BS6: =IFERROR(AY6/BM6,"") | BT6: =IFERROR(SUM(AK6:AL6)/AY6,"") | BU6: =BL6-G6 -> 0 | BV6: 78125 | BW6: Area Sales Manager | BX6: 33 | BY6: =BV6-AJ6 -> 0 | CA6: Jul | CB6: =COUNTIF($F:$F, "<=" & DATE(2025,6,30))-COUNTIFS(AZ:AZ, ">=" & DATE(2025,4,1), AZ:AZ, "<=" & DATE(2025,6,30)) -> 176 | CC6: =COUNTIFS(F:F, ">=" & DATE(2025,7,1), F:F, "<=" & DATE(2025,7,31)) -> 12 | CD6: =COUNTIFS(AZ:AZ, ">=" & DATE(2025,7,1), AZ:AZ, "<=" & DATE(2025,7,31)) -> 9 | CE6: =CB6+CC6 -> 188 | CF6: =SUM(CB6:CD6) -> 197 | CG6: =IF(N6<60,"Below 60"," ") | CH6: =IF(T6 = 0, "Not 50%", IF(T6 >= 0.5 * N6, "Business Achieved 50%", "Not 50%")) -> Business Achieved 50% | CI6: =IFERROR((T6/N6),) -> 0.52941176 | CJ6: =IFERROR(__xludf.DUMMYFUNCTION("""COMPUTED_VALUE"""),991) -> 991 | CK6: =IFERROR(__xludf.DUMMYFUNCTION("""COMPUTED_VALUE"""),395) -> 395 | CL6: =IFERROR(__xludf.DUMMYFUNCTION("""COMPUTED_VALUE"""),0) -> 0 | CM6: =AE6-SUM(CJ6:CL6) -> 0 | CP6: Delhi | CQ6: =COUNTIFS($B:$B,$CP6,$BG:$BG,"Secondary",$BA:$BA,"Active") -> 2 | CR6: =COUNTIFS($B:$B,$CP6,$BG:$BG,"Primary",$BA:$BA,"Active") -> 0 | CS6: #NAME? | CT6: =COUNTIFS(A:A,CS6,BA:BA,"Active") -> 0
A7: Sandeep Dadheech | B7: West Bengal | C7: Suven Sengupta | D7: WEST BENGAL | E7: KOLKATA | F7: 41400 | G7: 0 | H7: 102000000 | I7: 61300488 | J7: 0 | K7: 54 | L7: 53 | M7: 4 | N7: 58 | O7: 5 | P7: 61245045 | Q7: 55443 | R7: 47 | S7: 2 | T7: 49 | U7: 0 | V7: 2 | W7: 4 | X7: 17 | Y7: 3 | Z7: 174 | AA7: 0 | AB7: 0 | AC7: 0 | AD7: 0 | AE7: 1633 | AF7: 1811 | AG7: 245 | AH7: =IFERROR(SUM(I7:J7)/AG7,"") -> 250206.07 | AI7: =IFERROR(AF7/AG7,"") -> 7.3918367 | AJ7: 83075 | AK7: =AJ7*BD7 -> 996900 | AL7: 72733 | AM7: =IFERROR(SUM(AK7:AL7)/SUM(I7:J7),"") -> 0.017449013 | AN7: =IFERROR(I7/T7,"") -> 1251030.4 | AO7: =IFERROR(SUM(I7:J7)/SUM(G7:H7),"") -> 0.60098517 | AP7: 0 | AQ7: 1005 | AR7: 2357 | AS7: 807.74 | AT7: 2 | AU7: 15 | AV7: 49 | AW7: 6 | AX7: 3 | AY7: =IFERROR(VLOOKUP(C7,#REF!,13,0),"") | BA7: =IF(ISBLANK(AZ7),"Active","LEFT" ) -> Active | BB7: =_xludf.ifs(F7<$BB$1,"Old",F7>$BB$1,"New") -> #NAME? | BC7: =_xludf.ifs(AO7<50%,"Below 50%",AO7<70%,"50%-70%",AO7<90%,"70%-90%",AO7<100%,"90%-100%",AO7>100%,"Above 100%") -> #NAME? | BD7: =MATCH($BD$2,{"Apr","May","Jun","Jul","Aug","Sep","Oct","Nov","Dec","Jan","Feb","Mar"},0) -> 12 | BF7: =M7-AT7 -> 2 | BG7: Secondary | BH7: =IFERROR(__xludf.DUMMYFUNCTION("""COMPUTED_VALUE"""),67969652.42) -> 67969652 | BI7: =IFERROR(__xludf.DUMMYFUNCTION("""COMPUTED_VALUE"""),66863516.29) -> 66863516 | BL7: =BK7*BD7 -> 0 | BM7: =H7+BL7 -> 102000000 | BO7: =IFERROR(__xludf.DUMMYFUNCTION("IFERROR(ArrayFormula(SUM(VLOOKUP($C7,importrange(""1MwNMVzWE3QBVOyJjKr3eFX-Sq1Ng0Q1sghWJbgbE_8g"",""ORDER BOOKING REPORT 2024-25!C:CV""),{16,23,30},0))))"),13545550.98) -> 13545551 | BP7: =IFERROR(__xludf.DUMMYFUNCTION("IFERROR(ArrayFormula(SUM(VLOOKUP($C7,importrange(""1MwNMVzWE3QBVOyJjKr3eFX-Sq1Ng0Q1sghWJbgbE_8g"",""ORDER BOOKING REPORT 2024-25!C:CV""),{37,44,51},0))))"),15540769.1399999) -> 15540769 | BQ7: =IFERROR(__xludf.DUMMYFUNCTION("IFERROR(ArrayFormula(SUM(VLOOKUP($C7,importrange(""1MwNMVzWE3QBVOyJjKr3eFX-Sq1Ng0Q1sghWJbgbE_8g"",""ORDER BOOKING REPORT 2024-25!C:CV""),{58,65,72},0))))"),15171394.53) -> 15171395 | BR7: =IFERROR(__xludf.DUMMYFUNCTION("IFERROR(ArrayFormula(SUM(VLOOKUP($C7,importrange(""1MwNMVzWE3QBVOyJjKr3eFX-Sq1Ng0Q1sghWJbgbE_8g"",""ORDER BOOKING REPORT 2024-25!C:CV""),{79,86,93},0))))"),22605801.64) -> 22605802 | BS7: =IFERROR(AY7/BM7,"") | BT7: =IFERROR(SUM(AK7:AL7)/AY7,"") | BU7: =BL7-G7 -> 0 | BV7: 83075 | BW7: Area Sales Manager | BX7: 82 | BY7: =BV7-AJ7 -> 0 | CA7: Aug | CB7: =COUNTIF($F:$F, "<=" & DATE(2025,7,31))-COUNTIFS(AZ:AZ, ">=" & DATE(2025,4,1), AZ:AZ, "<=" & DATE(2025,7,31)) -> 179 | CC7: =COUNTIFS(F:F, ">=" & DATE(2025,8,1), F:F, "<=" & DATE(2025,8,31)) -> 6 | CD7: =COUNTIFS(AZ:AZ, ">=" & DATE(2025,8,1), AZ:AZ, "<=" & DATE(2025,8,31)) -> 12 | CE7: =CB7+CC7 -> 185 | CF7: =SUM(CB7:CD7) -> 197 | CG7: =IF(N7<60,"Below 60"," ") -> Below 60 | CH7: =IF(T7 = 0, "Not 50%", IF(T7 >= 0.5 * N7, "Business Achieved 50%", "Not 50%")) -> Business Achieved 50% | CI7: =IFERROR((T7/N7),) -> 0.84482759 | CJ7: =IFERROR(__xludf.DUMMYFUNCTION("""COMPUTED_VALUE"""),1620) -> 1620 | CK7: =IFERROR(__xludf.DUMMYFUNCTION("""COMPUTED_VALUE"""),13) -> 13 | CL7: =IFERROR(__xludf.DUMMYFUNCTION("""COMPUTED_VALUE"""),0) -> 0 | CM7: =AE7-SUM(CJ7:CL7) -> 0 | CP7: Delhi NCR | CQ7: =COUNTIFS($B:$B,$CP7,$BG:$BG,"Secondary",$BA:$BA,"Active") -> 1 | CR7: =COUNTIFS($B:$B,$CP7,$BG:$BG,"Primary",$BA:$BA,"Active") -> 0 | CS7: #NAME? | CT7: =COUNTIFS(A:A,CS7,BA:BA,"Active") -> 0
A8: Sandeep Dadheech | B8: Odisha | C8: Kailash Ch. Ghadei | D8: ODISHA | E8: CUTTACK | F8: 41563 | G8: 0 | H8: 25200000 | I8: 22853663 | J8: 0 | K8: 38 | L8: 39 | M8: 2 | N8: 40 | O8: 1 | P8: 22820007 | Q8: 33656 | R8: 26 | S8: 1 | T8: 27 | U8: 0 | V8: 3 | W8: 6 | X8: 30 | Y8: 1 | Z8: 17 | AA8: 0 | AB8: 0 | AC8: 0 | AD8: 0 | AE8: 821 | AF8: 844 | AG8: 292 | AH8: =IFERROR(SUM(I8:J8)/AG8,"") -> 78265.969 | AI8: =IFERROR(AF8/AG8,"") -> 2.890411 | AJ8: 48500 | AK8: =AJ8*BD8 -> 582000 | AL8: 225701 | AM8: =IFERROR(SUM(AK8:AL8)/SUM(I8:J8),"") -> 0.035342299 | AN8: =IFERROR(I8/T8,"") -> 846431.96 | AO8: =IFERROR(SUM(I8:J8)/SUM(G8:H8),"") -> 0.90689139 | AP8: 0 | AQ8: 314 | AR8: 3477 | AS8: 3895.5 | AT8: 1 | AU8: 100 | AV8: 27 | AW8: 12 | AX8: 1 | AY8: =IFERROR(VLOOKUP(C8,#REF!,13,0),"") | BA8: =IF(ISBLANK(AZ8),"Active","LEFT" ) -> Active | BB8: =_xludf.ifs(F8<$BB$1,"Old",F8>$BB$1,"New") -> #NAME? | BC8: =_xludf.ifs(AO8<50%,"Below 50%",AO8<70%,"50%-70%",AO8<90%,"70%-90%",AO8<100%,"90%-100%",AO8>100%,"Above 100%") -> #NAME? | BD8: =MATCH($BD$2,{"Apr","May","Jun","Jul","Aug","Sep","Oct","Nov","Dec","Jan","Feb","Mar"},0) -> 12 | BF8: =M8-AT8 -> 1 | BG8: Secondary | BH8: =IFERROR(__xludf.DUMMYFUNCTION("""COMPUTED_VALUE"""),17275853.09) -> 17275853 | BI8: =IFERROR(__xludf.DUMMYFUNCTION("""COMPUTED_VALUE"""),19757187.56) -> 19757188 | BL8: =BK8*BD8 -> 0 | BM8: =H8+BL8 -> 25200000 | BO8: =IFERROR(__xludf.DUMMYFUNCTION("IFERROR(ArrayFormula(SUM(VLOOKUP($C8,importrange(""1MwNMVzWE3QBVOyJjKr3eFX-Sq1Ng0Q1sghWJbgbE_8g"",""ORDER BOOKING REPORT 2024-25!C:CV""),{16,23,30},0))))"),4426946.2) -> 4426946.2 | BP8: =IFERROR(__xludf.DUMMYFUNCTION("IFERROR(ArrayFormula(SUM(VLOOKUP($C8,importrange(""1MwNMVzWE3QBVOyJjKr3eFX-Sq1Ng0Q1sghWJbgbE_8g"",""ORDER BOOKING REPORT 2024-25!C:CV""),{37,44,51},0))))"),4924133.03999999) -> 4924133 | BQ8: =IFERROR(__xludf.DUMMYFUNCTION("IFERROR(ArrayFormula(SUM(VLOOKUP($C8,importrange(""1MwNMVzWE3QBVOyJjKr3eFX-Sq1Ng0Q1sghWJbgbE_8g"",""ORDER BOOKING REPORT 2024-25!C:CV""),{58,65,72},0))))"),4739381.66) -> 4739381.7 | BR8: =IFERROR(__xludf.DUMMYFUNCTION("IFERROR(ArrayFormula(SUM(VLOOKUP($C8,importrange(""1MwNMVzWE3QBVOyJjKr3eFX-Sq1Ng0Q1sghWJbgbE_8g"",""ORDER BOOKING REPORT 2024-25!C:CV""),{79,86,93},0))))"),5666726.66) -> 5666726.7 | BS8: =IFERROR(AY8/BM8,"") | BT8: =IFERROR(SUM(AK8:AL8)/AY8,"") | BU8: =BL8-G8 -> 0 | BV8: 48500 | BW8: Sr. Executive - Sales & Mktg. | BX8: 111 | BY8: =BV8-AJ8 -> 0 | CA8: Sep | CB8: =COUNTIF($F:$F, "<=" & DATE(2025,8,31))-COUNTIFS(AZ:AZ, ">=" & DATE(2025,4,1), AZ:AZ, "<=" & DATE(2025,8,31)) -> 173 | CC8: =COUNTIFS(F:F, ">=" & DATE(2025,9,1), F:F, "<=" & DATE(2025,9,30)) -> 3 | CD8: =COUNTIFS(AZ:AZ, ">=" & DATE(2025,9,1), AZ:AZ, "<=" & DATE(2025,9,30)) -> 7 | CE8: =CB8+CC8 -> 176 | CF8: =SUM(CB8:CD8) -> 183 | CG8: =IF(N8<60,"Below 60"," ") -> Below 60 | CH8: =IF(T8 = 0, "Not 50%", IF(T8 >= 0.5 * N8, "Business Achieved 50%", "Not 50%")) -> Business Achieved 50% | CI8: =IFERROR((T8/N8),) -> 0.675 | CJ8: =IFERROR(__xludf.DUMMYFUNCTION("""COMPUTED_VALUE"""),654) -> 654 | CK8: =IFERROR(__xludf.DUMMYFUNCTION("""COMPUTED_VALUE"""),167) -> 167 | CL8: =IFERROR(__xludf.DUMMYFUNCTION("""COMPUTED_VALUE"""),0) -> 0 | CM8: =AE8-SUM(CJ8:CL8) -> 0 | CP8: East U.P | CQ8: =COUNTIFS($B:$B,$CP8,$BG:$BG,"Secondary",$BA:$BA,"Active") -> 15 | CR8: =COUNTIFS($B:$B,$CP8,$BG:$BG,"Primary",$BA:$BA,"Active") -> 0 | CS8: #NAME? | CT8: =COUNTIFS(A:A,CS8,BA:BA,"Active") -> 0
A9: Sandeep Dadheech | B9: Bihar | C9: Sujeet Singh | D9: BIHAR | E9: Motihari | F9: 41719 | G9: 0 | H9: 0 | I9: 0 | J9: 0 | K9: 167 | L9: 79 | M9: 17 | N9: 184 | O9: 105 | P9: 0 | Q9: 0 | R9: 0 | S9: 0 | T9: 0 | U9: 0 | V9: 62 | W9: 98 | X9: 220 | Y9: 20 | Z9: 263 | AA9: 4 | AB9: 45 | AC9: 9 | AD9: 24 | AE9: 184 | AF9: 614 | AG9: 287 | AH9: =IFERROR(SUM(I9:J9)/AG9,"") -> 0 | AI9: =IFERROR(AF9/AG9,"") -> 2.1393728 | AJ9: 88170 | AK9: =AJ9*BD9 -> 1058040 | AL9: 367576 | AM9: =IFERROR(SUM(AK9:AL9)/SUM(I9:J9),"") | AN9: =IFERROR(I9/T9,"") | AO9: No Target | AP9: 0 | AQ9: 0 | AR9: 2790 | AS9: 1334.02 | AT9: 0 | AU9: 17 | AV9: 0 | AW9: 79 | AX9: 105 | AY9: =IFERROR(VLOOKUP(C9,#REF!,13,0),"") | BA9: =IF(ISBLANK(AZ9),"Active","LEFT" ) -> Active | BB9: =_xludf.ifs(F9<$BB$1,"Old",F9>$BB$1,"New") -> #NAME? | BC9: No Target | BD9: =MATCH($BD$2,{"Apr","May","Jun","Jul","Aug","Sep","Oct","Nov","Dec","Jan","Feb","Mar"},0) -> 12 | BF9: =M9-AT9 -> 17 | BG9: Primary | BL9: =BK9*BD9 -> 0 | BM9: =H9+BL9 -> 0 | BO9: =IFERROR(__xludf.DUMMYFUNCTION("IFERROR(ArrayFormula(SUM(VLOOKUP($C9,importrange(""1MwNMVzWE3QBVOyJjKr3eFX-Sq1Ng0Q1sghWJbgbE_8g"",""ORDER BOOKING REPORT 2024-25!C:CV""),{16,23,30},0))))"),"") | BP9: =IFERROR(__xludf.DUMMYFUNCTION("IFERROR(ArrayFormula(SUM(VLOOKUP($C9,importrange(""1MwNMVzWE3QBVOyJjKr3eFX-Sq1Ng0Q1sghWJbgbE_8g"",""ORDER BOOKING REPORT 2024-25!C:CV""),{37,44,51},0))))"),"") | BQ9: =IFERROR(__xludf.DUMMYFUNCTION("IFERROR(ArrayFormula(SUM(VLOOKUP($C9,importrange(""1MwNMVzWE3QBVOyJjKr3eFX-Sq1Ng0Q1sghWJbgbE_8g"",""ORDER BOOKING REPORT 2024-25!C:CV""),{58,65,72},0))))"),"") | BR9: =IFERROR(__xludf.DUMMYFUNCTION("IFERROR(ArrayFormula(SUM(VLOOKUP($C9,importrange(""1MwNMVzWE3QBVOyJjKr3eFX-Sq1Ng0Q1sghWJbgbE_8g"",""ORDER BOOKING REPORT 2024-25!C:CV""),{79,86,93},0))))"),"") | BS9: =IFERROR(AY9/BM9,"") | BT9: =IFERROR(SUM(AK9:AL9)/AY9,"") | BU9: =BL9-G9 -> 0 | BV9: 88170 | BW9: Sr. Area Sales Manager | BX9: 130 | BY9: =BV9-AJ9 -> 0 | CA9: Oct | CB9: =COUNTIF($F:$F, "<=" & DATE(2025,9,30))-COUNTIFS(AZ:AZ, ">=" & DATE(2025,4,1), AZ:AZ, "<=" & DATE(2025,9,30)) -> 169 | CC9: =COUNTIFS(F:F, ">=" & DATE(2025,10,1), F:F, "<=" & DATE(2025,10,31)) -> 3 | CD9: =COUNTIFS(AZ:AZ, ">=" & DATE(2025,10,1), AZ:AZ, "<=" & DATE(2025,10,31)) -> 7 | CE9: =CB9+CC9 -> 172 | CF9: =SUM(CB9:CD9) -> 179 | CG9: =IF(N9<60,"Below 60"," ") | CH9: =IF(T9 = 0, "Not 50%", IF(T9 >= 0.5 * N9, "Business Achieved 50%", "Not 50%")) -> Not 50% | CI9: =IFERROR((T9/N9),) -> 0 | CM9: =AE9-SUM(CJ9:CL9) -> 184 | CP9: Gujarat | CQ9: =COUNTIFS($B:$B,$CP9,$BG:$BG,"Secondary",$BA:$BA,"Active") -> 5 | CR9: =COUNTIFS($B:$B,$CP9,$BG:$BG,"Primary",$BA:$BA,"Active") -> 0 | CS9: #NAME? | CT9: =COUNTIFS(A:A,CS9,BA:BA,"Active") -> 0
A10: Sandeep Dadheech | B10: West Bengal | C10: Debasish Adhikary | D10: WEST BENGAL | E10: MEDNIPORE | F10: 41791 | G10: 0 | H10: 150000000 | I10: 80016578 | J10: 0 | K10: 100 | L10: 82 | M10: 2 | N10: 102 | O10: 20 | P10: 80016578 | Q10: 0 | R10: 74 | S10: 0 | T10: 74 | U10: 0 | V10: 7 | W10: 7 | X10: 24 | Y10: 4 | Z10: 160 | AA10: 0 | AB10: 0 | AC10: 0 | AD10: 0 | AE10: 1021 | AF10: 1188 | AG10: 269 | AH10: =IFERROR(SUM(I10:J10)/AG10,"") -> 297459.4 | AI10: =IFERROR(AF10/AG10,"") -> 4.4163569 | AJ10: 87460 | AK10: =AJ10*BD10 -> 1027655 | AL10: 163196 | AM10: =IFERROR(SUM(AK10:AL10)/SUM(I10:J10),"") -> 0.014882554 | AN10: =IFERROR(I10/T10,"") -> 1081305.1 | AO10: =IFERROR(SUM(I10:J10)/SUM(G10:H10),"") -> 0.53344385 | AP10: 0 | AQ10: 765 | AR10: 3246 | AS10: 2691.5 | AT10: 0 | AU10: 33 | AV10: 74 | AW10: 8 | AX10: 20 | AY10: =IFERROR(VLOOKUP(C10,#REF!,13,0),"") | BA10: =IF(ISBLANK(AZ10),"Active","LEFT" ) -> Active | BB10: =_xludf.ifs(F10<$BB$1,"Old",F10>$BB$1,"New") -> #NAME? | BC10: =_xludf.ifs(AO10<50%,"Below 50%",AO10<70%,"50%-70%",AO10<90%,"70%-90%",AO10<100%,"90%-100%",AO10>100%,"Above 100%") -> #NAME? | BD10: 11.75 | BF10: =M10-AT10 -> 2 | BG10: Secondary | BH10: =IFERROR(__xludf.DUMMYFUNCTION("""COMPUTED_VALUE"""),103680911.2) -> 1.0368091e+08 | BI10: =IFERROR(__xludf.DUMMYFUNCTION("""COMPUTED_VALUE"""),101906858.6) -> 1.0190686e+08 | BL10: =BK10*BD10 -> 0 | BM10: =H10+BL10 -> 150000000 | BO10: =IFERROR(__xludf.DUMMYFUNCTION("IFERROR(ArrayFormula(SUM(VLOOKUP($C10,importrange(""1MwNMVzWE3QBVOyJjKr3eFX-Sq1Ng0Q1sghWJbgbE_8g"",""ORDER BOOKING REPORT 2024-25!C:CV""),{16,23,30},0))))"),22922417.2) -> 22922417 | BP10: =IFERROR(__xludf.DUMMYFUNCTION("IFERROR(ArrayFormula(SUM(VLOOKUP($C10,importrange(""1MwNMVzWE3QBVOyJjKr3eFX-Sq1Ng0Q1sghWJbgbE_8g"",""ORDER BOOKING REPORT 2024-25!C:CV""),{37,44,51},0))))"),25515495.7999999) -> 25515496 | BQ10: =IFERROR(__xludf.DUMMYFUNCTION("IFERROR(ArrayFormula(SUM(VLOOKUP($C10,importrange(""1MwNMVzWE3QBVOyJjKr3eFX-Sq1Ng0Q1sghWJbgbE_8g"",""ORDER BOOKING REPORT 2024-25!C:CV""),{58,65,72},0))))"),23428766.5) -> 23428766 | BR10: =IFERROR(__xludf.DUMMYFUNCTION("IFERROR(ArrayFormula(SUM(VLOOKUP($C10,importrange(""1MwNMVzWE3QBVOyJjKr3eFX-Sq1Ng0Q1sghWJbgbE_8g"",""ORDER BOOKING REPORT 2024-25!C:CV""),{79,86,93},0))))"),30040179.0999999) -> 30040179 | BS10: =IFERROR(AY10/BM10,"") | BT10: =IFERROR(SUM(AK10:AL10)/AY10,"") | BU10: =BL10-G10 -> 0 | BV10: 87460 | BW10: Sr. Area Sales Manager | BX10: 148 | BY10: =BV10-AJ10 -> 0 | CA10: Nov | CB10: =COUNTIF($F:$F, "<=" & DATE(2025,10,31))-COUNTIFS(AZ:AZ, ">=" & DATE(2025,4,1), AZ:AZ, "<=" & DATE(2025,10,31)) -> 165 | CC10: =COUNTIFS(F:F, ">=" & DATE(2025,11,1), F:F, "<=" & DATE(2025,11,30)) -> 6 | CD10: =COUNTIFS(AZ:AZ, ">=" & DATE(2025,11,1), AZ:AZ, "<=" & DATE(2025,11,30)) -> 8 | CE10: =CB10+CC10 -> 171 | CF10: =SUM(CB10:CD10) -> 179 | CG10: =IF(N10<60,"Below 60"," ") | CH10: =IF(T10 = 0, "Not 50%", IF(T10 >= 0.5 * N10, "Business Achieved 50%", "Not 50%")) -> Business Achieved 50% | CI10: =IFERROR((T10/N10),) -> 0.7254902 | CJ10: =IFERROR(__xludf.DUMMYFUNCTION("""COMPUTED_VALUE"""),981) -> 981 | CK10: =IFERROR(__xludf.DUMMYFUNCTION("""COMPUTED_VALUE"""),40) -> 40 | CL10: =IFERROR(__xludf.DUMMYFUNCTION("""COMPUTED_VALUE"""),0) -> 0 | CM10: =AE10-SUM(CJ10:CL10) -> 0 | CP10: Haryana | CQ10: =COUNTIFS($B:$B,$CP10,$BG:$BG,"Secondary",$BA:$BA,"Active") -> 4 | CR10: =COUNTIFS($B:$B,$CP10,$BG:$BG,"Primary",$BA:$BA,"Active") -> 0 | CS10: #NAME? | CT10: =COUNTIFS(A:A,CS10,BA:BA,"Active") -> 0
A11: Sandeep Dadheech | B11: Odisha | C11: Pravat Kumar Dash | D11: ODISHA | E11: BALASORE | F11: 42125 | G11: 0 | H11: 78696000 | I11: 72128325 | J11: 0 | K11: 125 | L11: 137 | M11: 13 | N11: 138 | O11: 1 | P11: 69031739 | Q11: 3096586.3 | R11: 78 | S11: 8 | T11: 86 | U11: 0 | V11: 1 | W11: 1 | X11: 3 | Y11: 5 | Z11: 184 | AA11: 0 | AB11: 0 | AC11: 0 | AD11: 0 | AE11: 1397 | AF11: 1582 | AG11: 303 | AH11: =IFERROR(SUM(I11:J11)/AG11,"") -> 238047.28 | AI11: =IFERROR(AF11/AG11,"") -> 5.2211221 | AJ11: 79340 | AK11: =AJ11*BD11 -> 952080 | AL11: 219017 | AM11: =IFERROR(SUM(AK11:AL11)/SUM(I11:J11),"") -> 0.016236298 | AN11: =IFERROR(I11/T11,"") -> 838701.45 | AO11: =IFERROR(SUM(I11:J11)/SUM(G11:H11),"") -> 0.91654373 | AP11: 0 | AQ11: 1469 | AR11: 3663 | AS11: 2880.47 | AT11: 8 | AU11: 21 | AV11: 86 | AW11: 51 | AX11: 1 | AY11: =IFERROR(VLOOKUP(C11,#REF!,13,0),"") | BA11: =IF(ISBLANK(AZ11),"Active","LEFT" ) -> Active | BB11: =_xludf.ifs(F11<$BB$1,"Old",F11>$BB$1,"New") -> #NAME? | BC11: =_xludf.ifs(AO11<50%,"Below 50%",AO11<70%,"50%-70%",AO11<90%,"70%-90%",AO11<100%,"90%-100%",AO11>100%,"Above 100%") -> #NAME? | BD11: =MATCH($BD$2,{"Apr","May","Jun","Jul","Aug","Sep","Oct","Nov","Dec","Jan","Feb","Mar"},0) -> 12 | BF11: =M11-AT11 -> 5 | BG11: Secondary | BH11: =IFERROR(__xludf.DUMMYFUNCTION("""COMPUTED_VALUE"""),60223274.44) -> 60223274 | BI11: =IFERROR(__xludf.DUMMYFUNCTION("""COMPUTED_VALUE"""),61970724.91) -> 61970725 | BL11: =BK11*BD11 -> 0 | BM11: =H11+BL11 -> 78696000 | BO11: =IFERROR(__xludf.DUMMYFUNCTION("IFERROR(ArrayFormula(SUM(VLOOKUP($C11,importrange(""1MwNMVzWE3QBVOyJjKr3eFX-Sq1Ng0Q1sghWJbgbE_8g"",""ORDER BOOKING REPORT 2024-25!C:CV""),{16,23,30},0))))"),16487834.6799999) -> 16487835 | BP11: =IFERROR(__xludf.DUMMYFUNCTION("IFERROR(ArrayFormula(SUM(VLOOKUP($C11,importrange(""1MwNMVzWE3QBVOyJjKr3eFX-Sq1Ng0Q1sghWJbgbE_8g"",""ORDER BOOKING REPORT 2024-25!C:CV""),{37,44,51},0))))"),14456037.66) -> 14456038 | BQ11: =IFERROR(__xludf.DUMMYFUNCTION("IFERROR(ArrayFormula(SUM(VLOOKUP($C11,importrange(""1MwNMVzWE3QBVOyJjKr3eFX-Sq1Ng0Q1sghWJbgbE_8g"",""ORDER BOOKING REPORT 2024-25!C:CV""),{58,65,72},0))))"),14904938.15) -> 14904938 | BR11: =IFERROR(__xludf.DUMMYFUNCTION("IFERROR(ArrayFormula(SUM(VLOOKUP($C11,importrange(""1MwNMVzWE3QBVOyJjKr3eFX-Sq1Ng0Q1sghWJbgbE_8g"",""ORDER BOOKING REPORT 2024-25!C:CV""),{79,86,93},0))))"),16121914.42) -> 16121914 | BS11: =IFERROR(AY11/BM11,"") | BT11: =IFERROR(SUM(AK11:AL11)/AY11,"") | BU11: =BL11-G11 -> 0 | BV11: 79340 | BW11: Area Sales Manager | BX11: 221 | BY11: =BV11-AJ11 -> 0 | CA11: Dec | CB11: =COUNTIF($F:$F, "<=" & DATE(2025,11,30))-COUNTIFS(AZ:AZ, ">=" & DATE(2025,4,1), AZ:AZ, "<=" & DATE(2025,11,30)) -> 163 | CC11: =COUNTIFS(F:F, ">=" & DATE(2025,12,1), F:F, "<=" & DATE(2025,12,31)) -> 4 | CD11: =COUNTIFS(AZ:AZ, ">=" & DATE(2025,12,1), AZ:AZ, "<=" & DATE(2025,12,31)) -> 7 | CE11: =CB11+CC11 -> 167 | CF11: =SUM(CB11:CD11) -> 174 | CG11: =IF(N11<60,"Below 60"," ") | CH11: =IF(T11 = 0, "Not 50%", IF(T11 >= 0.5 * N11, "Business Achieved 50%", "Not 50%")) -> Business Achieved 50% | CI11: =IFERROR((T11/N11),) -> 0.62318841 | CJ11: =IFERROR(__xludf.DUMMYFUNCTION("""COMPUTED_VALUE"""),1294) -> 1294 | CK11: =IFERROR(__xludf.DUMMYFUNCTION("""COMPUTED_VALUE"""),103) -> 103 | CL11: =IFERROR(__xludf.DUMMYFUNCTION("""COMPUTED_VALUE"""),0) -> 0 | CM11: =AE11-SUM(CJ11:CL11) -> 0 | CP11: Himachal Pradesh | CQ11: =COUNTIFS($B:$B,$CP11,$BG:$BG,"Secondary",$BA:$BA,"Active") -> 0 | CR11: =COUNTIFS($B:$B,$CP11,$BG:$BG,"Primary",$BA:$BA,"Active") -> 2 | CS11: #NAME? | CT11: =COUNTIFS(A:A,CS11,BA:BA,"Active") -> 0
A12: Syed Aqil Rizvi | B12: East U.P | C12: Ravi Kumar Verma | D12: East U.P | E12: Faizbad | F12: 42530 | G12: 6000000 | H12: 31500000 | I12: 20294789 | J12: 0 | K12: 75 | L12: 92 | M12: 29 | N12: 104 | O12: 12 | P12: 18477281 | Q12: 1817507.9 | R12: 48 | S12: 10 | T12: 58 | U12: 0 | V12: 97 | W12: 158 | X12: 104 | Y12: 7 | Z12: 152 | AA12: 0 | AB12: 0 | AC12: 0 | AD12: 0 | AE12: 639 | AF12: 949 | AG12: 281 | AH12: =IFERROR(SUM(I12:J12)/AG12,"") -> 72223.45 | AI12: =IFERROR(AF12/AG12,"") -> 3.3772242 | AJ12: =BV12 -> 76210 | AK12: =AJ12*BD12 -> 914520 | AL12: 250348 | AM12: =IFERROR(SUM(AK12:AL12)/SUM(I12:J12),"") -> 0.057397393 | AN12: =IFERROR(I12/T12,"") -> 349910.16 | AO12: =IFERROR(SUM(I12:J12)/SUM(G12:H12),"") -> 0.54119438 | AP12: 0 | AQ12: 222 | AR12: 2398 | AS12: 2080.46 | AT12: 10 | AU12: 23 | AV12: 58 | AW12: 36 | AX12: 10 | AY12: =IFERROR(VLOOKUP(C12,#REF!,13,0),"") | BA12: =IF(ISBLANK(AZ12),"Active","LEFT" ) -> Active | BB12: =_xludf.ifs(F12<$BB$1,"Old",F12>$BB$1,"New") -> #NAME? | BC12: =_xludf.ifs(AO12<50%,"Below 50%",AO12<70%,"50%-70%",AO12<90%,"70%-90%",AO12<100%,"90%-100%",AO12>100%,"Above 100%") -> #NAME? | BD12: =MATCH($BD$2,{"Apr","May","Jun","Jul","Aug","Sep","Oct","Nov","Dec","Jan","Feb","Mar"},0) -> 12 | BF12: =M12-AT12 -> 19 | BG12: Secondary | BH12: =IFERROR(__xludf.DUMMYFUNCTION("""COMPUTED_VALUE"""),21287274) -> 21287274 | BI12: =IFERROR(__xludf.DUMMYFUNCTION("""COMPUTED_VALUE"""),20392999.86) -> 20393000 | BK12: 500000 | BL12: =BK12*BD12 -> 6000000 | BM12: =H12+BL12 -> 37500000 | BO12: =IFERROR(__xludf.DUMMYFUNCTION("IFERROR(ArrayFormula(SUM(VLOOKUP($C12,importrange(""1MwNMVzWE3QBVOyJjKr3eFX-Sq1Ng0Q1sghWJbgbE_8g"",""ORDER BOOKING REPORT 2024-25!C:CV""),{16,23,30},0))))"),3572895.8) -> 3572895.8 | BP12: =IFERROR(__xludf.DUMMYFUNCTION("IFERROR(ArrayFormula(SUM(VLOOKUP($C12,importrange(""1MwNMVzWE3QBVOyJjKr3eFX-Sq1Ng0Q1sghWJbgbE_8g"",""ORDER BOOKING REPORT 2024-25!C:CV""),{37,44,51},0))))"),5092431.5) -> 5092431.5 | BQ12: =IFERROR(__xludf.DUMMYFUNCTION("IFERROR(ArrayFormula(SUM(VLOOKUP($C12,importrange(""1MwNMVzWE3QBVOyJjKr3eFX-Sq1Ng0Q1sghWJbgbE_8g"",""ORDER BOOKING REPORT 2024-25!C:CV""),{58,65,72},0))))"),4695979.26) -> 4695979.3 | BR12: =IFERROR(__xludf.DUMMYFUNCTION("IFERROR(ArrayFormula(SUM(VLOOKUP($C12,importrange(""1MwNMVzWE3QBVOyJjKr3eFX-Sq1Ng0Q1sghWJbgbE_8g"",""ORDER BOOKING REPORT 2024-25!C:CV""),{79,86,93},0))))"),7031693.3) -> 7031693.3 | BS12: =IFERROR(AY12/BM12,"") | BT12: =IFERROR(SUM(AK12:AL12)/AY12,"") | BU12: =BL12-G12 -> 0 | BV12: 76210 | BW12: Assistant Area Sales Manager | BX12: 304 | BY12: =BV12-AJ12 -> 0 | CA12: Jan | CB12: =COUNTIF($F:$F, "<=" & DATE(2025,12,31))-COUNTIFS(AZ:AZ, ">=" & DATE(2025,4,1), AZ:AZ, "<=" & DATE(2025,12,31)) -> 160 | CC12: =COUNTIFS(F:F, ">=" & DATE(2026,1,1), F:F, "<=" & DATE(2026,1,31)) -> 7 | CD12: =COUNTIFS(AZ:AZ, ">=" & DATE(2026,1,1), AZ:AZ, "<=" & DATE(2026,1,31)) -> 7 | CE12: =CB12+CC12 -> 167 | CF12: =SUM(CB12:CD12) -> 174 | CG12: =IF(N12<60,"Below 60"," ") | CH12: =IF(T12 = 0, "Not 50%", IF(T12 >= 0.5 * N12, "Business Achieved 50%", "Not 50%")) -> Business Achieved 50% | CI12: =IFERROR((T12/N12),) -> 0.55769231 | CJ12: =IFERROR(__xludf.DUMMYFUNCTION("""COMPUTED_VALUE"""),510) -> 510 | CK12: =IFERROR(__xludf.DUMMYFUNCTION("""COMPUTED_VALUE"""),129) -> 129 | CL12: =IFERROR(__xludf.DUMMYFUNCTION("""COMPUTED_VALUE"""),0) -> 0 | CM12: =AE12-SUM(CJ12:CL12) -> 0 | CP12: JAMMU AND KASHMIR | CQ12: =COUNTIFS($B:$B,$CP12,$BG:$BG,"Secondary",$BA:$BA,"Active") -> 5 | CR12: =COUNTIFS($B:$B,$CP12,$BG:$BG,"Primary",$BA:$BA,"Active") -> 0 | CS12: #NAME? | CT12: =COUNTIFS(A:A,CS12,BA:BA,"Active") -> 0
A13: Sandeep Dadheech | B13: West Bengal | C13: Priyabrata Biswas | D13: WEST BENGAL | E13: BANKURA | F13: 42660 | G13: 0 | H13: 40599996 | I13: 33140270 | J13: 0 | K13: 56 | L13: 58 | M13: 6 | N13: 62 | O13: 4 | P13: 32421767 | Q13: 718502.3 | R13: 38 | S13: 6 | T13: 44 | U13: 0 | V13: 3 | W13: 6 | X13: 4 | Y13: 3 | Z13: 264 | AA13: 0 | AB13: 0 | AC13: 0 | AD13: 0 | AE13: 858 | AF13: 1128 | AG13: 283 | AH13: =IFERROR(SUM(I13:J13)/AG13,"") -> 117103.43 | AI13: =IFERROR(AF13/AG13,"") -> 3.9858657 | AJ13: 48608 | AK13: =AJ13*BD13 -> 583296 | AL13: 187741 | AM13: =IFERROR(SUM(AK13:AL13)/SUM(I13:J13),"") -> 0.023265864 | AN13: =IFERROR(I13/T13,"") -> 753187.95 | AO13: =IFERROR(SUM(I13:J13)/SUM(G13:H13),"") -> 0.81626288 | AP13: 0 | AQ13: 408 | AR13: 3089 | AS13: 1927.17 | AT13: 6 | AU13: 33 | AV13: 44 | AW13: 15 | AX13: 3 | AY13: =IFERROR(VLOOKUP(C13,#REF!,13,0),"") | BA13: =IF(ISBLANK(AZ13),"Active","LEFT" ) -> Active | BB13: =_xludf.ifs(F13<$BB$1,"Old",F13>$BB$1,"New") -> #NAME? | BC13: =_xludf.ifs(AO13<50%,"Below 50%",AO13<70%,"50%-70%",AO13<90%,"70%-90%",AO13<100%,"90%-100%",AO13>100%,"Above 100%") -> #NAME? | BD13: =MATCH($BD$2,{"Apr","May","Jun","Jul","Aug","Sep","Oct","Nov","Dec","Jan","Feb","Mar"},0) -> 12 | BF13: =M13-AT13 -> 0 | BG13: Secondary | BH13: =IFERROR(__xludf.DUMMYFUNCTION("""COMPUTED_VALUE"""),27594897) -> 27594897 | BI13: =IFERROR(__xludf.DUMMYFUNCTION("""COMPUTED_VALUE"""),27934642.2) -> 27934642 | BL13: =BK13*BD13 -> 0 | BM13: =H13+BL13 -> 40599996 | BO13: =IFERROR(__xludf.DUMMYFUNCTION("IFERROR(ArrayFormula(SUM(VLOOKUP($C13,importrange(""1MwNMVzWE3QBVOyJjKr3eFX-Sq1Ng0Q1sghWJbgbE_8g"",""ORDER BOOKING REPORT 2024-25!C:CV""),{16,23,30},0))))"),6726878.5) -> 6726878.5 | BP13: =IFERROR(__xludf.DUMMYFUNCTION("IFERROR(ArrayFormula(SUM(VLOOKUP($C13,importrange(""1MwNMVzWE3QBVOyJjKr3eFX-Sq1Ng0Q1sghWJbgbE_8g"",""ORDER BOOKING REPORT 2024-25!C:CV""),{37,44,51},0))))"),7101797.49999999) -> 7101797.5 | BQ13: =IFERROR(__xludf.DUMMYFUNCTION("IFERROR(ArrayFormula(SUM(VLOOKUP($C13,importrange(""1MwNMVzWE3QBVOyJjKr3eFX-Sq1Ng0Q1sghWJbgbE_8g"",""ORDER BOOKING REPORT 2024-25!C:CV""),{58,65,72},0))))"),6808447.79999999) -> 6808447.8 | BR13: =IFERROR(__xludf.DUMMYFUNCTION("IFERROR(ArrayFormula(SUM(VLOOKUP($C13,importrange(""1MwNMVzWE3QBVOyJjKr3eFX-Sq1Ng0Q1sghWJbgbE_8g"",""ORDER BOOKING REPORT 2024-25!C:CV""),{79,86,93},0))))"),7297518.4) -> 7297518.4 | BS13: =IFERROR(AY13/BM13,"") | BT13: =IFERROR(SUM(AK13:AL13)/AY13,"") | BU13: =BL13-G13 -> 0 | BV13: 48608 | BW13: Assistant Area Sales Manager | BX13: 438 | BY13: =BV13-AJ13 -> 0 | CA13: Feb | CB13: =COUNTIF($F:$F, "<=" & DATE(2026,1,31))-COUNTIFS(AZ:AZ, ">=" & DATE(2025,4,1), AZ:AZ, "<=" & DATE(2026,1,31)) -> 160 | CC13: =COUNTIFS(F:F, ">=" & DATE(2026,2,1), F:F, "<=" & DATE(2026,2,28)) -> 1 | CD13: =COUNTIFS(AZ:AZ, ">=" & DATE(2026,2,1), AZ:AZ, "<=" & DATE(2026,2,28)) -> 3 | CE13: =CB13+CC13 -> 161 | CF13: =SUM(CB13:CD13) -> 164 | CG13: =IF(N13<60,"Below 60"," ") | CH13: =IF(T13 = 0, "Not 50%", IF(T13 >= 0.5 * N13, "Business Achieved 50%", "Not 50%")) -> Business Achieved 50% | CI13: =IFERROR((T13/N13),) -> 0.70967742 | CJ13: =IFERROR(__xludf.DUMMYFUNCTION("""COMPUTED_VALUE"""),781) -> 781 | CK13: =IFERROR(__xludf.DUMMYFUNCTION("""COMPUTED_VALUE"""),77) -> 77 | CL13: =IFERROR(__xludf.DUMMYFUNCTION("""COMPUTED_VALUE"""),0) -> 0 | CM13: =AE13-SUM(CJ13:CL13) -> 0 | CP13: Jharkhand | CQ13: =COUNTIFS($B:$B,$CP13,$BG:$BG,"Secondary",$BA:$BA,"Active") -> 7 | CR13: =COUNTIFS($B:$B,$CP13,$BG:$BG,"Primary",$BA:$BA,"Active") -> 1 | CS13: #NAME? | CT13: =COUNTIFS(A:A,CS13,BA:BA,"Active") -> 0
A14: Syed Aqil Rizvi | B14: Madhya Pradesh | C14: Jitender Birla | D14: MADHYA PRADESH | E14: Indore | F14: 42720 | G14: 5028000 | H14: 32472000 | I14: 23497643 | J14: =2302523.38+1470312.5 -> 3772835.9 | K14: 68 | L14: 81 | M14: 32 | N14: 100 | O14: 19 | P14: 15192121 | Q14: 8305522 | R14: 47 | S14: 24 | T14: 71 | U14: 3 | V14: 61 | W14: 121 | X14: 136 | Y14: 3 | Z14: 82 | AA14: 4 | AB14: 42 | AC14: 1 | AD14: 48 | AE14: 816 | AF14: 1109 | AG14: 296 | AH14: =IFERROR(SUM(I14:J14)/AG14,"") -> 92129.996 | AI14: =IFERROR(AF14/AG14,"") -> 3.7466216 | AJ14: =BV14 -> 61850 | AK14: =AJ14*BD14 -> 742200 | AL14: 279525 | AM14: =IFERROR(SUM(AK14:AL14)/SUM(I14:J14),"") -> 0.037466339 | AN14: =IFERROR(I14/T14,"") -> 330952.72 | AO14: =IFERROR(SUM(I14:J14)/SUM(G14:H14),"") -> 0.72721277 | AP14: 0.75 | AQ14: 528 | AR14: 2088 | AS14: 3658.44 | AT14: 24 | AU14: 45 | AV14: 71 | AW14: 16 | AX14: 13 | AY14: =IFERROR(VLOOKUP(C14,#REF!,13,0),"") | BA14: =IF(ISBLANK(AZ14),"Active","LEFT" ) -> Active | BB14: =_xludf.ifs(F14<$BB$1,"Old",F14>$BB$1,"New") -> #NAME? | BC14: =_xludf.ifs(AO14<50%,"Below 50%",AO14<70%,"50%-70%",AO14<90%,"70%-90%",AO14<100%,"90%-100%",AO14>100%,"Above 100%") -> #NAME? | BD14: =MATCH($BD$2,{"Apr","May","Jun","Jul","Aug","Sep","Oct","Nov","Dec","Jan","Feb","Mar"},0) -> 12 | BF14: =M14-AT14 -> 8 | BG14: Secondary | BH14: =IFERROR(__xludf.DUMMYFUNCTION("""COMPUTED_VALUE"""),19644499) -> 19644499 | BI14: =IFERROR(__xludf.DUMMYFUNCTION("""COMPUTED_VALUE"""),19561872.2599999) -> 19561872 | BK14: 419000 | BL14: =BK14*BD14 -> 5028000 | BM14: =H14+BL14 -> 37500000 | BO14: =IFERROR(__xludf.DUMMYFUNCTION("IFERROR(ArrayFormula(SUM(VLOOKUP($C14,importrange(""1MwNMVzWE3QBVOyJjKr3eFX-Sq1Ng0Q1sghWJbgbE_8g"",""ORDER BOOKING REPORT 2024-25!C:CV""),{16,23,30},0))))"),4285421.91) -> 4285421.9 | BP14: =IFERROR(__xludf.DUMMYFUNCTION("IFERROR(ArrayFormula(SUM(VLOOKUP($C14,importrange(""1MwNMVzWE3QBVOyJjKr3eFX-Sq1Ng0Q1sghWJbgbE_8g"",""ORDER BOOKING REPORT 2024-25!C:CV""),{37,44,51},0))))"),5088733.93999999) -> 5088733.9 | BQ14: =IFERROR(__xludf.DUMMYFUNCTION("IFERROR(ArrayFormula(SUM(VLOOKUP($C14,importrange(""1MwNMVzWE3QBVOyJjKr3eFX-Sq1Ng0Q1sghWJbgbE_8g"",""ORDER BOOKING REPORT 2024-25!C:CV""),{58,65,72},0))))"),4523058.39) -> 4523058.4 | BR14: =IFERROR(__xludf.DUMMYFUNCTION("IFERROR(ArrayFormula(SUM(VLOOKUP($C14,importrange(""1MwNMVzWE3QBVOyJjKr3eFX-Sq1Ng0Q1sghWJbgbE_8g"",""ORDER BOOKING REPORT 2024-25!C:CV""),{79,86,93},0))))"),5664658.02) -> 5664658 | BS14: =IFERROR(AY14/BM14,"") | BT14: =IFERROR(SUM(AK14:AL14)/AY14,"") | BU14: =BL14-G14 -> 0 | BV14: 61850 | BW14: Sr. Area Sales Manager | BX14: 323 | BY14: =BV14-AJ14 -> 0 | CA14: Mar | CB14: =COUNTIF($F:$F, "<=" & DATE(2026,2,28))-COUNTIFS(AZ:AZ, ">=" & DATE(2025,4,1), AZ:AZ, "<=" & DATE(2026,2,28)) -> 158 | CC14: =COUNTIFS(F:F, ">=" & DATE(2026,3,1), F:F, "<=" & DATE(2026,3,31)) -> 7 | CD14: =COUNTIFS(AZ:AZ, ">=" & DATE(2026,3,1), AZ:AZ, "<=" & DATE(2026,3,31)) -> 5 | CE14: =CB14+CC14 -> 165 | CF14: =SUM(CB14:CD14) -> 170 | CG14: =IF(N14<60,"Below 60"," ") | CH14: =IF(T14 = 0, "Not 50%", IF(T14 >= 0.5 * N14, "Business Achieved 50%", "Not 50%")) -> Business Achieved 50% | CI14: =IFERROR((T14/N14),) -> 0.71 | CJ14: =IFERROR(__xludf.DUMMYFUNCTION("""COMPUTED_VALUE"""),764) -> 764 | CK14: =IFERROR(__xludf.DUMMYFUNCTION("""COMPUTED_VALUE"""),52) -> 52 | CL14: =IFERROR(__xludf.DUMMYFUNCTION("""COMPUTED_VALUE"""),0) -> 0 | CM14: =AE14-SUM(CJ14:CL14) -> 0 | CP14: Karnataka | CQ14: =COUNTIFS($B:$B,$CP14,$BG:$BG,"Secondary",$BA:$BA,"Active") -> 2 | CR14: =COUNTIFS($B:$B,$CP14,$BG:$BG,"Primary",$BA:$BA,"Active") -> 2 | CT14: =COUNTIFS(A:A,CS14,BA:BA,"Active") -> 0
A15: Sandeep Dadheech | B15: Andhra Pradesh | C15: S.Tirumala Rao | D15: ANDHRA PRADESH | E15: Srikakulam | F15: 42769 | G15: 0 | H15: 11200000 | I15: 3645541.3 | J15: 0 | K15: 44 | L15: 45 | M15: 1 | N15: 45 | O15: 0 | P15: 3626768.2 | Q15: 18773.1 | R15: 33 | S15: 1 | T15: 34 | U15: 0 | V15: 12 | W15: 27 | X15: 66 | Y15: 2 | Z15: 18 | AA15: 0 | AB15: 0 | AC15: 0 | AD15: 0 | AE15: 812 | AF15: 857 | AG15: 204 | AH15: =IFERROR(SUM(I15:J15)/AG15,"") -> 17870.3 | AI15: =IFERROR(AF15/AG15,"") -> 4.2009804 | AJ15: =BV15 -> 37355 | AK15: =AJ15*BD15 -> 298840 | AL15: 138168 | AM15: =IFERROR(SUM(AK15:AL15)/SUM(I15:J15),"") -> 0.11987465 | AN15: =IFERROR(I15/T15,"") -> 107221.8 | AO15: =IFERROR(SUM(I15:J15)/SUM(G15:H15),"") -> 0.32549476 | AP15: 0 | AQ15: 136 | AR15: 2241 | AS15: 0 | AT15: 1 | AU15: 0 | AV15: 34 | AW15: 11 | AX15: 0 | AY15: =IFERROR(VLOOKUP(C15,#REF!,13,0),"") | AZ15: 45991 | BA15: =IF(ISBLANK(AZ15),"Active","LEFT" ) -> LEFT | BB15: =_xludf.ifs(F15<$BB$1,"Old",F15>$BB$1,"New") -> #NAME? | BC15: =_xludf.ifs(AO15<50%,"Below 50%",AO15<70%,"50%-70%",AO15<90%,"70%-90%",AO15<100%,"90%-100%",AO15>100%,"Above 100%") -> #NAME? | BD15: 8 | BF15: =M15-AT15 -> 0 | BG15: Secondary | BH15: =IFERROR(__xludf.DUMMYFUNCTION("""COMPUTED_VALUE"""),8136889) -> 8136889 | BI15: =IFERROR(__xludf.DUMMYFUNCTION("""COMPUTED_VALUE"""),8549887.04) -> 8549887 | BL15: =BK15*BD15 -> 0 | BM15: =H15+BL15 -> 11200000 | BO15: =IFERROR(__xludf.DUMMYFUNCTION("IFERROR(ArrayFormula(SUM(VLOOKUP($C15,importrange(""1MwNMVzWE3QBVOyJjKr3eFX-Sq1Ng0Q1sghWJbgbE_8g"",""ORDER BOOKING REPORT 2024-25!C:CV""),{16,23,30},0))))"),2883632.9) -> 2883632.9 | BP15: =IFERROR(__xludf.DUMMYFUNCTION("IFERROR(ArrayFormula(SUM(VLOOKUP($C15,importrange(""1MwNMVzWE3QBVOyJjKr3eFX-Sq1Ng0Q1sghWJbgbE_8g"",""ORDER BOOKING REPORT 2024-25!C:CV""),{37,44,51},0))))"),1822099.32) -> 1822099.3 | BQ15: =IFERROR(__xludf.DUMMYFUNCTION("IFERROR(ArrayFormula(SUM(VLOOKUP($C15,importrange(""1MwNMVzWE3QBVOyJjKr3eFX-Sq1Ng0Q1sghWJbgbE_8g"",""ORDER BOOKING REPORT 2024-25!C:CV""),{58,65,72},0))))"),1985247.96) -> 1985248 | BR15: =IFERROR(__xludf.DUMMYFUNCTION("IFERROR(ArrayFormula(SUM(VLOOKUP($C15,importrange(""1MwNMVzWE3QBVOyJjKr3eFX-Sq1Ng0Q1sghWJbgbE_8g"",""ORDER BOOKING REPORT 2024-25!C:CV""),{79,86,93},0))))"),1858906.86) -> 1858906.9 | BS15: =IFERROR(AY15/BM15,"") | BT15: =IFERROR(SUM(AK15:AL15)/AY15,"") | BU15: =BL15-G15 -> 0 | BV15: 37355 | BW15: Executive - Sales & Mkt. | BX15: 341 | BY15: =BV15-AJ15 -> 0 | CB15: =COUNTIF($F:$F, "<=" & DATE(2026,3,31))-COUNTIFS(AZ:AZ, ">=" & DATE(2025,4,1), AZ:AZ, "<=" & DATE(2026,3,31)) -> 160 | CG15: =IF(N15<60,"Below 60"," ") -> Below 60 | CH15: =IF(T15 = 0, "Not 50%", IF(T15 >= 0.5 * N15, "Business Achieved 50%", "Not 50%")) -> Business Achieved 50% | CI15: =IFERROR((T15/N15),) -> 0.75555556 | CJ15: =IFERROR(__xludf.DUMMYFUNCTION("""COMPUTED_VALUE"""),632) -> 632 | CK15: =IFERROR(__xludf.DUMMYFUNCTION("""COMPUTED_VALUE"""),180) -> 180 | CL15: =IFERROR(__xludf.DUMMYFUNCTION("""COMPUTED_VALUE"""),0) -> 0 | CM15: =AE15-SUM(CJ15:CL15) -> 0 | CP15: Kerala | CQ15: =COUNTIFS($B:$B,$CP15,$BG:$BG,"Secondary",$BA:$BA,"Active") -> 7 | CR15: =COUNTIFS($B:$B,$CP15,$BG:$BG,"Primary",$BA:$BA,"Active") -> 0 | CT15: =COUNTIFS(A:A,CS15,BA:BA,"Active") -> 0
A16: Sandeep Dadheech | B16: Odisha | C16: Arijit Roychowdhury | D16: ODISHA | E16: BHUBANESWAR | F16: 42826 | G16: 0 | H16: 24000000 | I16: 6304004.2 | J16: 0 | K16: 73 | L16: 86 | M16: 21 | N16: 94 | O16: 8 | P16: 4934942 | Q16: 1369062.2 | R16: 49 | S16: 21 | T16: 70 | U16: 0 | V16: 2 | W16: 6 | X16: 9 | Y16: 3 | Z16: 143 | AA16: 0 | AB16: 0 | AC16: 0 | AD16: 0 | AE16: 1011 | AF16: 1160 | AG16: 235 | AH16: =IFERROR(SUM(I16:J16)/AG16,"") -> 26825.55 | AI16: =IFERROR(AF16/AG16,"") -> 4.9361702 | AJ16: 76300 | AK16: =AJ16*BD16 -> 763000 | AL16: 101548 | AM16: =IFERROR(SUM(AK16:AL16)/SUM(I16:J16),"") -> 0.13714267 | AN16: =IFERROR(I16/T16,"") -> 90057.203 | AO16: =IFERROR(SUM(I16:J16)/SUM(G16:H16),"") -> 0.26266684 | AP16: 0 | AQ16: 250 | AR16: 2035 | AS16: 0 | AT16: 21 | AU16: 0 | AV16: 70 | AW16: 17 | AX16: 7 | AY16: =IFERROR(VLOOKUP(C16,#REF!,13,0),"") | AZ16: 46053 | BA16: =IF(ISBLANK(AZ16),"Active","LEFT" ) -> LEFT | BB16: =_xludf.ifs(F16<$BB$1,"Old",F16>$BB$1,"New") -> #NAME? | BC16: =_xludf.ifs(AO16<50%,"Below 50%",AO16<70%,"50%-70%",AO16<90%,"70%-90%",AO16<100%,"90%-100%",AO16>100%,"Above 100%") -> #NAME? | BD16: 10 | BF16: =M16-AT16 -> 0 | BG16: Secondary | BH16: =IFERROR(__xludf.DUMMYFUNCTION("""COMPUTED_VALUE"""),5631228.72) -> 5631228.7 | BI16: =IFERROR(__xludf.DUMMYFUNCTION("""COMPUTED_VALUE"""),4942730.67) -> 4942730.7 | BL16: =BK16*BD16 -> 0 | BM16: =H16+BL16 -> 24000000 | BO16: =IFERROR(__xludf.DUMMYFUNCTION("IFERROR(ArrayFormula(SUM(VLOOKUP($C16,importrange(""1MwNMVzWE3QBVOyJjKr3eFX-Sq1Ng0Q1sghWJbgbE_8g"",""ORDER BOOKING REPORT 2024-25!C:CV""),{16,23,30},0))))"),1698763.63) -> 1698763.6 | BP16: =IFERROR(__xludf.DUMMYFUNCTION("IFERROR(ArrayFormula(SUM(VLOOKUP($C16,importrange(""1MwNMVzWE3QBVOyJjKr3eFX-Sq1Ng0Q1sghWJbgbE_8g"",""ORDER BOOKING REPORT 2024-25!C:CV""),{37,44,51},0))))"),399087.1) -> 399087.1 | BQ16: =IFERROR(__xludf.DUMMYFUNCTION("IFERROR(ArrayFormula(SUM(VLOOKUP($C16,importrange(""1MwNMVzWE3QBVOyJjKr3eFX-Sq1Ng0Q1sghWJbgbE_8g"",""ORDER BOOKING REPORT 2024-25!C:CV""),{58,65,72},0))))"),1345957.72) -> 1345957.7 | BR16: =IFERROR(__xludf.DUMMYFUNCTION("IFERROR(ArrayFormula(SUM(VLOOKUP($C16,importrange(""1MwNMVzWE3QBVOyJjKr3eFX-Sq1Ng0Q1sghWJbgbE_8g"",""ORDER BOOKING REPORT 2024-25!C:CV""),{79,86,93},0))))"),1498922.21999999) -> 1498922.2 | BS16: =IFERROR(AY16/BM16,"") | BT16: =IFERROR(SUM(AK16:AL16)/AY16,"") | BU16: =BL16-G16 -> 0 | BV16: 76300 | BW16: Sr. Area Sales Manager | BX16: 354 | BY16: =BV16-AJ16 -> 0 | CG16: =IF(N16<60,"Below 60"," ") | CH16: =IF(T16 = 0, "Not 50%", IF(T16 >= 0.5 * N16, "Business Achieved 50%", "Not 50%")) -> Business Achieved 50% | CI16: =IFERROR((T16/N16),) -> 0.74468085 | CJ16: =IFERROR(__xludf.DUMMYFUNCTION("""COMPUTED_VALUE"""),940) -> 940 | CK16: =IFERROR(__xludf.DUMMYFUNCTION("""COMPUTED_VALUE"""),71) -> 71 | CL16: =IFERROR(__xludf.DUMMYFUNCTION("""COMPUTED_VALUE"""),0) -> 0 | CM16: =AE16-SUM(CJ16:CL16) -> 0 | CP16: Madhya Pradesh | CQ16: =COUNTIFS($B:$B,$CP16,$BG:$BG,"Secondary",$BA:$BA,"Active") -> 10 | CR16: =COUNTIFS($B:$B,$CP16,$BG:$BG,"Primary",$BA:$BA,"Active") -> 0 | CT16: =COUNTIFS(A:A,CS16,BA:BA,"Active") -> 0
A17: Sandeep Dadheech | B17: West Bengal | C17: Sarbjit Singh Chawla | D17: WEST BENGAL | E17: ANDAL | F17: 42826 | G17: 0 | H17: 45600000 | I17: 38462589 | J17: 0 | K17: 129 | L17: 94 | M17: 9 | N17: 138 | O17: 44 | P17: 38462589 | Q17: 0 | R17: 20 | S17: 0 | T17: 20 | U17: 0 | V17: 13 | W17: 19 | X17: 28 | Y17: 4 | Z17: 99 | AA17: 0 | AB17: 0 | AC17: 0 | AD17: 0 | AE17: 852 | AF17: 970 | AG17: 300 | AH17: =IFERROR(SUM(I17:J17)/AG17,"") -> 128208.63 | AI17: =IFERROR(AF17/AG17,"") -> 3.2333333 | AJ17: 63250 | AK17: =AJ17*BD17 -> 759000 | AL17: 264598 | AM17: =IFERROR(SUM(AK17:AL17)/SUM(I17:J17),"") -> 0.026612821 | AN17: =IFERROR(I17/T17,"") -> 1923129.4 | AO17: =IFERROR(SUM(I17:J17)/SUM(G17:H17),"") -> 0.84347783 | AP17: 0 | AQ17: 116 | AR17: 3649 | AS17: 1702.39 | AT17: 0 | AU17: 18 | AV17: 20 | AW17: 74 | AX17: 44 | AY17: =IFERROR(VLOOKUP(C17,#REF!,13,0),"") | BA17: =IF(ISBLANK(AZ17),"Active","LEFT" ) -> Active | BB17: =_xludf.ifs(F17<$BB$1,"Old",F17>$BB$1,"New") -> #NAME? | BC17: =_xludf.ifs(AO17<50%,"Below 50%",AO17<70%,"50%-70%",AO17<90%,"70%-90%",AO17<100%,"90%-100%",AO17>100%,"Above 100%") -> #NAME? | BD17: =MATCH($BD$2,{"Apr","May","Jun","Jul","Aug","Sep","Oct","Nov","Dec","Jan","Feb","Mar"},0) -> 12 | BF17: =M17-AT17 -> 9 | BG17: Secondary | BH17: =IFERROR(__xludf.DUMMYFUNCTION("""COMPUTED_VALUE"""),44970678.61) -> 44970679 | BI17: =IFERROR(__xludf.DUMMYFUNCTION("""COMPUTED_VALUE"""),68311270.3) -> 68311270 | BL17: =BK17*BD17 -> 0 | BM17: =H17+BL17 -> 45600000 | BO17: =IFERROR(__xludf.DUMMYFUNCTION("IFERROR(ArrayFormula(SUM(VLOOKUP($C17,importrange(""1MwNMVzWE3QBVOyJjKr3eFX-Sq1Ng0Q1sghWJbgbE_8g"",""ORDER BOOKING REPORT 2024-25!C:CV""),{16,23,30},0))))"),16343405) -> 16343405 | BP17: =IFERROR(__xludf.DUMMYFUNCTION("IFERROR(ArrayFormula(SUM(VLOOKUP($C17,importrange(""1MwNMVzWE3QBVOyJjKr3eFX-Sq1Ng0Q1sghWJbgbE_8g"",""ORDER BOOKING REPORT 2024-25!C:CV""),{37,44,51},0))))"),15567088.4) -> 15567088 | BQ17: =IFERROR(__xludf.DUMMYFUNCTION("IFERROR(ArrayFormula(SUM(VLOOKUP($C17,importrange(""1MwNMVzWE3QBVOyJjKr3eFX-Sq1Ng0Q1sghWJbgbE_8g"",""ORDER BOOKING REPORT 2024-25!C:CV""),{58,65,72},0))))"),17148584.3) -> 17148584 | BR17: =IFERROR(__xludf.DUMMYFUNCTION("IFERROR(ArrayFormula(SUM(VLOOKUP($C17,importrange(""1MwNMVzWE3QBVOyJjKr3eFX-Sq1Ng0Q1sghWJbgbE_8g"",""ORDER BOOKING REPORT 2024-25!C:CV""),{79,86,93},0))))"),19252192.6) -> 19252193 | BS17: =IFERROR(AY17/BM17,"") | BT17: =IFERROR(SUM(AK17:AL17)/AY17,"") | BU17: =BL17-G17 -> 0 | BV17: 63250 | BW17: Area Sales Manager | BX17: 360 | BY17: =BV17-AJ17 -> 0 | CG17: =IF(N17<60,"Below 60"," ") | CH17: =IF(T17 = 0, "Not 50%", IF(T17 >= 0.5 * N17, "Business Achieved 50%", "Not 50%")) -> Not 50% | CI17: =IFERROR((T17/N17),) -> 0.14492754 | CJ17: =IFERROR(__xludf.DUMMYFUNCTION("""COMPUTED_VALUE"""),382) -> 382 | CK17: =IFERROR(__xludf.DUMMYFUNCTION("""COMPUTED_VALUE"""),470) -> 470 | CL17: =IFERROR(__xludf.DUMMYFUNCTION("""COMPUTED_VALUE"""),0) -> 0 | CM17: =AE17-SUM(CJ17:CL17) -> 0 | CP17: Maharashtra | CQ17: =COUNTIFS($B:$B,$CP17,$BG:$BG,"Secondary",$BA:$BA,"Active") -> 12 | CR17: =COUNTIFS($B:$B,$CP17,$BG:$BG,"Primary",$BA:$BA,"Active") -> 0 | CT17: =COUNTIFS(A:A,CS17,BA:BA,"Active") -> 0
A18: Lalan Kumar | B18: Maharashtra | C18: Amey Deodhar | D18: KARNATAKA, MAHARASHTRA | E18: Miraj (Mh) | F18: 42926 | G18: 0 | H18: 24000000 | I18: 20796267 | J18: 0 | K18: 156 | L18: 134 | M18: 16 | N18: 172 | O18: 38 | P18: 20102077 | Q18: 694190.5 | R18: 88 | S18: 9 | T18: 97 | U18: 0 | V18: 17 | W18: 25 | X18: 42 | Y18: 3 | Z18: 106 | AA18: 0 | AB18: 0 | AC18: 0 | AD18: 0 | AE18: 812 | AF18: 943 | AG18: 293 | AH18: =IFERROR(SUM(I18:J18)/AG18,"") -> 70977.021 | AI18: =IFERROR(AF18/AG18,"") -> 3.21843 | AJ18: 44575 | AK18: =AJ18*BD18 -> 534900 | AL18: 284111 | AM18: =IFERROR(SUM(AK18:AL18)/SUM(I18:J18),"") -> 0.039382597 | AN18: =IFERROR(I18/T18,"") -> 214394.51 | AO18: =IFERROR(SUM(I18:J18)/SUM(G18:H18),"") -> 0.86651113 | AP18: 0 | AQ18: 665 | AR18: 2219 | AS18: 4875.51 | AT18: 9 | AU18: 36 | AV18: 97 | AW18: 48 | AX18: 27 | AY18: =IFERROR(VLOOKUP(C18,#REF!,13,0),"") | BA18: =IF(ISBLANK(AZ18),"Active","LEFT" ) -> Active | BB18: =_xludf.ifs(F18<$BB$1,"Old",F18>$BB$1,"New") -> #NAME? | BC18: =_xludf.ifs(AO18<50%,"Below 50%",AO18<70%,"50%-70%",AO18<90%,"70%-90%",AO18<100%,"90%-100%",AO18>100%,"Above 100%") -> #NAME? | BD18: =MATCH($BD$2,{"Apr","May","Jun","Jul","Aug","Sep","Oct","Nov","Dec","Jan","Feb","Mar"},0) -> 12 | BF18: =M18-AT18 -> 7 | BG18: Secondary | BH18: =IFERROR(__xludf.DUMMYFUNCTION("""COMPUTED_VALUE"""),20081138) -> 20081138 | BI18: =IFERROR(__xludf.DUMMYFUNCTION("""COMPUTED_VALUE"""),16655458.01) -> 16655458 | BL18: =BK18*BD18 -> 0 | BM18: =H18+BL18 -> 24000000 | BO18: =IFERROR(__xludf.DUMMYFUNCTION("IFERROR(ArrayFormula(SUM(VLOOKUP($C18,importrange(""1MwNMVzWE3QBVOyJjKr3eFX-Sq1Ng0Q1sghWJbgbE_8g"",""ORDER BOOKING REPORT 2024-25!C:CV""),{16,23,30},0))))"),3414186.4) -> 3414186.4 | BP18: =IFERROR(__xludf.DUMMYFUNCTION("IFERROR(ArrayFormula(SUM(VLOOKUP($C18,importrange(""1MwNMVzWE3QBVOyJjKr3eFX-Sq1Ng0Q1sghWJbgbE_8g"",""ORDER BOOKING REPORT 2024-25!C:CV""),{37,44,51},0))))"),3785622.06) -> 3785622.1 | BQ18: =IFERROR(__xludf.DUMMYFUNCTION("IFERROR(ArrayFormula(SUM(VLOOKUP($C18,importrange(""1MwNMVzWE3QBVOyJjKr3eFX-Sq1Ng0Q1sghWJbgbE_8g"",""ORDER BOOKING REPORT 2024-25!C:CV""),{58,65,72},0))))"),4615195.56999999) -> 4615195.6 | BR18: =IFERROR(__xludf.DUMMYFUNCTION("IFERROR(ArrayFormula(SUM(VLOOKUP($C18,importrange(""1MwNMVzWE3QBVOyJjKr3eFX-Sq1Ng0Q1sghWJbgbE_8g"",""ORDER BOOKING REPORT 2024-25!C:CV""),{79,86,93},0))))"),4840453.98) -> 4840454 | BS18: =IFERROR(AY18/BM18,"") | BT18: =IFERROR(SUM(AK18:AL18)/AY18,"") | BU18: =BL18-G18 -> 0 | BV18: 44575 | BW18: Executive - Sales & Mkt. | BX18: 371 | BY18: =BV18-AJ18 -> 0 | CG18: =IF(N18<60,"Below 60"," ") | CH18: =IF(T18 = 0, "Not 50%", IF(T18 >= 0.5 * N18, "Business Achieved 50%", "Not 50%")) -> Business Achieved 50% | CI18: =IFERROR((T18/N18),) -> 0.56395349 | CJ18: =IFERROR(__xludf.DUMMYFUNCTION("""COMPUTED_VALUE"""),710) -> 710 | CK18: =IFERROR(__xludf.DUMMYFUNCTION("""COMPUTED_VALUE"""),102) -> 102 | CL18: =IFERROR(__xludf.DUMMYFUNCTION("""COMPUTED_VALUE"""),0) -> 0 | CM18: =AE18-SUM(CJ18:CL18) -> 0 | CP18: Maharashtra 2 | CQ18: =COUNTIFS($B:$B,$CP18,$BG:$BG,"Secondary",$BA:$BA,"Active") -> 3 | CR18: =COUNTIFS($B:$B,$CP18,$BG:$BG,"Primary",$BA:$BA,"Active") -> 0 | CT18: =COUNTIFS(A:A,CS18,BA:BA,"Active") -> 0
