Workbook

Sheet INDEX
A1: https://docs.google.com/spreadsheets/d/15fA3q2UYXXJTnJSsdBETDZNP24tMnVOMP19XKJNjnmk/edit#gid=886997750 | B1: TOTAL | C1: =SUM(C3:C10) -> 1075 | D1: =SUM(D3:D10) -> #REF! | E1: =SUM(E3:E10) -> #REF! | F1: =IFERROR(E1-D1,"")/E1 -> #REF!
C2: No. of Items | D2: Old MRP | E2: New MRP | F2: Diff.
B3: CPVC PIPE | C3: 20 | D3: =sum(' CPVC PIPE'!F11,' CPVC PIPE'!F43,' CPVC PIPE'!F18,' CPVC PIPE'!F50) -> 71566 | E3: =sum(#REF!,#REF!,#REF!,#REF!) -> #REF! | F3: =IFERROR(E3-D3,"")/E3 -> #REF! | Z3: A-503
B4: CPVC FITTING | C4: 252 | D4: =SUM('C Fittings'!F11,'C Fittings'!F17,'C Fittings'!F20,'C Fittings'!F25,'C Fittings'!F33,'C Fittings'!F42,'C Fittings'!F48,'C Fittings'!F51,'C Fittings'!F65,'C Fittings'!F76,'C Fittings'!F85,'C Fittings'!F91,'C Fittings'!F94,'C Fittings'!F108,'C Fittings'!F115,'C Fittings'!F124,'C Fittings'!F130,'C Fittings'!F145,'C Fittings'!F155,'C Fittings'!F166,'C Fittings'!F172,'C Fittings'!F182,'C Fittings'!F188,'C Fittings'!F193,'C Fittings'!F207,'C Fittings'!F218,'C Fittings'!F226,'C Fittings'!F234,'C Fittings'!F242,'C Fittings'!F253,'C Fittings'!F263,'C Fittings'!F273,'C Fittings'!F279,#REF!,'C Fittings'!F287,'C Fittings'!F295,'C Fittings'!F303,'C Fittings'!F298,'C Fittings'!F310,#REF!,'C Fittings'!F318,'C Fittings'!F324,'C Fittings'!F330,'C Fittings'!F339,'C Fittings'!F348,'C Fittings'!F353,'C Fittings'!F361,'C Fittings'!F370,'C Fittings'!F379,'C Fittings'!F388) -> #REF! | E4: =SUM(#REF!,#REF!,#REF!,#REF!,#REF!,#REF!,#REF!,#REF!,#REF!,#REF!,#REF!,#REF!,#REF!,#REF!,#REF!,#REF!,#REF!,#REF!,#REF!,#REF!,#REF!,#REF!,#REF!,#REF!,#REF!,#REF!,#REF!,#REF!,#REF!,#REF!,#REF!,#REF!,#REF!,#REF!,#REF!,#REF!,#REF!,#REF!,#REF!,#REF!,#REF!,#REF!,#REF!,#REF!,#REF!,#REF!,#REF!,#REF!,#REF!,#REF!) -> #REF! | F4: =IFERROR(E4-D4,"")/E4 -> #REF! | Z4: A-504
B5: UPVC PIPE | C5: 20 | D5: =SUM('UPVC PIPE'!F15,'UPVC PIPE'!F50) -> 33523 | E5: =SUM(#REF!,#REF!) -> #REF! | F5: =IFERROR(E5-D5,"")/E5 -> #REF! | Z5: A-702
B6: UPVC FITTING | C6: 263 | D6: =SUM('U Fittings'!F15,'U Fittings'!F18,'U Fittings'!F30,'U Fittings'!F38,'U Fittings'!F46,'U Fittings'!F55,'U Fittings'!F61,'U Fittings'!F64,'U Fittings'!F82,'U Fittings'!F94,'U Fittings'!F112,'U Fittings'!F122,'U Fittings'!F140,'U Fittings'!F149,'U Fittings'!F155,'U Fittings'!F158,'U Fittings'!F167,'U Fittings'!F173,'U Fittings'!F182,'U Fittings'!F188,'U Fittings'!F199,'U Fittings'!F205,'U Fittings'!F216,'U Fittings'!F227,'U Fittings'!F234,'U Fittings'!F243,'U Fittings'!F252,'U Fittings'!F261,'U Fittings'!F269,'U Fittings'!F277,'U Fittings'!F285,'U Fittings'!F296,'U Fittings'!F303,'U Fittings'!F311,'U Fittings'!F317,'U Fittings'!F323,#REF!,'U Fittings'!F332,'U Fittings'!F341,'U Fittings'!F349,'U Fittings'!F358,'U Fittings'!F367,'U Fittings'!F376,'U Fittings'!F385) -> #REF! | E6: =SUM(#REF!,#REF!,#REF!,#REF!,#REF!,#REF!,#REF!,#REF!,#REF!,#REF!,#REF!,#REF!,#REF!,#REF!,#REF!,#REF!,#REF!,#REF!,#REF!,#REF!,#REF!,#REF!,#REF!,#REF!,#REF!,#REF!,#REF!,#REF!,#REF!,#REF!,#REF!,#REF!,#REF!,#REF!,#REF!,#REF!,#REF!,#REF!,#REF!,#REF!,#REF!,#REF!,#REF!,#REF!) -> #REF! | F6: =IFERROR(E6-D6,"")/E6 -> #REF! | Z6: A-703
B7: SWR PIPE | C7: 160 | D7: =SUM('SWR PIPE'!H45,'SWR PIPE'!S45,'SWR PIPE'!H88,'SWR PIPE'!S88) -> 184679.15 | E7: =SUM(#REF!,#REF!,#REF!,#REF!) -> #REF! | F7: =IFERROR(E7-D7,"")/E7 -> #REF! | Z7: A-704
B8: SWR FITTING | C8: 137 | D8: =SUM('SWR Fittings'!F9,'SWR Fittings'!F16,'SWR Fittings'!F21,'SWR Fittings'!F28,'SWR Fittings'!F33,'SWR Fittings'!F40,'SWR Fittings'!F47,'SWR Fittings'!F52,'SWR Fittings'!F59,'SWR Fittings'!F70,'SWR Fittings'!F77,'SWR Fittings'!F84,'SWR Fittings'!F91,'SWR Fittings'!F98,'SWR Fittings'!F103,'SWR Fittings'!F106,'SWR Fittings'!F111,'SWR Fittings'!F116,'SWR Fittings'!F123,'SWR Fittings'!F128,'SWR Fittings'!F131,'SWR Fittings'!F136,'SWR Fittings'!F142,'SWR Fittings'!F150,'SWR Fittings'!F157,'SWR Fittings'!F162,'SWR Fittings'!F169,'SWR Fittings'!F176,'SWR Fittings'!F183,'SWR Fittings'!F186,'SWR Fittings'!F199,'SWR Fittings'!F204,'SWR Fittings'!F209,'SWR Fittings'!F212,'SWR Fittings'!F226,'SWR Fittings'!F235,'SWR Fittings'!F242,'SWR Fittings'!F249,'SWR Fittings'!F256,'SWR Fittings'!F263,'SWR Fittings'!F270,'SWR Fittings'!F277,'SWR Fittings'!F284,'SWR Fittings'!F291) -> 30946.5 | E8: =SUM(#REF!,#REF!,#REF!,#REF!,#REF!,#REF!,#REF!,#REF!,#REF!,#REF!,#REF!,#REF!,#REF!,#REF!,#REF!,#REF!,#REF!,#REF!,#REF!,#REF!,#REF!,#REF!,#REF!,#REF!,#REF!,#REF!,#REF!,#REF!,#REF!,#REF!,#REF!,#REF!,#REF!,#REF!,#REF!,#REF!,#REF!,#REF!,#REF!,#REF!,#REF!,#REF!,#REF!,#REF!) -> #REF! | F8: =IFERROR(E8-D8,"")/E8 -> #REF! | Z8: A-227
B9: AGRI PIPE | C9: 123 | D9: =SUM('AGRI PIPE'!F46,'AGRI PIPE'!F90,'AGRI PIPE'!F134) -> 380189 | E9: =SUM(#REF!,#REF!,#REF!) -> #REF! | F9: =IFERROR(E9-D9,"")/E9 -> #REF! | Z9: A-228
B10: AGRI FITTING | C10: 100 | D10: =SUM('AGRI Fittings'!E49,'AGRI Fittings'!E60,'AGRI Fittings'!E71,'AGRI Fittings'!E87,'AGRI Fittings'!E101,'AGRI Fittings'!E113,'AGRI Fittings'!E118,'AGRI Fittings'!E128,'AGRI Fittings'!E136,'AGRI Fittings'!E144,'AGRI Fittings'!E152) -> 20599.49 | E10: =SUM(#REF!,#REF!,#REF!,#REF!,#REF!,#REF!,#REF!,#REF!,#REF!,#REF!,#REF!) -> #REF! | F10: =IFERROR(E10-D10,"")/E10 -> #REF! | Z10: A-229
B11: AGRI SMART FITTING | C11: 33 | E11: =SUM(#REF!,#REF!,#REF!,#REF!,#REF!,#REF!,#REF!) -> #REF! | F11: =IFERROR(E11-D11,"")/E11 -> #REF! | Z11: A-327
Z12: A-328
B13: TTS-01 | Z13: A-329
B14: TTS-02 | Z14: A-427
B15: TTS-03 | Z15: A-428
Z16: A-429

Sheet MASTER
A1: S.NO. | B1: GROUP | C1: CODE | D1: NAME | E1: WEIGHT | F1: OLD MRP | G1: NEW MRP
A2: 1 | B2: CPVC PIPE | C2: PS-1 | D2: Pipe SDR 11 (3 MTR) 1⁄2 inch 15 mm | E2: =VLOOKUP(C2,' CPVC PIPE'!$C$5:$G2469,5,0) -> 0.36 | F2: =VLOOKUP(C2,' CPVC PIPE'!$C$5:$F2469,4,0) -> 237 | G2: =VLOOKUP(C2,' CPVC PIPE'!$C$5:$I2469,7,0) -> 237
A3: =A2+1 -> 2 | B3: CPVC PIPE | C3: PS-2 | D3: Pipe SDR 11 (3 MTR) 3⁄4 inch 20 mm | E3: =VLOOKUP(C3,' CPVC PIPE'!$C$5:$G2469,5,0) -> 0.62 | F3: =VLOOKUP(C3,' CPVC PIPE'!$C$5:$F2469,4,0) -> 369 | G3: =VLOOKUP(C3,' CPVC PIPE'!$C$5:$I2469,7,0) -> 369
A4: =A3+1 -> 3 | B4: CPVC PIPE | C4: PS-3 | D4: Pipe SDR 11 (3 MTR) 1 inch 25 mm | E4: =VLOOKUP(C4,' CPVC PIPE'!$C$5:$G2469,5,0) -> 1 | F4: =VLOOKUP(C4,' CPVC PIPE'!$C$5:$F2469,4,0) -> 597 | G4: =VLOOKUP(C4,' CPVC PIPE'!$C$5:$I2469,7,0) -> 597
A5: =A4+1 -> 4 | B5: CPVC PIPE | C5: PS-4 | D5: Pipe SDR 11 (3 MTR) 1 1⁄4 inch 32 mm | E5: =VLOOKUP(C5,' CPVC PIPE'!$C$5:$G2469,5,0) -> 1.5 | F5: =VLOOKUP(C5,' CPVC PIPE'!$C$5:$F2469,4,0) -> 927 | G5: =VLOOKUP(C5,' CPVC PIPE'!$C$5:$I2469,7,0) -> 927
A6: =A5+1 -> 5 | B6: CPVC PIPE | C6: PS-5 | D6: Pipe SDR 11 (3 MTR) 1 1⁄2 inch 40 mm | E6: =VLOOKUP(C6,' CPVC PIPE'!$C$5:$G2469,5,0) -> 2.05 | F6: =VLOOKUP(C6,' CPVC PIPE'!$C$5:$F2469,4,0) -> 1287 | G6: =VLOOKUP(C6,' CPVC PIPE'!$C$5:$I2469,7,0) -> 1287
A7: =A6+1 -> 6 | B7: CPVC PIPE | C7: PS-6 | D7: Pipe SDR 11 (3 MTR) 2 inch 50 mm | E7: =VLOOKUP(C7,' CPVC PIPE'!$C$5:$G2469,5,0) -> 3.5 | F7: =VLOOKUP(C7,' CPVC PIPE'!$C$5:$F2469,4,0) -> 2196 | G7: =VLOOKUP(C7,' CPVC PIPE'!$C$5:$I2469,7,0) -> 2196
A8: =A7+1 -> 7 | B8: CPVC PIPE | C8: PS-7 | D8: Pipe SCH 80 (3 MTR) 2 1⁄2 inch 65 mm | E8: =VLOOKUP(C8,' CPVC PIPE'!$C$5:$G2469,5,0) -> 6.326 | F8: =VLOOKUP(C8,' CPVC PIPE'!$C$5:$F2469,4,0) -> 4480 | G8: =VLOOKUP(C8,' CPVC PIPE'!$C$5:$I2469,7,0) -> 4480
A9: =A8+1 -> 8 | B9: CPVC PIPE | C9: PS-8 | D9: Pipe SCH 80 (3 MTR) 3 inch 80 mm | E9: =VLOOKUP(C9,' CPVC PIPE'!$C$5:$G2469,5,0) -> 8.473 | F9: =VLOOKUP(C9,' CPVC PIPE'!$C$5:$F2469,4,0) -> 5980 | G9: =VLOOKUP(C9,' CPVC PIPE'!$C$5:$I2469,7,0) -> 5980
A10: =A9+1 -> 9 | B10: CPVC PIPE | C10: PS-9 | D10: Pipe SCH 80 (3 MTR) 4 inch 100 mm | E10: =VLOOKUP(C10,' CPVC PIPE'!$C$5:$G2469,5,0) -> 12.39 | F10: =VLOOKUP(C10,' CPVC PIPE'!$C$5:$F2469,4,0) -> 8680 | G10: =VLOOKUP(C10,' CPVC PIPE'!$C$5:$I2469,7,0) -> 8680
A11: =A10+1 -> 10 | B11: CPVC PIPE | C11: PS-10 | D11: Pipe SCH 80 (3 MTR) 6 inch 150 mm | E11: =VLOOKUP(C11,' CPVC PIPE'!$C$5:$G2469,5,0) -> 23.651 | F11: =VLOOKUP(C11,' CPVC PIPE'!$C$5:$F2469,4,0) -> 16800 | G11: =VLOOKUP(C11,' CPVC PIPE'!$C$5:$I2469,7,0) -> 16800
A12: =A11+1 -> 11 | B12: CPVC PIPE | C12: PS-11 | D12: Pipe SDR 13.5 (3 MTR) 1⁄2 inch 15 mm | E12: =VLOOKUP(C12,' CPVC PIPE'!$C$5:$G2469,5,0) -> 0.33 | F12: =VLOOKUP(C12,' CPVC PIPE'!$C$5:$F2469,4,0) -> 219 | G12: =VLOOKUP(C12,' CPVC PIPE'!$C$5:$I2469,7,0) -> 219
A13: =A12+1 -> 12 | B13: CPVC PIPE | C13: PS-12 | D13: Pipe SDR 13.5 (3 MTR) 3⁄4 inch 20 mm | E13: =VLOOKUP(C13,' CPVC PIPE'!$C$5:$G2469,5,0) -> 0.53 | F13: =VLOOKUP(C13,' CPVC PIPE'!$C$5:$F2469,4,0) -> 324 | G13: =VLOOKUP(C13,' CPVC PIPE'!$C$5:$I2469,7,0) -> 324
A14: =A13+1 -> 13 | B14: CPVC PIPE | C14: PS-13 | D14: Pipe SDR 13.5 (3 MTR) 1 inch 25 mm | E14: =VLOOKUP(C14,' CPVC PIPE'!$C$5:$G2469,5,0) -> 0.83 | F14: =VLOOKUP(C14,' CPVC PIPE'!$C$5:$F2469,4,0) -> 498 | G14: =VLOOKUP(C14,' CPVC PIPE'!$C$5:$I2469,7,0) -> 498
A15: =A14+1 -> 14 | B15: CPVC PIPE | C15: PS-14 | D15: Pipe SDR 13.5 (3 MTR) 1 1⁄4 inch 32 mm | E15: =VLOOKUP(C15,' CPVC PIPE'!$C$5:$G2469,5,0) -> 1.25 | F15: =VLOOKUP(C15,' CPVC PIPE'!$C$5:$F2469,4,0) -> 778 | G15: =VLOOKUP(C15,' CPVC PIPE'!$C$5:$I2469,7,0) -> 778
A16: =A15+1 -> 15 | B16: CPVC PIPE | C16: PS-15 | D16: Pipe SDR 13.5 (3 MTR) 1 1⁄2 inch 40 mm | E16: =VLOOKUP(C16,' CPVC PIPE'!$C$5:$G2469,5,0) -> 1.75 | F16: =VLOOKUP(C16,' CPVC PIPE'!$C$5:$F2469,4,0) -> 1092 | G16: =VLOOKUP(C16,' CPVC PIPE'!$C$5:$I2469,7,0) -> 1092
A17: =A16+1 -> 16 | B17: CPVC PIPE | C17: PS-16 | D17: Pipe SDR 13.5 (3 MTR) 2 inch 50 mm | E17: =VLOOKUP(C17,' CPVC PIPE'!$C$5:$G2469,5,0) -> 2.9 | F17: =VLOOKUP(C17,' CPVC PIPE'!$C$5:$F2469,4,0) -> 1842 | G17: =VLOOKUP(C17,' CPVC PIPE'!$C$5:$I2469,7,0) -> 1842
A18: =A17+1 -> 17 | B18: CPVC PIPE | C18: PS-17 | D18: Pipe SCH 40 (3 MTR) 2 1⁄2 inch 65 mm | E18: =VLOOKUP(C18,' CPVC PIPE'!$C$5:$G2469,5,0) -> 4.774 | F18: =VLOOKUP(C18,' CPVC PIPE'!$C$5:$F2469,4,0) -> 3390 | G18: =VLOOKUP(C18,' CPVC PIPE'!$C$5:$I2469,7,0) -> 3390
A19: =A18+1 -> 18 | B19: CPVC PIPE | C19: PS-18 | D19: Pipe SCH 40 (3 MTR) 3 inch 80 mm | E19: =VLOOKUP(C19,' CPVC PIPE'!$C$5:$G2469,5,0) -> 6.248 | F19: =VLOOKUP(C19,' CPVC PIPE'!$C$5:$F2469,4,0) -> 4490 | G19: =VLOOKUP(C19,' CPVC PIPE'!$C$5:$I2469,7,0) -> 4490
A20: =A19+1 -> 19 | B20: CPVC PIPE | C20: PS-19 | D20: Pipe SCH 40 (3 MTR) 4 inch 100 mm | E20: =VLOOKUP(C20,' CPVC PIPE'!$C$5:$G2469,5,0) -> 8.9 | F20: =VLOOKUP(C20,' CPVC PIPE'!$C$5:$F2469,4,0) -> 6390 | G20: =VLOOKUP(C20,' CPVC PIPE'!$C$5:$I2469,7,0) -> 6390
A21: =A20+1 -> 20 | B21: CPVC PIPE | C21: PS-20 | D21: Pipe SCH 40 (3 MTR) 6 inch 150 mm | E21: =VLOOKUP(C21,' CPVC PIPE'!$C$5:$G2469,5,0) -> 15.666 | F21: =VLOOKUP(C21,' CPVC PIPE'!$C$5:$F2469,4,0) -> 10990 | G21: =VLOOKUP(C21,' CPVC PIPE'!$C$5:$I2469,7,0) -> 10990
A22: =A21+1 -> 21 | B22: CPVC PIPE | C22: PS-1S | D22: Pipe SDR 11 (5 MTR) 1⁄2 inch 15 mm | E22: =VLOOKUP(C22,' CPVC PIPE'!$C$5:$G2469,5,0) -> 0.6 | F22: =VLOOKUP(C22,' CPVC PIPE'!$C$5:$F2469,4,0) -> 395 | G22: =VLOOKUP(C22,' CPVC PIPE'!$C$5:$I2469,7,0) -> 395
A23: =A22+1 -> 22 | B23: CPVC PIPE | C23: PS-2S | D23: Pipe SDR 11 (5 MTR) 3⁄4 inch 20 mm | E23: =VLOOKUP(C23,' CPVC PIPE'!$C$5:$G2469,5,0) -> 1.0333333 | F23: =VLOOKUP(C23,' CPVC PIPE'!$C$5:$F2469,4,0) -> 615 | G23: =VLOOKUP(C23,' CPVC PIPE'!$C$5:$I2469,7,0) -> 615
A24: =A23+1 -> 23 | B24: CPVC PIPE | C24: PS-3S | D24: Pipe SDR 11 (5 MTR) 1 inch 25 mm | E24: =VLOOKUP(C24,' CPVC PIPE'!$C$5:$G2469,5,0) -> 1.6666667 | F24: =VLOOKUP(C24,' CPVC PIPE'!$C$5:$F2469,4,0) -> 995 | G24: =VLOOKUP(C24,' CPVC PIPE'!$C$5:$I2469,7,0) -> 995
A25: =A24+1 -> 24 | B25: CPVC PIPE | C25: PS-4S | D25: Pipe SDR 11 (5 MTR) 1 1⁄4 inch 32 mm | E25: =VLOOKUP(C25,' CPVC PIPE'!$C$5:$G2469,5,0) -> 2.5 | F25: =VLOOKUP(C25,' CPVC PIPE'!$C$5:$F2469,4,0) -> 1545 | G25: =VLOOKUP(C25,' CPVC PIPE'!$C$5:$I2469,7,0) -> 1545
A26: =A25+1 -> 25 | B26: CPVC PIPE | C26: PS-5S | D26: Pipe SDR 11 (5 MTR) 1 1⁄2 inch 40 mm | E26: =VLOOKUP(C26,' CPVC PIPE'!$C$5:$G2469,5,0) -> 3.4166667 | F26: =VLOOKUP(C26,' CPVC PIPE'!$C$5:$F2469,4,0) -> 2145 | G26: =VLOOKUP(C26,' CPVC PIPE'!$C$5:$I2469,7,0) -> 2145
A27: =A26+1 -> 26 | B27: CPVC PIPE | C27: PS-6S | D27: Pipe SDR 11 (5 MTR) 2 inch 50 mm | E27: =VLOOKUP(C27,' CPVC PIPE'!$C$5:$G2469,5,0) -> 5.8333333 | F27: =VLOOKUP(C27,' CPVC PIPE'!$C$5:$F2469,4,0) -> 3660 | G27: =VLOOKUP(C27,' CPVC PIPE'!$C$5:$I2469,7,0) -> 3660
A28: =A27+1 -> 27 | B28: CPVC PIPE | C28: PS-7S | D28: Pipe SCH 80 (5 MTR) 2 1⁄2 inch 65 mm | E28: =VLOOKUP(C28,' CPVC PIPE'!$C$5:$G2469,5,0) -> 10.543333 | F28: =VLOOKUP(C28,' CPVC PIPE'!$C$5:$F2469,4,0) -> 7466.67 | G28: =VLOOKUP(C28,' CPVC PIPE'!$C$5:$I2469,7,0) -> 7466.67
A29: =A28+1 -> 28 | B29: CPVC PIPE | C29: PS-8S | D29: Pipe SCH 80 (5 MTR) 3 inch 80 mm | E29: =VLOOKUP(C29,' CPVC PIPE'!$C$5:$G2469,5,0) -> 14.121667 | F29: =VLOOKUP(C29,' CPVC PIPE'!$C$5:$F2469,4,0) -> 9966.67 | G29: =VLOOKUP(C29,' CPVC PIPE'!$C$5:$I2469,7,0) -> 9966.67
A30: =A29+1 -> 29 | B30: CPVC PIPE | C30: PS-9S | D30: Pipe SCH 80 (5 MTR) 4 inch 100 mm | E30: =VLOOKUP(C30,' CPVC PIPE'!$C$5:$G2469,5,0) -> 20.65 | F30: =VLOOKUP(C30,' CPVC PIPE'!$C$5:$F2469,4,0) -> 14466.67 | G30: =VLOOKUP(C30,' CPVC PIPE'!$C$5:$I2469,7,0) -> 14466.67
A31: =A30+1 -> 30 | B31: CPVC PIPE | C31: PS-10S | D31: Pipe SCH 80 (5 MTR) 6 inch 150 mm | E31: =VLOOKUP(C31,' CPVC PIPE'!$C$5:$G2469,5,0) -> 39.418333 | F31: =VLOOKUP(C31,' CPVC PIPE'!$C$5:$F2469,4,0) -> 28000 | G31: =VLOOKUP(C31,' CPVC PIPE'!$C$5:$I2469,7,0) -> 28000
A32: =A31+1 -> 31 | B32: CPVC PIPE | C32: PS-11S | D32: Pipe SDR 13.5 (5 MTR) 1⁄2 inch 15 mm | E32: =VLOOKUP(C32,' CPVC PIPE'!$C$5:$G2469,5,0) -> 0.66 | F32: =VLOOKUP(C32,' CPVC PIPE'!$C$5:$F2469,4,0) -> 365 | G32: =VLOOKUP(C32,' CPVC PIPE'!$C$5:$I2469,7,0) -> 365
A33: =A32+1 -> 32 | B33: CPVC PIPE | C33: PS-12S | D33: Pipe SDR 13.5 (5 MTR) 3⁄4 inch 20 mm | E33: =VLOOKUP(C33,' CPVC PIPE'!$C$5:$G2469,5,0) -> 1.06 | F33: =VLOOKUP(C33,' CPVC PIPE'!$C$5:$F2469,4,0) -> 540 | G33: =VLOOKUP(C33,' CPVC PIPE'!$C$5:$I2469,7,0) -> 540
A34: =A33+1 -> 33 | B34: CPVC PIPE | C34: PS-13S | D34: Pipe SDR 13.5 (5 MTR) 1 inch 25 mm | E34: =VLOOKUP(C34,' CPVC PIPE'!$C$5:$G2469,5,0) -> 1.66 | F34: =VLOOKUP(C34,' CPVC PIPE'!$C$5:$F2469,4,0) -> 830 | G34: =VLOOKUP(C34,' CPVC PIPE'!$C$5:$I2469,7,0) -> 830
A35: =A34+1 -> 34 | B35: CPVC PIPE | C35: PS-14S | D35: Pipe SDR 13.5 (5 MTR) 1 1⁄4 inch 32 mm | E35: =VLOOKUP(C35,' CPVC PIPE'!$C$5:$G2469,5,0) -> 2.5 | F35: =VLOOKUP(C35,' CPVC PIPE'!$C$5:$F2469,4,0) -> 1296.67 | G35: =VLOOKUP(C35,' CPVC PIPE'!$C$5:$I2469,7,0) -> 1296.67
A36: =A35+1 -> 35 | B36: CPVC PIPE | C36: PS-15S | D36: Pipe SDR 13.5 (5 MTR) 1 1⁄2 inch 40 mm | E36: =VLOOKUP(C36,' CPVC PIPE'!$C$5:$G2469,5,0) -> 3.5 | F36: =VLOOKUP(C36,' CPVC PIPE'!$C$5:$F2469,4,0) -> 1820 | G36: =VLOOKUP(C36,' CPVC PIPE'!$C$5:$I2469,7,0) -> 1820
A37: =A36+1 -> 36 | B37: CPVC PIPE | C37: PS-16S | D37: Pipe SDR 13.5 (5 MTR) 2 inch 50 mm | E37: =VLOOKUP(C37,' CPVC PIPE'!$C$5:$G2469,5,0) -> 5.8 | F37: =VLOOKUP(C37,' CPVC PIPE'!$C$5:$F2469,4,0) -> 3070 | G37: =VLOOKUP(C37,' CPVC PIPE'!$C$5:$I2469,7,0) -> 3070
A38: =A37+1 -> 37 | B38: CPVC PIPE | C38: PS-17S | D38: Pipe SCH 40 (5 MTR) 2 1⁄2 inch 65 mm | E38: =VLOOKUP(C38,' CPVC PIPE'!$C$5:$G2469,5,0) -> 9.548 | F38: =VLOOKUP(C38,' CPVC PIPE'!$C$5:$F2469,4,0) -> 5650 | G38: =VLOOKUP(C38,' CPVC PIPE'!$C$5:$I2469,7,0) -> 5650
A39: =A38+1 -> 38 | B39: CPVC PIPE | C39: PS-18S | D39: Pipe SCH 40 (5 MTR) 3 inch 80 mm | E39: =VLOOKUP(C39,' CPVC PIPE'!$C$5:$G2469,5,0) -> 12.496 | F39: =VLOOKUP(C39,' CPVC PIPE'!$C$5:$F2469,4,0) -> 7483.33 | G39: =VLOOKUP(C39,' CPVC PIPE'!$C$5:$I2469,7,0) -> 7483.33
A40: =A39+1 -> 39 | B40: CPVC PIPE | C40: PS-19S | D40: Pipe SCH 40 (5 MTR) 4 inch 100 mm | E40: =VLOOKUP(C40,' CPVC PIPE'!$C$5:$G2469,5,0) -> 17.8 | F40: =VLOOKUP(C40,' CPVC PIPE'!$C$5:$F2469,4,0) -> 10650 | G40: =VLOOKUP(C40,' CPVC PIPE'!$C$5:$I2469,7,0) -> 10650
...

Sheet  CPVC PIPE
A1: https://docs.google.com/spreadsheets/d/1TX-9XGjxpqHQahWoH9tryIBWer6h9pqOFfc8QE1-51Y/edit#gid=1686480931
B2: S.NO. | C2: ITEM CODE | D2: Size (in) | E2: Size (mm) | F2: MRP as on 1st May, 2024 | G2: WEIGHT | H2: KG COST | I2: NEW MRP
B4: Pipe SDR 11 (3 MTR)
B5: 1 | C5: PS-1 | D5: 1⁄2 | E5: 15 | F5: 237 | G5: 0.36 | H5: =IFERROR(F5/G5,"") -> 658.33333 | I5: 237
B6: 2 | C6: PS-2 | D6: 3⁄4 | E6: 20 | F6: 369 | G6: 0.62 | H6: =IFERROR(F6/G6,"") -> 595.16129 | I6: 369
B7: 3 | C7: PS-3 | D7: 1 | E7: 25 | F7: 597 | G7: 1 | H7: =IFERROR(F7/G7,"") -> 597 | I7: 597
B8: 4 | C8: PS-4 | D8: 1 1⁄4 | E8: 32 | F8: 927 | G8: 1.5 | H8: =IFERROR(F8/G8,"") -> 618 | I8: 927
B9: 5 | C9: PS-5 | D9: 1 1⁄2 | E9: 40 | F9: 1287 | G9: 2.05 | H9: =IFERROR(F9/G9,"") -> 627.80488 | I9: 1287
B10: 6 | C10: PS-6 | D10: 2 | E10: 50 | F10: 2196 | G10: 3.5 | H10: =IFERROR(F10/G10,"") -> 627.42857 | I10: 2196
B11: TOTAL | F11: =SUM(F5:F10) -> 5613 | I11: =SUM(I5:I10) -> 5613
B13: Pipe SCH 80 (3 MTR)
B14: 7 | C14: PS-7 | D14: 2 1⁄2 | E14: 65 | F14: 4480 | G14: 6.326 | H14: =IFERROR(F14/G14,"") -> 708.18843 | I14: 4480
B15: 8 | C15: PS-8 | D15: 3 | E15: 80 | F15: 5980 | G15: 8.473 | H15: =IFERROR(F15/G15,"") -> 705.77127 | I15: 5980
B16: 9 | C16: PS-9 | D16: 4 | E16: 100 | F16: 8680 | G16: 12.39 | H16: =IFERROR(F16/G16,"") -> 700.56497 | I16: 8680
B17: 10 | C17: PS-10 | D17: 6 | E17: 150 | F17: 16800 | G17: 23.651 | H17: =IFERROR(F17/G17,"") -> 710.32937 | I17: 16800
B18: TOTAL | F18: =SUM(F14:F17) -> 35940 | I18: =SUM(I14:I17) -> 35940
B20: Pipe SDR 11 (5 MTR)
B21: 11 | C21: PS-1S | D21: 1⁄2 | E21: 15 | F21: 395 | G21: =(G5/3)*5 -> 0.6 | H21: =IFERROR(F21/G21,"") -> 658.33333 | I21: 395
B22: 12 | C22: PS-2S | D22: 3⁄4 | E22: 20 | F22: 615 | G22: =(G6/3)*5 -> 1.0333333 | H22: =IFERROR(F22/G22,"") -> 595.16129 | I22: 615
B23: 13 | C23: PS-3S | D23: 1 | E23: 25 | F23: 995 | G23: =(G7/3)*5 -> 1.6666667 | H23: =IFERROR(F23/G23,"") -> 597 | I23: 995
B24: 14 | C24: PS-4S | D24: 1 1⁄4 | E24: 32 | F24: 1545 | G24: =(G8/3)*5 -> 2.5 | H24: =IFERROR(F24/G24,"") -> 618 | I24: 1545
B25: 15 | C25: PS-5S | D25: 1 1⁄2 | E25: 40 | F25: 2145 | G25: =(G9/3)*5 -> 3.4166667 | H25: =IFERROR(F25/G25,"") -> 627.80488 | I25: 2145
B26: 16 | C26: PS-6S | D26: 2 | E26: 50 | F26: 3660 | G26: =(G10/3)*5 -> 5.8333333 | H26: =IFERROR(F26/G26,"") -> 627.42857 | I26: 3660
B27: TOTAL | F27: =SUM(F21:F26) -> 9355 | I27: =SUM(I21:I26) -> 9355
B29: Pipe SCH 80 (5 MTR)
B30: 17 | C30: PS-7S | D30: 2 1⁄2 | E30: 65 | F30: 7466.67 | G30: =(G14/3)*5 -> 10.543333 | H30: =IFERROR(F30/G30,"") -> 708.18874 | I30: 7466.67
B31: 18 | C31: PS-8S | D31: 3 | E31: 80 | F31: 9966.67 | G31: =(G15/3)*5 -> 14.121667 | H31: =IFERROR(F31/G31,"") -> 705.77151 | I31: 9966.67
B32: 19 | C32: PS-9S | D32: 4 | E32: 100 | F32: 14466.67 | G32: =(G16/3)*5 -> 20.65 | H32: =IFERROR(F32/G32,"") -> 700.56513 | I32: 14466.67
B33: 20 | C33: PS-10S | D33: 6 | E33: 150 | F33: 28000 | G33: =(G17/3)*5 -> 39.418333 | H33: =IFERROR(F33/G33,"") -> 710.32937 | I33: 28000
B34: TOTAL | F34: =SUM(F30:F33) -> 59900.01 | I34: =SUM(I30:I33) -> 59900.01
B36: Pipe SDR 13.5 (3 MTR)
B37: 21 | C37: PS-11 | D37: 1⁄2 | E37: 15 | F37: 219 | G37: 0.33 | H37: =IFERROR(F37/G37,"") -> 663.63636 | I37: 219
B38: 22 | C38: PS-12 | D38: 3⁄4 | E38: 20 | F38: 324 | G38: 0.53 | H38: =IFERROR(F38/G38,"") -> 611.32075 | I38: 324
B39: 23 | C39: PS-13 | D39: 1 | E39: 25 | F39: 498 | G39: 0.83 | H39: =IFERROR(F39/G39,"") -> 600 | I39: 498
B40: 24 | C40: PS-14 | D40: 1 1⁄4 | E40: 32 | F40: 778 | G40: 1.25 | H40: =IFERROR(F40/G40,"") -> 622.4 | I40: 778
B41: 25 | C41: PS-15 | D41: 1 1⁄2 | E41: 40 | F41: 1092 | G41: 1.75 | H41: =IFERROR(F41/G41,"") -> 624 | I41: 1092
B42: 26 | C42: PS-16 | D42: 2 | E42: 50 | F42: 1842 | G42: 2.9 | H42: =IFERROR(F42/G42,"") -> 635.17241 | I42: 1842
B43: TOTAL | F43: =SUM(F37:F42) -> 4753 | I43: =SUM(I37:I42) -> 4753
B45: Pipe SCH 40 (3 MTR)
B46: 27 | C46: PS-17 | D46: 2 1⁄2 | E46: 65 | F46: 3390 | G46: 4.774 | H46: =IFERROR(F46/G46,"") -> 710.09636 | I46: 3390
...

Sheet C Fittings
A1: FPP
B2: S.NO. | C2: Size (in) | D2: Size (mm) | E2: ITEM CODE | F2: =' CPVC PIPE'!F2 -> MRP as on 1st May, 2024 | G2: WEIGHT | H2: BRASS | I2: WEIGHT WITH BRASS | J2: KG COST | K2: G*250 | L2: H*750 | M2: K+L | N2: O/M | O2: MRP as on 1st Feb, 2026 | P2: CONCEALED COST
B4: Elbow 90⁰
A5: =$B$4&C5 -> Elbow 90⁰1⁄2 | B5: 1 | C5: 1⁄2 | D5: 15 | E5: C51 | F5: 16.8 | G5: =IFERROR(__xludf.DUMMYFUNCTION("ArrayFormula(IFERROR(VLOOKUP(E5,IMPORTRANGE(""https://docs.google.com/spreadsheets/d/1xZyKy-UzMmtPDLpV5jQdYum1LtbR8XKDuasLSjmBRMI/edit#gid=1241094406"",""COMBINED DATA!E3:L""),{7,8},0)))"),0.011) -> 0.011 | H5: =IFERROR(__xludf.DUMMYFUNCTION("""COMPUTED_VALUE"""),0.0) -> 0 | I5: =G5+H5 -> 0.011 | J5: =IFERROR(F5/$I5,"") -> 1527.2727 | K5: =IFERROR(G5*250,) -> 2.75 | L5: =IFERROR(H5*750,"") -> 0 | M5: =K5+L5 -> 2.75 | N5: =IFERROR(F5/M5,"") -> 6.1090909 | O5: 16.8
A6: =$B$4&C6 -> Elbow 90⁰3⁄4 | B6: 2 | C6: 3⁄4 | D6: 20 | E6: C52 | F6: 19.9 | G6: =IFERROR(__xludf.DUMMYFUNCTION("ArrayFormula(IFERROR(VLOOKUP(E6,IMPORTRANGE(""https://docs.google.com/spreadsheets/d/1xZyKy-UzMmtPDLpV5jQdYum1LtbR8XKDuasLSjmBRMI/edit#gid=1241094406"",""COMBINED DATA!E3:L""),{7,8},0)))"),0.0229) -> 0.0229 | H6: =IFERROR(__xludf.DUMMYFUNCTION("""COMPUTED_VALUE"""),0.0) -> 0 | I6: =G6+H6 -> 0.0229 | J6: =IFERROR(F6/$I6,"") -> 868.99563 | K6: =IFERROR(G6*250,) -> 5.725 | L6: =IFERROR(H6*750,"") -> 0 | M6: =K6+L6 -> 5.725 | N6: =IFERROR(F6/M6,"") -> 3.4759825 | O6: 19.9
A7: =$B$4&C7 -> Elbow 90⁰1 | B7: 3 | C7: 1 | D7: 25 | E7: C53 | F7: 39.8 | G7: =IFERROR(__xludf.DUMMYFUNCTION("ArrayFormula(IFERROR(VLOOKUP(E7,IMPORTRANGE(""https://docs.google.com/spreadsheets/d/1xZyKy-UzMmtPDLpV5jQdYum1LtbR8XKDuasLSjmBRMI/edit#gid=1241094406"",""COMBINED DATA!E3:L""),{7,8},0)))"),0.0363) -> 0.0363 | H7: =IFERROR(__xludf.DUMMYFUNCTION("""COMPUTED_VALUE"""),0.0) -> 0 | I7: =G7+H7 -> 0.0363 | J7: =IFERROR(F7/$I7,"") -> 1096.4187 | K7: =IFERROR(G7*250,) -> 9.075 | L7: =IFERROR(H7*750,"") -> 0 | M7: =K7+L7 -> 9.075 | N7: =IFERROR(F7/M7,"") -> 4.3856749 | O7: 39.8
A8: =$B$4&C8 -> Elbow 90⁰1 1⁄4 | B8: 4 | C8: 1 1⁄4 | D8: 32 | E8: C54 | F8: 89.9 | G8: =IFERROR(__xludf.DUMMYFUNCTION("ArrayFormula(IFERROR(VLOOKUP(E8,IMPORTRANGE(""https://docs.google.com/spreadsheets/d/1xZyKy-UzMmtPDLpV5jQdYum1LtbR8XKDuasLSjmBRMI/edit#gid=1241094406"",""COMBINED DATA!E3:L""),{7,8},0)))"),0.07095) -> 0.07095 | H8: =IFERROR(__xludf.DUMMYFUNCTION("""COMPUTED_VALUE"""),0.0) -> 0 | I8: =G8+H8 -> 0.07095 | J8: =IFERROR(F8/$I8,"") -> 1267.0895 | K8: =IFERROR(G8*250,) -> 17.7375 | L8: =IFERROR(H8*750,"") -> 0 | M8: =K8+L8 -> 17.7375 | N8: =IFERROR(F8/M8,"") -> 5.068358 | O8: 89.9
A9: =$B$4&C9 -> Elbow 90⁰1 1⁄2 | B9: 5 | C9: 1 1⁄2 | D9: 40 | E9: C55 | F9: 164.4 | G9: =IFERROR(__xludf.DUMMYFUNCTION("ArrayFormula(IFERROR(VLOOKUP(E9,IMPORTRANGE(""https://docs.google.com/spreadsheets/d/1xZyKy-UzMmtPDLpV5jQdYum1LtbR8XKDuasLSjmBRMI/edit#gid=1241094406"",""COMBINED DATA!E3:L""),{7,8},0)))"),0.11225) -> 0.11225 | H9: =IFERROR(__xludf.DUMMYFUNCTION("""COMPUTED_VALUE"""),0.0) -> 0 | I9: =G9+H9 -> 0.11225 | J9: =IFERROR(F9/$I9,"") -> 1464.588 | K9: =IFERROR(G9*250,) -> 28.0625 | L9: =IFERROR(H9*750,"") -> 0 | M9: =K9+L9 -> 28.0625 | N9: =IFERROR(F9/M9,"") -> 5.8583519 | O9: 164.4
A10: =$B$4&C10 -> Elbow 90⁰2 | B10: 6 | C10: 2 | D10: 50 | E10: C56 | F10: 338 | G10: =IFERROR(__xludf.DUMMYFUNCTION("ArrayFormula(IFERROR(VLOOKUP(E10,IMPORTRANGE(""https://docs.google.com/spreadsheets/d/1xZyKy-UzMmtPDLpV5jQdYum1LtbR8XKDuasLSjmBRMI/edit#gid=1241094406"",""COMBINED DATA!E3:L""),{7,8},0)))"),0.2132) -> 0.2132 | H10: =IFERROR(__xludf.DUMMYFUNCTION("""COMPUTED_VALUE"""),0.0) -> 0 | I10: =G10+H10 -> 0.2132 | J10: =IFERROR(F10/$I10,"") -> 1585.3659 | K10: =IFERROR(G10*250,) -> 53.3 | L10: =IFERROR(H10*750,"") -> 0 | M10: =K10+L10 -> 53.3 | N10: =IFERROR(F10/M10,"") -> 6.3414634 | O10: 338
B11: TOTAL | F11: =SUM(F5:F10) -> 668.8 | H11: =IFERROR(__xludf.DUMMYFUNCTION("IFERROR(VLOOKUP(E11,IMPORTRANGE(""https://docs.google.com/spreadsheets/d/1xZyKy-UzMmtPDLpV5jQdYum1LtbR8XKDuasLSjmBRMI/edit#gid=1241094406"",""COMBINED DATA!E3:L""),8,0))"),"") | N11: =IFERROR(F11/M11,"") | O11: =SUM(O5:O10) -> 668.8
H12: =IFERROR(__xludf.DUMMYFUNCTION("IFERROR(VLOOKUP(E12,IMPORTRANGE(""https://docs.google.com/spreadsheets/d/1xZyKy-UzMmtPDLpV5jQdYum1LtbR8XKDuasLSjmBRMI/edit#gid=1241094406"",""COMBINED DATA!E3:L""),8,0))"),"") | N12: =IFERROR(F12/M12,"")
B13: Elbow 90⁰ (SCH-80) | H13: =IFERROR(__xludf.DUMMYFUNCTION("IFERROR(VLOOKUP(E13,IMPORTRANGE(""https://docs.google.com/spreadsheets/d/1xZyKy-UzMmtPDLpV5jQdYum1LtbR8XKDuasLSjmBRMI/edit#gid=1241094406"",""COMBINED DATA!E3:L""),8,0))"),"") | N13: =IFERROR(F13/M13,"")
A14: =$B$13&C14 -> Elbow 90⁰ (SCH-80)2 1⁄2 | B14: 1 | C14: 2 1⁄2 | D14: 65 | E14: C57 | F14: 898 | G14: =IFERROR(__xludf.DUMMYFUNCTION("ArrayFormula(IFERROR(VLOOKUP(E14,IMPORTRANGE(""https://docs.google.com/spreadsheets/d/1xZyKy-UzMmtPDLpV5jQdYum1LtbR8XKDuasLSjmBRMI/edit#gid=1241094406"",""COMBINED DATA!E3:L""),{7,8},0)))"),0.522) -> 0.522 | H14: =IFERROR(__xludf.DUMMYFUNCTION("""COMPUTED_VALUE"""),0.0) -> 0 | I14: =G14+H14 -> 0.522 | J14: =IFERROR(F14/$I14,"") -> 1720.3065 | K14: =IFERROR(G14*250,) -> 130.5 | L14: =IFERROR(H14*750,"") -> 0 | M14: =K14+L14 -> 130.5 | N14: =IFERROR(F14/M14,"") -> 6.8812261 | O14: 898
A15: =$B$13&C15 -> Elbow 90⁰ (SCH-80)3 | B15: 2 | C15: 3 | D15: 80 | E15: C58 | F15: 1368 | G15: =IFERROR(__xludf.DUMMYFUNCTION("ArrayFormula(IFERROR(VLOOKUP(E15,IMPORTRANGE(""https://docs.google.com/spreadsheets/d/1xZyKy-UzMmtPDLpV5jQdYum1LtbR8XKDuasLSjmBRMI/edit#gid=1241094406"",""COMBINED DATA!E3:L""),{7,8},0)))"),0.8142) -> 0.8142 | H15: =IFERROR(__xludf.DUMMYFUNCTION("""COMPUTED_VALUE"""),0.0) -> 0 | I15: =G15+H15 -> 0.8142 | J15: =IFERROR(F15/$I15,"") -> 1680.1769 | K15: =IFERROR(G15*250,) -> 203.55 | L15: =IFERROR(H15*750,"") -> 0 | M15: =K15+L15 -> 203.55 | N15: =IFERROR(F15/M15,"") -> 6.7207074 | O15: 1368
A16: =$B$13&C16 -> Elbow 90⁰ (SCH-80)4 | B16: 3 | C16: 4 | D16: 100 | E16: C59 | F16: 2288 | G16: =IFERROR(__xludf.DUMMYFUNCTION("ArrayFormula(IFERROR(VLOOKUP(E16,IMPORTRANGE(""https://docs.google.com/spreadsheets/d/1xZyKy-UzMmtPDLpV5jQdYum1LtbR8XKDuasLSjmBRMI/edit#gid=1241094406"",""COMBINED DATA!E3:L""),{7,8},0)))"),1.362) -> 1.362 | H16: =IFERROR(__xludf.DUMMYFUNCTION("""COMPUTED_VALUE"""),0.0) -> 0 | I16: =G16+H16 -> 1.362 | J16: =IFERROR(F16/$I16,"") -> 1679.8825 | K16: =IFERROR(G16*250,) -> 340.5 | L16: =IFERROR(H16*750,"") -> 0 | M16: =K16+L16 -> 340.5 | N16: =IFERROR(F16/M16,"") -> 6.7195301 | O16: 2288
B17: TOTAL | F17: =SUM(F14:F16) -> 4554 | H17: =IFERROR(__xludf.DUMMYFUNCTION("IFERROR(VLOOKUP(E17,IMPORTRANGE(""https://docs.google.com/spreadsheets/d/1xZyKy-UzMmtPDLpV5jQdYum1LtbR8XKDuasLSjmBRMI/edit#gid=1241094406"",""COMBINED DATA!E3:L""),8,0))"),"") | N17: =IFERROR(F17/M17,"") | O17: =SUM(O14:O16) -> 4554
H18: =IFERROR(__xludf.DUMMYFUNCTION("IFERROR(VLOOKUP(E18,IMPORTRANGE(""https://docs.google.com/spreadsheets/d/1xZyKy-UzMmtPDLpV5jQdYum1LtbR8XKDuasLSjmBRMI/edit#gid=1241094406"",""COMBINED DATA!E3:L""),8,0))"),"") | N18: =IFERROR(F18/M18,"")
B19: Elbow 90⁰ (SCH-40) | H19: =IFERROR(__xludf.DUMMYFUNCTION("IFERROR(VLOOKUP(E19,IMPORTRANGE(""https://docs.google.com/spreadsheets/d/1xZyKy-UzMmtPDLpV5jQdYum1LtbR8XKDuasLSjmBRMI/edit#gid=1241094406"",""COMBINED DATA!E3:L""),8,0))"),"") | N19: =IFERROR(F19/M19,"")
A20: =$B$19&C20 -> Elbow 90⁰ (SCH-40)6 | B20: 1 | C20: 6 | D20: 150 | E20: C59N | F20: 3580 | G20: =IFERROR(__xludf.DUMMYFUNCTION("ArrayFormula(IFERROR(VLOOKUP(E20,IMPORTRANGE(""https://docs.google.com/spreadsheets/d/1xZyKy-UzMmtPDLpV5jQdYum1LtbR8XKDuasLSjmBRMI/edit#gid=1241094406"",""COMBINED DATA!E3:L""),{7,8},0)))"),1.975) -> 1.975 | H20: =IFERROR(__xludf.DUMMYFUNCTION("""COMPUTED_VALUE"""),0.0) -> 0 | I20: =G20+H20 -> 1.975 | J20: =IFERROR(F20/$I20,"") -> 1812.6582 | K20: =IFERROR(G20*250,) -> 493.75 | L20: =IFERROR(H20*750,"") -> 0 | M20: =K20+L20 -> 493.75 | N20: =IFERROR(F20/M20,"") -> 7.2506329 | O20: 3580
H21: =IFERROR(__xludf.DUMMYFUNCTION("IFERROR(VLOOKUP(E21,IMPORTRANGE(""https://docs.google.com/spreadsheets/d/1xZyKy-UzMmtPDLpV5jQdYum1LtbR8XKDuasLSjmBRMI/edit#gid=1241094406"",""COMBINED DATA!E3:L""),8,0))"),"") | N21: =IFERROR(F21/M21,"")
B22: Reducer Elbow | H22: =IFERROR(__xludf.DUMMYFUNCTION("IFERROR(VLOOKUP(E22,IMPORTRANGE(""https://docs.google.com/spreadsheets/d/1xZyKy-UzMmtPDLpV5jQdYum1LtbR8XKDuasLSjmBRMI/edit#gid=1241094406"",""COMBINED DATA!E3:L""),8,0))"),"") | N22: =IFERROR(F22/M22,"")
A23: =$B$22&C23 -> Reducer Elbow3⁄4 x 1⁄2 | B23: 1 | C23: 3⁄4 x 1⁄2 | D23: 20x15 | E23: C50 | F23: 29.8 | G23: =IFERROR(__xludf.DUMMYFUNCTION("ArrayFormula(IFERROR(VLOOKUP(E23,IMPORTRANGE(""https://docs.google.com/spreadsheets/d/1xZyKy-UzMmtPDLpV5jQdYum1LtbR8XKDuasLSjmBRMI/edit#gid=1241094406"",""COMBINED DATA!E3:L""),{7,8},0)))"),0.017) -> 0.017 | H23: =IFERROR(__xludf.DUMMYFUNCTION("""COMPUTED_VALUE"""),0.0) -> 0 | I23: =G23+H23 -> 0.017 | J23: =IFERROR(F23/$I23,"") -> 1752.9412 | K23: =IFERROR(G23*250,) -> 4.25 | L23: =IFERROR(H23*750,"") -> 0 | M23: =K23+L23 -> 4.25 | N23: =IFERROR(F23/M23,"") -> 7.0117647 | O23: 29.8
A24: =$B$22&C24 -> Reducer Elbow1 x 3⁄4 | B24: 2 | C24: 1 x 3⁄4 | D24: 25x20 | E24: C532 | F24: 78 | G24: =IFERROR(__xludf.DUMMYFUNCTION("ArrayFormula(IFERROR(VLOOKUP(E24,IMPORTRANGE(""https://docs.google.com/spreadsheets/d/1xZyKy-UzMmtPDLpV5jQdYum1LtbR8XKDuasLSjmBRMI/edit#gid=1241094406"",""COMBINED DATA!E3:L""),{7,8},0)))"),0.03025) -> 0.03025 | H24: =IFERROR(__xludf.DUMMYFUNCTION("""COMPUTED_VALUE"""),0.0) -> 0 | I24: =G24+H24 -> 0.03025 | J24: =IFERROR(F24/$I24,"") -> 2578.5124 | K24: =IFERROR(G24*250,) -> 7.5625 | L24: =IFERROR(H24*750,"") -> 0 | M24: =K24+L24 -> 7.5625 | N24: =IFERROR(F24/M24,"") -> 10.31405 | O24: 78
B25: TOTAL | F25: =SUM(F23:F24) -> 107.8 | H25: =IFERROR(__xludf.DUMMYFUNCTION("IFERROR(VLOOKUP(E25,IMPORTRANGE(""https://docs.google.com/spreadsheets/d/1xZyKy-UzMmtPDLpV5jQdYum1LtbR8XKDuasLSjmBRMI/edit#gid=1241094406"",""COMBINED DATA!E3:L""),8,0))"),"") | N25: =IFERROR(F25/M25,"") | O25: =SUM(O23:O24) -> 107.8
H26: =IFERROR(__xludf.DUMMYFUNCTION("IFERROR(VLOOKUP(E26,IMPORTRANGE(""https://docs.google.com/spreadsheets/d/1xZyKy-UzMmtPDLpV5jQdYum1LtbR8XKDuasLSjmBRMI/edit#gid=1241094406"",""COMBINED DATA!E3:L""),8,0))"),"") | N26: =IFERROR(F26/M26,"")
B27: Elbow 45⁰ | H27: =IFERROR(__xludf.DUMMYFUNCTION("IFERROR(VLOOKUP(E27,IMPORTRANGE(""https://docs.google.com/spreadsheets/d/1xZyKy-UzMmtPDLpV5jQdYum1LtbR8XKDuasLSjmBRMI/edit#gid=1241094406"",""COMBINED DATA!E3:L""),8,0))"),"") | N27: =IFERROR(F27/M27,"")
A28: =$B$27&C28 -> Elbow 45⁰3⁄4 | B28: 1 | C28: 3⁄4 | D28: 20 | E28: C502 | F28: 27.8 | G28: =IFERROR(__xludf.DUMMYFUNCTION("ArrayFormula(IFERROR(VLOOKUP(E28,IMPORTRANGE(""https://docs.google.com/spreadsheets/d/1xZyKy-UzMmtPDLpV5jQdYum1LtbR8XKDuasLSjmBRMI/edit#gid=1241094406"",""COMBINED DATA!E3:L""),{7,8},0)))"),0.017) -> 0.017 | H28: =IFERROR(__xludf.DUMMYFUNCTION("""COMPUTED_VALUE"""),0.0) -> 0 | I28: =G28+H28 -> 0.017 | J28: =IFERROR(F28/$I28,"") -> 1635.2941 | K28: =IFERROR(G28*250,) -> 4.25 | L28: =IFERROR(H28*750,"") -> 0 | M28: =K28+L28 -> 4.25 | N28: =IFERROR(F28/M28,"") -> 6.5411765 | O28: 27.8
A29: =$B$27&C29 -> Elbow 45⁰1 | B29: 2 | C29: 1 | D29: 25 | E29: C503 | F29: 48.8 | G29: =IFERROR(__xludf.DUMMYFUNCTION("ArrayFormula(IFERROR(VLOOKUP(E29,IMPORTRANGE(""https://docs.google.com/spreadsheets/d/1xZyKy-UzMmtPDLpV5jQdYum1LtbR8XKDuasLSjmBRMI/edit#gid=1241094406"",""COMBINED DATA!E3:L""),{7,8},0)))"),0.029) -> 0.029 | H29: =IFERROR(__xludf.DUMMYFUNCTION("""COMPUTED_VALUE"""),0.0) -> 0 | I29: =G29+H29 -> 0.029 | J29: =IFERROR(F29/$I29,"") -> 1682.7586 | K29: =IFERROR(G29*250,) -> 7.25 | L29: =IFERROR(H29*750,"") -> 0 | M29: =K29+L29 -> 7.25 | N29: =IFERROR(F29/M29,"") -> 6.7310345 | O29: 48.8
A30: =$B$27&C30 -> Elbow 45⁰1 1⁄4 | B30: 3 | C30: 1 1⁄4 | D30: 32 | E30: C504 | F30: 106 | G30: =IFERROR(__xludf.DUMMYFUNCTION("ArrayFormula(IFERROR(VLOOKUP(E30,IMPORTRANGE(""https://docs.google.com/spreadsheets/d/1xZyKy-UzMmtPDLpV5jQdYum1LtbR8XKDuasLSjmBRMI/edit#gid=1241094406"",""COMBINED DATA!E3:L""),{7,8},0)))"),0.046) -> 0.046 | H30: =IFERROR(__xludf.DUMMYFUNCTION("""COMPUTED_VALUE"""),0.0) -> 0 | I30: =G30+H30 -> 0.046 | J30: =IFERROR(F30/$I30,"") -> 2304.3478 | K30: =IFERROR(G30*250,) -> 11.5 | L30: =IFERROR(H30*750,"") -> 0 | M30: =K30+L30 -> 11.5 | N30: =IFERROR(F30/M30,"") -> 9.2173913 | O30: 106
A31: =$B$27&C31 -> Elbow 45⁰1 1⁄2 | B31: 4 | C31: 1 1⁄2 | D31: 40 | E31: C505 | F31: 158 | G31: =IFERROR(__xludf.DUMMYFUNCTION("ArrayFormula(IFERROR(VLOOKUP(E31,IMPORTRANGE(""https://docs.google.com/spreadsheets/d/1xZyKy-UzMmtPDLpV5jQdYum1LtbR8XKDuasLSjmBRMI/edit#gid=1241094406"",""COMBINED DATA!E3:L""),{7,8},0)))"),0.078) -> 0.078 | H31: =IFERROR(__xludf.DUMMYFUNCTION("""COMPUTED_VALUE"""),0.0) -> 0 | I31: =G31+H31 -> 0.078 | J31: =IFERROR(F31/$I31,"") -> 2025.641 | K31: =IFERROR(G31*250,) -> 19.5 | L31: =IFERROR(H31*750,"") -> 0 | M31: =K31+L31 -> 19.5 | N31: =IFERROR(F31/M31,"") -> 8.1025641 | O31: 158
A32: =$B$27&C32 -> Elbow 45⁰2 | B32: 5 | C32: 2 | D32: 50 | E32: C506 | F32: 334 | G32: =IFERROR(__xludf.DUMMYFUNCTION("ArrayFormula(IFERROR(VLOOKUP(E32,IMPORTRANGE(""https://docs.google.com/spreadsheets/d/1xZyKy-UzMmtPDLpV5jQdYum1LtbR8XKDuasLSjmBRMI/edit#gid=1241094406"",""COMBINED DATA!E3:L""),{7,8},0)))"),0.161) -> 0.161 | H32: =IFERROR(__xludf.DUMMYFUNCTION("""COMPUTED_VALUE"""),0.0) -> 0 | I32: =G32+H32 -> 0.161 | J32: =IFERROR(F32/$I32,"") -> 2074.5342 | K32: =IFERROR(G32*250,) -> 40.25 | L32: =IFERROR(H32*750,"") -> 0 | M32: =K32+L32 -> 40.25 | N32: =IFERROR(F32/M32,"") -> 8.2981366 | O32: 334
B33: TOTAL | F33: =SUM(F28:F32) -> 674.6 | H33: =IFERROR(__xludf.DUMMYFUNCTION("IFERROR(VLOOKUP(E33,IMPORTRANGE(""https://docs.google.com/spreadsheets/d/1xZyKy-UzMmtPDLpV5jQdYum1LtbR8XKDuasLSjmBRMI/edit#gid=1241094406"",""COMBINED DATA!E3:L""),8,0))"),"") | N33: =IFERROR(F33/M33,"") | O33: =SUM(O28:O32) -> 674.6
H34: =IFERROR(__xludf.DUMMYFUNCTION("IFERROR(VLOOKUP(E34,IMPORTRANGE(""https://docs.google.com/spreadsheets/d/1xZyKy-UzMmtPDLpV5jQdYum1LtbR8XKDuasLSjmBRMI/edit#gid=1241094406"",""COMBINED DATA!E3:L""),8,0))"),"") | N34: =IFERROR(F34/M34,"")
B35: Tee | H35: =IFERROR(__xludf.DUMMYFUNCTION("IFERROR(VLOOKUP(E35,IMPORTRANGE(""https://docs.google.com/spreadsheets/d/1xZyKy-UzMmtPDLpV5jQdYum1LtbR8XKDuasLSjmBRMI/edit#gid=1241094406"",""COMBINED DATA!E3:L""),8,0))"),"") | N35: =IFERROR(F35/M35,"")
A36: =$B$35&C36 -> Tee1⁄2 | B36: 1 | C36: 1⁄2 | D36: 15 | E36: C61 | F36: 23.8 | G36: =IFERROR(__xludf.DUMMYFUNCTION("ArrayFormula(IFERROR(VLOOKUP(E36,IMPORTRANGE(""https://docs.google.com/spreadsheets/d/1xZyKy-UzMmtPDLpV5jQdYum1LtbR8XKDuasLSjmBRMI/edit#gid=1241094406"",""COMBINED DATA!E3:L""),{7,8},0)))"),0.015) -> 0.015 | H36: =IFERROR(__xludf.DUMMYFUNCTION("""COMPUTED_VALUE"""),0.0) -> 0 | I36: =G36+H36 -> 0.015 | J36: =IFERROR(F36/$I36,"") -> 1586.6667 | K36: =IFERROR(G36*250,) -> 3.75 | L36: =IFERROR(H36*750,"") -> 0 | M36: =K36+L36 -> 3.75 | N36: =IFERROR(F36/M36,"") -> 6.3466667 | O36: 23.8
A37: =$B$35&C37 -> Tee3⁄4 | B37: 2 | C37: 3⁄4 | D37: 20 | E37: C62 | F37: 32.4 | G37: =IFERROR(__xludf.DUMMYFUNCTION("ArrayFormula(IFERROR(VLOOKUP(E37,IMPORTRANGE(""https://docs.google.com/spreadsheets/d/1xZyKy-UzMmtPDLpV5jQdYum1LtbR8XKDuasLSjmBRMI/edit#gid=1241094406"",""COMBINED DATA!E3:L""),{7,8},0)))"),0.029) -> 0.029 | H37: =IFERROR(__xludf.DUMMYFUNCTION("""COMPUTED_VALUE"""),0.0) -> 0 | I37: =G37+H37 -> 0.029 | J37: =IFERROR(F37/$I37,"") -> 1117.2414 | K37: =IFERROR(G37*250,) -> 7.25 | L37: =IFERROR(H37*750,"") -> 0 | M37: =K37+L37 -> 7.25 | N37: =IFERROR(F37/M37,"") -> 4.4689655 | O37: 32.4
A38: =$B$35&C38 -> Tee1 | B38: 3 | C38: 1 | D38: 25 | E38: C63 | F38: 51.9 | G38: =IFERROR(__xludf.DUMMYFUNCTION("ArrayFormula(IFERROR(VLOOKUP(E38,IMPORTRANGE(""https://docs.google.com/spreadsheets/d/1xZyKy-UzMmtPDLpV5jQdYum1LtbR8XKDuasLSjmBRMI/edit#gid=1241094406"",""COMBINED DATA!E3:L""),{7,8},0)))"),0.0492) -> 0.0492 | H38: =IFERROR(__xludf.DUMMYFUNCTION("""COMPUTED_VALUE"""),0.0) -> 0 | I38: =G38+H38 -> 0.0492 | J38: =IFERROR(F38/$I38,"") -> 1054.878 | K38: =IFERROR(G38*250,) -> 12.3 | L38: =IFERROR(H38*750,"") -> 0 | M38: =K38+L38 -> 12.3 | N38: =IFERROR(F38/M38,"") -> 4.2195122 | O38: 51.9
A39: =$B$35&C39 -> Tee1 1⁄4 | B39: 4 | C39: 1 1⁄4 | D39: 32 | E39: C64 | F39: 112 | G39: =IFERROR(__xludf.DUMMYFUNCTION("ArrayFormula(IFERROR(VLOOKUP(E39,IMPORTRANGE(""https://docs.google.com/spreadsheets/d/1xZyKy-UzMmtPDLpV5jQdYum1LtbR8XKDuasLSjmBRMI/edit#gid=1241094406"",""COMBINED DATA!E3:L""),{7,8},0)))"),0.0873) -> 0.0873 | H39: =IFERROR(__xludf.DUMMYFUNCTION("""COMPUTED_VALUE"""),0.0) -> 0 | I39: =G39+H39 -> 0.0873 | J39: =IFERROR(F39/$I39,"") -> 1282.9324 | K39: =IFERROR(G39*250,) -> 21.825 | L39: =IFERROR(H39*750,"") -> 0 | M39: =K39+L39 -> 21.825 | N39: =IFERROR(F39/M39,"") -> 5.1317297 | O39: 112
A40: =$B$35&C40 -> Tee1 1⁄2 | B40: 5 | C40: 1 1⁄2 | D40: 40 | E40: C65 | F40: 204 | G40: =IFERROR(__xludf.DUMMYFUNCTION("ArrayFormula(IFERROR(VLOOKUP(E40,IMPORTRANGE(""https://docs.google.com/spreadsheets/d/1xZyKy-UzMmtPDLpV5jQdYum1LtbR8XKDuasLSjmBRMI/edit#gid=1241094406"",""COMBINED DATA!E3:L""),{7,8},0)))"),0.14545) -> 0.14545 | H40: =IFERROR(__xludf.DUMMYFUNCTION("""COMPUTED_VALUE"""),0.0) -> 0 | I40: =G40+H40 -> 0.14545 | J40: =IFERROR(F40/$I40,"") -> 1402.5438 | K40: =IFERROR(G40*250,) -> 36.3625 | L40: =IFERROR(H40*750,"") -> 0 | M40: =K40+L40 -> 36.3625 | N40: =IFERROR(F40/M40,"") -> 5.6101753 | O40: 204
A41: =$B$35&C41 -> Tee2 | B41: 6 | C41: 2 | D41: 50 | E41: C66 | F41: 418 | G41: =IFERROR(__xludf.DUMMYFUNCTION("ArrayFormula(IFERROR(VLOOKUP(E41,IMPORTRANGE(""https://docs.google.com/spreadsheets/d/1xZyKy-UzMmtPDLpV5jQdYum1LtbR8XKDuasLSjmBRMI/edit#gid=1241094406"",""COMBINED DATA!E3:L""),{7,8},0)))"),0.262) -> 0.262 | H41: =IFERROR(__xludf.DUMMYFUNCTION("""COMPUTED_VALUE"""),0.0) -> 0 | I41: =G41+H41 -> 0.262 | J41: =IFERROR(F41/$I41,"") -> 1595.4198 | K41: =IFERROR(G41*250,) -> 65.5 | L41: =IFERROR(H41*750,"") -> 0 | M41: =K41+L41 -> 65.5 | N41: =IFERROR(F41/M41,"") -> 6.3816794 | O41: 418
...

Sheet C Fittings (Brass)
A1: FPP+
B2: S.NO. | C2: Size (in) | D2: Size (mm) | E2: ITEM CODE | F2: =' CPVC PIPE'!F2 -> MRP as on 1st May, 2024 | G2: WEIGHT | H2: BRASS | I2: WEIGHT WITH BRASS | J2: KG COST | K2: G*250 | L2: W*1100 | M2: F/(K+L) | O2: BRASS RATE | Q2: MRP as on 1st Feb, 2026 | R2: Diff. in %age | S2: UPDATED BRASS RATE | U2: NEW MRP | V2: Diff. in %age | W2: UPDATED BRASS WEIGHT
K3: 250 | L3: 1100
B4: Male Adapter Brass Threads | H4: =IFERROR(__xludf.DUMMYFUNCTION("IFERROR(VLOOKUP(E4,IMPORTRANGE(""https://docs.google.com/spreadsheets/d/1xZyKy-UzMmtPDLpV5jQdYum1LtbR8XKDuasLSjmBRMI/edit#gid=1241094406"",""COMBINED DATA!E3:L""),8,0))"),"") | M4: =IFERROR(F4/#REF!,"")
A5: =$B$4&C5 -> Male Adapter Brass Threads3⁄4 x 1⁄2 | B5: 1 | C5: 3⁄4 x 1⁄2 | D5: 20x15 | E5: C71 | F5: 168.8 | G5: 0.011 | H5: 0.059 | I5: =G5+H5 -> 0.07 | J5: =IFERROR(F5/I5,"") -> 2411.4286 | K5: =IFERROR(G5*$K$3,) -> 2.75 | L5: =IFERROR(W5*$L$3,"") -> 63.978095 | M5: =IFERROR(F5/SUM(K5:L5),"") -> 2.5296691 | N5: =IFERROR(SUM(K5:L5)," ") -> 66.728095 | O5: 45.29 | P5: =IFERROR(Q5/N5,"") -> 2.8323902 | Q5: 189 | R5: =IFERROR(Q5-F5,"")/F5 -> 0.11966825 | S5: =VLOOKUP(E5,'Brass Cost'!$A$11:$D112,4,0) -> 61.07 | T5: =IFERROR(U5/N5,"") -> 3.6566307 | U5: 244 | V5: =IFERROR(U5-Q5,"")/Q5 -> 0.29100529 | W5: =IFERROR(S5/1050,"") -> 0.058161905
A6: =$B$4&C6 -> Male Adapter Brass Threads3⁄4 | B6: 2 | C6: 3⁄4 | D6: 20 | E6: C72 | F6: 248.6 | G6: 0.013125 | H6: 0.065 | I6: =G6+H6 -> 0.078125 | J6: =IFERROR(F6/I6,"") -> 3182.08 | K6: =IFERROR(G6*$K$3,) -> 3.28125 | L6: =IFERROR(W6*$L$3,"") -> 70.48381 | M6: =IFERROR(F6/SUM(K6:L6),"") -> 3.3701593 | N6: =IFERROR(SUM(K6:L6)," ") -> 73.76506 | O6: 50.12 | P6: =IFERROR(Q6/N6,"") -> 3.768722 | Q6: 278 | R6: =IFERROR(Q6-F6,"")/F6 -> 0.11826227 | S6: =VLOOKUP(E6,'Brass Cost'!$A$11:$D112,4,0) -> 67.28 | T6: =IFERROR(U6/N6,"") -> 3.6331564 | U6: 268 | V6: =IFERROR(U6-Q6,"")/Q6 -> -0.035971223 | W6: =IFERROR(S6/1050,"") -> 0.06407619
A7: =$B$4&C7 -> Male Adapter Brass Threads1 | B7: 3 | C7: 1 | D7: 25 | E7: C73 | F7: 368 | G7: 0.0195 | H7: 0.145 | I7: =G7+H7 -> 0.1645 | J7: =IFERROR(F7/I7,"") -> 2237.0821 | K7: =IFERROR(G7*$K$3,) -> 4.875 | L7: =IFERROR(W7*$L$3,"") -> 157.22667 | M7: =IFERROR(F7/SUM(K7:L7),"") -> 2.2701802 | N7: =IFERROR(SUM(K7:L7)," ") -> 162.10167 | O7: 111.8 | P7: =IFERROR(Q7/N7,"") -> 2.5416148 | Q7: 412 | R7: =IFERROR(Q7-F7,"")/F7 -> 0.11956522 | S7: =VLOOKUP(E7,'Brass Cost'!$A$11:$D112,4,0) -> 150.08 | T7: =IFERROR(U7/N7,"") -> 3.5656635 | U7: 578 | V7: =IFERROR(U7-Q7,"")/Q7 -> 0.40291262 | W7: =IFERROR(S7/1050,"") -> 0.14293333
A8: =$B$4&C8 -> Male Adapter Brass Threads1 1⁄4 | B8: 4 | C8: 1 1⁄4 | D8: 32 | E8: C74 | F8: 798 | G8: 0.04725 | H8: 0.242 | I8: =G8+H8 -> 0.28925 | J8: =IFERROR(F8/I8,"") -> 2758.8591 | K8: =IFERROR(G8*$K$3,) -> 11.8125 | L8: =IFERROR(W8*$L$3,"") -> 261.3181 | M8: =IFERROR(F8/SUM(K8:L8),"") -> 2.9216793 | N8: =IFERROR(SUM(K8:L8)," ") -> 273.1306 | O8: 250.92 | P8: =IFERROR(Q8/N8,"") -> 3.2878045 | Q8: 898 | R8: =IFERROR(Q8-F8,"")/F8 -> 0.12531328 | S8: =VLOOKUP(E8,'Brass Cost'!$A$11:$D112,4,0) -> 249.44 | T8: =IFERROR(U8/N8,"") -> 3.6026722 | U8: 984 | V8: =IFERROR(U8-Q8,"")/Q8 -> 0.095768374 | W8: =IFERROR(S8/1050,"") -> 0.2375619
A9: =$B$4&C9 -> Male Adapter Brass Threads1 1⁄2 | B9: 5 | C9: 1 1⁄2 | D9: 40 | E9: C75 | F9: 1058.6 | G9: 0.061 | H9: 0.367 | I9: =G9+H9 -> 0.428 | J9: =IFERROR(F9/I9,"") -> 2473.3645 | K9: =IFERROR(G9*$K$3,) -> 15.25 | L9: =IFERROR(W9*$L$3,"") -> 403.35429 | M9: =IFERROR(F9/SUM(K9:L9),"") -> 2.52888 | N9: =IFERROR(SUM(K9:L9)," ") -> 418.60429 | O9: 329.08 | P9: =IFERROR(Q9/N9,"") -> 2.8380025 | Q9: 1188 | R9: =IFERROR(Q9-F9,"")/F9 -> 0.12223692 | S9: =VLOOKUP(E9,'Brass Cost'!$A$11:$D112,4,0) -> 385.02 | T9: =IFERROR(U9/N9,"") -> 3.5785587 | U9: 1498 | V9: =IFERROR(U9-Q9,"")/Q9 -> 0.26094276 | W9: =IFERROR(S9/1050,"") -> 0.36668571
A10: =$B$4&C10 -> Male Adapter Brass Threads2 | B10: 6 | C10: 2 | D10: 50 | E10: C76 | F10: 1840 | G10: 0.111 | H10: 0.544 | I10: =G10+H10 -> 0.655 | J10: =IFERROR(F10/I10,"") -> 2809.1603 | K10: =IFERROR(G10*$K$3,) -> 27.75 | L10: =IFERROR(W10*$L$3,"") -> 596.35714 | M10: =IFERROR(F10/SUM(K10:L10),"") -> 2.9482117 | N10: =IFERROR(SUM(K10:L10)," ") -> 624.10714 | O10: 537.64 | P10: =IFERROR(Q10/N10,"") -> 3.3327611 | Q10: 2080 | R10: =IFERROR(Q10-F10,"")/F10 -> 0.13043478 | S10: =VLOOKUP(E10,'Brass Cost'!$A$11:$D112,4,0) -> 569.25 | T10: =IFERROR(U10/N10,"") -> 3.6532189 | U10: 2280 | V10: =IFERROR(U10-Q10,"")/Q10 -> 0.096153846 | W10: =IFERROR(S10/1050,"") -> 0.54214286
A11: =$B$4&C11 -> Male Adapter Brass Threads1 x 1⁄2 | B11: 7 | C11: 1 x 1⁄2 | D11: 25x15 | E11: C731 | F11: 254.4 | G11: 0.02 | H11: 0.059 | I11: =G11+H11 -> 0.079 | J11: =IFERROR(F11/I11,"") -> 3220.2532 | K11: =IFERROR(G11*$K$3,) -> 5 | L11: =IFERROR(W11*$L$3,"") -> 63.978095 | M11: =IFERROR(F11/SUM(K11:L11),"") -> 3.6881274 | N11: =IFERROR(SUM(K11:L11)," ") -> 68.978095 | O11: 45.29 | P11: =IFERROR(Q11/N11,"") -> 4.030265 | Q11: 278 | R11: =IFERROR(Q11-F11,"")/F11 -> 0.092767296 | S11: =VLOOKUP(E11,'Brass Cost'!$A$11:$D112,4,0) -> 61.07 | T11: =IFERROR(U11/N11,"") -> 3.7403178 | U11: 258 | V11: =IFERROR(U11-Q11,"")/Q11 -> -0.071942446 | W11: =IFERROR(S11/1050,"") -> 0.058161905
A12: =$B$4&C12 -> Male Adapter Brass Threads1 x 3⁄4 | B12: 8 | C12: 1 x 3⁄4 | D12: 25x20 | E12: C732 | F12: 262.2 | G12: 0.031 | H12: 0.065 | I12: =G12+H12 -> 0.096 | J12: =IFERROR(F12/I12,"") -> 2731.25 | K12: =IFERROR(G12*$K$3,) -> 7.75 | L12: =IFERROR(W12*$L$3,"") -> 70.48381 | M12: =IFERROR(F12/SUM(K12:L12),"") -> 3.3514922 | N12: =IFERROR(SUM(K12:L12)," ") -> 78.23381 | O12: 50.12 | P12: =IFERROR(Q12/N12,"") -> 3.6812729 | Q12: 288 | R12: =IFERROR(Q12-F12,"")/F12 -> 0.098398169 | S12: =VLOOKUP(E12,'Brass Cost'!$A$11:$D112,4,0) -> 67.28 | T12: =IFERROR(U12/N12,"") -> 3.6812729 | U12: 288 | V12: =IFERROR(U12-Q12,"")/Q12 -> 0 | W12: =IFERROR(S12/1050,"") -> 0.06407619
B13: TOTAL | F13: =SUM(F5:F12) -> 4998.6 | H13: =IFERROR(__xludf.DUMMYFUNCTION("IFERROR(VLOOKUP(E13,IMPORTRANGE(""https://docs.google.com/spreadsheets/d/1xZyKy-UzMmtPDLpV5jQdYum1LtbR8XKDuasLSjmBRMI/edit#gid=1241094406"",""COMBINED DATA!E3:L""),8,0))"),"") | M13: =IFERROR(F13/#REF!,"") | Q13: =SUM(Q5:Q12) -> 5611 | U13: =SUM(U5:U12) -> 6398
H14: =IFERROR(__xludf.DUMMYFUNCTION("IFERROR(VLOOKUP(E14,IMPORTRANGE(""https://docs.google.com/spreadsheets/d/1xZyKy-UzMmtPDLpV5jQdYum1LtbR8XKDuasLSjmBRMI/edit#gid=1241094406"",""COMBINED DATA!E3:L""),8,0))"),"") | M14: =IFERROR(F14/#REF!,"")
B15: Female Adapter Brass Threads | H15: =IFERROR(__xludf.DUMMYFUNCTION("IFERROR(VLOOKUP(E15,IMPORTRANGE(""https://docs.google.com/spreadsheets/d/1xZyKy-UzMmtPDLpV5jQdYum1LtbR8XKDuasLSjmBRMI/edit#gid=1241094406"",""COMBINED DATA!E3:L""),8,0))"),"") | M15: =IFERROR(F15/#REF!,"")
A16: =$B$15&C16 -> Female Adapter Brass Threads3⁄4 | B16: 1 | C16: 3⁄4 | D16: 20 | E16: C82 | F16: 246.2 | G16: 0.0127 | H16: 0.079 | I16: =G16+H16 -> 0.0917 | J16: =IFERROR(F16/I16,"") -> 2684.8419 | K16: =IFERROR(G16*$K$3,) -> 3.175 | L16: =IFERROR(W16*$L$3,"") -> 86.638095 | M16: =IFERROR(F16/SUM(K16:L16),"") -> 2.7412484 | N16: =IFERROR(SUM(K16:L16)," ") -> 89.813095 | O16: 61.76 | P16: =IFERROR(Q16/N16,"") -> 3.0730485 | Q16: 276 | R16: =IFERROR(Q16-F16,"")/F16 -> 0.12103981 | S16: =VLOOKUP(E16,'Brass Cost'!$A$11:$D112,4,0) -> 82.7 | T16: =IFERROR(U16/N16,"") -> 3.6074917 | U16: 324 | V16: =IFERROR(U16-Q16,"")/Q16 -> 0.17391304 | W16: =IFERROR(S16/1050,"") -> 0.078761905
A17: =$B$15&C17 -> Female Adapter Brass Threads1 | B17: 2 | C17: 1 | D17: 25 | E17: C83 | F17: 468.8 | G17: 0.020095 | H17: 0.187 | I17: =G17+H17 -> 0.207095 | J17: =IFERROR(F17/I17,"") -> 2263.6954 | K17: =IFERROR(G17*$K$3,) -> 5.02375 | L17: =IFERROR(W17*$L$3,"") -> 205.24952 | M17: =IFERROR(F17/SUM(K17:L17),"") -> 2.2294797 | N17: =IFERROR(SUM(K17:L17)," ") -> 210.27327 | O17: 146.33 | P17: =IFERROR(Q17/N17,"") -> 2.5110181 | Q17: 528 | R17: =IFERROR(Q17-F17,"")/F17 -> 0.12627986 | S17: =VLOOKUP(E17,'Brass Cost'!$A$11:$D112,4,0) -> 195.92 | T17: =IFERROR(U17/N17,"") -> 3.5572757 | U17: 748 | V17: =IFERROR(U17-Q17,"")/Q17 -> 0.41666667 | W17: =IFERROR(S17/1050,"") -> 0.18659048
A18: =$B$15&C18 -> Female Adapter Brass Threads1 1⁄4 | B18: 3 | C18: 1 1⁄4 | D18: 32 | E18: C84 | F18: 848.8 | G18: 0.047 | H18: 0.244 | I18: =G18+H18 -> 0.291 | J18: =IFERROR(F18/I18,"") -> 2916.8385 | K18: =IFERROR(G18*$K$3,) -> 11.75 | L18: =IFERROR(W18*$L$3,"") -> 265.65524 | M18: =IFERROR(F18/SUM(K18:L18),"") -> 3.0597836 | N18: =IFERROR(SUM(K18:L18)," ") -> 277.40524 | O18: 258.75 | P18: =IFERROR(Q18/N18,"") -> 3.4390122 | Q18: 954 | R18: =IFERROR(Q18-F18,"")/F18 -> 0.12393968 | S18: =VLOOKUP(E18,'Brass Cost'!$A$11:$D112,4,0) -> 253.58 | T18: =IFERROR(U18/N18,"") -> 3.5615766 | U18: 988 | V18: =IFERROR(U18-Q18,"")/Q18 -> 0.035639413 | W18: =IFERROR(S18/1050,"") -> 0.24150476
A19: =$B$15&C19 -> Female Adapter Brass Threads1 1⁄2 | B19: 4 | C19: 1 1⁄2 | D19: 40 | E19: C85 | F19: 958.4 | G19: 0.06275 | H19: 0.28 | I19: =G19+H19 -> 0.34275 | J19: =IFERROR(F19/I19,"") -> 2796.2071 | K19: =IFERROR(G19*$K$3,) -> 15.6875 | L19: =IFERROR(W19*$L$3,"") -> 306.8581 | M19: =IFERROR(F19/SUM(K19:L19),"") -> 2.9713629 | N19: =IFERROR(SUM(K19:L19)," ") -> 322.5456 | O19: 305.59 | P19: =IFERROR(Q19/N19,"") -> 3.3297618 | Q19: 1074 | R19: =IFERROR(Q19-F19,"")/F19 -> 0.1206177 | S19: =VLOOKUP(E19,'Brass Cost'!$A$11:$D112,4,0) -> 292.91 | T19: =IFERROR(U19/N19,"") -> 3.6211935 | U19: 1168 | V19: =IFERROR(U19-Q19,"")/Q19 -> 0.087523277 | W19: =IFERROR(S19/1050,"") -> 0.2789619
A20: =$B$15&C20 -> Female Adapter Brass Threads2 | B20: 5 | C20: 2 | D20: 50 | E20: C86 | F20: 1822.4 | G20: 0.108 | H20: 0.451 | I20: =G20+H20 -> 0.559 | J20: =IFERROR(F20/I20,"") -> 3260.1073 | K20: =IFERROR(G20*$K$3,) -> 27 | L20: =IFERROR(W20*$L$3,"") -> 493.35524 | M20: =IFERROR(F20/SUM(K20:L20),"") -> 3.5022228 | N20: =IFERROR(SUM(K20:L20)," ") -> 520.35524 | O20: 428.59 | P20: =IFERROR(Q20/N20,"") -> 3.9319293 | Q20: 2046 | R20: =IFERROR(Q20-F20,"")/F20 -> 0.12269535 | S20: =VLOOKUP(E20,'Brass Cost'!$A$11:$D112,4,0) -> 470.93 | T20: =IFERROR(U20/N20,"") -> 3.6129165 | U20: 1880 | V20: =IFERROR(U20-Q20,"")/Q20 -> -0.08113392 | W20: =IFERROR(S20/1050,"") -> 0.44850476
B21: TOTAL | F21: =SUM(F16:F20) -> 4344.6 | H21: =IFERROR(__xludf.DUMMYFUNCTION("IFERROR(VLOOKUP(E21,IMPORTRANGE(""https://docs.google.com/spreadsheets/d/1xZyKy-UzMmtPDLpV5jQdYum1LtbR8XKDuasLSjmBRMI/edit#gid=1241094406"",""COMBINED DATA!E3:L""),8,0))"),"") | M21: =IFERROR(F21/#REF!,"") | Q21: =SUM(Q16:Q20) -> 4878 | U21: =SUM(U16:U20) -> 5108
H22: =IFERROR(__xludf.DUMMYFUNCTION("IFERROR(VLOOKUP(E22,IMPORTRANGE(""https://docs.google.com/spreadsheets/d/1xZyKy-UzMmtPDLpV5jQdYum1LtbR8XKDuasLSjmBRMI/edit#gid=1241094406"",""COMBINED DATA!E3:L""),8,0))"),"") | M22: =IFERROR(F22/#REF!,"")
B23: Brass Elbow 90⁰ | H23: =IFERROR(__xludf.DUMMYFUNCTION("IFERROR(VLOOKUP(E23,IMPORTRANGE(""https://docs.google.com/spreadsheets/d/1xZyKy-UzMmtPDLpV5jQdYum1LtbR8XKDuasLSjmBRMI/edit#gid=1241094406"",""COMBINED DATA!E3:L""),8,0))"),"") | M23: =IFERROR(F23/#REF!,"")
A24: =$B$23&C24 -> Brass Elbow 90⁰3⁄4 x 1⁄2 | B24: 1 | C24: 3⁄4 x 1⁄2 | D24: 20x15 | E24: C521 | F24: 86.2 | G24: 0.03 | H24: 0.019 | I24: =G24+H24 -> 0.049 | J24: =IFERROR(F24/I24,"") -> 1759.1837 | K24: =IFERROR(G24*$K$3,) -> 7.5 | L24: =IFERROR(W24*$L$3,"") -> 20.700952 | M24: =IFERROR(F24/SUM(K24:L24),"") -> 3.0566344 | N24: =IFERROR(SUM(K24:L24)," ") -> 28.200952 | O24: 14.18 | P24: =IFERROR(Q24/N24,"") -> 3.4750599 | Q24: 98 | R24: =IFERROR(Q24-F24,"")/F24 -> 0.13689095 | S24: =VLOOKUP(E24,'Brass Cost'!$A$11:$D112,4,0) -> 19.76 | T24: =IFERROR(U24/N24,"") -> 3.6878187 | U24: 104 | V24: =IFERROR(U24-Q24,"")/Q24 -> 0.06122449 | W24: =IFERROR(S24/1050,"") -> 0.018819048
A25: =$B$23&C25 -> Brass Elbow 90⁰1 x 1⁄2 | B25: 2 | C25: 1 x 1⁄2 | D25: 25x15 | E25: C523 | F25: 158.6 | G25: 0.038 | H25: 0.019 | I25: =G25+H25 -> 0.057 | J25: =IFERROR(F25/I25,"") -> 2782.4561 | K25: =IFERROR(G25*$K$3,) -> 9.5 | L25: =IFERROR(W25*$L$3,"") -> 20.700952 | M25: =IFERROR(F25/SUM(K25:L25),"") -> 5.25149 | N25: =IFERROR(SUM(K25:L25)," ") -> 30.200952 | O25: 14.18 | P25: =IFERROR(Q25/N25,"") -> 5.5627385 | Q25: 168 | R25: =IFERROR(Q25-F25,"")/F25 -> 0.0592686 | S25: =VLOOKUP(E25,'Brass Cost'!$A$11:$D112,4,0) -> 19.76 | T25: =IFERROR(U25/N25,"") -> 3.9071616 | U25: 118 | V25: =IFERROR(U25-Q25,"")/Q25 -> -0.29761905 | W25: =IFERROR(S25/1050,"") -> 0.018819048
A26: =$B$23&C26 -> Brass Elbow 90⁰1 x 3⁄4 | B26: 3 | C26: 1 x 3⁄4 | D26: 25x20 | E26: C524 | F26: 248.4 | G26: 0.040875 | H26: 0.043125 | I26: =G26+H26 -> 0.084 | J26: =IFERROR(F26/I26,"") -> 2957.1429 | K26: =IFERROR(G26*$K$3,) -> 10.21875 | L26: =IFERROR(W26*$L$3,"") -> 46.126667 | M26: =IFERROR(F26/SUM(K26:L26),"") -> 4.4085218 | N26: =IFERROR(SUM(K26:L26)," ") -> 56.345417 | O26: 32.89 | P26: =IFERROR(Q26/N26,"") -> 4.7563762 | Q26: 268 | R26: =IFERROR(Q26-F26,"")/F26 -> 0.078904992 | S26: =VLOOKUP(E26,'Brass Cost'!$A$11:$D112,4,0) -> 44.03 | T26: =IFERROR(U26/N26,"") -> 3.7625066 | U26: 212 | V26: =IFERROR(U26-Q26,"")/Q26 -> -0.20895522 | W26: =IFERROR(S26/1050,"") -> 0.041933333
A27: =$B$23&C27 -> Brass Elbow 90⁰1⁄2 x 1⁄2 | B27: 4 | C27: 1⁄2 x 1⁄2 | D27: 15x15 | E27: C526 | F27: 82.6 | G27: 0.021 | H27: 0.019 | I27: =G27+H27 -> 0.04 | J27: =IFERROR(F27/I27,"") -> 2065 | K27: =IFERROR(G27*$K$3,) -> 5.25 | L27: =IFERROR(W27*$L$3,"") -> 20.700952 | M27: =IFERROR(F27/SUM(K27:L27),"") -> 3.1829275 | N27: =IFERROR(SUM(K27:L27)," ") -> 25.950952 | O27: 14.18 | P27: =IFERROR(Q27/N27,"") -> 3.6222177 | Q27: 94 | R27: =IFERROR(Q27-F27,"")/F27 -> 0.13801453 | S27: =VLOOKUP(E27,'Brass Cost'!$A$11:$D112,4,0) -> 19.76 | T27: =IFERROR(U27/N27,"") -> 3.6222177 | U27: 94 | V27: =IFERROR(U27-Q27,"")/Q27 -> 0 | W27: =IFERROR(S27/1050,"") -> 0.018819048
A28: =$B$23&C28 -> Brass Elbow 90⁰3⁄4 x 3⁄4 | B28: 5 | C28: 3⁄4 x 3⁄4 | D28: 20x20 | E28: C527 | F28: 158.8 | G28: 0.047125 | H28: 0.043125 | I28: =G28+H28 -> 0.09025 | J28: =IFERROR(F28/I28,"") -> 1759.5568 | K28: =IFERROR(G28*$K$3,) -> 11.78125 | L28: =IFERROR(W28*$L$3,"") -> 46.126667 | M28: =IFERROR(F28/SUM(K28:L28),"") -> 2.7422848 | N28: =IFERROR(SUM(K28:L28)," ") -> 57.907917 | O28: 32.89 | P28: =IFERROR(Q28/N28,"") -> 3.1774585 | Q28: 184 | R28: =IFERROR(Q28-F28,"")/F28 -> 0.15869018 | S28: =VLOOKUP(E28,'Brass Cost'!$A$11:$D112,4,0) -> 44.03 | T28: =IFERROR(U28/N28,"") -> 3.6609848 | U28: 212 | V28: =IFERROR(U28-Q28,"")/Q28 -> 0.15217391 | W28: =IFERROR(S28/1050,"") -> 0.041933333
A29: =$B$23&C29 -> Brass Elbow 90⁰1 x 1 | B29: 6 | C29: 1 x 1 | D29: 25x25 | E29: C528 | F29: 348 | G29: 0.047 | H29: 0.065 | I29: =G29+H29 -> 0.112 | J29: =IFERROR(F29/I29,"") -> 3107.1429 | K29: =IFERROR(G29*$K$3,) -> 11.75 | L29: =IFERROR(W29*$L$3,"") -> 70.211429 | M29: =IFERROR(F29/SUM(K29:L29),"") -> 4.2458996 | N29: =IFERROR(SUM(K29:L29)," ") -> 81.961429 | O29: 50.05 | P29: =IFERROR(Q29/N29,"") -> 4.3679083 | Q29: 358 | R29: =IFERROR(Q29-F29,"")/F29 -> 0.028735632 | S29: =VLOOKUP(E29,'Brass Cost'!$A$11:$D112,4,0) -> 67.02 | T29: =IFERROR(U29/N29,"") -> 3.6358566 | U29: 298 | V29: =IFERROR(U29-Q29,"")/Q29 -> -0.16759777 | W29: =IFERROR(S29/1050,"") -> 0.063828571
A30: =$B$23&C30 -> Brass Elbow 90⁰1 x 1 1⁄4 | B30: 7 | C30: 1 x 1 1⁄4 | D30: 25x32 | E30: C529 | F30: 594 | G30: 0.09 | H30: 0.1035 | I30: =G30+H30 -> 0.1935 | J30: =IFERROR(F30/I30,"") -> 3069.7674 | K30: =IFERROR(G30*$K$3,) -> 22.5 | L30: =IFERROR(W30*$L$3,"") -> 113.87619 | M30: =IFERROR(F30/SUM(K30:L30),"") -> 4.355599 | N30: =IFERROR(SUM(K30:L30)," ") -> 136.37619 | O30: 81.16 | P30: =IFERROR(Q30/N30,"") -> 4.7515626 | Q30: 648 | R30: =IFERROR(Q30-F30,"")/F30 -> 0.090909091 | S30: =VLOOKUP(E30,'Brass Cost'!$A$11:$D112,4,0) -> 108.7 | T30: =IFERROR(U30/N30,"") -> 3.6516638 | U30: 498 | V30: =IFERROR(U30-Q30,"")/Q30 -> -0.23148148 | W30: =IFERROR(S30/1050,"") -> 0.10352381
B31: TOTAL | F31: 3780 | H31: =IFERROR(__xludf.DUMMYFUNCTION("IFERROR(VLOOKUP(E31,IMPORTRANGE(""https://docs.google.com/spreadsheets/d/1xZyKy-UzMmtPDLpV5jQdYum1LtbR8XKDuasLSjmBRMI/edit#gid=1241094406"",""COMBINED DATA!E3:L""),8,0))"),"") | M31: =IFERROR(F31/#REF!,"") | Q31: 3780 | U31: 3780
H32: =IFERROR(__xludf.DUMMYFUNCTION("IFERROR(VLOOKUP(E32,IMPORTRANGE(""https://docs.google.com/spreadsheets/d/1xZyKy-UzMmtPDLpV5jQdYum1LtbR8XKDuasLSjmBRMI/edit#gid=1241094406"",""COMBINED DATA!E3:L""),8,0))"),"") | M32: =IFERROR(F32/#REF!,"")
B33: Reducer Brass Tee | H33: =IFERROR(__xludf.DUMMYFUNCTION("IFERROR(VLOOKUP(E33,IMPORTRANGE(""https://docs.google.com/spreadsheets/d/1xZyKy-UzMmtPDLpV5jQdYum1LtbR8XKDuasLSjmBRMI/edit#gid=1241094406"",""COMBINED DATA!E3:L""),8,0))"),"") | M33: =IFERROR(F33/#REF!,"")
A34: =$B$33&C34 -> Reducer Brass Tee1⁄2 x 1⁄2 x 1⁄2 | B34: 1 | C34: 1⁄2 x 1⁄2 x 1⁄2 | D34: 15x15x15 | E34: C321 | F34: 104.8 | G34: 0.031 | H34: 0.019 | I34: =G34+H34 -> 0.05 | J34: =IFERROR(F34/I34,"") -> 2096 | K34: =IFERROR(G34*$K$3,) -> 7.75 | L34: =IFERROR(W34*$L$3,"") -> 20.700952 | M34: =IFERROR(F34/SUM(K34:L34),"") -> 3.6835322 | N34: =IFERROR(SUM(K34:L34)," ") -> 28.450952 | O34: 14.18 | P34: =IFERROR(Q34/N34,"") -> 4.0771922 | Q34: 116 | R34: =IFERROR(Q34-F34,"")/F34 -> 0.10687023 | S34: =VLOOKUP(E34,'Brass Cost'!$A$11:$D112,4,0) -> 19.76 | T34: =IFERROR(U34/N34,"") -> 3.6554137 | U34: 104 | V34: =IFERROR(U34-Q34,"")/Q34 -> -0.10344828 | W34: =IFERROR(S34/1050,"") -> 0.018819048
A35: =$B$33&C35 -> Reducer Brass Tee3⁄4 x 3⁄4 x 1⁄2 | B35: 2 | C35: 3⁄4 x 3⁄4 x 1⁄2 | D35: 20x20x15 | E35: C322 | F35: 102.8 | G35: 0.037 | H35: 0.019 | I35: =G35+H35 -> 0.056 | J35: =IFERROR(F35/I35,"") -> 1835.7143 | K35: =IFERROR(G35*$K$3,) -> 9.25 | L35: =IFERROR(W35*$L$3,"") -> 20.700952 | M35: =IFERROR(F35/SUM(K35:L35),"") -> 3.4322782 | N35: =IFERROR(SUM(K35:L35)," ") -> 29.950952 | O35: 14.18 | P35: =IFERROR(Q35/N35,"") -> 3.8062229 | Q35: 114 | R35: =IFERROR(Q35-F35,"")/F35 -> 0.10894942 | S35: =VLOOKUP(E35,'Brass Cost'!$A$11:$D112,4,0) -> 19.76 | T35: =IFERROR(U35/N35,"") -> 3.8729987 | U35: 116 | V35: =IFERROR(U35-Q35,"")/Q35 -> 0.01754386 | W35: =IFERROR(S35/1050,"") -> 0.018819048
A36: =$B$33&C36 -> Reducer Brass Tee1 x 1 x 1⁄2 | B36: 3 | C36: 1 x 1 x 1⁄2 | D36: 25x25x15 | E36: C323 | F36: 168.8 | G36: 0.048125 | H36: 0.019 | I36: =G36+H36 -> 0.067125 | J36: =IFERROR(F36/I36,"") -> 2514.7114 | K36: =IFERROR(G36*$K$3,) -> 12.03125 | L36: =IFERROR(W36*$L$3,"") -> 20.700952 | M36: =IFERROR(F36/SUM(K36:L36),"") -> 5.157001 | N36: =IFERROR(SUM(K36:L36)," ") -> 32.732202 | O36: 14.18 | P36: =IFERROR(Q36/N36,"") -> 5.4380698 | Q36: 178 | R36: =IFERROR(Q36-F36,"")/F36 -> 0.05450237 | S36: =VLOOKUP(E36,'Brass Cost'!$A$11:$D112,4,0) -> 19.76 | T36: =IFERROR(U36/N36,"") -> 4.1549297 | U36: 136 | V36: =IFERROR(U36-Q36,"")/Q36 -> -0.23595506 | W36: =IFERROR(S36/1050,"") -> 0.018819048
B37: 4 | C37: 1 x 1 x 1 | D37: 25x25x25 | E37: C324 | F37: 368 | G37: 0.124 | H37: 0.065 | I37: =G37+H37 -> 0.189 | J37: =IFERROR(F37/I37,"") -> 1947.0899 | K37: =IFERROR(G37*$K$3,) -> 31 | L37: =IFERROR(W37*$L$3,"") -> 70.211429 | M37: =IFERROR(F37/SUM(K37:L37),"") -> 3.635953 | N37: =IFERROR(SUM(K37:L37)," ") -> 101.21143 | O37: 50.05 | P37: =IFERROR(Q37/N37,"") -> 3.9323622 | Q37: 398 | R37: =IFERROR(Q37-F37,"")/F37 -> 0.081521739 | S37: =VLOOKUP(E37,'Brass Cost'!$A$11:$D112,4,0) -> 67.02 | T37: =IFERROR(U37/N37,"") -> 3.7347561 | U37: 378 | V37: =IFERROR(U37-Q37,"")/Q37 -> -0.050251256 | W37: =IFERROR(S37/1050,"") -> 0.063828571
A38: =$B$33&C38 -> Reducer Brass Tee3⁄4 x 3⁄4 x 3⁄4 | B38: 5 | C38: 3⁄4 x 3⁄4 x 3⁄4 | D38: 20x20x20 | E38: C333 | F38: 158.6 | G38: 0.041 | H38: 0.043 | I38: =G38+H38 -> 0.084 | J38: =IFERROR(F38/I38,"") -> 1888.0952 | K38: =IFERROR(G38*$K$3,) -> 10.25 | L38: =IFERROR(W38*$L$3,"") -> 46.126667 | M38: =IFERROR(F38/SUM(K38:L38),"") -> 2.8132206 | N38: =IFERROR(SUM(K38:L38)," ") -> 56.376667 | O38: 32.89 | P38: =IFERROR(Q38/N38,"") -> 3.1573346 | Q38: 178 | R38: =IFERROR(Q38-F38,"")/F38 -> 0.1223203 | S38: =VLOOKUP(E38,'Brass Cost'!$A$11:$D112,4,0) -> 44.03 | T38: =IFERROR(U38/N38,"") -> 3.44114 | U38: 194 | V38: =IFERROR(U38-Q38,"")/Q38 -> 0.08988764 | W38: =IFERROR(S38/1050,"") -> 0.041933333
A39: =$B$33&C39 -> Reducer Brass Tee1 1⁄4 x 1 1⁄4 x 1⁄2 | B39: 6 | C39: 1 1⁄4 x 1 1⁄4 x 1⁄2 | D39: 32x32x15 | E39: C342 | F39: 212.8 | G39: 0.076 | H39: 0.019 | I39: =G39+H39 -> 0.095 | J39: =IFERROR(F39/I39,"") -> 2240 | K39: =IFERROR(G39*$K$3,) -> 19 | L39: =IFERROR(W39*$L$3,"") -> 20.700952 | M39: =IFERROR(F39/SUM(K39:L39),"") -> 5.3600729 | N39: =IFERROR(SUM(K39:L39)," ") -> 39.700952 | O39: 14.18 | P39: =IFERROR(Q39/N39,"") -> 5.4910522 | Q39: 218 | R39: =IFERROR(Q39-F39,"")/F39 -> 0.02443609 | S39: =VLOOKUP(E39,'Brass Cost'!$A$11:$D112,4,0) -> 19.76 | T39: =IFERROR(U39/N39,"") -> 4.3827664 | U39: 174 | V39: =IFERROR(U39-Q39,"")/Q39 -> -0.20183486 | W39: =IFERROR(S39/1050,"") -> 0.018819048
A40: =$B$33&C40 -> Reducer Brass Tee1 1⁄4 x 1 1⁄4 x 1 1⁄4 | B40: 7 | C40: 1 1⁄4 x 1 1⁄4 x 1 1⁄4 | D40: 32x32x32 | E40: C344 | F40: 358.8 | G40: 0.1065 | H40: 0.1035 | I40: =G40+H40 -> 0.21 | J40: =IFERROR(F40/I40,"") -> 1708.5714 | K40: =IFERROR(G40*$K$3,) -> 26.625 | L40: =IFERROR(W40*$L$3,"") -> 113.87619 | M40: =IFERROR(F40/SUM(K40:L40),"") -> 2.553715 | N40: =IFERROR(SUM(K40:L40)," ") -> 140.50119 | O40: 81.16 | P40: =IFERROR(Q40/N40,"") -> 2.8327162 | Q40: 398 | R40: =IFERROR(Q40-F40,"")/F40 -> 0.10925307 | S40: =VLOOKUP(E40,'Brass Cost'!$A$11:$D112,4,0) -> 108.7 | T40: =IFERROR(U40/N40,"") -> 3.544454 | U40: 498 | V40: =IFERROR(U40-Q40,"")/Q40 -> 0.25125628 | W40: =IFERROR(S40/1050,"") -> 0.10352381
...

Sheet Brass Cost
D1: 03.08.26
D2: 875 | E2: BRASS RATE
C3: MABT | D3: 160 | E3: CONVERSION RATE
D4: 1035
C5: FABT/MTA/FTA | D5: 165 | E5: CONVERSION RATE
D6: 1040
A7: ITEM | B7: ITEM CODE | C7: BRASS | D7: 03.08.26
A8: concelad body | B8: PLB25 | C8: 22X1.5 RING
A9: concelad body
A10: concelad body | B10: PLB338 | C10: 28X1.5 RING
A11: C521 | B11: PLB23 | C11: 1/2" RNG | D11: 19.76
A12: C523 | D12: 19.76
A13: C526 | D13: 19.76
A14: C321 | D14: 19.76
A15: C322 | D15: 19.76
A16: C323 | D16: 19.76
A17: C342 | D17: 19.76
A18: C920 | D18: 19.76
