Workbook

Sheet Main
A1: Code | B1: Old Name | C1: CATALOGUE Name | D1: ERP NAME | E1: NO.
A2: 2 | B2: Pillar Cock | C2: Pillar Cock | D2: Pillar Cock | E2: =LEN(D2) -> 11
A3: 3 | B3: Pillar Cock Tall Hight with Flange | C3: Pillar Cock Tall Body | D3: Pillar Cock Tall Hight | E3: =LEN(D3) -> 22
A4: 3-S | C4: Pillar Cock Tall Body (Small) | D4: Pillar Cock Tall Body (Small) | E4: =LEN(D4) -> 29
A5: 4 | B5: Pillar Cock Extended Body with Flange | C5: Pillar Cock Extended Body | D5: Pillar Cock Extended Body | E5: =LEN(D5) -> 25
A6: 5 | B6: Bib Cock Nozzle | C6: Bib Cock Nozzle with Wall Flange | D6: Bib Cock Nozzle with Flange | E6: =LEN(D6) -> 27
A7: 6 | B7: Bib Cock with Flange | C7: Bib Cock with Wall Flange | D7: Bib Cock with Flange | E7: =LEN(D7) -> 20
A8: 7 | B8: Concealed Wall Mount Pillar Cock | C8: Concealed Wall Mount Pillar Cock
A9: CP-07 | B9: Concealed Pillar Cock Body 15mm | C9: Concealed Pillar Cock Body 15mm
A10: CP | B10: Exposed Parts (Wall Flange, Handle & Spout) | C10: Exposed Parts (Wall Flange, Handle & Spout)
A11: 8 | B11: Bib Cock Long Body with Flange | C11: Bib Cock Long Body with Wall Flange | D11: Bib Cock Long Body with Flange | E11: =LEN(D11) -> 30
A12: 9 | B12: Bib Cock Long Nose with Flange | C12: Bib Cock Long Nose with Wall Flange | D12: Bib Cock Long Nose with Flange | E12: =LEN(D12) -> 30
A13: 10 | B13: Angle Cock with Flange | C13: Angular Stop Cock with Wall Flange | D13: Angle Cock with Flange | E13: =LEN(D13) -> 22
A14: 11 | B14: 2-Way Angle Cock with Flange | C14: 2-Way Angular Stop Cock with Wall Flange | D14: 2-Way Angle Cock with Flange | E14: =LEN(D14) -> 28
A15: 12 | B15: 2-Way Bib Cock with Flange | C15: 2-Way Bib Cock Double Handle with Wall Flange | D15: 2-Way Bib Cock Double Handle with Flange | E15: =LEN(D15) -> 40
A16: 13 | B16: 2-Way Bib Cock with Flange | C16: 2-Way Bib Cock Single Handle with Wall Flange | D16: 2-Way Bib Cock Single Handle with Flange | E16: =LEN(D16) -> 40
A17: 14 | B17: Pillar Cock Swan Neck (T/M) | C17: Swan Neck Table Mounted | D17: Pillar Cock Swan Neck T/M | E17: =LEN(D17) -> 25
A18: 16 | B18: Bib Tap Sink Cock Regular Spout with Flange (W/M) | C18: Sink Cock Wall Mounted with Flange | D18: Bib Tap Sink Cock Regular Spout W/M | E18: =LEN(D18) -> 35
A19: 17 | C19: Sink Cock Wall Mounted with Flange | D19: Bib Tap Sink Cock Regular Spout W/M | E19: =LEN(D19) -> 35 | F19: Sink Cock Wall Mounted with Flange (9" Spout)
A20: 18 | B20: Concealed Stop Cock 15mm with Flange | C20: Concealed Stop Cock 15mm with Wall Flange | D20: Concealed Stop Cock 15mm with Flange | E20: =LEN(D20) -> 36
A21: 20 | B21: Concealed Stop Cock 20mm with Flange | C21: Concealed Stop Cock 20mm with Wall Flange | D21: Concealed Stop Cock 20mm with Flange | E21: =LEN(D21) -> 36
A22: 26 | B22: Stop Cock 15 mm ( M/T ) | C22: Stop Cock 15mm (Male Thread) | D22: Stop Cock 15 mm M/T | E22: =LEN(D22) -> 19
A23: 28 | B23: Stop Cock 15 mm ( F/T ) | C23: Stop Cock 15mm (Female Thread) | D23: Stop Cock 15 mm F/T | E23: =LEN(D23) -> 19
A24: 50 | B24: Center Hole Basin Mixer W/O Pop Up | C24: Center Hole Basin Mixer without Popup | D24: Center Hole Basin Mixer W/O Pop Up | E24: =LEN(D24) -> 34
A25: 51 | B25: Single Lever Basin Mixer W/O Pop Up Waste System | C25: Single Lever Basin Mixer without Popup Waste System | D25: Single Lever Basin Mixer | E25: =LEN(D25) -> 24
A26: 52 | B26: Single Lever Basin Mixer Tall Height W/O Pop Up Waste System | C26: Single Lever Basin Mixer Tall Body without Popup Waste System | D26: Single Lever Basin Mixer Tall Height | E26: =LEN(D26) -> 36
A27: 54 | B27: Single Lever Basin Mixer Wall Mount (Conc) | C27: Single Lever Basin Mixer Wall Mount (Concealed) | D27: Single Lever Basin Mixer W/M Concealed | E27: =LEN(D27) -> 38
A28: BD-40 | B28: Body | C28: Single Lever Basin Mixer Wall Mount (Body, Cartridge, Sleeve & Nipple) | D28: Single Lever Basin Mixer W/M Conc. Body | E28: =LEN(D28) -> 39
A29: BB | B29: Upper (Plate & Handle) | C29: Exposed Parts (Wall Flange, Handle & Spout) | D29: Single Lever Basin Mixer W/M Upper Part | E29: =LEN(D29) -> 39
A30: 55 | B30: Sink Mixer with Regular Spout (W/M) with Flange | C30: Sink Mixer with Regular Spout Wall Mounted with Flange | D30: Sink Mixer with Regular Spout W/M | E30: =LEN(D30) -> 33
A31: 56 | B31: Single Lever Sink Mixer (W/M) with Flange | C31: Single Lever Sink Mixer Wall Mounted with Flange | D31: Single Lever Sink Mixer W/M | E31: =LEN(D31) -> 27
... A58: 98 | B58: Flush Cock 25mm Half Turn with Adjustable Flange | C58: Flush Cock 25mm Half Turn with Adjustable Flange | D58: Flush Cock 25mm Half Turn | E58: =LEN(D58) -> 25

Sheet Index
A1: Close | C1: Govt. | E1: New | X1: https://docs.google.com/spreadsheets/d/1_ynjsozdftZ4Yd8GDs4xtHjt1TsCfRpRp0NPM0CZm7g/edit#gid=2060610875
A2: Emerald (61) | C2: Matrix (65) | E2: Aspire (52) | X2: https://docs.google.com/spreadsheets/d/1MV6sU7gzgZPpIMlUS0UG11FSX0BsQ4n6XulPCn1NXVA/edit#gid=99474532
A3: Mist (85) | C3: Marco (P68) | E3: Orbit (53)
A4: Opus (89) | C4: Salsa (78N) | E4: Aqua (54)
A5: Balagra (64) | C5: Aster (93N) | E5: Ocean (55)
A6: Quincy (67) | C6: Neptune (PIS) | E6: Polo (60)
A7: Inox (79) | C7: Nuster (PIS-H) | E7: Blaze (62)
A8: Casa (92) | C8: Garnet (75)
A9: Astro (63-N)
A10: Opal (82)
A11: Lotus (87-N)
A12: Calder (91)
A13: Octavia (99)
A14: Dawn (98)

Sheet MASTER
A1: RANGE | B1: ERP CODE | C1: ITEM CODE | D1: NAME | E1: MRP as on 01st May, 2026 | F1: New MRP as on 01st Aug, 2026 | G1: Diff. in %age | H1: 500 | K1: OLD COST | M1: NEW COST | X1: 240 | Y1: 500
A2: ALLIED | B2: CNS-15 | C2: CNS-15 | D2: Concealed Stop Cock Suitable For 15mm Pipe Line with 1/2" Spindle | E2: 940 | F2: 1020 | G2: =IFERROR((F2-E2)/E2,"") -> 0.085106383 | I2: =L2*M2 -> 1075.7513 | K2: =IFERROR(__xludf.DUMMYFUNCTION("IFERROR(VLOOKUP(C2,IMPORTRANGE(""https://docs.google.com/spreadsheets/d/1HZUHB8NvANAZR0sHDmHYVAm2WE9kNv0pGIQA48Ryim8/edit?gid=1285727875#gid=1285727875"",""Sheet1!A2:G""),7,0))"),263.89) -> 263.89 | L2: =IFERROR(E2/$K2,"") -> 3.5620903 | M2: =IFERROR(__xludf.DUMMYFUNCTION("IFERROR(VLOOKUP(C2,IMPORTRANGE(""https://docs.google.com/spreadsheets/d/1HZUHB8NvANAZR0sHDmHYVAm2WE9kNv0pGIQA48Ryim8/edit?gid=1285727875#gid=1285727875"",""Cost!A2:G""),7,0))"),302.0) -> 302 | N2: =IFERROR(F2/$M2,"") -> 3.3774834
A3: ALLIED | B3: CNS-20 | C3: CNS-20 | D3: Concealed Stop Cock Suitable For 20mm Pipe Line with 1/2" Spindle | E3: 980 | F3: 1060 | G3: =IFERROR((F3-E3)/E3,"") -> 0.081632653 | I3: =L3*M3 -> 1123.1887 | K3: =IFERROR(__xludf.DUMMYFUNCTION("IFERROR(VLOOKUP(C3,IMPORTRANGE(""https://docs.google.com/spreadsheets/d/1HZUHB8NvANAZR0sHDmHYVAm2WE9kNv0pGIQA48Ryim8/edit?gid=1285727875#gid=1285727875"",""Sheet1!A2:G""),7,0))"),273.97) -> 273.97 | L3: =IFERROR(E3/$K3,"") -> 3.577034 | M3: =IFERROR(__xludf.DUMMYFUNCTION("IFERROR(VLOOKUP(C3,IMPORTRANGE(""https://docs.google.com/spreadsheets/d/1HZUHB8NvANAZR0sHDmHYVAm2WE9kNv0pGIQA48Ryim8/edit?gid=1285727875#gid=1285727875"",""Cost!A2:G""),7,0))"),314.0) -> 314 | N3: =IFERROR(F3/$M3,"") -> 3.3757962
A4: ALLIED | B4: CSS-15 | C4: CSS-15 | D4: Concealed Stop Cock Suitable For 15mm Pipe Line with 3/4" Spindle | E4: 1140 | F4: 1280 | G4: =IFERROR((F4-E4)/E4,"") -> 0.12280702 | I4: =L4*M4 -> 1405.7881 | K4: =IFERROR(__xludf.DUMMYFUNCTION("IFERROR(VLOOKUP(C4,IMPORTRANGE(""https://docs.google.com/spreadsheets/d/1HZUHB8NvANAZR0sHDmHYVAm2WE9kNv0pGIQA48Ryim8/edit?gid=1285727875#gid=1285727875"",""Sheet1!A2:G""),7,0))"),338.97) -> 338.97 | L4: =IFERROR(E4/$K4,"") -> 3.3631295 | M4: =IFERROR(__xludf.DUMMYFUNCTION("IFERROR(VLOOKUP(C4,IMPORTRANGE(""https://docs.google.com/spreadsheets/d/1HZUHB8NvANAZR0sHDmHYVAm2WE9kNv0pGIQA48Ryim8/edit?gid=1285727875#gid=1285727875"",""Cost!A2:G""),7,0))"),418.0) -> 418 | N4: =IFERROR(F4/$M4,"") -> 3.062201
A5: ALLIED | B5: CSS-20 | C5: CSS-20 | D5: Concealed Stop Cock Suitable For 20mm Pipe Line with 3/4" Spindle | E5: 1190 | F5: 1330 | G5: =IFERROR((F5-E5)/E5,"") -> 0.11764706 | I5: =L5*M5 -> 1462.4121 | K5: =IFERROR(__xludf.DUMMYFUNCTION("IFERROR(VLOOKUP(C5,IMPORTRANGE(""https://docs.google.com/spreadsheets/d/1HZUHB8NvANAZR0sHDmHYVAm2WE9kNv0pGIQA48Ryim8/edit?gid=1285727875#gid=1285727875"",""Sheet1!A2:G""),7,0))"),353.97) -> 353.97 | L5: =IFERROR(E5/$K5,"") -> 3.3618668 | M5: =IFERROR(__xludf.DUMMYFUNCTION("IFERROR(VLOOKUP(C5,IMPORTRANGE(""https://docs.google.com/spreadsheets/d/1HZUHB8NvANAZR0sHDmHYVAm2WE9kNv0pGIQA48Ryim8/edit?gid=1285727875#gid=1285727875"",""Cost!A2:G""),7,0))"),435.0) -> 435 | N5: =IFERROR(F5/$M5,"") -> 3.0574713
A6: ALLIED | B6: CPS-15 | C6: CPS-15 | D6: Concealed Stop Cock Suitable For 15mm Pipe Line with 3/4" Spindle | E6: 1320 | F6: 1460 | G6: =IFERROR((F6-E6)/E6,"") -> 0.10606061 | I6: =L6*M6 -> 1522.1077 | K6: =IFERROR(__xludf.DUMMYFUNCTION("IFERROR(VLOOKUP(C6,IMPORTRANGE(""https://docs.google.com/spreadsheets/d/1HZUHB8NvANAZR0sHDmHYVAm2WE9kNv0pGIQA48Ryim8/edit?gid=1285727875#gid=1285727875"",""Sheet1!A2:G""),7,0))"),392.85) -> 392.85 | L6: =IFERROR(E6/$K6,"") -> 3.3600611 | M6: =IFERROR(__xludf.DUMMYFUNCTION("IFERROR(VLOOKUP(C6,IMPORTRANGE(""https://docs.google.com/spreadsheets/d/1HZUHB8NvANAZR0sHDmHYVAm2WE9kNv0pGIQA48Ryim8/edit?gid=1285727875#gid=1285727875"",""Cost!A2:G""),7,0))"),453.0) -> 453 | N6: =IFERROR(F6/$M6,"") -> 3.2229581
A7: ALLIED | B7: CPS-20 | C7: CPS-20 | D7: Concealed Stop Cock Suitable For 20mm Pipe Line with 3/4" Spindle | E7: 1380 | F7: 1520 | G7: =IFERROR((F7-E7)/E7,"") -> 0.10144928 | I7: =L7*M7 -> 1590.4602 | K7: =IFERROR(__xludf.DUMMYFUNCTION("IFERROR(VLOOKUP(C7,IMPORTRANGE(""https://docs.google.com/spreadsheets/d/1HZUHB8NvANAZR0sHDmHYVAm2WE9kNv0pGIQA48Ryim8/edit?gid=1285727875#gid=1285727875"",""Sheet1!A2:G""),7,0))"),387.85) -> 387.85 | L7: =IFERROR(E7/$K7,"") -> 3.5580766 | M7: =IFERROR(__xludf.DUMMYFUNCTION("IFERROR(VLOOKUP(C7,IMPORTRANGE(""https://docs.google.com/spreadsheets/d/1HZUHB8NvANAZR0sHDmHYVAm2WE9kNv0pGIQA48Ryim8/edit?gid=1285727875#gid=1285727875"",""Cost!A2:G""),7,0))"),447.0) -> 447 | N7: =IFERROR(F7/$M7,"") -> 3.4004474
A8: ALLIED | B8: CNS-52 | C8: CNS-52 | D8: Concealed Flange, Handle & Sleeve | E8: 340 | F8: 370 | G8: =IFERROR((F8-E8)/E8,"") -> 0.088235294 | I8: =L8*M8 -> 344.93291 | K8: =IFERROR(__xludf.DUMMYFUNCTION("IFERROR(VLOOKUP(C8,IMPORTRANGE(""https://docs.google.com/spreadsheets/d/1HZUHB8NvANAZR0sHDmHYVAm2WE9kNv0pGIQA48Ryim8/edit?gid=1285727875#gid=1285727875"",""Sheet1!A2:G""),7,0))"),91.67) -> 91.67 | L8: =IFERROR(E8/$K8,"") -> 3.708956 | M8: =IFERROR(__xludf.DUMMYFUNCTION("IFERROR(VLOOKUP(C8,IMPORTRANGE(""https://docs.google.com/spreadsheets/d/1HZUHB8NvANAZR0sHDmHYVAm2WE9kNv0pGIQA48Ryim8/edit?gid=1285727875#gid=1285727875"",""Cost!A2:G""),7,0))"),93.0) -> 93 | N8: =IFERROR(F8/$M8,"") -> 3.9784946
A9: ALLIED | B9: CNS-53 | C9: CNS-53 | D9: Concealed Flange, Handle & Sleeve | E9: 350 | F9: 390 | G9: =IFERROR((F9-E9)/E9,"") -> 0.11428571 | I9: =L9*M9 -> 356.20354 | K9: =IFERROR(__xludf.DUMMYFUNCTION("IFERROR(VLOOKUP(C9,IMPORTRANGE(""https://docs.google.com/spreadsheets/d/1HZUHB8NvANAZR0sHDmHYVAm2WE9kNv0pGIQA48Ryim8/edit?gid=1285727875#gid=1285727875"",""Sheet1!A2:G""),7,0))"),87.45) -> 87.45 | L9: =IFERROR(E9/$K9,"") -> 4.002287 | M9: =IFERROR(__xludf.DUMMYFUNCTION("IFERROR(VLOOKUP(C9,IMPORTRANGE(""https://docs.google.com/spreadsheets/d/1HZUHB8NvANAZR0sHDmHYVAm2WE9kNv0pGIQA48Ryim8/edit?gid=1285727875#gid=1285727875"",""Cost!A2:G""),7,0))"),89.0) -> 89 | N9: =IFERROR(F9/$M9,"") -> 4.3820225
A10: ALLIED | B10: CNS-54 | C10: CNS-54 | D10: Concealed Flange, Handle & Sleeve | E10: 390 | F10: 410 | G10: =IFERROR((F10-E10)/E10,"") -> 0.051282051 | I10: =L10*M10 -> 414.98018 | K10: =IFERROR(__xludf.DUMMYFUNCTION("IFERROR(VLOOKUP(C10,IMPORTRANGE(""https://docs.google.com/spreadsheets/d/1HZUHB8NvANAZR0sHDmHYVAm2WE9kNv0pGIQA48Ryim8/edit?gid=1285727875#gid=1285727875"",""Sheet1!A2:G""),7,0))"),95.86) -> 95.86 | L10: =IFERROR(E10/$K10,"") -> 4.0684331 | M10: =IFERROR(__xludf.DUMMYFUNCTION("IFERROR(VLOOKUP(C10,IMPORTRANGE(""https://docs.google.com/spreadsheets/d/1HZUHB8NvANAZR0sHDmHYVAm2WE9kNv0pGIQA48Ryim8/edit?gid=1285727875#gid=1285727875"",""Cost!A2:G""),7,0))"),102.0) -> 102 | N10: =IFERROR(F10/$M10,"") -> 4.0196078
A11: ALLIED | B11: CNS-55 | C11: CNS-55 | D11: Concealed Flange, Handle & Sleeve | E11: 410 | F11: 470 | G11: =IFERROR((F11-E11)/E11,"") -> 0.14634146 | I11: =L11*M11 -> 390.36001 | K11: =IFERROR(__xludf.DUMMYFUNCTION("IFERROR(VLOOKUP(C11,IMPORTRANGE(""https://docs.google.com/spreadsheets/d/1HZUHB8NvANAZR0sHDmHYVAm2WE9kNv0pGIQA48Ryim8/edit?gid=1285727875#gid=1285727875"",""Sheet1!A2:G""),7,0))"),100.83) -> 100.83 | L11: =IFERROR(E11/$K11,"") -> 4.0662501 | M11: =IFERROR(__xludf.DUMMYFUNCTION("IFERROR(VLOOKUP(C11,IMPORTRANGE(""https://docs.google.com/spreadsheets/d/1HZUHB8NvANAZR0sHDmHYVAm2WE9kNv0pGIQA48Ryim8/edit?gid=1285727875#gid=1285727875"",""Cost!A2:G""),7,0))"),96.0) -> 96 | N11: =IFERROR(F11/$M11,"") -> 4.8958333
A12: ALLIED | B12: CNS-60 | C12: CNS-60 | D12: Concealed Flange, Handle & Sleeve | E12: 370 | F12: 410 | G12: =IFERROR((F12-E12)/E12,"") -> 0.10810811 | I12: =L12*M12 -> 408.65672 | K12: =IFERROR(__xludf.DUMMYFUNCTION("IFERROR(VLOOKUP(C12,IMPORTRANGE(""https://docs.google.com/spreadsheets/d/1HZUHB8NvANAZR0sHDmHYVAm2WE9kNv0pGIQA48Ryim8/edit?gid=1285727875#gid=1285727875"",""Sheet1!A2:G""),7,0))"),100.5) -> 100.5 | L12: =IFERROR(E12/$K12,"") -> 3.681592 | M12: =IFERROR(__xludf.DUMMYFUNCTION("IFERROR(VLOOKUP(C12,IMPORTRANGE(""https://docs.google.com/spreadsheets/d/1HZUHB8NvANAZR0sHDmHYVAm2WE9kNv0pGIQA48Ryim8/edit?gid=1285727875#gid=1285727875"",""Cost!A2:G""),7,0))"),111.0) -> 111 | N12: =IFERROR(F12/$M12,"") -> 3.6936937
A13: ALLIED | B13: CNS-61 | C13: CNS-61 | D13: Concealed Flange, Handle & Sleeve | E13: 450 | F13: REMOVED | G13: =IFERROR((F13-E13)/E13,"") | I13: =L13*M13 -> 456.1974 | K13: =IFERROR(__xludf.DUMMYFUNCTION("IFERROR(VLOOKUP(C13,IMPORTRANGE(""https://docs.google.com/spreadsheets/d/1HZUHB8NvANAZR0sHDmHYVAm2WE9kNv0pGIQA48Ryim8/edit?gid=1285727875#gid=1285727875"",""Sheet1!A2:G""),7,0))"),104.56) -> 104.56 | L13: =IFERROR(E13/$K13,"") -> 4.303749 | M13: =IFERROR(__xludf.DUMMYFUNCTION("IFERROR(VLOOKUP(C13,IMPORTRANGE(""https://docs.google.com/spreadsheets/d/1HZUHB8NvANAZR0sHDmHYVAm2WE9kNv0pGIQA48Ryim8/edit?gid=1285727875#gid=1285727875"",""Cost!A2:G""),7,0))"),106.0) -> 106 | N13: =IFERROR(F13/$M13,"")
A14: ALLIED | B14: CNS-62 | C14: CNS-62 | D14: Concealed Flange, Handle & Sleeve | E14: 390 | F14: 430 | G14: =IFERROR((F14-E14)/E14,"") -> 0.1025641 | I14: =L14*M14 -> 355.98377 | K14: =IFERROR(__xludf.DUMMYFUNCTION("IFERROR(VLOOKUP(C14,IMPORTRANGE(""https://docs.google.com/spreadsheets/d/1HZUHB8NvANAZR0sHDmHYVAm2WE9kNv0pGIQA48Ryim8/edit?gid=1285727875#gid=1285727875"",""Sheet1!A2:G""),7,0))"),108.46) -> 108.46 | L14: =IFERROR(E14/$K14,"") -> 3.5957957 | M14: =IFERROR(__xludf.DUMMYFUNCTION("IFERROR(VLOOKUP(C14,IMPORTRANGE(""https://docs.google.com/spreadsheets/d/1HZUHB8NvANAZR0sHDmHYVAm2WE9kNv0pGIQA48Ryim8/edit?gid=1285727875#gid=1285727875"",""Cost!A2:G""),7,0))"),99.0) -> 99 | N14: =IFERROR(F14/$M14,"") -> 4.3434343
A15: ALLIED | B15: CNS-66 | C15: CNS-66 | D15: Concealed Flange, Handle & Sleeve | E15: 450 | F15: 480 | G15: =IFERROR((F15-E15)/E15,"") -> 0.066666667 | I15: =L15*M15 -> 469.20678 | K15: =IFERROR(__xludf.DUMMYFUNCTION("IFERROR(VLOOKUP(C15,IMPORTRANGE(""https://docs.google.com/spreadsheets/d/1HZUHB8NvANAZR0sHDmHYVAm2WE9kNv0pGIQA48Ryim8/edit?gid=1285727875#gid=1285727875"",""Sheet1!A2:G""),7,0))"),102.62) -> 102.62 | L15: =IFERROR(E15/$K15,"") -> 4.3851101 | M15: =IFERROR(__xludf.DUMMYFUNCTION("IFERROR(VLOOKUP(C15,IMPORTRANGE(""https://docs.google.com/spreadsheets/d/1HZUHB8NvANAZR0sHDmHYVAm2WE9kNv0pGIQA48Ryim8/edit?gid=1285727875#gid=1285727875"",""Cost!A2:G""),7,0))"),107.0) -> 107 | N15: =IFERROR(F15/$M15,"") -> 4.4859813
A16: ALLIED | B16: CNS-P66 | C16: CNS-P66 | D16: Concealed Flange, Handle & Sleeve | E16: 390 | F16: 410 | G16: =IFERROR((F16-E16)/E16,"") -> 0.051282051 | I16: =L16*M16 -> 406.64588 | K16: =IFERROR(__xludf.DUMMYFUNCTION("IFERROR(VLOOKUP(C16,IMPORTRANGE(""https://docs.google.com/spreadsheets/d/1HZUHB8NvANAZR0sHDmHYVAm2WE9kNv0pGIQA48Ryim8/edit?gid=1285727875#gid=1285727875"",""Sheet1!A2:G""),7,0))"),102.62) -> 102.62 | L16: =IFERROR(E16/$K16,"") -> 3.8004288 | M16: =IFERROR(__xludf.DUMMYFUNCTION("IFERROR(VLOOKUP(C16,IMPORTRANGE(""https://docs.google.com/spreadsheets/d/1HZUHB8NvANAZR0sHDmHYVAm2WE9kNv0pGIQA48Ryim8/edit?gid=1285727875#gid=1285727875"",""Cost!A2:G""),7,0))"),107.0) -> 107 | N16: =IFERROR(F16/$M16,"") -> 3.8317757
A17: ALLIED | B17: CNS-68 | C17: CNS-68 | D17: Concealed Flange, Handle & Sleeve | E17: 500 | F17: 480 | G17: =IFERROR((F17-E17)/E17,"") -> -0.04 | I17: =L17*M17 -> 509.95629 | K17: =IFERROR(__xludf.DUMMYFUNCTION("IFERROR(VLOOKUP(C17,IMPORTRANGE(""https://docs.google.com/spreadsheets/d/1HZUHB8NvANAZR0sHDmHYVAm2WE9kNv0pGIQA48Ryim8/edit?gid=1285727875#gid=1285727875"",""Sheet1!A2:G""),7,0))"),102.95) -> 102.95 | L17: =IFERROR(E17/$K17,"") -> 4.8567266 | M17: =IFERROR(__xludf.DUMMYFUNCTION("IFERROR(VLOOKUP(C17,IMPORTRANGE(""https://docs.google.com/spreadsheets/d/1HZUHB8NvANAZR0sHDmHYVAm2WE9kNv0pGIQA48Ryim8/edit?gid=1285727875#gid=1285727875"",""Cost!A2:G""),7,0))"),105.0) -> 105 | N17: =IFERROR(F17/$M17,"") -> 4.5714286
A18: ALLIED | B18: CSS-71 | C18: CSS-71 | D18: Concealed Flange, Handle & Sleeve | E18: 890 | F18: 940 | G18: =IFERROR((F18-E18)/E18,"") -> 0.056179775 | I18: =L18*M18 -> 933.22078 | K18: =IFERROR(__xludf.DUMMYFUNCTION("IFERROR(VLOOKUP(C18,IMPORTRANGE(""https://docs.google.com/spreadsheets/d/1HZUHB8NvANAZR0sHDmHYVAm2WE9kNv0pGIQA48Ryim8/edit?gid=1285727875#gid=1285727875"",""Sheet1!A2:G""),7,0))"),225.07) -> 225.07 | L18: =IFERROR(E18/$K18,"") -> 3.9543253 | M18: =IFERROR(__xludf.DUMMYFUNCTION("IFERROR(VLOOKUP(C18,IMPORTRANGE(""https://docs.google.com/spreadsheets/d/1HZUHB8NvANAZR0sHDmHYVAm2WE9kNv0pGIQA48Ryim8/edit?gid=1285727875#gid=1285727875"",""Cost!A2:G""),7,0))"),236.0) -> 236 | N18: =IFERROR(F18/$M18,"") -> 3.9830508
A19: ALLIED | B19: CSS-72 | C19: CSS-72 | D19: Concealed Flange, Handle & Sleeve | E19: 540 | F19: 570 | G19: =IFERROR((F19-E19)/E19,"") -> 0.055555556 | I19: =L19*M19 -> 538.15798 | K19: =IFERROR(__xludf.DUMMYFUNCTION("IFERROR(VLOOKUP(C19,IMPORTRANGE(""https://docs.google.com/spreadsheets/d/1HZUHB8NvANAZR0sHDmHYVAm2WE9kNv0pGIQA48Ryim8/edit?gid=1285727875#gid=1285727875"",""Sheet1!A2:G""),7,0))"),149.51) -> 149.51 | L19: =IFERROR(E19/$K19,"") -> 3.6117985 | M19: =IFERROR(__xludf.DUMMYFUNCTION("IFERROR(VLOOKUP(C19,IMPORTRANGE(""https://docs.google.com/spreadsheets/d/1HZUHB8NvANAZR0sHDmHYVAm2WE9kNv0pGIQA48Ryim8/edit?gid=1285727875#gid=1285727875"",""Cost!A2:G""),7,0))"),149.0) -> 149 | N19: =IFERROR(F19/$M19,"") -> 3.8255034
A20: ALLIED | B20: CSS-73 | C20: CSS-73 | D20: Concealed Flange, Handle & Sleeve | E20: 520 | F20: 580 | G20: =IFERROR((F20-E20)/E20,"") -> 0.11538462 | I20: =L20*M20 -> 551.82626 | K20: =IFERROR(__xludf.DUMMYFUNCTION("IFERROR(VLOOKUP(C20,IMPORTRANGE(""https://docs.google.com/spreadsheets/d/1HZUHB8NvANAZR0sHDmHYVAm2WE9kNv0pGIQA48Ryim8/edit?gid=1285727875#gid=1285727875"",""Sheet1!A2:G""),7,0))"),121.56) -> 121.56 | L20: =IFERROR(E20/$K20,"") -> 4.2777229 | M20: =IFERROR(__xludf.DUMMYFUNCTION("IFERROR(VLOOKUP(C20,IMPORTRANGE(""https://docs.google.com/spreadsheets/d/1HZUHB8NvANAZR0sHDmHYVAm2WE9kNv0pGIQA48Ryim8/edit?gid=1285727875#gid=1285727875"",""Cost!A2:G""),7,0))"),129.0) -> 129 | N20: =IFERROR(F20/$M20,"") -> 4.496124
A21: ALLIED | B21: CSS-74 | C21: CSS-74 | D21: Concealed Flange, Handle & Sleeve | E21: 550 | F21: 550 | G21: =IFERROR((F21-E21)/E21,"") -> 0 | I21: =L21*M21 -> 571.92374 | K21: =IFERROR(__xludf.DUMMYFUNCTION("IFERROR(VLOOKUP(C21,IMPORTRANGE(""https://docs.google.com/spreadsheets/d/1HZUHB8NvANAZR0sHDmHYVAm2WE9kNv0pGIQA48Ryim8/edit?gid=1285727875#gid=1285727875"",""Sheet1!A2:G""),7,0))"),109.63) -> 109.63 | L21: =IFERROR(E21/$K21,"") -> 5.0168749 | M21: =IFERROR(__xludf.DUMMYFUNCTION("IFERROR(VLOOKUP(C21,IMPORTRANGE(""https://docs.google.com/spreadsheets/d/1HZUHB8NvANAZR0sHDmHYVAm2WE9kNv0pGIQA48Ryim8/edit?gid=1285727875#gid=1285727875"",""Cost!A2:G""),7,0))"),114.0) -> 114 | N21: =IFERROR(F21/$M21,"") -> 4.8245614
A22: ALLIED | B22: CSS-76 | C22: CSS-76 | D22: Concealed Flange, Handle & Sleeve | E22: 450 | F22: 510 | G22: =IFERROR((F22-E22)/E22,"") -> 0.13333333 | I22: =L22*M22 -> 462.02252 | K22: =IFERROR(__xludf.DUMMYFUNCTION("IFERROR(VLOOKUP(C22,IMPORTRANGE(""https://docs.google.com/spreadsheets/d/1HZUHB8NvANAZR0sHDmHYVAm2WE9kNv0pGIQA48Ryim8/edit?gid=1285727875#gid=1285727875"",""Sheet1!A2:G""),7,0))"),90.58) -> 90.58 | L22: =IFERROR(E22/$K22,"") -> 4.9679841 | M22: =IFERROR(__xludf.DUMMYFUNCTION("IFERROR(VLOOKUP(C22,IMPORTRANGE(""https://docs.google.com/spreadsheets/d/1HZUHB8NvANAZR0sHDmHYVAm2WE9kNv0pGIQA48Ryim8/edit?gid=1285727875#gid=1285727875"",""Cost!A2:G""),7,0))"),93.0) -> 93 | N22: =IFERROR(F22/$M22,"") -> 5.483871
A23: ALLIED | B23: CSS-77 | C23: CSS-77 | D23: Concealed Flange, Handle & Sleeve | E23: 580 | F23: 580 | G23: =IFERROR((F23-E23)/E23,"") -> 0 | I23: =L23*M23 -> 617.67838 | K23: =IFERROR(__xludf.DUMMYFUNCTION("IFERROR(VLOOKUP(C23,IMPORTRANGE(""https://docs.google.com/spreadsheets/d/1HZUHB8NvANAZR0sHDmHYVAm2WE9kNv0pGIQA48Ryim8/edit?gid=1285727875#gid=1285727875"",""Sheet1!A2:G""),7,0))"),103.29) -> 103.29 | L23: =IFERROR(E23/$K23,"") -> 5.615258 | M23: =IFERROR(__xludf.DUMMYFUNCTION("IFERROR(VLOOKUP(C23,IMPORTRANGE(""https://docs.google.com/spreadsheets/d/1HZUHB8NvANAZR0sHDmHYVAm2WE9kNv0pGIQA48Ryim8/edit?gid=1285727875#gid=1285727875"",""Cost!A2:G""),7,0))"),110.0) -> 110 | N23: =IFERROR(F23/$M23,"") -> 5.2727273
A24: ALLIED | B24: CSS-78 | C24: CSS-78 | D24: Concealed Flange, Handle & Sleeve | E24: 550 | F24: 550 | G24: =IFERROR((F24-E24)/E24,"") -> 0 | I24: =L24*M24 -> 557.5746 | K24: =IFERROR(__xludf.DUMMYFUNCTION("IFERROR(VLOOKUP(C24,IMPORTRANGE(""https://docs.google.com/spreadsheets/d/1HZUHB8NvANAZR0sHDmHYVAm2WE9kNv0pGIQA48Ryim8/edit?gid=1285727875#gid=1285727875"",""Sheet1!A2:G""),7,0))"),104.56) -> 104.56 | L24: =IFERROR(E24/$K24,"") -> 5.2601377 | M24: =IFERROR(__xludf.DUMMYFUNCTION("IFERROR(VLOOKUP(C24,IMPORTRANGE(""https://docs.google.com/spreadsheets/d/1HZUHB8NvANAZR0sHDmHYVAm2WE9kNv0pGIQA48Ryim8/edit?gid=1285727875#gid=1285727875"",""Cost!A2:G""),7,0))"),106.0) -> 106 | N24: =IFERROR(F24/$M24,"") -> 5.1886792
A25: ALLIED | B25: CSS-79F | C25: CSS-79F | D25: Concealed Flange, Handle & Sleeve | E25: 640 | F25: 670 | G25: =IFERROR((F25-E25)/E25,"") -> 0.046875 | I25: =L25*M25 -> 676.47556 | K25: =IFERROR(__xludf.DUMMYFUNCTION("IFERROR(VLOOKUP(C25,IMPORTRANGE(""https://docs.google.com/spreadsheets/d/1HZUHB8NvANAZR0sHDmHYVAm2WE9kNv0pGIQA48Ryim8/edit?gid=1285727875#gid=1285727875"",""Sheet1!A2:G""),7,0))"),118.26) -> 118.26 | L25: =IFERROR(E25/$K25,"") -> 5.4118045 | M25: =IFERROR(__xludf.DUMMYFUNCTION("IFERROR(VLOOKUP(C25,IMPORTRANGE(""https://docs.google.com/spreadsheets/d/1HZUHB8NvANAZR0sHDmHYVAm2WE9kNv0pGIQA48Ryim8/edit?gid=1285727875#gid=1285727875"",""Cost!A2:G""),7,0))"),125.0) -> 125 | N25: =IFERROR(F25/$M25,"") -> 5.36
A26: ALLIED | B26: CPS-81 | C26: CPS-81 | D26: Concealed Flange, Handle & Sleeve | E26: 790 | F26: 860 | G26: =IFERROR((F26-E26)/E26,"") -> 0.088607595 | I26: =L26*M26 -> 863.34866 | K26: =IFERROR(__xludf.DUMMYFUNCTION("IFERROR(VLOOKUP(C26,IMPORTRANGE(""https://docs.google.com/spreadsheets/d/1HZUHB8NvANAZR0sHDmHYVAm2WE9kNv0pGIQA48Ryim8/edit?gid=1285727875#gid=1285727875"",""Sheet1!A2:G""),7,0))"),219.61) -> 219.61 | L26: =IFERROR(E26/$K26,"") -> 3.5972861 | M26: =IFERROR(__xludf.DUMMYFUNCTION("IFERROR(VLOOKUP(C26,IMPORTRANGE(""https://docs.google.com/spreadsheets/d/1HZUHB8NvANAZR0sHDmHYVAm2WE9kNv0pGIQA48Ryim8/edit?gid=1285727875#gid=1285727875"",""Cost!A2:G""),7,0))"),240.0) -> 240 | N26: =IFERROR(F26/$M26,"") -> 3.5833333
A27: ALLIED | B27: CPS-83 | C27: CPS-83 | D27: Concealed Flange, Handle & Sleeve | E27: 750 | F27: 750 | G27: =IFERROR((F27-E27)/E27,"") -> 0 | I27: =L27*M27 -> 781.32365 | K27: =IFERROR(__xludf.DUMMYFUNCTION("IFERROR(VLOOKUP(C27,IMPORTRANGE(""https://docs.google.com/spreadsheets/d/1HZUHB8NvANAZR0sHDmHYVAm2WE9kNv0pGIQA48Ryim8/edit?gid=1285727875#gid=1285727875"",""Sheet1!A2:G""),7,0))"),212.14) -> 212.14 | L27: =IFERROR(E27/$K27,"") -> 3.5354012 | M27: =IFERROR(__xludf.DUMMYFUNCTION("IFERROR(VLOOKUP(C27,IMPORTRANGE(""https://docs.google.com/spreadsheets/d/1HZUHB8NvANAZR0sHDmHYVAm2WE9kNv0pGIQA48Ryim8/edit?gid=1285727875#gid=1285727875"",""Cost!A2:G""),7,0))"),221.0) -> 221 | N27: =IFERROR(F27/$M27,"") -> 3.3936652
A28: ALLIED | B28: CPS-85 | C28: CPS-85 | D28: Concealed Flange, Handle & Sleeve | E28: 790 | F28: REMOVED | G28: =IFERROR((F28-E28)/E28,"") | I28: =L28*M28 -> 849.61787 | K28: =IFERROR(__xludf.DUMMYFUNCTION("IFERROR(VLOOKUP(C28,IMPORTRANGE(""https://docs.google.com/spreadsheets/d/1HZUHB8NvANAZR0sHDmHYVAm2WE9kNv0pGIQA48Ryim8/edit?gid=1285727875#gid=1285727875"",""Sheet1!A2:G""),7,0))"),218.51) -> 218.51 | L28: =IFERROR(E28/$K28,"") -> 3.6153952 | M28: =IFERROR(__xludf.DUMMYFUNCTION("IFERROR(VLOOKUP(C28,IMPORTRANGE(""https://docs.google.com/spreadsheets/d/1HZUHB8NvANAZR0sHDmHYVAm2WE9kNv0pGIQA48Ryim8/edit?gid=1285727875#gid=1285727875"",""Cost!A2:G""),7,0))"),235.0) -> 235 | N28: =IFERROR(F28/$M28,"")
A29: ALLIED | B29: CPS-87 | C29: CPS-87 | D29: Concealed Flange, Handle & Sleeve | E29: 680 | F29: 720 | G29: =IFERROR((F29-E29)/E29,"") -> 0.058823529 | I29: =L29*M29 -> 691.8039 | K29: =IFERROR(__xludf.DUMMYFUNCTION("IFERROR(VLOOKUP(C29,IMPORTRANGE(""https://docs.google.com/spreadsheets/d/1HZUHB8NvANAZR0sHDmHYVAm2WE9kNv0pGIQA48Ryim8/edit?gid=1285727875#gid=1285727875"",""Sheet1!A2:G""),7,0))"),157.27) -> 157.27 | L29: =IFERROR(E29/$K29,"") -> 4.3237744 | M29: =IFERROR(__xludf.DUMMYFUNCTION("IFERROR(VLOOKUP(C29,IMPORTRANGE(""https://docs.google.com/spreadsheets/d/1HZUHB8NvANAZR0sHDmHYVAm2WE9kNv0pGIQA48Ryim8/edit?gid=1285727875#gid=1285727875"",""Cost!A2:G""),7,0))"),160.0) -> 160 | N29: =IFERROR(F29/$M29,"") -> 4.5
A30: ALLIED | B30: CPS-89 | C30: CPS-89 | D30: Concealed Flange, Handle & Sleeve | E30: 750 | F30: REMOVED | G30: =IFERROR((F30-E30)/E30,"") | I30: =L30*M30 -> 757.70332 | K30: =IFERROR(__xludf.DUMMYFUNCTION("IFERROR(VLOOKUP(C30,IMPORTRANGE(""https://docs.google.com/spreadsheets/d/1HZUHB8NvANAZR0sHDmHYVAm2WE9kNv0pGIQA48Ryim8/edit?gid=1285727875#gid=1285727875"",""Sheet1!A2:G""),7,0))"),178.17) -> 178.17 | L30: =IFERROR(E30/$K30,"") -> 4.2094629 | M30: =IFERROR(__xludf.DUMMYFUNCTION("IFERROR(VLOOKUP(C30,IMPORTRANGE(""https://docs.google.com/spreadsheets/d/1HZUHB8NvANAZR0sHDmHYVAm2WE9kNv0pGIQA48Ryim8/edit?gid=1285727875#gid=1285727875"",""Cost!A2:G""),7,0))"),180.0) -> 180 | N30: =IFERROR(F30/$M30,"")
A31: ALLIED | B31: CPS-90 | C31: CPS-90 | D31: Concealed Flange, Handle & Sleeve | E31: 750 | F31: 790 | G31: =IFERROR((F31-E31)/E31,"") -> 0.053333333 | I31: =L31*M31 -> 772.99362 | K31: =IFERROR(__xludf.DUMMYFUNCTION("IFERROR(VLOOKUP(C31,IMPORTRANGE(""https://docs.google.com/spreadsheets/d/1HZUHB8NvANAZR0sHDmHYVAm2WE9kNv0pGIQA48Ryim8/edit?gid=1285727875#gid=1285727875"",""Sheet1!A2:G""),7,0))"),191.14) -> 191.14 | L31: =IFERROR(E31/$K31,"") -> 3.9238255 | M31: =IFERROR(__xludf.DUMMYFUNCTION("IFERROR(VLOOKUP(C31,IMPORTRANGE(""https://docs.google.com/spreadsheets/d/1HZUHB8NvANAZR0sHDmHYVAm2WE9kNv0pGIQA48Ryim8/edit?gid=1285727875#gid=1285727875"",""Cost!A2:G""),7,0))"),197.0) -> 197 | N31: =IFERROR(F31/$M31,"") -> 4.0101523
A32: ALLIED | B32: CPS-93 | C32: CPS-93 | D32: Concealed Flange, Handle & Sleeve | E32: 790 | F32: 790 | G32: =IFERROR((F32-E32)/E32,"") -> 0 | I32: =L32*M32 -> 811.97944 | K32: =IFERROR(__xludf.DUMMYFUNCTION("IFERROR(VLOOKUP(C32,IMPORTRANGE(""https://docs.google.com/spreadsheets/d/1HZUHB8NvANAZR0sHDmHYVAm2WE9kNv0pGIQA48Ryim8/edit?gid=1285727875#gid=1285727875"",""Sheet1!A2:G""),7,0))"),169.29) -> 169.29 | L32: =IFERROR(E32/$K32,"") -> 4.6665485 | M32: =IFERROR(__xludf.DUMMYFUNCTION("IFERROR(VLOOKUP(C32,IMPORTRANGE(""https://docs.google.com/spreadsheets/d/1HZUHB8NvANAZR0sHDmHYVAm2WE9kNv0pGIQA48Ryim8/edit?gid=1285727875#gid=1285727875"",""Cost!A2:G""),7,0))"),174.0) -> 174 | N32: =IFERROR(F32/$M32,"") -> 4.5402299
A33: ASPIRE 52 | B33: =C33 -> 5202 | C33: 5202 | D33: Pillar Cock | E33: 1290 | F33: 1390 | G33: =IFERROR((F33-E33)/E33,"") -> 0.07751938 | I33: =L33*M33 -> 1413.6811 | K33: =IFERROR(__xludf.DUMMYFUNCTION("IFERROR(VLOOKUP(C33,IMPORTRANGE(""https://docs.google.com/spreadsheets/d/1HZUHB8NvANAZR0sHDmHYVAm2WE9kNv0pGIQA48Ryim8/edit?gid=1285727875#gid=1285727875"",""Sheet1!A2:G""),7,0))"),403.33) -> 403.33 | L33: =IFERROR(E33/$K33,"") -> 3.1983735 | M33: =IFERROR(__xludf.DUMMYFUNCTION("IFERROR(VLOOKUP(C33,IMPORTRANGE(""https://docs.google.com/spreadsheets/d/1HZUHB8NvANAZR0sHDmHYVAm2WE9kNv0pGIQA48Ryim8/edit?gid=1285727875#gid=1285727875"",""Cost!A2:G""),7,0))"),442.0) -> 442 | N33: =IFERROR(F33/$M33,"") -> 3.1447964 | X33: 02 | Y33: =A33&X33 -> ASPIRE 5202
A34: ASPIRE 52 | B34: =C34 -> 5203 | C34: 5203 | D34: Pillar Cock Tall Body | E34: 2890 | F34: 3240 | G34: =IFERROR((F34-E34)/E34,"") -> 0.12110727 | I34: =L34*M34 -> 3233.8426 | K34: =IFERROR(__xludf.DUMMYFUNCTION("IFERROR(VLOOKUP(C34,IMPORTRANGE(""https://docs.google.com/spreadsheets/d/1HZUHB8NvANAZR0sHDmHYVAm2WE9kNv0pGIQA48Ryim8/edit?gid=1285727875#gid=1285727875"",""Sheet1!A2:G""),7,0))"),936.57) -> 936.57 | L34: =IFERROR(E34/$K34,"") -> 3.0857277 | M34: =IFERROR(__xludf.DUMMYFUNCTION("IFERROR(VLOOKUP(C34,IMPORTRANGE(""https://docs.google.com/spreadsheets/d/1HZUHB8NvANAZR0sHDmHYVAm2WE9kNv0pGIQA48Ryim8/edit?gid=1285727875#gid=1285727875"",""Cost!A2:G""),7,0))"),1048.0) -> 1048 | N34: =IFERROR(F34/$M34,"") -> 3.0916031 | X34: 03 | Y34: =A34&X34 -> ASPIRE 5203
A35: ASPIRE 52 | B35: =C35 -> 5204 | C35: 5204 | D35: Pillar Cock Extended Body | E35: 1890 | F35: 2090 | G35: =IFERROR((F35-E35)/E35,"") -> 0.10582011 | I35: =L35*M35 -> 2101.8103 | K35: =IFERROR(__xludf.DUMMYFUNCTION("IFERROR(VLOOKUP(C35,IMPORTRANGE(""https://docs.google.com/spreadsheets/d/1HZUHB8NvANAZR0sHDmHYVAm2WE9kNv0pGIQA48Ryim8/edit?gid=1285727875#gid=1285727875"",""Sheet1!A2:G""),7,0))"),580.0) -> 580 | L35: =IFERROR(E35/$K35,"") -> 3.2586207 | M35: =IFERROR(__xludf.DUMMYFUNCTION("IFERROR(VLOOKUP(C35,IMPORTRANGE(""https://docs.google.com/spreadsheets/d/1HZUHB8NvANAZR0sHDmHYVAm2WE9kNv0pGIQA48Ryim8/edit?gid=1285727875#gid=1285727875"",""Cost!A2:G""),7,0))"),645.0) -> 645 | N35: =IFERROR(F35/$M35,"") -> 3.2403101 | X35: 04 | Y35: =A35&X35 -> ASPIRE 5204
A36: ASPIRE 52 | B36: =C36 -> 5206 | C36: 5206 | D36: Bib Cock with Wall Flange | E36: 1070 | F36: 1180 | G36: =IFERROR((F36-E36)/E36,"") -> 0.10280374 | I36: =L36*M36 -> 1167.0029 | K36: =IFERROR(__xludf.DUMMYFUNCTION("IFERROR(VLOOKUP(C36,IMPORTRANGE(""https://docs.google.com/spreadsheets/d/1HZUHB8NvANAZR0sHDmHYVAm2WE9kNv0pGIQA48Ryim8/edit?gid=1285727875#gid=1285727875"",""Sheet1!A2:G""),7,0))"),317.24) -> 317.24 | L36: =IFERROR(E36/$K36,"") -> 3.3728408 | M36: =IFERROR(__xludf.DUMMYFUNCTION("IFERROR(VLOOKUP(C36,IMPORTRANGE(""https://docs.google.com/spreadsheets/d/1HZUHB8NvANAZR0sHDmHYVAm2WE9kNv0pGIQA48Ryim8/edit?gid=1285727875#gid=1285727875"",""Cost!A2:G""),7,0))"),346.0) -> 346 | N36: =IFERROR(F36/$M36,"") -> 3.4104046 | X36: 06 | Y36: =A36&X36 -> ASPIRE 5206
A37: ASPIRE 52 | B37: =C37 -> 5207 | C37: 5207 | D37: Concealed Wall Mount Pillar Cock | E37: =SUM(E38:E39) -> 2680 | F37: =SUM(F38:F39) -> 2850 | G37: =IFERROR((F37-E37)/E37,"") -> 0.063432836 | I37: =L37*M37 -> 2888.9071 | K37: =IFERROR(__xludf.DUMMYFUNCTION("IFERROR(VLOOKUP(C37,IMPORTRANGE(""https://docs.google.com/spreadsheets/d/1HZUHB8NvANAZR0sHDmHYVAm2WE9kNv0pGIQA48Ryim8/edit?gid=1285727875#gid=1285727875"",""Sheet1!A2:G""),7,0))"),733.8) -> 733.8 | L37: =IFERROR(E37/$K37,"") -> 3.6522213 | M37: =IFERROR(__xludf.DUMMYFUNCTION("IFERROR(VLOOKUP(C37,IMPORTRANGE(""https://docs.google.com/spreadsheets/d/1HZUHB8NvANAZR0sHDmHYVAm2WE9kNv0pGIQA48Ryim8/edit?gid=1285727875#gid=1285727875"",""Cost!A2:G""),7,0))"),791.0) -> 791 | N37: =IFERROR(F37/$M37,"") -> 3.6030341 | X37: 07 | Y37: =A37&X37 -> ASPIRE 5207
A38: ASPIRE 52 | B38: =C38 -> CP-07 | C38: CP-07 | D38: Concealed Pillar Cock Body 15mm | E38: 1390 | F38: 1490 | G38: =IFERROR((F38-E38)/E38,"") -> 0.071942446 | I38: =L38*M38 -> 1515.4596 | K38: =IFERROR(__xludf.DUMMYFUNCTION("IFERROR(VLOOKUP(C38,IMPORTRANGE(""https://docs.google.com/spreadsheets/d/1HZUHB8NvANAZR0sHDmHYVAm2WE9kNv0pGIQA48Ryim8/edit?gid=1285727875#gid=1285727875"",""Sheet1!A2:G""),7,0))"),408.16) -> 408.16 | L38: =IFERROR(E38/$K38,"") -> 3.4055272 | M38: =IFERROR(__xludf.DUMMYFUNCTION("IFERROR(VLOOKUP(C38,IMPORTRANGE(""https://docs.google.com/spreadsheets/d/1HZUHB8NvANAZR0sHDmHYVAm2WE9kNv0pGIQA48Ryim8/edit?gid=1285727875#gid=1285727875"",""Cost!A2:G""),7,0))"),445.0) -> 445 | N38: =IFERROR(F38/$M38,"") -> 3.3483146 | X38: CP-07 | Y38: =A38&X38 -> ASPIRE 52CP-07
A39: ASPIRE 52 | B39: =C39 -> CP-52 | C39: CP-52 | D39: Exposed Parts (Wall Flange, Handle & Spout) | E39: 1290 | F39: 1360 | G39: =IFERROR((F39-E39)/E39,"") -> 0.054263566 | I39: =L39*M39 -> 1292.1714 | K39: =IFERROR(__xludf.DUMMYFUNCTION("IFERROR(VLOOKUP(C39,IMPORTRANGE(""https://docs.google.com/spreadsheets/d/1HZUHB8NvANAZR0sHDmHYVAm2WE9kNv0pGIQA48Ryim8/edit?gid=1285727875#gid=1285727875"",""Sheet1!A2:G""),7,0))"),362.39) -> 362.39 | L39: =IFERROR(E39/$K39,"") -> 3.5597009 | M39: =IFERROR(__xludf.DUMMYFUNCTION("IFERROR(VLOOKUP(C39,IMPORTRANGE(""https://docs.google.com/spreadsheets/d/1HZUHB8NvANAZR0sHDmHYVAm2WE9kNv0pGIQA48Ryim8/edit?gid=1285727875#gid=1285727875"",""Cost!A2:G""),7,0))"),363.0) -> 363 | N39: =IFERROR(F39/$M39,"") -> 3.7465565 | X39: CP | Y39: =A39&X39 -> ASPIRE 52CP
A40: ASPIRE 52 | B40: =C40 -> 5208 | C40: 5208 | D40: Bib Cock Long Body with Wall Flange | E40: 1290 | F40: 1390 | G40: =IFERROR((F40-E40)/E40,"") -> 0.07751938 | I40: =L40*M40 -> 1408.6756 | K40: =IFERROR(__xludf.DUMMYFUNCTION("IFERROR(VLOOKUP(C40,IMPORTRANGE(""https://docs.google.com/spreadsheets/d/1HZUHB8NvANAZR0sHDmHYVAm2WE9kNv0pGIQA48Ryim8/edit?gid=1285727875#gid=1285727875"",""Sheet1!A2:G""),7,0))"),364.47) -> 364.47 | L40: =IFERROR(E40/$K40,"") -> 3.539386 | M40: =IFERROR(__xludf.DUMMYFUNCTION("IFERROR(VLOOKUP(C40,IMPORTRANGE(""https://docs.google.com/spreadsheets/d/1HZUHB8NvANAZR0sHDmHYVAm2WE9kNv0pGIQA48Ryim8/edit?gid=1285727875#gid=1285727875"",""Cost!A2:G""),7,0))"),398.0) -> 398 | N40: =IFERROR(F40/$M40,"") -> 3.4924623 | X40: 08 | Y40: =A40&X40 -> ASPIRE 5208
...

Sheet ALL INDIA ACCESORIES
A1: S.No. | B1: Cat No. | C1: Product | D1: {=MASTER!E1:G1} -> MRP as on 01st May, 2026 | E1: New MRP as on 01st Aug, 2026 | F1: Diff. in %age | J1: Cost
A2: 1 | B2: TM-06C | C2: Thermostatic Diverter Click Tec Series 3-Outlet Chrome Finish Brass Body | D2: {=VLOOKUP(B2,MASTER!$C279:$F$1048,{3,4},0)} -> 48380 | E2: 48380 | F2: =(E2-D2)/D2 -> 0 | I2: =IFERROR(E2/J2,"") -> 193.52 | J2: 250
A3: 2 | B3: TM-07C | C3: Thermostatic Diverter Click Tec Series 4-Outlet Chrome Finish Brass Body | D3: {=VLOOKUP(B3,MASTER!$C279:$F$1048,{3,4},0)} -> 59180 | E3: 59180 | F3: =(E3-D3)/D3 -> 0 | I3: =IFERROR(E3/J3,"") -> 305.05155 | J3: 194
A4: 3 | B4: TM-08C | C4: Thermostatic Diverter Click Tec Series 5-Outlet Chrome Finish Brass Body | D4: {=VLOOKUP(B4,MASTER!$C279:$F$1048,{3,4},0)} -> 64580 | E4: 64580 | F4: =(E4-D4)/D4 -> 0 | I4: =IFERROR(E4/J4,"") -> 134.26195 | J4: 481
A5: 4 | B5: TM-09C | C5: Thermostatic Diverter Click Tec Series 6-Outlet Chrome Finish Brass Body | D5: {=VLOOKUP(B5,MASTER!$C279:$F$1048,{3,4},0)} -> 75380 | E5: 75380 | F5: =(E5-D5)/D5 -> 0 | I5: =IFERROR(E5/J5,"") -> 272.12996 | J5: 277
A6: 5 | B6: TM-10C | C6: Thermostatic Diverter Click Tec Series 4-Outlet with Water-Flow Control | D6: {=VLOOKUP(B6,MASTER!$C279:$F$1048,{3,4},0)} -> 62890 | E6: 62890 | F6: =(E6-D6)/D6 -> 0 | I6: =IFERROR(E6/J6,"") -> 231.21324 | J6: 272
A7: 6 | B7: BNS-01 | C7: Round Body Jet 45mm SS Matt Finish | D7: {=VLOOKUP(B7,MASTER!$C279:$F$1048,{3,4},0)} -> 2510 | E7: 2510 | F7: =(E7-D7)/D7 -> 0 | I7: =IFERROR(E7/J7,"") -> 7.943038 | J7: 316
A8: 7 | B8: BNS-02 | C8: Square Body Jet 45X45mm SS Matt Finish | D8: {=VLOOKUP(B8,MASTER!$C279:$F$1048,{3,4},0)} -> 2510 | E8: 2510 | F8: =(E8-D8)/D8 -> 0 | I8: =IFERROR(E8/J8,"") -> 8.0967742 | J8: 310
A9: 8 | B9: BNS-03 | C9: Round 100mm Wall Shower (Cascade) | D9: {=VLOOKUP(B9,MASTER!$C279:$F$1048,{3,4},0)} -> 6280 | E9: 6680 | F9: =(E9-D9)/D9 -> 0.063694268 | I9: =IFERROR(E9/J9,"") -> 27.603306 | J9: 242
A10: 9 | B10: BNS-04 | C10: Square 100mm Wall Shower (Cascade) | D10: {=VLOOKUP(B10,MASTER!$C279:$F$1048,{3,4},0)} -> 6280 | E10: 6280 | F10: =(E10-D10)/D10 -> 0 | I10: =IFERROR(E10/J10,"") -> 25.950413 | J10: 242
A11: 10 | B11: BNS-05 | C11: Body Jet Dancing Brass | D11: {=VLOOKUP(B11,MASTER!$C279:$F$1048,{3,4},0)} -> 3950 | E11: 3950 | F11: =(E11-D11)/D11 -> 0 | I11: =IFERROR(E11/J11,"") -> 10.025381 | J11: 394
A12: 11 | B12: BS-73 | C12: ABS Overhead Shower 100mm with Brass Arm 225mm & Flange | D12: {=VLOOKUP(B12,MASTER!$C279:$F$1048,{3,4},0)} -> 1540 | E12: 1540 | F12: =(E12-D12)/D12 -> 0 | I12: =IFERROR(E12/J12,"") -> 6.3374486 | J12: 243
A13: 12 | B13: BS-73SS | C13: ABS Overhead Shower 100mm with SS Arm 225mm & Flange | D13: {=VLOOKUP(B13,MASTER!$C279:$F$1048,{3,4},0)} -> 920 | E13: 980 | F13: =(E13-D13)/D13 -> 0.065217391 | I13: =IFERROR(E13/J13,"") -> 2.3222749 | J13: 422
A14: 13 | B14: BS-79 | C14: ABS Overhead Shower Square 100mm with Brass Arm 225mm & Flange | D14: {=VLOOKUP(B14,MASTER!$C279:$F$1048,{3,4},0)} -> 1680 | E14: 1680 | F14: =(E14-D14)/D14 -> 0 | I14: =IFERROR(E14/J14,"") -> 6.2222222 | J14: 270
A15: 14 | B15: BS-79SS | C15: ABS Overhead Shower Square 100mm with SS Arm 225mm & Flange | D15: {=VLOOKUP(B15,MASTER!$C279:$F$1048,{3,4},0)} -> 1030 | E15: 1090 | F15: =(E15-D15)/D15 -> 0.058252427 | I15: =IFERROR(E15/J15,"") -> 2.1330724 | J15: 511
A16: 15 | B16: BS-78 | C16: ABS Overhead Shower 150mm with Brass Arm 225mm & Flange | D16: {=VLOOKUP(B16,MASTER!$C279:$F$1048,{3,4},0)} -> 1930 | E16: 1990 | F16: =(E16-D16)/D16 -> 0.031088083 | I16: =IFERROR(E16/J16,"") -> 5.5586592 | J16: 358
A17: 16 | B17: BS-78SS | C17: ABS Overhead Shower 150mm with SS Arm 225mm & Flange | D17: {=VLOOKUP(B17,MASTER!$C279:$F$1048,{3,4},0)} -> 1290 | E17: 1390 | F17: =(E17-D17)/D17 -> 0.07751938 | I17: =IFERROR(E17/J17,"") -> 1.7013464 | J17: 817
A18: 17 | B18: BS-89 | C18: ABS Overhead Shower Square 150mm with Brass Arm 375mm & Flange | D18: {=VLOOKUP(B18,MASTER!$C279:$F$1048,{3,4},0)} -> 2840 | E18: 2840 | F18: =(E18-D18)/D18 -> 0 | I18: =IFERROR(E18/J18,"") -> 4.9912127 | J18: 569
A19: 18 | B19: BS-89SS | C19: ABS Overhead Shower Square 150mm with SS Arm 375mm & Flange | D19: {=VLOOKUP(B19,MASTER!$C279:$F$1048,{3,4},0)} -> 2190 | E19: 2260 | F19: =(E19-D19)/D19 -> 0.03196347 | I19: =IFERROR(E19/J19,"") -> 3.9579685 | J19: 571
A20: 19 | B20: BS-104 | C20: Pluto Multi Flow Round Shower 110 mm | D20: {=VLOOKUP(B20,MASTER!$C279:$F$1048,{3,4},0)} -> 840 | E20: 840 | F20: =(E20-D20)/D20 -> 0 | I20: =IFERROR(E20/J20,"") -> 2.7722772 | J20: 303
A21: 20 | B21: BS-41 | C21: Optus Mini Shower Oval 125 mm | D21: {=VLOOKUP(B21,MASTER!$C279:$F$1048,{3,4},0)} -> 690 | E21: 690 | F21: =(E21-D21)/D21 -> 0 | I21: =IFERROR(E21/J21,"") -> 2.9237288 | J21: 236
A22: 21 | B22: BS-108 | C22: Over Head Shower Round Full CP 225 MM | D22: {=VLOOKUP(B22,MASTER!$C279:$F$1048,{3,4},0)} -> 1730 | E22: 1730 | F22: =(E22-D22)/D22 -> 0 | I22: =IFERROR(E22/J22,"") -> 4.0801887 | J22: 424
A23: 22 | B23: BS-109 | C23: Over Head Shower Aesthetic Round 100 mm with 225 mm ss arm | D23: {=VLOOKUP(B23,MASTER!$C279:$F$1048,{3,4},0)} -> 930 | E23: 990 | F23: =(E23-D23)/D23 -> 0.064516129 | I23: =IFERROR(E23/J23,"") -> 1.2328767 | J23: 803
A24: 23 | B24: BS-112 | C24: Over Head Shower Aesthetic Square 100 mm with 225 mm ss arm | D24: {=VLOOKUP(B24,MASTER!$C279:$F$1048,{3,4},0)} -> 940 | E24: 990 | F24: =(E24-D24)/D24 -> 0.053191489 | I24: =IFERROR(E24/J24,"") -> 1.7837838 | J24: 555
A25: 24 | B25: BOS-04 | C25: Brass Overhead Shower 100mm with Brass Arm 150 mm & Flange | D25: {=VLOOKUP(B25,MASTER!$C279:$F$1048,{3,4},0)} -> 2290 | E25: 2460 | F25: =(E25-D25)/D25 -> 0.074235808 | I25: =IFERROR(E25/J25,"") -> 5.4910714 | J25: 448
A26: 25 | B26: BS-30 | C26: ABS Water Fall Square Overhead Shower 100mm with Brass Arm 150mm & Flange | D26: {=VLOOKUP(B26,MASTER!$C279:$F$1048,{3,4},0)} -> 1230 | E26: 1290 | F26: =(E26-D26)/D26 -> 0.048780488 | I26: =IFERROR(E26/J26,"") -> 1.557971 | J26: 828
A27: 26 | B27: BS-30SS | C27: ABS Water Fall Square Overhead Shower 100mm with SS Arm 225mm & Flange | D27: {=VLOOKUP(B27,MASTER!$C279:$F$1048,{3,4},0)} -> 920 | E27: 920 | F27: =(E27-D27)/D27 -> 0 | I27: =IFERROR(E27/J27,"") -> 1.5862069 | J27: 580
A28: 27 | B28: ECO-65 | C28: ABS Round Overhead Shower 75mm Full CP with SS Arm 225mm and Flange | D28: {=VLOOKUP(B28,MASTER!$C279:$F$1048,{3,4},0)} -> 850 | E28: 920 | F28: =(E28-D28)/D28 -> 0.082352941 | I28: =IFERROR(E28/J28,"") -> 3.8983051 | J28: 236
A29: 28 | B29: BOS-41 | C29: Round Rain Shower 200mm with SS Plate | D29: {=VLOOKUP(B29,MASTER!$C279:$F$1048,{3,4},0)} -> 1720 | E29: 1840 | F29: =(E29-D29)/D29 -> 0.069767442 | I29: =IFERROR(E29/J29,"") -> 8.9320388 | J29: 206
A30: 29 | B30: BOS-41SB | C30: Round Rain Shower 200mm with SS Plate and Brass Arm 375mm & Flange | D30: {=VLOOKUP(B30,MASTER!$C279:$F$1048,{3,4},0)} -> 3090 | E30: 3090 | F30: =(E30-D30)/D30 -> 0 | I30: =IFERROR(E30/J30,"") -> 10.265781 | J30: 301
A31: 30 | B31: BOS-41SS | C31: Round Rain Shower 200mm with SS Plate and SS Arm 375mm & Flange | D31: {=VLOOKUP(B31,MASTER!$C279:$F$1048,{3,4},0)} -> 2290 | E31: 2470 | F31: =(E31-D31)/D31 -> 0.07860262 | I31: =IFERROR(E31/J31,"") -> 10.291667 | J31: 240
A32: 31 | B32: BOS-42 | C32: Square Rain Shower 200mm with SS Plate | D32: {=VLOOKUP(B32,MASTER!$C279:$F$1048,{3,4},0)} -> 1880 | E32: 1960 | F32: =(E32-D32)/D32 -> 0.042553191 | I32: =IFERROR(E32/J32,"") -> 8.558952 | J32: 229
A33: 32 | B33: BOS-42SB | C33: Square Rain Shower 200mm with SS Plate and Brass Arm 375mm & Flange | D33: {=VLOOKUP(B33,MASTER!$C279:$F$1048,{3,4},0)} -> 3450 | E33: 3450 | F33: =(E33-D33)/D33 -> 0 | I33: =IFERROR(E33/J33,"") -> 19.942197 | J33: 173
A34: 33 | B34: BOS-42SS | C34: Square Rain Shower 200mm with SS Plate and SS Arm 375mm & Flange | D34: {=VLOOKUP(B34,MASTER!$C279:$F$1048,{3,4},0)} -> 2380 | E34: 2380 | F34: =(E34-D34)/D34 -> 0 | I34: =IFERROR(E34/J34,"") -> 6.5384615 | J34: 364
A35: 34 | B35: ECO-63 | C35: ABS Round Overhead Shower 75mm with SS Arm 225mm and Flange | D35: {=VLOOKUP(B35,MASTER!$C279:$F$1048,{3,4},0)} -> 830 | E35: 890 | F35: =(E35-D35)/D35 -> 0.072289157 | I35: =IFERROR(E35/J35,"") -> 2.4860335 | J35: 358
A36: 35 | B36: BS-66 | C36: ABS Overhead Shower 125mm Round with SS Arm 225mm & Flange | D36: {=VLOOKUP(B36,MASTER!$C279:$F$1048,{3,4},0)} -> 1190 | E36: 1290 | F36: =(E36-D36)/D36 -> 0.084033613 | I36: =IFERROR(E36/J36,"") -> 3.7175793 | J36: 347
A37: 36 | B37: BS-69 | C37: ABS Overhead Shower 125mm Round with SS Arm 225mm & Flange | D37: {=VLOOKUP(B37,MASTER!$C279:$F$1048,{3,4},0)} -> 940 | E37: 990 | F37: =(E37-D37)/D37 -> 0.053191489 | I37: =IFERROR(E37/J37,"") -> 2.2197309 | J37: 446
A38: 37 | B38: BOS-6003 | C38: Chrome Plated Over Head Steppo Shower 150x150mm | D38: {=VLOOKUP(B38,MASTER!$C279:$F$1048,{3,4},0)} -> 980 | E38: 1040 | F38: =(E38-D38)/D38 -> 0.06122449 | I38: =IFERROR(E38/J38,"") -> 6.0465116 | J38: 172
A39: 38 | B39: BOS-4009 | C39: Chrome Plated Over Head Steppo Shower 100x100mm | D39: {=VLOOKUP(B39,MASTER!$C279:$F$1048,{3,4},0)} -> 780 | E39: 690 | F39: =(E39-D39)/D39 -> -0.11538462 | I39: =IFERROR(E39/J39,"") -> 2.4210526 | J39: 285
A40: 39 | B40: BOS-195 | C40: ABS Overhead Shower Square 150mm with SS Arm 325mm & Flange | D40: {=VLOOKUP(B40,MASTER!$C279:$F$1048,{3,4},0)} -> 1690 | E40: 1690 | F40: =(E40-D40)/D40 -> 0 | I40: =IFERROR(E40/J40,"") -> 4.3333333 | J40: 390
...

Sheet MRP CHART
A1: 0.08
D2: 02 | E2: 03 | F2: 03-S | G2: 04 | H2: 05 | I2: 06 | J2: 07 | K2: CP-07 | L2: CP | M2: 08 | N2: 09 | O2: 10 | P2: 11 | Q2: 12 | R2: 13 | S2: 14 | T2: 16 | U2: 17 | V2: 18 | W2: 20 | X2: 26 | Y2: 28 | Z2: 50 | AA2: 51 | AB2: 52 | AC2: 54 | AD2: 54-S | AE2: BD-40 | AF2: BB | AG2: BB-S | AH2: 55 | AI2: 56 | AJ2: 60 | AK2: 61 | AL2: 65 | AM2: 70 | AN2: 71 | AO2: 75 | AP2: 76 | AQ2: 80 | AR2: 91 | AS2: 92 | AT2: 92-P | AU2: 93 | AV2: 92-ON-OFF | AW2: 92-ON-OFF-P | AX2: 93-ON-OFF | AY2: 94 | AZ2: 95 | BA2: 96 | BB2: 98
D3: PILLAR COCK (02) | E3: PILLAR COCK TALL HIGHT (03) | F3: PILLAR COCK TALL HIGHT (03) | G3: PILLAR COCK EXTENDED BODY (04) | H3: BIB COCK NOZZLE (05) | I3: BIB COCK (06) | J3: CONCEALED PILLAR COCK (07) | K3: BODY | L3: EXPOSED PARTS | M3: BIB COCK LONG BODY (08) | N3: BIB COCK LONG NOSE (09) | O3: ANGLE COCK (10) | P3: 2-WAY ANGLE COCK (11) | Q3: 2-WAY BIB COCK (12) | R3: 2-WAY BIB COCK (13) | S3: PILLAR COCK SINK TAP (T/M ) (14) | T3: PILLAR COCK SINK TAP (W/M) (16) | U3: PILLAR COCK SINK TAP (W/M) (17) | V3: STOP COCK 15 MM (18) | W3: STOP COCK 20 MM (20) | X3: STOP COCK 15 MM ( M/T ) (26) | Y3: STOP COCK 15 MM ( F/T ) (28) | Z3: CENTER HOLE BASIN MIXER (50) | AA3: SINGLE LEVER BASIN MIXER | AB3: SINGLE LIVER BASIN MIXER TALL HIGHT | AC3: SINGLE LEVER BASIN MIXER WALL MONTED | AD3: SINGLE LEVER BASIN MIXER WALL MONTED | AE3: BODY | AF3: EXPOSED PARTS | AG3: EXPOSED PARTS | AH3: SINK MIXER ( W/M) | AI3: SINGLE LEVER SINK MIXER (W/M ) | AJ3: SINK MIXER (T/M) | AK3: SINGLE LEVER SINK MIXER (T/M ) | AL3: WALL MIXER NON TELEPHONIC | AM3: WALL MIXER TELEPHONIC | AN3: SINGLE LEVER WALL MIXER | AO3: WALL MIXER L-BEND | AP3: SINGLE LEVER WALL MIXER "L" BEND (EXPOSE TYPE) | AQ3: WALL MIXER 3 IN ONE | AR3: CONCEALED DIVERTOR | AS3: DIVERTOR HIGH FLOW | AT3: DIVERTOR HIGH FLOW (Tipton Without Plated) | AU3: DIVERTOR 3 IN ONE | AV3: DIVERTOR HIGH FLOW (ON-OFF) | AW3: DIVERTOR HIGH FLOW (ON-OFF) | AX3: DIVERTOR 3 IN ONE (ON-OFF) | AY3: 4 - WAY DIVERTER (COMPLETE) | AZ3: SPOUT PLAIN | BA3: SPOUT TIP TON | BB3: FLUSH COCK
A4: =COUNT(D4:BB4) -> 37 | B4: 5000 | C4: ASPIRE 52 | D4: {=IFERROR(VLOOKUP($C4&D$2,{MASTER!$Y$2:$Y992,MASTER!$F$2:$F992},2,0),"")} -> 1390 | E4: {=IFERROR(VLOOKUP($C4&E$2,{MASTER!$Y$2:$Y992,MASTER!$F$2:$F992},2,0),"")} -> 3240 | F4: {=IFERROR(VLOOKUP($C4&F$2,{MASTER!$Y$2:$Y992,MASTER!$F$2:$F992},2,0),"")} | G4: {=IFERROR(VLOOKUP($C4&G$2,{MASTER!$Y$2:$Y992,MASTER!$F$2:$F992},2,0),"")} -> 2090 | H4: {=IFERROR(VLOOKUP($C4&H$2,{MASTER!$Y$2:$Y992,MASTER!$F$2:$F992},2,0),"")} | I4: {=IFERROR(VLOOKUP($C4&I$2,{MASTER!$Y$2:$Y992,MASTER!$F$2:$F992},2,0),"")} -> 1180 | J4: {=IFERROR(VLOOKUP($C4&J$2,{MASTER!$Y$2:$Y992,MASTER!$F$2:$F992},2,0),"")} -> 2850 | K4: {=IFERROR(VLOOKUP($C4&K$2,{MASTER!$Y$2:$Y992,MASTER!$F$2:$F992},2,0),"")} -> 1490 | ... BB4: {=IFERROR(VLOOKUP($C4&BB$2,{MASTER!$Y$2:$Y992,MASTER!$F$2:$F992},2,0),"")} -> 2380
A5: =COUNT(D5:BB5) -> 34 | C5: ORBIT 53 | D5: {=IFERROR(VLOOKUP($C5&D$2,{MASTER!$Y$2:$Y992,MASTER!$F$2:$F992},2,0),"")} -> 1390 | E5: {=IFERROR(VLOOKUP($C5&E$2,{MASTER!$Y$2:$Y992,MASTER!$F$2:$F992},2,0),"")} | F5: {=IFERROR(VLOOKUP($C5&F$2,{MASTER!$Y$2:$Y992,MASTER!$F$2:$F992},2,0),"")} | G5: {=IFERROR(VLOOKUP($C5&G$2,{MASTER!$Y$2:$Y992,MASTER!$F$2:$F992},2,0),"")} | H5: {=IFERROR(VLOOKUP($C5&H$2,{MASTER!$Y$2:$Y992,MASTER!$F$2:$F992},2,0),"")} | I5: {=IFERROR(VLOOKUP($C5&I$2,{MASTER!$Y$2:$Y992,MASTER!$F$2:$F992},2,0),"")} -> 1140 | J5: {=IFERROR(VLOOKUP($C5&J$2,{MASTER!$Y$2:$Y992,MASTER!$F$2:$F992},2,0),"")} -> 2840 | K5: {=IFERROR(VLOOKUP($C5&K$2,{MASTER!$Y$2:$Y992,MASTER!$F$2:$F992},2,0),"")} -> 1490 | ... BB5: {=IFERROR(VLOOKUP($C5&BB$2,{MASTER!$Y$2:$Y992,MASTER!$F$2:$F992},2,0),"")} -> 2380
A6: =COUNT(D6:BB6) -> 34 | C6: AQUA 54 | D6: {=IFERROR(VLOOKUP($C6&D$2,{MASTER!$Y$2:$Y992,MASTER!$F$2:$F992},2,0),"")} -> 1590 | E6: {=IFERROR(VLOOKUP($C6&E$2,{MASTER!$Y$2:$Y992,MASTER!$F$2:$F992},2,0),"")} | F6: {=IFERROR(VLOOKUP($C6&F$2,{MASTER!$Y$2:$Y992,MASTER!$F$2:$F992},2,0),"")} | G6: {=IFERROR(VLOOKUP($C6&G$2,{MASTER!$Y$2:$Y992,MASTER!$F$2:$F992},2,0),"")} -> 2440 | H6: {=IFERROR(VLOOKUP($C6&H$2,{MASTER!$Y$2:$Y992,MASTER!$F$2:$F992},2,0),"")} | I6: {=IFERROR(VLOOKUP($C6&I$2,{MASTER!$Y$2:$Y992,MASTER!$F$2:$F992},2,0),"")} -> 1540 | J6: {=IFERROR(VLOOKUP($C6&J$2,{MASTER!$Y$2:$Y992,MASTER!$F$2:$F992},2,0),"")} -> 2850 | K6: {=IFERROR(VLOOKUP($C6&K$2,{MASTER!$Y$2:$Y992,MASTER!$F$2:$F992},2,0),"")} -> 1490 | ... BB6: {=IFERROR(VLOOKUP($C6&BB$2,{MASTER!$Y$2:$Y992,MASTER!$F$2:$F992},2,0),"")} -> 2480
A7: =COUNT(D7:BB7) -> 34 | C7: OCEAN 55 | D7: {=IFERROR(VLOOKUP($C7&D$2,{MASTER!$Y$2:$Y992,MASTER!$F$2:$F992},2,0),"")} -> 1640 | E7: {=IFERROR(VLOOKUP($C7&E$2,{MASTER!$Y$2:$Y992,MASTER!$F$2:$F992},2,0),"")} | F7: {=IFERROR(VLOOKUP($C7&F$2,{MASTER!$Y$2:$Y992,MASTER!$F$2:$F992},2,0),"")} | G7: {=IFERROR(VLOOKUP($C7&G$2,{MASTER!$Y$2:$Y992,MASTER!$F$2:$F992},2,0),"")} -> 2460 | H7: {=IFERROR(VLOOKUP($C7&H$2,{MASTER!$Y$2:$Y992,MASTER!$F$2:$F992},2,0),"")} | I7: {=IFERROR(VLOOKUP($C7&I$2,{MASTER!$Y$2:$Y992,MASTER!$F$2:$F992},2,0),"")} -> 1490 | J7: {=IFERROR(VLOOKUP($C7&J$2,{MASTER!$Y$2:$Y992,MASTER!$F$2:$F992},2,0),"")} -> 2850 | K7: {=IFERROR(VLOOKUP($C7&K$2,{MASTER!$Y$2:$Y992,MASTER!$F$2:$F992},2,0),"")} -> 1490 | ... BB7: {=IFERROR(VLOOKUP($C7&BB$2,{MASTER!$Y$2:$Y992,MASTER!$F$2:$F992},2,0),"")} -> 2340
A8: =COUNT(D8:BB8) -> 33 | B8: 6000 | C8: POLO 60 | D8: {=IFERROR(VLOOKUP($C8&D$2,{MASTER!$Y$2:$Y992,MASTER!$F$2:$F992},2,0),"")} -> 1940 | E8: {=IFERROR(VLOOKUP($C8&E$2,{MASTER!$Y$2:$Y992,MASTER!$F$2:$F992},2,0),"")} | F8: {=IFERROR(VLOOKUP($C8&F$2,{MASTER!$Y$2:$Y992,MASTER!$F$2:$F992},2,0),"")} | G8: {=IFERROR(VLOOKUP($C8&G$2,{MASTER!$Y$2:$Y992,MASTER!$F$2:$F992},2,0),"")} -> 2680 | H8: {=IFERROR(VLOOKUP($C8&H$2,{MASTER!$Y$2:$Y992,MASTER!$F$2:$F992},2,0),"")} | I8: {=IFERROR(VLOOKUP($C8&I$2,{MASTER!$Y$2:$Y992,MASTER!$F$2:$F992},2,0),"")} -> 1580 | J8: {=IFERROR(VLOOKUP($C8&J$2,{MASTER!$Y$2:$Y992,MASTER!$F$2:$F992},2,0),"")} -> 2880 | K8: {=IFERROR(VLOOKUP($C8&K$2,{MASTER!$Y$2:$Y992,MASTER!$F$2:$F992},2,0),"")} -> 1490 | ... BB8: {=IFERROR(VLOOKUP($C8&BB$2,{MASTER!$Y$2:$Y992,MASTER!$F$2:$F992},2,0),"")} -> 2640
A9: =COUNT(D9:BB9) -> 0 | C9: EMERALD 61 | D9: {=IFERROR(VLOOKUP($C9&D$2,{MASTER!$Y$2:$Y992,MASTER!$F$2:$F992},2,0),"")} -> REMOVED | E9: {=IFERROR(VLOOKUP($C9&E$2,{MASTER!$Y$2:$Y992,MASTER!$F$2:$F992},2,0),"")} -> REMOVED | F9: {=IFERROR(VLOOKUP($C9&F$2,{MASTER!$Y$2:$Y992,MASTER!$F$2:$F992},2,0),"")} -> REMOVED | G9: {=IFERROR(VLOOKUP($C9&G$2,{MASTER!$Y$2:$Y992,MASTER!$F$2:$F992},2,0),"")} -> REMOVED | H9: {=IFERROR(VLOOKUP($C9&H$2,{MASTER!$Y$2:$Y992,MASTER!$F$2:$F992},2,0),"")} | I9: {=IFERROR(VLOOKUP($C9&I$2,{MASTER!$Y$2:$Y992,MASTER!$F$2:$F992},2,0),"")} -> REMOVED | J9: {=IFERROR(VLOOKUP($C9&J$2,{MASTER!$Y$2:$Y992,MASTER!$F$2:$F992},2,0),"")} -> REMOVED | K9: {=IFERROR(VLOOKUP($C9&K$2,{MASTER!$Y$2:$Y992,MASTER!$F$2:$F992},2,0),"")} -> REMOVED | ... BB9: {=IFERROR(VLOOKUP($C9&BB$2,{MASTER!$Y$2:$Y992,MASTER!$F$2:$F992},2,0),"")} -> REMOVED
A10: =COUNT(D10:BB10) -> 33 | C10: BLAZE 62 | D10: {=IFERROR(VLOOKUP($C10&D$2,{MASTER!$Y$2:$Y992,MASTER!$F$2:$F992},2,0),"")} -> 1880 | E10: {=IFERROR(VLOOKUP($C10&E$2,{MASTER!$Y$2:$Y992,MASTER!$F$2:$F992},2,0),"")} | F10: {=IFERROR(VLOOKUP($C10&F$2,{MASTER!$Y$2:$Y992,MASTER!$F$2:$F992},2,0),"")} | G10: {=IFERROR(VLOOKUP($C10&G$2,{MASTER!$Y$2:$Y992,MASTER!$F$2:$F992},2,0),"")} -> 2580 | H10: {=IFERROR(VLOOKUP($C10&H$2,{MASTER!$Y$2:$Y992,MASTER!$F$2:$F992},2,0),"")} | I10: {=IFERROR(VLOOKUP($C10&I$2,{MASTER!$Y$2:$Y992,MASTER!$F$2:$F992},2,0),"")} -> 1580 | J10: {=IFERROR(VLOOKUP($C10&J$2,{MASTER!$Y$2:$Y992,MASTER!$F$2:$F992},2,0),"")} -> 2880 | K10: {=IFERROR(VLOOKUP($C10&K$2,{MASTER!$Y$2:$Y992,MASTER!$F$2:$F992},2,0),"")} -> 1490 | ... BB10: {=IFERROR(VLOOKUP($C10&BB$2,{MASTER!$Y$2:$Y992,MASTER!$F$2:$F992},2,0),"")} -> 2350
A11: =COUNT(D11:BB11) -> 37 | C11: VINCENT 66 | D11: {=IFERROR(VLOOKUP($C11&D$2,{MASTER!$Y$2:$Y992,MASTER!$F$2:$F992},2,0),"")} -> 1960 | E11: {=IFERROR(VLOOKUP($C11&E$2,{MASTER!$Y$2:$Y992,MASTER!$F$2:$F992},2,0),"")} -> 3930 | F11: {=IFERROR(VLOOKUP($C11&F$2,{MASTER!$Y$2:$Y992,MASTER!$F$2:$F992},2,0),"")} -> 3940 | G11: {=IFERROR(VLOOKUP($C11&G$2,{MASTER!$Y$2:$Y992,MASTER!$F$2:$F992},2,0),"")} -> 2640 | H11: {=IFERROR(VLOOKUP($C11&H$2,{MASTER!$Y$2:$Y992,MASTER!$F$2:$F992},2,0),"")} -> 1390 | I11: {=IFERROR(VLOOKUP($C11&I$2,{MASTER!$Y$2:$Y992,MASTER!$F$2:$F992},2,0),"")} -> 1640 | J11: {=IFERROR(VLOOKUP($C11&J$2,{MASTER!$Y$2:$Y992,MASTER!$F$2:$F992},2,0),"")} -> 2880 | K11: {=IFERROR(VLOOKUP($C11&K$2,{MASTER!$Y$2:$Y992,MASTER!$F$2:$F992},2,0),"")} -> 1490 | ... BB11: {=IFERROR(VLOOKUP($C11&BB$2,{MASTER!$Y$2:$Y992,MASTER!$F$2:$F992},2,0),"")} -> 2580
A12: =COUNT(D12:BB12) -> 39 | C12: MARCUS 68 | D12: {=IFERROR(VLOOKUP($C12&D$2,{MASTER!$Y$2:$Y992,MASTER!$F$2:$F992},2,0),"")} -> 1920 | E12: {=IFERROR(VLOOKUP($C12&E$2,{MASTER!$Y$2:$Y992,MASTER!$F$2:$F992},2,0),"")} -> 3980 | F12: {=IFERROR(VLOOKUP($C12&F$2,{MASTER!$Y$2:$Y992,MASTER!$F$2:$F992},2,0),"")} -> 3680 | G12: {=IFERROR(VLOOKUP($C12&G$2,{MASTER!$Y$2:$Y992,MASTER!$F$2:$F992},2,0),"")} -> 2440 | H12: {=IFERROR(VLOOKUP($C12&H$2,{MASTER!$Y$2:$Y992,MASTER!$F$2:$F992},2,0),"")} -> 1690 | I12: {=IFERROR(VLOOKUP($C12&I$2,{MASTER!$Y$2:$Y992,MASTER!$F$2:$F992},2,0),"")} -> 1580 | J12: {=IFERROR(VLOOKUP($C12&J$2,{MASTER!$Y$2:$Y992,MASTER!$F$2:$F992},2,0),"")} -> 2880 | K12: {=IFERROR(VLOOKUP($C12&K$2,{MASTER!$Y$2:$Y992,MASTER!$F$2:$F992},2,0),"")} -> 1490 | ... BB12: {=IFERROR(VLOOKUP($C12&BB$2,{MASTER!$Y$2:$Y992,MASTER!$F$2:$F992},2,0),"")} -> 2490
A13: =COUNT(D13:BB13) -> 34 | C13: VIRGO P66 | D13: {=IFERROR(VLOOKUP($C13&D$2,{MASTER!$Y$2:$Y992,MASTER!$F$2:$F992},2,0),"")} -> 1640 | E13: {=IFERROR(VLOOKUP($C13&E$2,{MASTER!$Y$2:$Y992,MASTER!$F$2:$F992},2,0),"")} -> 4110 | F13: {=IFERROR(VLOOKUP($C13&F$2,{MASTER!$Y$2:$Y992,MASTER!$F$2:$F992},2,0),"")} | G13: {=IFERROR(VLOOKUP($C13&G$2,{MASTER!$Y$2:$Y992,MASTER!$F$2:$F992},2,0),"")} | H13: {=IFERROR(VLOOKUP($C13&H$2,{MASTER!$Y$2:$Y992,MASTER!$F$2:$F992},2,0),"")} -> 1430 | I13: {=IFERROR(VLOOKUP($C13&I$2,{MASTER!$Y$2:$Y992,MASTER!$F$2:$F992},2,0),"")} -> 1410 | J13: {=IFERROR(VLOOKUP($C13&J$2,{MASTER!$Y$2:$Y992,MASTER!$F$2:$F992},2,0),"")} -> 2880 | K13: {=IFERROR(VLOOKUP($C13&K$2,{MASTER!$Y$2:$Y992,MASTER!$F$2:$F992},2,0),"")} -> 1490 | ... BB13: {=IFERROR(VLOOKUP($C13&BB$2,{MASTER!$Y$2:$Y992,MASTER!$F$2:$F992},2,0),"")} -> 2490
A14: =COUNT(D14:BB14) -> 0 | C14: NEW 69 | D14: {=IFERROR(VLOOKUP($C14&D$2,{MASTER!$Y$2:$Y992,MASTER!$F$2:$F992},2,0),"")} | E14: {=IFERROR(VLOOKUP($C14&E$2,{MASTER!$Y$2:$Y992,MASTER!$F$2:$F992},2,0),"")} | F14: {=IFERROR(VLOOKUP($C14&F$2,{MASTER!$Y$2:$Y992,MASTER!$F$2:$F992},2,0),"")} | G14: {=IFERROR(VLOOKUP($C14&G$2,{MASTER!$Y$2:$Y992,MASTER!$F$2:$F992},2,0),"")} | H14: {=IFERROR(VLOOKUP($C14&H$2,{MASTER!$Y$2:$Y992,MASTER!$F$2:$F992},2,0),"")} | I14: {=IFERROR(VLOOKUP($C14&I$2,{MASTER!$Y$2:$Y992,MASTER!$F$2:$F992},2,0),"")} | J14: {=IFERROR(VLOOKUP($C14&J$2,{MASTER!$Y$2:$Y992,MASTER!$F$2:$F992},2,0),"")} | K14: {=IFERROR(VLOOKUP($C14&K$2,{MASTER!$Y$2:$Y992,MASTER!$F$2:$F992},2,0),"")} | ... BB14: {=IFERROR(VLOOKUP($C14&BB$2,{MASTER!$Y$2:$Y992,MASTER!$F$2:$F992},2,0),"")}
A15: =COUNT(D15:BB15) -> 30 | B15: 7000 | C15: CYGNUS 71 | D15: {=IFERROR(VLOOKUP($C15&D$2,{MASTER!$Y$2:$Y992,MASTER!$F$2:$F992},2,0),"")} -> 2590 | E15: {=IFERROR(VLOOKUP($C15&E$2,{MASTER!$Y$2:$Y992,MASTER!$F$2:$F992},2,0),"")} -> 5480 | F15: {=IFERROR(VLOOKUP($C15&F$2,{MASTER!$Y$2:$Y992,MASTER!$F$2:$F992},2,0),"")} | G15: {=IFERROR(VLOOKUP($C15&G$2,{MASTER!$Y$2:$Y992,MASTER!$F$2:$F992},2,0),"")} -> 3180 | H15: {=IFERROR(VLOOKUP($C15&H$2,{MASTER!$Y$2:$Y992,MASTER!$F$2:$F992},2,0),"")} | I15: {=IFERROR(VLOOKUP($C15&I$2,{MASTER!$Y$2:$Y992,MASTER!$F$2:$F992},2,0),"")} -> 2270 | J15: {=IFERROR(VLOOKUP($C15&J$2,{MASTER!$Y$2:$Y992,MASTER!$F$2:$F992},2,0),"")} | K15: {=IFERROR(VLOOKUP($C15&K$2,{MASTER!$Y$2:$Y992,MASTER!$F$2:$F992},2,0),"")} | ... BB15: {=IFERROR(VLOOKUP($C15&BB$2,{MASTER!$Y$2:$Y992,MASTER!$F$2:$F992},2,0),"")} -> 3080
A16: =COUNT(D16:BB16) -> 20 | C16: VIVA 72 | D16: {=IFERROR(VLOOKUP($C16&D$2,{MASTER!$Y$2:$Y992,MASTER!$F$2:$F992},2,0),"")} -> 1640 | E16: {=IFERROR(VLOOKUP($C16&E$2,{MASTER!$Y$2:$Y992,MASTER!$F$2:$F992},2,0),"")} | F16: {=IFERROR(VLOOKUP($C16&F$2,{MASTER!$Y$2:$Y992,MASTER!$F$2:$F992},2,0),"")} | G16: {=IFERROR(VLOOKUP($C16&G$2,{MASTER!$Y$2:$Y992,MASTER!$F$2:$F992},2,0),"")} | H16: {=IFERROR(VLOOKUP($C16&H$2,{MASTER!$Y$2:$Y992,MASTER!$F$2:$F992},2,0),"")} -> 1490 | I16: {=IFERROR(VLOOKUP($C16&I$2,{MASTER!$Y$2:$Y992,MASTER!$F$2:$F992},2,0),"")} -> 1490 | J16: {=IFERROR(VLOOKUP($C16&J$2,{MASTER!$Y$2:$Y992,MASTER!$F$2:$F992},2,0),"")} | K16: {=IFERROR(VLOOKUP($C16&K$2,{MASTER!$Y$2:$Y992,MASTER!$F$2:$F992},2,0),"")} | ... BB16: {=IFERROR(VLOOKUP($C16&BB$2,{MASTER!$Y$2:$Y992,MASTER!$F$2:$F992},2,0),"")} -> 2520
A17: =COUNT(D17:BB17) -> 20 | C17: TRANQUIL 73 | D17: {=IFERROR(VLOOKUP($C17&D$2,{MASTER!$Y$2:$Y992,MASTER!$F$2:$F992},2,0),"")} -> 1670 | E17: {=IFERROR(VLOOKUP($C17&E$2,{MASTER!$Y$2:$Y992,MASTER!$F$2:$F992},2,0),"")} | F17: {=IFERROR(VLOOKUP($C17&F$2,{MASTER!$Y$2:$Y992,MASTER!$F$2:$F992},2,0),"")} | G17: {=IFERROR(VLOOKUP($C17&G$2,{MASTER!$Y$2:$Y992,MASTER!$F$2:$F992},2,0),"")} | H17: {=IFERROR(VLOOKUP($C17&H$2,{MASTER!$Y$2:$Y992,MASTER!$F$2:$F992},2,0),"")} -> 1550 | I17: {=IFERROR(VLOOKUP($C17&I$2,{MASTER!$Y$2:$Y992,MASTER!$F$2:$F992},2,0),"")} -> 1540 | J17: {=IFERROR(VLOOKUP($C17&J$2,{MASTER!$Y$2:$Y992,MASTER!$F$2:$F992},2,0),"")} | K17: {=IFERROR(VLOOKUP($C17&K$2,{MASTER!$Y$2:$Y992,MASTER!$F$2:$F992},2,0),"")} | ... BB17: {=IFERROR(VLOOKUP($C17&BB$2,{MASTER!$Y$2:$Y992,MASTER!$F$2:$F992},2,0),"")} -> 2580
A18: =COUNT(D18:BB18) -> 21 | C18: GRACIA 74 | D18: {=IFERROR(VLOOKUP($C18&D$2,{MASTER!$Y$2:$Y992,MASTER!$F$2:$F992},2,0),"")} -> 1990 | E18: {=IFERROR(VLOOKUP($C18&E$2,{MASTER!$Y$2:$Y992,MASTER!$F$2:$F992},2,0),"")} -> 3990 | F18: {=IFERROR(VLOOKUP($C18&F$2,{MASTER!$Y$2:$Y992,MASTER!$F$2:$F992},2,0),"")} | G18: {=IFERROR(VLOOKUP($C18&G$2,{MASTER!$Y$2:$Y992,MASTER!$F$2:$F992},2,0),"")} -> 2690 | H18: {=IFERROR(VLOOKUP($C18&H$2,{MASTER!$Y$2:$Y992,MASTER!$F$2:$F992},2,0),"")} | I18: {=IFERROR(VLOOKUP($C18&I$2,{MASTER!$Y$2:$Y992,MASTER!$F$2:$F992},2,0),"")} -> 1740 | J18: {=IFERROR(VLOOKUP($C18&J$2,{MASTER!$Y$2:$Y992,MASTER!$F$2:$F992},2,0),"")} -> 2880 | K18: {=IFERROR(VLOOKUP($C18&K$2,{MASTER!$Y$2:$Y992,MASTER!$F$2:$F992},2,0),"")} -> 1490 | ... BB18: {=IFERROR(VLOOKUP($C18&BB$2,{MASTER!$Y$2:$Y992,MASTER!$F$2:$F992},2,0),"")} -> 2380
A19: =COUNT(D19:BB19) -> 38 | C19: MACASA 76 | D19: {=IFERROR(VLOOKUP($C19&D$2,{MASTER!$Y$2:$Y992,MASTER!$F$2:$F992},2,0),"")} -> 1880 | E19: {=IFERROR(VLOOKUP($C19&E$2,{MASTER!$Y$2:$Y992,MASTER!$F$2:$F992},2,0),"")} -> 3880 | F19: {=IFERROR(VLOOKUP($C19&F$2,{MASTER!$Y$2:$Y992,MASTER!$F$2:$F992},2,0),"")} | G19: {=IFERROR(VLOOKUP($C19&G$2,{MASTER!$Y$2:$Y992,MASTER!$F$2:$F992},2,0),"")} -> 2490 | H19: {=IFERROR(VLOOKUP($C19&H$2,{MASTER!$Y$2:$Y992,MASTER!$F$2:$F992},2,0),"")} | I19: {=IFERROR(VLOOKUP($C19&I$2,{MASTER!$Y$2:$Y992,MASTER!$F$2:$F992},2,0),"")} -> 1490 | J19: {=IFERROR(VLOOKUP($C19&J$2,{MASTER!$Y$2:$Y992,MASTER!$F$2:$F992},2,0),"")} -> 2880 | K19: {=IFERROR(VLOOKUP($C19&K$2,{MASTER!$Y$2:$Y992,MASTER!$F$2:$F992},2,0),"")} -> 1490 | ... BB19: {=IFERROR(VLOOKUP($C19&BB$2,{MASTER!$Y$2:$Y992,MASTER!$F$2:$F992},2,0),"")} -> 2350
